
TEST CASE 1 Retry 0
---------------
from sqlalchemy.dialects.postgresql import JSONB, UUID
from sqlalchemy import (
    Column,
    Integer,
    String,
    TIMESTAMP,
    create_engine,
    Float,
    ForeignKey,
    Text,
    UniqueConstraint,
)
from sqlalchemy.ext.declarative import declarative_base
from sqlalchemy.sql import func
import uuid
from theory_evaluation.models import Base, ConsultantChat, CurrentUserTable, Curriculum, MentorChat, Projects, SprintIssues, TheoryEvalUserPerformance, UserInfo, UserRepo, UserScoreLog
import pytest

@pytest.fixture(scope="module")
def engine():
    return create_engine("sqlite:///:memory:")

@pytest.fixture(scope="module")
def tables(engine):
    Base.metadata.create_all(engine)
    yield
    Base.metadata.drop_all(engine)

@pytest.fixture(scope="function")
def session(engine, tables):
    connection = engine.connect()
    transaction = connection.begin()
    Session = sessionmaker(bind=connection)
    session = Session()
    yield session
    session.close()
    transaction.rollback()
    connection.close()

def test_user_info_creation(session):
    user = UserInfo(
        first_name="John",
        last_name="Doe",
        email="john.doe@example.com",
        github_username="johndoe",
        status=1
    )
    session.add(user)
    session.commit()
    retrieved_user = session.query(UserInfo).filter_by(email="john.doe@example.com").first()
    assert retrieved_user is not None
    assert retrieved_user.first_name == "John"
    assert retrieved_user.last_name == "Doe"

---------------
TEST CASE 1 Retry 0 - Result - Failed
Test Error -
c:\ChenKhoon\JupyterNotebook\GenerateUnitTestCases\unit_test_env\Lib\site-packages\pytest_asyncio\plugin.py:217: PytestDeprecationWarning: The configuration option "asyncio_default_fixture_loop_scope" is unset.
The event loop scope for asynchronous fixtures will default to the fixture caching scope. Future versions of pytest-asyncio will default the loop scope for asynchronous fixtures to function scope. Set the default fixture loop scope explicitly in order to avoid unexpected behavior in the future. Valid fixture loop scopes are: "function", "class", "module", "package", "session"

  warnings.warn(PytestDeprecationWarning(_DEFAULT_FIXTURE_LOOP_SCOPE_UNSET))
E                                                                        [100%]
=================================== ERRORS ====================================
__________________ ERROR at setup of test_user_info_creation __________________
unit_test_env\Lib\site-packages\sqlalchemy\sql\visitors.py:137: in _compiler_dispatch
    meth = getter(visitor)
E   AttributeError: 'SQLiteTypeCompiler' object has no attribute 'visit_JSONB'. Did you mean: 'visit_JSON'?

The above exception was the direct cause of the following exception:
unit_test_env\Lib\site-packages\sqlalchemy\sql\compiler.py:6716: in visit_create_table
    processed = self.process(
unit_test_env\Lib\site-packages\sqlalchemy\sql\compiler.py:932: in process
    return obj._compiler_dispatch(self, **kwargs)
unit_test_env\Lib\site-packages\sqlalchemy\sql\visitors.py:141: in _compiler_dispatch
    return meth(self, **kw)  # type: ignore  # noqa: E501
unit_test_env\Lib\site-packages\sqlalchemy\sql\compiler.py:6747: in visit_create_column
    text = self.get_column_specification(column, first_pk=first_pk)
unit_test_env\Lib\site-packages\sqlalchemy\dialects\sqlite\base.py:1598: in get_column_specification
    coltype = self.dialect.type_compiler_instance.process(
unit_test_env\Lib\site-packages\sqlalchemy\sql\compiler.py:977: in process
    return type_._compiler_dispatch(self, **kw)
unit_test_env\Lib\site-packages\sqlalchemy\sql\visitors.py:139: in _compiler_dispatch
    return visitor.visit_unsupported_compilation(self, err, **kw)  # type: ignore  # noqa: E501
unit_test_env\Lib\site-packages\sqlalchemy\sql\compiler.py:982: in visit_unsupported_compilation
    raise exc.UnsupportedCompilationError(self, element) from err
E   sqlalchemy.exc.UnsupportedCompilationError: Compiler <sqlalchemy.dialects.sqlite.base.SQLiteTypeCompiler object at 0x000002052C49FB60> can't render element of type JSONB (Background on this error at: https://sqlalche.me/e/20/l7de)

The above exception was the direct cause of the following exception:
temp\temp.py:25: in tables
    Base.metadata.create_all(engine)
unit_test_env\Lib\site-packages\sqlalchemy\sql\schema.py:5925: in create_all
    bind._run_ddl_visitor(
unit_test_env\Lib\site-packages\sqlalchemy\engine\base.py:3249: in _run_ddl_visitor
    conn._run_ddl_visitor(visitorcallable, element, **kwargs)
unit_test_env\Lib\site-packages\sqlalchemy\engine\base.py:2456: in _run_ddl_visitor
    visitorcallable(self.dialect, self, **kwargs).traverse_single(element)
unit_test_env\Lib\site-packages\sqlalchemy\sql\visitors.py:664: in traverse_single
    return meth(obj, **kw)
unit_test_env\Lib\site-packages\sqlalchemy\sql\ddl.py:981: in visit_metadata
    self.traverse_single(
unit_test_env\Lib\site-packages\sqlalchemy\sql\visitors.py:664: in traverse_single
    return meth(obj, **kw)
unit_test_env\Lib\site-packages\sqlalchemy\sql\ddl.py:1019: in visit_table
    )._invoke_with(self.connection)
unit_test_env\Lib\site-packages\sqlalchemy\sql\ddl.py:321: in _invoke_with
    return bind.execute(self)
unit_test_env\Lib\site-packages\sqlalchemy\engine\base.py:1416: in execute
    return meth(
unit_test_env\Lib\site-packages\sqlalchemy\sql\ddl.py:187: in _execute_on_connection
    return connection._execute_ddl(
unit_test_env\Lib\site-packages\sqlalchemy\engine\base.py:1524: in _execute_ddl
    compiled = ddl.compile(
unit_test_env\Lib\site-packages\sqlalchemy\sql\elements.py:308: in compile
    return self._compiler(dialect, **kw)
unit_test_env\Lib\site-packages\sqlalchemy\sql\ddl.py:76: in _compiler
    return dialect.ddl_compiler(dialect, self, **kw)
unit_test_env\Lib\site-packages\sqlalchemy\sql\compiler.py:886: in __init__
    self.string = self.process(self.statement, **compile_kwargs)
unit_test_env\Lib\site-packages\sqlalchemy\sql\compiler.py:932: in process
    return obj._compiler_dispatch(self, **kwargs)
unit_test_env\Lib\site-packages\sqlalchemy\sql\visitors.py:141: in _compiler_dispatch
    return meth(self, **kw)  # type: ignore  # noqa: E501
unit_test_env\Lib\site-packages\sqlalchemy\sql\compiler.py:6726: in visit_create_table
    raise exc.CompileError(
E   sqlalchemy.exc.CompileError: (in table 'projects', column 'problem_statement'): Compiler <sqlalchemy.dialects.sqlite.base.SQLiteTypeCompiler object at 0x000002052C49FB60> can't render element of type JSONB
============================== warnings summary ===============================
theory_evaluation\models.py:17
  C:\ChenKhoon\JupyterNotebook\GenerateUnitTestCases\theory_evaluation\models.py:17: MovedIn20Warning: The ``declarative_base()`` function is now available as sqlalchemy.orm.declarative_base(). (deprecated since: 2.0) (Background on SQLAlchemy 2.0 at: https://sqlalche.me/e/b8d9)
    Base = declarative_base()

-- Docs: https://docs.pytest.org/en/stable/how-to/capture-warnings.html
=========================== short test summary info ===========================
ERROR temp/temp.py::test_user_info_creation - sqlalchemy.exc.CompileError: (i...
1 warning, 1 error in 1.43s
TEST CASE 1 Retry 1
---------------
from sqlalchemy.dialects.postgresql import JSONB, UUID
from sqlalchemy import (
    Column,
    Integer,
    String,
    TIMESTAMP,
    create_engine,
    Float,
    ForeignKey,
    Text,
    UniqueConstraint,
)
from sqlalchemy.ext.declarative import declarative_base
from sqlalchemy.sql import func
import uuid
from theory_evaluation.models import Base, ConsultantChat, CurrentUserTable, Curriculum, MentorChat, Projects, SprintIssues, TheoryEvalUserPerformance, UserInfo, UserRepo, UserScoreLog
import pytest

@pytest.fixture(scope="module")
def engine():
    return create_engine("sqlite:///:memory:")

@pytest.fixture(scope="module")
def tables(engine):
    Base.metadata.create_all(engine)
    yield
    Base.metadata.drop_all(engine)

@pytest.fixture(scope="function")
def session(engine, tables):
    connection = engine.connect()
    transaction = connection.begin()
    Session = sessionmaker(bind=connection)
    session = Session()
    yield session
    session.close()
    transaction.rollback()
    connection.close()

import pytest
from sqlalchemy import create_engine
from sqlalchemy.orm import sessionmaker
from your_module import UserInfo, Base  # Assuming the source code is in 'your_module'

# Setup the database engine and session
engine = create_engine('postgresql://user:password@localhost/testdb')  # Use PostgreSQL
Base.metadata.create_all(engine)
Session = sessionmaker(bind=engine)

@pytest.fixture
def session():
    session = Session()
    yield session
    session.close()

def test_user_info_creation(session):
    user = UserInfo(
        first_name="John",
        last_name="Doe",
        email="john.doe@example.com",
        github_username="johndoe",
        status=1
    )
    session.add(user)
    session.commit()
    retrieved_user = session.query(UserInfo).filter_by(email="john.doe@example.com").first()
    assert retrieved_user is not None
    assert retrieved_user.first_name == "John"
    assert retrieved_user.last_name == "Doe"

---------------
TEST CASE 1 Retry 1 - Result - Failed
Test Error -
c:\ChenKhoon\JupyterNotebook\GenerateUnitTestCases\unit_test_env\Lib\site-packages\pytest_asyncio\plugin.py:217: PytestDeprecationWarning: The configuration option "asyncio_default_fixture_loop_scope" is unset.
The event loop scope for asynchronous fixtures will default to the fixture caching scope. Future versions of pytest-asyncio will default the loop scope for asynchronous fixtures to function scope. Set the default fixture loop scope explicitly in order to avoid unexpected behavior in the future. Valid fixture loop scopes are: "function", "class", "module", "package", "session"

  warnings.warn(PytestDeprecationWarning(_DEFAULT_FIXTURE_LOOP_SCOPE_UNSET))

=================================== ERRORS ====================================
________________________ ERROR collecting temp/temp.py ________________________
ImportError while importing test module 'C:\ChenKhoon\JupyterNotebook\GenerateUnitTestCases\temp\temp.py'.
Hint: make sure your test modules/packages have valid Python names.
Traceback:
C:\Users\User\AppData\Local\Programs\Python\Python313\Lib\importlib\__init__.py:88: in import_module
    return _bootstrap._gcd_import(name[level:], package, level)
temp\temp.py:43: in <module>
    from your_module import UserInfo, Base  # Assuming the source code is in 'your_module'
E   ModuleNotFoundError: No module named 'your_module'
============================== warnings summary ===============================
theory_evaluation\models.py:17
  C:\ChenKhoon\JupyterNotebook\GenerateUnitTestCases\theory_evaluation\models.py:17: MovedIn20Warning: The ``declarative_base()`` function is now available as sqlalchemy.orm.declarative_base(). (deprecated since: 2.0) (Background on SQLAlchemy 2.0 at: https://sqlalche.me/e/b8d9)
    Base = declarative_base()

-- Docs: https://docs.pytest.org/en/stable/how-to/capture-warnings.html
=========================== short test summary info ===========================
ERROR temp/temp.py
!!!!!!!!!!!!!!!!!!! Interrupted: 1 error during collection !!!!!!!!!!!!!!!!!!!!
1 warning, 1 error in 0.88s
TEST CASE 1 Retry 2
---------------
from sqlalchemy.dialects.postgresql import JSONB, UUID
from sqlalchemy import (
    Column,
    Integer,
    String,
    TIMESTAMP,
    create_engine,
    Float,
    ForeignKey,
    Text,
    UniqueConstraint,
)
from sqlalchemy.ext.declarative import declarative_base
from sqlalchemy.sql import func
import uuid
from theory_evaluation.models import Base, ConsultantChat, CurrentUserTable, Curriculum, MentorChat, Projects, SprintIssues, TheoryEvalUserPerformance, UserInfo, UserRepo, UserScoreLog
import pytest

@pytest.fixture(scope="module")
def engine():
    return create_engine("sqlite:///:memory:")

@pytest.fixture(scope="module")
def tables(engine):
    Base.metadata.create_all(engine)
    yield
    Base.metadata.drop_all(engine)

@pytest.fixture(scope="function")
def session(engine, tables):
    connection = engine.connect()
    transaction = connection.begin()
    Session = sessionmaker(bind=connection)
    session = Session()
    yield session
    session.close()
    transaction.rollback()
    connection.close()

import pytest
from sqlalchemy import create_engine
from sqlalchemy.orm import sessionmaker
from sqlalchemy.ext.declarative import declarative_base
from sqlalchemy.dialects.postgresql import JSONB, UUID
from sqlalchemy import Column, Integer, String, TIMESTAMP, Float, ForeignKey, Text, UniqueConstraint
import uuid

Base = declarative_base()

class UserInfo(Base):
    __tablename__ = "user_info"
    id = Column(Integer, primary_key=True, index=True)
    first_name = Column(String(50))
    last_name = Column(String(50))
    email = Column(String(100), unique=True, nullable=False)
    github_username = Column(String(50), nullable=False)
    payment_date = Column(TIMESTAMP(timezone=True))
    current_duration = Column(Integer)
    course_duration = Column(Integer)
    end_date = Column(TIMESTAMP(timezone=True))
    status = Column(Integer)

# Setup the database engine and session
engine = create_engine('postgresql://user:password@localhost/testdb')  # Use PostgreSQL
Base.metadata.create_all(engine)
Session = sessionmaker(bind=engine)

@pytest.fixture
def session():
    session = Session()
    yield session
    session.close()

def test_user_info_creation(session):
    user = UserInfo(
        first_name="John",
        last_name="Doe",
        email="john.doe@example.com",
        github_username="johndoe",
        status=1
    )
    session.add(user)
    session.commit()
    retrieved_user = session.query(UserInfo).filter_by(email="john.doe@example.com").first()
    assert retrieved_user is not None
    assert retrieved_user.first_name == "John"
    assert retrieved_user.last_name == "Doe"

---------------
TEST CASE 1 Retry 2 - Result - Failed
Test Error -
c:\ChenKhoon\JupyterNotebook\GenerateUnitTestCases\unit_test_env\Lib\site-packages\pytest_asyncio\plugin.py:217: PytestDeprecationWarning: The configuration option "asyncio_default_fixture_loop_scope" is unset.
The event loop scope for asynchronous fixtures will default to the fixture caching scope. Future versions of pytest-asyncio will default the loop scope for asynchronous fixtures to function scope. Set the default fixture loop scope explicitly in order to avoid unexpected behavior in the future. Valid fixture loop scopes are: "function", "class", "module", "package", "session"

  warnings.warn(PytestDeprecationWarning(_DEFAULT_FIXTURE_LOOP_SCOPE_UNSET))

=================================== ERRORS ====================================
________________________ ERROR collecting temp/temp.py ________________________
ImportError while importing test module 'C:\ChenKhoon\JupyterNotebook\GenerateUnitTestCases\temp\temp.py'.
Hint: make sure your test modules/packages have valid Python names.
Traceback:
C:\Users\User\AppData\Local\Programs\Python\Python313\Lib\importlib\__init__.py:88: in import_module
    return _bootstrap._gcd_import(name[level:], package, level)
temp\temp.py:64: in <module>
    engine = create_engine('postgresql://user:password@localhost/testdb')  # Use PostgreSQL
unit_test_env\Lib\site-packages\sqlalchemy\util\deprecations.py:281: in warned
    return fn(*args, **kwargs)  # type: ignore[no-any-return]
unit_test_env\Lib\site-packages\sqlalchemy\engine\create.py:602: in create_engine
    dbapi = dbapi_meth(**dbapi_args)
unit_test_env\Lib\site-packages\sqlalchemy\dialects\postgresql\psycopg2.py:696: in import_dbapi
    import psycopg2
E   ModuleNotFoundError: No module named 'psycopg2'
============================== warnings summary ===============================
theory_evaluation\models.py:17
  C:\ChenKhoon\JupyterNotebook\GenerateUnitTestCases\theory_evaluation\models.py:17: MovedIn20Warning: The ``declarative_base()`` function is now available as sqlalchemy.orm.declarative_base(). (deprecated since: 2.0) (Background on SQLAlchemy 2.0 at: https://sqlalche.me/e/b8d9)
    Base = declarative_base()

temp\temp.py:48
  C:\ChenKhoon\JupyterNotebook\GenerateUnitTestCases\temp\temp.py:48: MovedIn20Warning: The ``declarative_base()`` function is now available as sqlalchemy.orm.declarative_base(). (deprecated since: 2.0) (Background on SQLAlchemy 2.0 at: https://sqlalche.me/e/b8d9)
    Base = declarative_base()

-- Docs: https://docs.pytest.org/en/stable/how-to/capture-warnings.html
=========================== short test summary info ===========================
ERROR temp/temp.py
!!!!!!!!!!!!!!!!!!! Interrupted: 1 error during collection !!!!!!!!!!!!!!!!!!!!
2 warnings, 1 error in 0.79s

TEST CASE 2 Retry 0
---------------
from sqlalchemy.dialects.postgresql import JSONB, UUID
from sqlalchemy import (
    Column,
    Integer,
    String,
    TIMESTAMP,
    create_engine,
    Float,
    ForeignKey,
    Text,
    UniqueConstraint,
)
from sqlalchemy.ext.declarative import declarative_base
from sqlalchemy.sql import func
import uuid
from theory_evaluation.models import Base, ConsultantChat, CurrentUserTable, Curriculum, MentorChat, Projects, SprintIssues, TheoryEvalUserPerformance, UserInfo, UserRepo, UserScoreLog
import pytest

@pytest.fixture(scope="module")
def engine():
    return create_engine("sqlite:///:memory:")

@pytest.fixture(scope="module")
def tables(engine):
    Base.metadata.create_all(engine)
    yield
    Base.metadata.drop_all(engine)

@pytest.fixture(scope="function")
def session(engine, tables):
    connection = engine.connect()
    transaction = connection.begin()
    Session = sessionmaker(bind=connection)
    session = Session()
    yield session
    session.close()
    transaction.rollback()
    connection.close()

def test_user_info_unique_email_constraint(session):
    user1 = UserInfo(
        first_name="Jane",
        last_name="Doe",
        email="jane.doe@example.com",
        github_username="janedoe",
        status=1
    )
    user2 = UserInfo(
        first_name="Jane",
        last_name="Smith",
        email="jane.doe@example.com",
        github_username="janesmith",
        status=1
    )
    session.add(user1)
    session.commit()
    session.add(user2)
    with pytest.raises(IntegrityError):
        session.commit()

---------------
TEST CASE 2 Retry 0 - Result - Failed
Test Error -
c:\ChenKhoon\JupyterNotebook\GenerateUnitTestCases\unit_test_env\Lib\site-packages\pytest_asyncio\plugin.py:217: PytestDeprecationWarning: The configuration option "asyncio_default_fixture_loop_scope" is unset.
The event loop scope for asynchronous fixtures will default to the fixture caching scope. Future versions of pytest-asyncio will default the loop scope for asynchronous fixtures to function scope. Set the default fixture loop scope explicitly in order to avoid unexpected behavior in the future. Valid fixture loop scopes are: "function", "class", "module", "package", "session"

  warnings.warn(PytestDeprecationWarning(_DEFAULT_FIXTURE_LOOP_SCOPE_UNSET))
E                                                                        [100%]
=================================== ERRORS ====================================
__________ ERROR at setup of test_user_info_unique_email_constraint ___________
unit_test_env\Lib\site-packages\sqlalchemy\sql\visitors.py:137: in _compiler_dispatch
    meth = getter(visitor)
E   AttributeError: 'SQLiteTypeCompiler' object has no attribute 'visit_JSONB'. Did you mean: 'visit_JSON'?

The above exception was the direct cause of the following exception:
unit_test_env\Lib\site-packages\sqlalchemy\sql\compiler.py:6716: in visit_create_table
    processed = self.process(
unit_test_env\Lib\site-packages\sqlalchemy\sql\compiler.py:932: in process
    return obj._compiler_dispatch(self, **kwargs)
unit_test_env\Lib\site-packages\sqlalchemy\sql\visitors.py:141: in _compiler_dispatch
    return meth(self, **kw)  # type: ignore  # noqa: E501
unit_test_env\Lib\site-packages\sqlalchemy\sql\compiler.py:6747: in visit_create_column
    text = self.get_column_specification(column, first_pk=first_pk)
unit_test_env\Lib\site-packages\sqlalchemy\dialects\sqlite\base.py:1598: in get_column_specification
    coltype = self.dialect.type_compiler_instance.process(
unit_test_env\Lib\site-packages\sqlalchemy\sql\compiler.py:977: in process
    return type_._compiler_dispatch(self, **kw)
unit_test_env\Lib\site-packages\sqlalchemy\sql\visitors.py:139: in _compiler_dispatch
    return visitor.visit_unsupported_compilation(self, err, **kw)  # type: ignore  # noqa: E501
unit_test_env\Lib\site-packages\sqlalchemy\sql\compiler.py:982: in visit_unsupported_compilation
    raise exc.UnsupportedCompilationError(self, element) from err
E   sqlalchemy.exc.UnsupportedCompilationError: Compiler <sqlalchemy.dialects.sqlite.base.SQLiteTypeCompiler object at 0x000001452824FCB0> can't render element of type JSONB (Background on this error at: https://sqlalche.me/e/20/l7de)

The above exception was the direct cause of the following exception:
temp\temp.py:25: in tables
    Base.metadata.create_all(engine)
unit_test_env\Lib\site-packages\sqlalchemy\sql\schema.py:5925: in create_all
    bind._run_ddl_visitor(
unit_test_env\Lib\site-packages\sqlalchemy\engine\base.py:3249: in _run_ddl_visitor
    conn._run_ddl_visitor(visitorcallable, element, **kwargs)
unit_test_env\Lib\site-packages\sqlalchemy\engine\base.py:2456: in _run_ddl_visitor
    visitorcallable(self.dialect, self, **kwargs).traverse_single(element)
unit_test_env\Lib\site-packages\sqlalchemy\sql\visitors.py:664: in traverse_single
    return meth(obj, **kw)
unit_test_env\Lib\site-packages\sqlalchemy\sql\ddl.py:981: in visit_metadata
    self.traverse_single(
unit_test_env\Lib\site-packages\sqlalchemy\sql\visitors.py:664: in traverse_single
    return meth(obj, **kw)
unit_test_env\Lib\site-packages\sqlalchemy\sql\ddl.py:1019: in visit_table
    )._invoke_with(self.connection)
unit_test_env\Lib\site-packages\sqlalchemy\sql\ddl.py:321: in _invoke_with
    return bind.execute(self)
unit_test_env\Lib\site-packages\sqlalchemy\engine\base.py:1416: in execute
    return meth(
unit_test_env\Lib\site-packages\sqlalchemy\sql\ddl.py:187: in _execute_on_connection
    return connection._execute_ddl(
unit_test_env\Lib\site-packages\sqlalchemy\engine\base.py:1524: in _execute_ddl
    compiled = ddl.compile(
unit_test_env\Lib\site-packages\sqlalchemy\sql\elements.py:308: in compile
    return self._compiler(dialect, **kw)
unit_test_env\Lib\site-packages\sqlalchemy\sql\ddl.py:76: in _compiler
    return dialect.ddl_compiler(dialect, self, **kw)
unit_test_env\Lib\site-packages\sqlalchemy\sql\compiler.py:886: in __init__
    self.string = self.process(self.statement, **compile_kwargs)
unit_test_env\Lib\site-packages\sqlalchemy\sql\compiler.py:932: in process
    return obj._compiler_dispatch(self, **kwargs)
unit_test_env\Lib\site-packages\sqlalchemy\sql\visitors.py:141: in _compiler_dispatch
    return meth(self, **kw)  # type: ignore  # noqa: E501
unit_test_env\Lib\site-packages\sqlalchemy\sql\compiler.py:6726: in visit_create_table
    raise exc.CompileError(
E   sqlalchemy.exc.CompileError: (in table 'projects', column 'problem_statement'): Compiler <sqlalchemy.dialects.sqlite.base.SQLiteTypeCompiler object at 0x000001452824FCB0> can't render element of type JSONB
============================== warnings summary ===============================
theory_evaluation\models.py:17
  C:\ChenKhoon\JupyterNotebook\GenerateUnitTestCases\theory_evaluation\models.py:17: MovedIn20Warning: The ``declarative_base()`` function is now available as sqlalchemy.orm.declarative_base(). (deprecated since: 2.0) (Background on SQLAlchemy 2.0 at: https://sqlalche.me/e/b8d9)
    Base = declarative_base()

-- Docs: https://docs.pytest.org/en/stable/how-to/capture-warnings.html
=========================== short test summary info ===========================
ERROR temp/temp.py::test_user_info_unique_email_constraint - sqlalchemy.exc.C...
1 warning, 1 error in 1.40s
TEST CASE 2 Retry 1
---------------
from sqlalchemy.dialects.postgresql import JSONB, UUID
from sqlalchemy import (
    Column,
    Integer,
    String,
    TIMESTAMP,
    create_engine,
    Float,
    ForeignKey,
    Text,
    UniqueConstraint,
)
from sqlalchemy.ext.declarative import declarative_base
from sqlalchemy.sql import func
import uuid
from theory_evaluation.models import Base, ConsultantChat, CurrentUserTable, Curriculum, MentorChat, Projects, SprintIssues, TheoryEvalUserPerformance, UserInfo, UserRepo, UserScoreLog
import pytest

@pytest.fixture(scope="module")
def engine():
    return create_engine("sqlite:///:memory:")

@pytest.fixture(scope="module")
def tables(engine):
    Base.metadata.create_all(engine)
    yield
    Base.metadata.drop_all(engine)

@pytest.fixture(scope="function")
def session(engine, tables):
    connection = engine.connect()
    transaction = connection.begin()
    Session = sessionmaker(bind=connection)
    session = Session()
    yield session
    session.close()
    transaction.rollback()
    connection.close()

import pytest
from sqlalchemy import create_engine
from sqlalchemy.exc import IntegrityError
from sqlalchemy.orm import sessionmaker
from your_module import UserInfo, Base  # Replace 'your_module' with the actual module name

# Configure test database (using PostgreSQL)
DATABASE_URL = "postgresql://user:password@localhost/test_db"  # Update with actual credentials
engine = create_engine(DATABASE_URL)
Base.metadata.create_all(engine)
Session = sessionmaker(bind=engine)

def test_user_info_unique_email_constraint():
    session = Session()
    user1 = UserInfo(
        first_name="Jane",
        last_name="Doe",
        email="jane.doe@example.com",
        github_username="janedoe",
        status=1
    )
    user2 = UserInfo(
        first_name="Jane",
        last_name="Smith",
        email="jane.doe@example.com",
        github_username="janesmith",
        status=1
    )
    session.add(user1)
    session.commit()
    session.add(user2)
    with pytest.raises(IntegrityError):
        session.commit()
    session.close()

---------------
TEST CASE 2 Retry 1 - Result - Failed
Test Error -
c:\ChenKhoon\JupyterNotebook\GenerateUnitTestCases\unit_test_env\Lib\site-packages\pytest_asyncio\plugin.py:217: PytestDeprecationWarning: The configuration option "asyncio_default_fixture_loop_scope" is unset.
The event loop scope for asynchronous fixtures will default to the fixture caching scope. Future versions of pytest-asyncio will default the loop scope for asynchronous fixtures to function scope. Set the default fixture loop scope explicitly in order to avoid unexpected behavior in the future. Valid fixture loop scopes are: "function", "class", "module", "package", "session"

  warnings.warn(PytestDeprecationWarning(_DEFAULT_FIXTURE_LOOP_SCOPE_UNSET))

=================================== ERRORS ====================================
________________________ ERROR collecting temp/temp.py ________________________
ImportError while importing test module 'C:\ChenKhoon\JupyterNotebook\GenerateUnitTestCases\temp\temp.py'.
Hint: make sure your test modules/packages have valid Python names.
Traceback:
C:\Users\User\AppData\Local\Programs\Python\Python313\Lib\importlib\__init__.py:88: in import_module
    return _bootstrap._gcd_import(name[level:], package, level)
temp\temp.py:44: in <module>
    from your_module import UserInfo, Base  # Replace 'your_module' with the actual module name
E   ModuleNotFoundError: No module named 'your_module'
============================== warnings summary ===============================
theory_evaluation\models.py:17
  C:\ChenKhoon\JupyterNotebook\GenerateUnitTestCases\theory_evaluation\models.py:17: MovedIn20Warning: The ``declarative_base()`` function is now available as sqlalchemy.orm.declarative_base(). (deprecated since: 2.0) (Background on SQLAlchemy 2.0 at: https://sqlalche.me/e/b8d9)
    Base = declarative_base()

-- Docs: https://docs.pytest.org/en/stable/how-to/capture-warnings.html
=========================== short test summary info ===========================
ERROR temp/temp.py
!!!!!!!!!!!!!!!!!!! Interrupted: 1 error during collection !!!!!!!!!!!!!!!!!!!!
1 warning, 1 error in 0.84s
TEST CASE 2 Retry 2
---------------
from sqlalchemy.dialects.postgresql import JSONB, UUID
from sqlalchemy import (
    Column,
    Integer,
    String,
    TIMESTAMP,
    create_engine,
    Float,
    ForeignKey,
    Text,
    UniqueConstraint,
)
from sqlalchemy.ext.declarative import declarative_base
from sqlalchemy.sql import func
import uuid
from theory_evaluation.models import Base, ConsultantChat, CurrentUserTable, Curriculum, MentorChat, Projects, SprintIssues, TheoryEvalUserPerformance, UserInfo, UserRepo, UserScoreLog
import pytest

@pytest.fixture(scope="module")
def engine():
    return create_engine("sqlite:///:memory:")

@pytest.fixture(scope="module")
def tables(engine):
    Base.metadata.create_all(engine)
    yield
    Base.metadata.drop_all(engine)

@pytest.fixture(scope="function")
def session(engine, tables):
    connection = engine.connect()
    transaction = connection.begin()
    Session = sessionmaker(bind=connection)
    session = Session()
    yield session
    session.close()
    transaction.rollback()
    connection.close()

import pytest
from sqlalchemy import create_engine
from sqlalchemy.exc import IntegrityError
from sqlalchemy.orm import sessionmaker
from sqlalchemy.ext.declarative import declarative_base
from sqlalchemy import Column, Integer, String, TIMESTAMP

Base = declarative_base()

class UserInfo(Base):
    __tablename__ = "user_info"
    id = Column(Integer, primary_key=True, index=True)
    first_name = Column(String(50))
    last_name = Column(String(50))
    email = Column(String(100), unique=True, nullable=False)
    github_username = Column(String(50), nullable=False)
    status = Column(Integer)

# Configure test database (using PostgreSQL)
DATABASE_URL = "postgresql://user:password@localhost/test_db"  # Update with actual credentials
engine = create_engine(DATABASE_URL)
Base.metadata.create_all(engine)
Session = sessionmaker(bind=engine)

def test_user_info_unique_email_constraint():
    session = Session()
    user1 = UserInfo(
        first_name="Jane",
        last_name="Doe",
        email="jane.doe@example.com",
        github_username="janedoe",
        status=1
    )
    user2 = UserInfo(
        first_name="Jane",
        last_name="Smith",
        email="jane.doe@example.com",
        github_username="janesmith",
        status=1
    )
    session.add(user1)
    session.commit()
    session.add(user2)
    with pytest.raises(IntegrityError):
        session.commit()
    session.close()

---------------
TEST CASE 2 Retry 2 - Result - Failed
Test Error -
c:\ChenKhoon\JupyterNotebook\GenerateUnitTestCases\unit_test_env\Lib\site-packages\pytest_asyncio\plugin.py:217: PytestDeprecationWarning: The configuration option "asyncio_default_fixture_loop_scope" is unset.
The event loop scope for asynchronous fixtures will default to the fixture caching scope. Future versions of pytest-asyncio will default the loop scope for asynchronous fixtures to function scope. Set the default fixture loop scope explicitly in order to avoid unexpected behavior in the future. Valid fixture loop scopes are: "function", "class", "module", "package", "session"

  warnings.warn(PytestDeprecationWarning(_DEFAULT_FIXTURE_LOOP_SCOPE_UNSET))

=================================== ERRORS ====================================
________________________ ERROR collecting temp/temp.py ________________________
ImportError while importing test module 'C:\ChenKhoon\JupyterNotebook\GenerateUnitTestCases\temp\temp.py'.
Hint: make sure your test modules/packages have valid Python names.
Traceback:
C:\Users\User\AppData\Local\Programs\Python\Python313\Lib\importlib\__init__.py:88: in import_module
    return _bootstrap._gcd_import(name[level:], package, level)
temp\temp.py:60: in <module>
    engine = create_engine(DATABASE_URL)
unit_test_env\Lib\site-packages\sqlalchemy\util\deprecations.py:281: in warned
    return fn(*args, **kwargs)  # type: ignore[no-any-return]
unit_test_env\Lib\site-packages\sqlalchemy\engine\create.py:602: in create_engine
    dbapi = dbapi_meth(**dbapi_args)
unit_test_env\Lib\site-packages\sqlalchemy\dialects\postgresql\psycopg2.py:696: in import_dbapi
    import psycopg2
E   ModuleNotFoundError: No module named 'psycopg2'
============================== warnings summary ===============================
theory_evaluation\models.py:17
  C:\ChenKhoon\JupyterNotebook\GenerateUnitTestCases\theory_evaluation\models.py:17: MovedIn20Warning: The ``declarative_base()`` function is now available as sqlalchemy.orm.declarative_base(). (deprecated since: 2.0) (Background on SQLAlchemy 2.0 at: https://sqlalche.me/e/b8d9)
    Base = declarative_base()

temp\temp.py:47
  C:\ChenKhoon\JupyterNotebook\GenerateUnitTestCases\temp\temp.py:47: MovedIn20Warning: The ``declarative_base()`` function is now available as sqlalchemy.orm.declarative_base(). (deprecated since: 2.0) (Background on SQLAlchemy 2.0 at: https://sqlalche.me/e/b8d9)
    Base = declarative_base()

-- Docs: https://docs.pytest.org/en/stable/how-to/capture-warnings.html
=========================== short test summary info ===========================
ERROR temp/temp.py
!!!!!!!!!!!!!!!!!!! Interrupted: 1 error during collection !!!!!!!!!!!!!!!!!!!!
2 warnings, 1 error in 0.87s

TEST CASE 5 Retry 0
---------------
from sqlalchemy.dialects.postgresql import JSONB, UUID
from sqlalchemy import (
    Column,
    Integer,
    String,
    TIMESTAMP,
    create_engine,
    Float,
    ForeignKey,
    Text,
    UniqueConstraint,
)
from sqlalchemy.ext.declarative import declarative_base
from sqlalchemy.sql import func
import uuid
from theory_evaluation.models import Base, ConsultantChat, CurrentUserTable, Curriculum, MentorChat, Projects, SprintIssues, TheoryEvalUserPerformance, UserInfo, UserRepo, UserScoreLog
import pytest

@pytest.fixture(scope="module")
def engine():
    return create_engine("sqlite:///:memory:")

@pytest.fixture(scope="module")
def tables(engine):
    Base.metadata.create_all(engine)
    yield
    Base.metadata.drop_all(engine)

@pytest.fixture(scope="function")
def session(engine, tables):
    connection = engine.connect()
    transaction = connection.begin()
    Session = sessionmaker(bind=connection)
    session = Session()
    yield session
    session.close()
    transaction.rollback()
    connection.close()

def test_curriculum_creation(session):
    curriculum = Curriculum(
        question="What is Python?",
        marking_scheme="Correctness",
        model_answer="Python is a programming language."
    )
    session.add(curriculum)
    session.commit()
    retrieved_curriculum = session.query(Curriculum).filter_by(question="What is Python?").first()
    assert retrieved_curriculum is not None
    assert retrieved_curriculum.marking_scheme == "Correctness"

---------------
TEST CASE 5 Retry 0 - Result - Failed
Test Error -
c:\ChenKhoon\JupyterNotebook\GenerateUnitTestCases\unit_test_env\Lib\site-packages\pytest_asyncio\plugin.py:217: PytestDeprecationWarning: The configuration option "asyncio_default_fixture_loop_scope" is unset.
The event loop scope for asynchronous fixtures will default to the fixture caching scope. Future versions of pytest-asyncio will default the loop scope for asynchronous fixtures to function scope. Set the default fixture loop scope explicitly in order to avoid unexpected behavior in the future. Valid fixture loop scopes are: "function", "class", "module", "package", "session"

  warnings.warn(PytestDeprecationWarning(_DEFAULT_FIXTURE_LOOP_SCOPE_UNSET))
E                                                                        [100%]
=================================== ERRORS ====================================
_________________ ERROR at setup of test_curriculum_creation __________________
unit_test_env\Lib\site-packages\sqlalchemy\sql\visitors.py:137: in _compiler_dispatch
    meth = getter(visitor)
E   AttributeError: 'SQLiteTypeCompiler' object has no attribute 'visit_JSONB'. Did you mean: 'visit_JSON'?

The above exception was the direct cause of the following exception:
unit_test_env\Lib\site-packages\sqlalchemy\sql\compiler.py:6716: in visit_create_table
    processed = self.process(
unit_test_env\Lib\site-packages\sqlalchemy\sql\compiler.py:932: in process
    return obj._compiler_dispatch(self, **kwargs)
unit_test_env\Lib\site-packages\sqlalchemy\sql\visitors.py:141: in _compiler_dispatch
    return meth(self, **kw)  # type: ignore  # noqa: E501
unit_test_env\Lib\site-packages\sqlalchemy\sql\compiler.py:6747: in visit_create_column
    text = self.get_column_specification(column, first_pk=first_pk)
unit_test_env\Lib\site-packages\sqlalchemy\dialects\sqlite\base.py:1598: in get_column_specification
    coltype = self.dialect.type_compiler_instance.process(
unit_test_env\Lib\site-packages\sqlalchemy\sql\compiler.py:977: in process
    return type_._compiler_dispatch(self, **kw)
unit_test_env\Lib\site-packages\sqlalchemy\sql\visitors.py:139: in _compiler_dispatch
    return visitor.visit_unsupported_compilation(self, err, **kw)  # type: ignore  # noqa: E501
unit_test_env\Lib\site-packages\sqlalchemy\sql\compiler.py:982: in visit_unsupported_compilation
    raise exc.UnsupportedCompilationError(self, element) from err
E   sqlalchemy.exc.UnsupportedCompilationError: Compiler <sqlalchemy.dialects.sqlite.base.SQLiteTypeCompiler object at 0x000001EC65FDFB60> can't render element of type JSONB (Background on this error at: https://sqlalche.me/e/20/l7de)

The above exception was the direct cause of the following exception:
temp\temp.py:25: in tables
    Base.metadata.create_all(engine)
unit_test_env\Lib\site-packages\sqlalchemy\sql\schema.py:5925: in create_all
    bind._run_ddl_visitor(
unit_test_env\Lib\site-packages\sqlalchemy\engine\base.py:3249: in _run_ddl_visitor
    conn._run_ddl_visitor(visitorcallable, element, **kwargs)
unit_test_env\Lib\site-packages\sqlalchemy\engine\base.py:2456: in _run_ddl_visitor
    visitorcallable(self.dialect, self, **kwargs).traverse_single(element)
unit_test_env\Lib\site-packages\sqlalchemy\sql\visitors.py:664: in traverse_single
    return meth(obj, **kw)
unit_test_env\Lib\site-packages\sqlalchemy\sql\ddl.py:981: in visit_metadata
    self.traverse_single(
unit_test_env\Lib\site-packages\sqlalchemy\sql\visitors.py:664: in traverse_single
    return meth(obj, **kw)
unit_test_env\Lib\site-packages\sqlalchemy\sql\ddl.py:1019: in visit_table
    )._invoke_with(self.connection)
unit_test_env\Lib\site-packages\sqlalchemy\sql\ddl.py:321: in _invoke_with
    return bind.execute(self)
unit_test_env\Lib\site-packages\sqlalchemy\engine\base.py:1416: in execute
    return meth(
unit_test_env\Lib\site-packages\sqlalchemy\sql\ddl.py:187: in _execute_on_connection
    return connection._execute_ddl(
unit_test_env\Lib\site-packages\sqlalchemy\engine\base.py:1524: in _execute_ddl
    compiled = ddl.compile(
unit_test_env\Lib\site-packages\sqlalchemy\sql\elements.py:308: in compile
    return self._compiler(dialect, **kw)
unit_test_env\Lib\site-packages\sqlalchemy\sql\ddl.py:76: in _compiler
    return dialect.ddl_compiler(dialect, self, **kw)
unit_test_env\Lib\site-packages\sqlalchemy\sql\compiler.py:886: in __init__
    self.string = self.process(self.statement, **compile_kwargs)
unit_test_env\Lib\site-packages\sqlalchemy\sql\compiler.py:932: in process
    return obj._compiler_dispatch(self, **kwargs)
unit_test_env\Lib\site-packages\sqlalchemy\sql\visitors.py:141: in _compiler_dispatch
    return meth(self, **kw)  # type: ignore  # noqa: E501
unit_test_env\Lib\site-packages\sqlalchemy\sql\compiler.py:6726: in visit_create_table
    raise exc.CompileError(
E   sqlalchemy.exc.CompileError: (in table 'projects', column 'problem_statement'): Compiler <sqlalchemy.dialects.sqlite.base.SQLiteTypeCompiler object at 0x000001EC65FDFB60> can't render element of type JSONB
============================== warnings summary ===============================
theory_evaluation\models.py:17
  C:\ChenKhoon\JupyterNotebook\GenerateUnitTestCases\theory_evaluation\models.py:17: MovedIn20Warning: The ``declarative_base()`` function is now available as sqlalchemy.orm.declarative_base(). (deprecated since: 2.0) (Background on SQLAlchemy 2.0 at: https://sqlalche.me/e/b8d9)
    Base = declarative_base()

-- Docs: https://docs.pytest.org/en/stable/how-to/capture-warnings.html
=========================== short test summary info ===========================
ERROR temp/temp.py::test_curriculum_creation - sqlalchemy.exc.CompileError: (...
1 warning, 1 error in 1.64s
TEST CASE 5 Retry 1
---------------
from sqlalchemy.dialects.postgresql import JSONB, UUID
from sqlalchemy import (
    Column,
    Integer,
    String,
    TIMESTAMP,
    create_engine,
    Float,
    ForeignKey,
    Text,
    UniqueConstraint,
)
from sqlalchemy.ext.declarative import declarative_base
from sqlalchemy.sql import func
import uuid
from theory_evaluation.models import Base, ConsultantChat, CurrentUserTable, Curriculum, MentorChat, Projects, SprintIssues, TheoryEvalUserPerformance, UserInfo, UserRepo, UserScoreLog
import pytest

@pytest.fixture(scope="module")
def engine():
    return create_engine("sqlite:///:memory:")

@pytest.fixture(scope="module")
def tables(engine):
    Base.metadata.create_all(engine)
    yield
    Base.metadata.drop_all(engine)

@pytest.fixture(scope="function")
def session(engine, tables):
    connection = engine.connect()
    transaction = connection.begin()
    Session = sessionmaker(bind=connection)
    session = Session()
    yield session
    session.close()
    transaction.rollback()
    connection.close()

from sqlalchemy import create_engine
from sqlalchemy.orm import sessionmaker
from sqlalchemy.dialects.postgresql import UUID
from sqlalchemy import Column, Text, TIMESTAMP, func
import uuid

Base = declarative_base()

class Curriculum(Base):
    __tablename__ = "curriculum"
    id = Column(
        UUID(as_uuid=True), primary_key=True, default=uuid.uuid4, nullable=False
    )
    question = Column(Text, unique=True, nullable=False)
    marking_scheme = Column(Text, nullable=False)
    model_answer = Column(Text, nullable=False)
    timestamp = Column(TIMESTAMP(timezone=True), server_default=func.now())

def test_curriculum_creation():
    engine = create_engine('postgresql://user:password@localhost/testdb')
    Session = sessionmaker(bind=engine)
    session = Session()

    curriculum = Curriculum(
        question="What is Python?",
        marking_scheme="Correctness",
        model_answer="Python is a programming language."
    )
    session.add(curriculum)
    session.commit()
    retrieved_curriculum = session.query(Curriculum).filter_by(question="What is Python?").first()
    assert retrieved_curriculum is not None
    assert retrieved_curriculum.marking_scheme == "Correctness"

---------------
TEST CASE 5 Retry 1 - Result - Failed
Test Error -
c:\ChenKhoon\JupyterNotebook\GenerateUnitTestCases\unit_test_env\Lib\site-packages\pytest_asyncio\plugin.py:217: PytestDeprecationWarning: The configuration option "asyncio_default_fixture_loop_scope" is unset.
The event loop scope for asynchronous fixtures will default to the fixture caching scope. Future versions of pytest-asyncio will default the loop scope for asynchronous fixtures to function scope. Set the default fixture loop scope explicitly in order to avoid unexpected behavior in the future. Valid fixture loop scopes are: "function", "class", "module", "package", "session"

  warnings.warn(PytestDeprecationWarning(_DEFAULT_FIXTURE_LOOP_SCOPE_UNSET))
F                                                                        [100%]
================================== FAILURES ===================================
__________________________ test_curriculum_creation ___________________________
temp\temp.py:59: in test_curriculum_creation
    engine = create_engine('postgresql://user:password@localhost/testdb')
<string>:2: in create_engine
    ???
unit_test_env\Lib\site-packages\sqlalchemy\util\deprecations.py:281: in warned
    return fn(*args, **kwargs)  # type: ignore[no-any-return]
unit_test_env\Lib\site-packages\sqlalchemy\engine\create.py:602: in create_engine
    dbapi = dbapi_meth(**dbapi_args)
unit_test_env\Lib\site-packages\sqlalchemy\dialects\postgresql\psycopg2.py:696: in import_dbapi
    import psycopg2
E   ModuleNotFoundError: No module named 'psycopg2'
============================== warnings summary ===============================
theory_evaluation\models.py:17
  C:\ChenKhoon\JupyterNotebook\GenerateUnitTestCases\theory_evaluation\models.py:17: MovedIn20Warning: The ``declarative_base()`` function is now available as sqlalchemy.orm.declarative_base(). (deprecated since: 2.0) (Background on SQLAlchemy 2.0 at: https://sqlalche.me/e/b8d9)
    Base = declarative_base()

temp\temp.py:46
  C:\ChenKhoon\JupyterNotebook\GenerateUnitTestCases\temp\temp.py:46: MovedIn20Warning: The ``declarative_base()`` function is now available as sqlalchemy.orm.declarative_base(). (deprecated since: 2.0) (Background on SQLAlchemy 2.0 at: https://sqlalche.me/e/b8d9)
    Base = declarative_base()

-- Docs: https://docs.pytest.org/en/stable/how-to/capture-warnings.html
=========================== short test summary info ===========================
FAILED temp/temp.py::test_curriculum_creation - ModuleNotFoundError: No modul...
1 failed, 2 warnings in 0.84s
TEST CASE 5 Retry 2
---------------
from sqlalchemy.dialects.postgresql import JSONB, UUID
from sqlalchemy import (
    Column,
    Integer,
    String,
    TIMESTAMP,
    create_engine,
    Float,
    ForeignKey,
    Text,
    UniqueConstraint,
)
from sqlalchemy.ext.declarative import declarative_base
from sqlalchemy.sql import func
import uuid
from theory_evaluation.models import Base, ConsultantChat, CurrentUserTable, Curriculum, MentorChat, Projects, SprintIssues, TheoryEvalUserPerformance, UserInfo, UserRepo, UserScoreLog
import pytest

@pytest.fixture(scope="module")
def engine():
    return create_engine("sqlite:///:memory:")

@pytest.fixture(scope="module")
def tables(engine):
    Base.metadata.create_all(engine)
    yield
    Base.metadata.drop_all(engine)

@pytest.fixture(scope="function")
def session(engine, tables):
    connection = engine.connect()
    transaction = connection.begin()
    Session = sessionmaker(bind=connection)
    session = Session()
    yield session
    session.close()
    transaction.rollback()
    connection.close()

from sqlalchemy import create_engine
from sqlalchemy.orm import sessionmaker
from sqlalchemy.dialects.postgresql import UUID
from sqlalchemy import Column, Text, TIMESTAMP, func
import uuid
import psycopg2

Base = declarative_base()

class Curriculum(Base):
    __tablename__ = "curriculum"
    id = Column(
        UUID(as_uuid=True), primary_key=True, default=uuid.uuid4, nullable=False
    )
    question = Column(Text, unique=True, nullable=False)
    marking_scheme = Column(Text, nullable=False)
    model_answer = Column(Text, nullable=False)
    timestamp = Column(TIMESTAMP(timezone=True), server_default=func.now())

def test_curriculum_creation():
    engine = create_engine('postgresql+psycopg2://user:password@localhost/testdb')
    Session = sessionmaker(bind=engine)
    session = Session()

    curriculum = Curriculum(
        question="What is Python?",
        marking_scheme="Correctness",
        model_answer="Python is a programming language."
    )
    session.add(curriculum)
    session.commit()
    retrieved_curriculum = session.query(Curriculum).filter_by(question="What is Python?").first()
    assert retrieved_curriculum is not None
    assert retrieved_curriculum.marking_scheme == "Correctness"

---------------
TEST CASE 5 Retry 2 - Result - Failed
Test Error -
c:\ChenKhoon\JupyterNotebook\GenerateUnitTestCases\unit_test_env\Lib\site-packages\pytest_asyncio\plugin.py:217: PytestDeprecationWarning: The configuration option "asyncio_default_fixture_loop_scope" is unset.
The event loop scope for asynchronous fixtures will default to the fixture caching scope. Future versions of pytest-asyncio will default the loop scope for asynchronous fixtures to function scope. Set the default fixture loop scope explicitly in order to avoid unexpected behavior in the future. Valid fixture loop scopes are: "function", "class", "module", "package", "session"

  warnings.warn(PytestDeprecationWarning(_DEFAULT_FIXTURE_LOOP_SCOPE_UNSET))

=================================== ERRORS ====================================
________________________ ERROR collecting temp/temp.py ________________________
ImportError while importing test module 'C:\ChenKhoon\JupyterNotebook\GenerateUnitTestCases\temp\temp.py'.
Hint: make sure your test modules/packages have valid Python names.
Traceback:
C:\Users\User\AppData\Local\Programs\Python\Python313\Lib\importlib\__init__.py:88: in import_module
    return _bootstrap._gcd_import(name[level:], package, level)
temp\temp.py:45: in <module>
    import psycopg2
E   ModuleNotFoundError: No module named 'psycopg2'
============================== warnings summary ===============================
theory_evaluation\models.py:17
  C:\ChenKhoon\JupyterNotebook\GenerateUnitTestCases\theory_evaluation\models.py:17: MovedIn20Warning: The ``declarative_base()`` function is now available as sqlalchemy.orm.declarative_base(). (deprecated since: 2.0) (Background on SQLAlchemy 2.0 at: https://sqlalche.me/e/b8d9)
    Base = declarative_base()

-- Docs: https://docs.pytest.org/en/stable/how-to/capture-warnings.html
=========================== short test summary info ===========================
ERROR temp/temp.py
!!!!!!!!!!!!!!!!!!! Interrupted: 1 error during collection !!!!!!!!!!!!!!!!!!!!
1 warning, 1 error in 0.65s

TEST CASE 6 Retry 0
---------------
from sqlalchemy.dialects.postgresql import JSONB, UUID
from sqlalchemy import (
    Column,
    Integer,
    String,
    TIMESTAMP,
    create_engine,
    Float,
    ForeignKey,
    Text,
    UniqueConstraint,
)
from sqlalchemy.ext.declarative import declarative_base
from sqlalchemy.sql import func
import uuid
from theory_evaluation.models import Base, ConsultantChat, CurrentUserTable, Curriculum, MentorChat, Projects, SprintIssues, TheoryEvalUserPerformance, UserInfo, UserRepo, UserScoreLog
import pytest

@pytest.fixture(scope="module")
def engine():
    return create_engine("sqlite:///:memory:")

@pytest.fixture(scope="module")
def tables(engine):
    Base.metadata.create_all(engine)
    yield
    Base.metadata.drop_all(engine)

@pytest.fixture(scope="function")
def session(engine, tables):
    connection = engine.connect()
    transaction = connection.begin()
    Session = sessionmaker(bind=connection)
    session = Session()
    yield session
    session.close()
    transaction.rollback()
    connection.close()

def test_theory_eval_user_performance_creation(session):
    user_info = UserInfo(
        first_name="Alice",
        last_name="Smith",
        email="alice.smith@example.com",
        github_username="alicesmith",
        status=1
    )
    curriculum = Curriculum(
        question="Explain SQLAlchemy",
        marking_scheme="Detail",
        model_answer="SQLAlchemy is a SQL toolkit and ORM."
    )
    session.add(user_info)
    session.add(curriculum)
    session.commit()

---------------
TEST CASE 6 Retry 0 - Result - Failed
Test Error -
c:\ChenKhoon\JupyterNotebook\GenerateUnitTestCases\unit_test_env\Lib\site-packages\pytest_asyncio\plugin.py:217: PytestDeprecationWarning: The configuration option "asyncio_default_fixture_loop_scope" is unset.
The event loop scope for asynchronous fixtures will default to the fixture caching scope. Future versions of pytest-asyncio will default the loop scope for asynchronous fixtures to function scope. Set the default fixture loop scope explicitly in order to avoid unexpected behavior in the future. Valid fixture loop scopes are: "function", "class", "module", "package", "session"

  warnings.warn(PytestDeprecationWarning(_DEFAULT_FIXTURE_LOOP_SCOPE_UNSET))
E                                                                        [100%]
=================================== ERRORS ====================================
________ ERROR at setup of test_theory_eval_user_performance_creation _________
unit_test_env\Lib\site-packages\sqlalchemy\sql\visitors.py:137: in _compiler_dispatch
    meth = getter(visitor)
E   AttributeError: 'SQLiteTypeCompiler' object has no attribute 'visit_JSONB'. Did you mean: 'visit_JSON'?

The above exception was the direct cause of the following exception:
unit_test_env\Lib\site-packages\sqlalchemy\sql\compiler.py:6716: in visit_create_table
    processed = self.process(
unit_test_env\Lib\site-packages\sqlalchemy\sql\compiler.py:932: in process
    return obj._compiler_dispatch(self, **kwargs)
unit_test_env\Lib\site-packages\sqlalchemy\sql\visitors.py:141: in _compiler_dispatch
    return meth(self, **kw)  # type: ignore  # noqa: E501
unit_test_env\Lib\site-packages\sqlalchemy\sql\compiler.py:6747: in visit_create_column
    text = self.get_column_specification(column, first_pk=first_pk)
unit_test_env\Lib\site-packages\sqlalchemy\dialects\sqlite\base.py:1598: in get_column_specification
    coltype = self.dialect.type_compiler_instance.process(
unit_test_env\Lib\site-packages\sqlalchemy\sql\compiler.py:977: in process
    return type_._compiler_dispatch(self, **kw)
unit_test_env\Lib\site-packages\sqlalchemy\sql\visitors.py:139: in _compiler_dispatch
    return visitor.visit_unsupported_compilation(self, err, **kw)  # type: ignore  # noqa: E501
unit_test_env\Lib\site-packages\sqlalchemy\sql\compiler.py:982: in visit_unsupported_compilation
    raise exc.UnsupportedCompilationError(self, element) from err
E   sqlalchemy.exc.UnsupportedCompilationError: Compiler <sqlalchemy.dialects.sqlite.base.SQLiteTypeCompiler object at 0x000001C40DB7FB60> can't render element of type JSONB (Background on this error at: https://sqlalche.me/e/20/l7de)

The above exception was the direct cause of the following exception:
temp\temp.py:25: in tables
    Base.metadata.create_all(engine)
unit_test_env\Lib\site-packages\sqlalchemy\sql\schema.py:5925: in create_all
    bind._run_ddl_visitor(
unit_test_env\Lib\site-packages\sqlalchemy\engine\base.py:3249: in _run_ddl_visitor
    conn._run_ddl_visitor(visitorcallable, element, **kwargs)
unit_test_env\Lib\site-packages\sqlalchemy\engine\base.py:2456: in _run_ddl_visitor
    visitorcallable(self.dialect, self, **kwargs).traverse_single(element)
unit_test_env\Lib\site-packages\sqlalchemy\sql\visitors.py:664: in traverse_single
    return meth(obj, **kw)
unit_test_env\Lib\site-packages\sqlalchemy\sql\ddl.py:981: in visit_metadata
    self.traverse_single(
unit_test_env\Lib\site-packages\sqlalchemy\sql\visitors.py:664: in traverse_single
    return meth(obj, **kw)
unit_test_env\Lib\site-packages\sqlalchemy\sql\ddl.py:1019: in visit_table
    )._invoke_with(self.connection)
unit_test_env\Lib\site-packages\sqlalchemy\sql\ddl.py:321: in _invoke_with
    return bind.execute(self)
unit_test_env\Lib\site-packages\sqlalchemy\engine\base.py:1416: in execute
    return meth(
unit_test_env\Lib\site-packages\sqlalchemy\sql\ddl.py:187: in _execute_on_connection
    return connection._execute_ddl(
unit_test_env\Lib\site-packages\sqlalchemy\engine\base.py:1524: in _execute_ddl
    compiled = ddl.compile(
unit_test_env\Lib\site-packages\sqlalchemy\sql\elements.py:308: in compile
    return self._compiler(dialect, **kw)
unit_test_env\Lib\site-packages\sqlalchemy\sql\ddl.py:76: in _compiler
    return dialect.ddl_compiler(dialect, self, **kw)
unit_test_env\Lib\site-packages\sqlalchemy\sql\compiler.py:886: in __init__
    self.string = self.process(self.statement, **compile_kwargs)
unit_test_env\Lib\site-packages\sqlalchemy\sql\compiler.py:932: in process
    return obj._compiler_dispatch(self, **kwargs)
unit_test_env\Lib\site-packages\sqlalchemy\sql\visitors.py:141: in _compiler_dispatch
    return meth(self, **kw)  # type: ignore  # noqa: E501
unit_test_env\Lib\site-packages\sqlalchemy\sql\compiler.py:6726: in visit_create_table
    raise exc.CompileError(
E   sqlalchemy.exc.CompileError: (in table 'projects', column 'problem_statement'): Compiler <sqlalchemy.dialects.sqlite.base.SQLiteTypeCompiler object at 0x000001C40DB7FB60> can't render element of type JSONB
============================== warnings summary ===============================
theory_evaluation\models.py:17
  C:\ChenKhoon\JupyterNotebook\GenerateUnitTestCases\theory_evaluation\models.py:17: MovedIn20Warning: The ``declarative_base()`` function is now available as sqlalchemy.orm.declarative_base(). (deprecated since: 2.0) (Background on SQLAlchemy 2.0 at: https://sqlalche.me/e/b8d9)
    Base = declarative_base()

-- Docs: https://docs.pytest.org/en/stable/how-to/capture-warnings.html
=========================== short test summary info ===========================
ERROR temp/temp.py::test_theory_eval_user_performance_creation - sqlalchemy.e...
1 warning, 1 error in 1.29s
TEST CASE 6 Retry 1
---------------
from sqlalchemy.dialects.postgresql import JSONB, UUID
from sqlalchemy import (
    Column,
    Integer,
    String,
    TIMESTAMP,
    create_engine,
    Float,
    ForeignKey,
    Text,
    UniqueConstraint,
)
from sqlalchemy.ext.declarative import declarative_base
from sqlalchemy.sql import func
import uuid
from theory_evaluation.models import Base, ConsultantChat, CurrentUserTable, Curriculum, MentorChat, Projects, SprintIssues, TheoryEvalUserPerformance, UserInfo, UserRepo, UserScoreLog
import pytest

@pytest.fixture(scope="module")
def engine():
    return create_engine("sqlite:///:memory:")

@pytest.fixture(scope="module")
def tables(engine):
    Base.metadata.create_all(engine)
    yield
    Base.metadata.drop_all(engine)

@pytest.fixture(scope="function")
def session(engine, tables):
    connection = engine.connect()
    transaction = connection.begin()
    Session = sessionmaker(bind=connection)
    session = Session()
    yield session
    session.close()
    transaction.rollback()
    connection.close()

from sqlalchemy import create_engine
from sqlalchemy.orm import sessionmaker
from sqlalchemy.exc import CompileError
import pytest

# Assuming the Base and all models are imported from the source code

# Create an in-memory SQLite database for testing
engine = create_engine('sqlite:///:memory:')
Session = sessionmaker(bind=engine)
session = Session()

# Create all tables in the database
try:
    Base.metadata.create_all(engine)
except CompileError as e:
    print(f"Error creating tables: {e}")

def test_theory_eval_user_performance_creation():
    user_info = UserInfo(
        first_name="Alice",
        last_name="Smith",
        email="alice.smith@example.com",
        github_username="alicesmith",
        status=1
    )
    curriculum = Curriculum(
        question="Explain SQLAlchemy",
        marking_scheme="Detail",
        model_answer="SQLAlchemy is a SQL toolkit and ORM."
    )
    session.add(user_info)
    session.add(curriculum)
    session.commit()

    assert session.query(UserInfo).filter_by(email="alice.smith@example.com").first() is not None
    assert session.query(Curriculum).filter_by(question="Explain SQLAlchemy").first() is not None

# Run the test
if __name__ == "__main__":
    pytest.main([__file__])

---------------
TEST CASE 6 Retry 1 - Result - Failed
Test Error -
c:\ChenKhoon\JupyterNotebook\GenerateUnitTestCases\unit_test_env\Lib\site-packages\pytest_asyncio\plugin.py:217: PytestDeprecationWarning: The configuration option "asyncio_default_fixture_loop_scope" is unset.
The event loop scope for asynchronous fixtures will default to the fixture caching scope. Future versions of pytest-asyncio will default the loop scope for asynchronous fixtures to function scope. Set the default fixture loop scope explicitly in order to avoid unexpected behavior in the future. Valid fixture loop scopes are: "function", "class", "module", "package", "session"

  warnings.warn(PytestDeprecationWarning(_DEFAULT_FIXTURE_LOOP_SCOPE_UNSET))
F                                                                        [100%]
================================== FAILURES ===================================
_________________ test_theory_eval_user_performance_creation __________________
unit_test_env\Lib\site-packages\sqlalchemy\engine\base.py:1964: in _exec_single_context
    self.dialect.do_execute(
unit_test_env\Lib\site-packages\sqlalchemy\engine\default.py:945: in do_execute
    cursor.execute(statement, parameters)
E   sqlite3.OperationalError: no such table: curriculum

The above exception was the direct cause of the following exception:
temp\temp.py:73: in test_theory_eval_user_performance_creation
    session.commit()
unit_test_env\Lib\site-packages\sqlalchemy\orm\session.py:2032: in commit
    trans.commit(_to_root=True)
<string>:2: in commit
    ???
unit_test_env\Lib\site-packages\sqlalchemy\orm\state_changes.py:139: in _go
    ret_value = fn(self, *arg, **kw)
unit_test_env\Lib\site-packages\sqlalchemy\orm\session.py:1313: in commit
    self._prepare_impl()
<string>:2: in _prepare_impl
    ???
unit_test_env\Lib\site-packages\sqlalchemy\orm\state_changes.py:139: in _go
    ret_value = fn(self, *arg, **kw)
unit_test_env\Lib\site-packages\sqlalchemy\orm\session.py:1288: in _prepare_impl
    self.session.flush()
unit_test_env\Lib\site-packages\sqlalchemy\orm\session.py:4353: in flush
    self._flush(objects)
unit_test_env\Lib\site-packages\sqlalchemy\orm\session.py:4488: in _flush
    with util.safe_reraise():
unit_test_env\Lib\site-packages\sqlalchemy\util\langhelpers.py:146: in __exit__
    raise exc_value.with_traceback(exc_tb)
unit_test_env\Lib\site-packages\sqlalchemy\orm\session.py:4449: in _flush
    flush_context.execute()
unit_test_env\Lib\site-packages\sqlalchemy\orm\unitofwork.py:466: in execute
    rec.execute(self)
unit_test_env\Lib\site-packages\sqlalchemy\orm\unitofwork.py:642: in execute
    util.preloaded.orm_persistence.save_obj(
unit_test_env\Lib\site-packages\sqlalchemy\orm\persistence.py:93: in save_obj
    _emit_insert_statements(
unit_test_env\Lib\site-packages\sqlalchemy\orm\persistence.py:1233: in _emit_insert_statements
    result = connection.execute(
unit_test_env\Lib\site-packages\sqlalchemy\engine\base.py:1416: in execute
    return meth(
unit_test_env\Lib\site-packages\sqlalchemy\sql\elements.py:523: in _execute_on_connection
    return connection._execute_clauseelement(
unit_test_env\Lib\site-packages\sqlalchemy\engine\base.py:1638: in _execute_clauseelement
    ret = self._execute_context(
unit_test_env\Lib\site-packages\sqlalchemy\engine\base.py:1843: in _execute_context
    return self._exec_single_context(
unit_test_env\Lib\site-packages\sqlalchemy\engine\base.py:1983: in _exec_single_context
    self._handle_dbapi_exception(
unit_test_env\Lib\site-packages\sqlalchemy\engine\base.py:2352: in _handle_dbapi_exception
    raise sqlalchemy_exception.with_traceback(exc_info[2]) from e
unit_test_env\Lib\site-packages\sqlalchemy\engine\base.py:1964: in _exec_single_context
    self.dialect.do_execute(
unit_test_env\Lib\site-packages\sqlalchemy\engine\default.py:945: in do_execute
    cursor.execute(statement, parameters)
E   sqlalchemy.exc.OperationalError: (sqlite3.OperationalError) no such table: curriculum
E   [SQL: INSERT INTO curriculum (id, question, marking_scheme, model_answer) VALUES (?, ?, ?, ?) RETURNING timestamp]
E   [parameters: ('bf72c1fc010648e692623b252c9454f3', 'Explain SQLAlchemy', 'Detail', 'SQLAlchemy is a SQL toolkit and ORM.')]
E   (Background on this error at: https://sqlalche.me/e/20/e3q8)
============================== warnings summary ===============================
theory_evaluation\models.py:17
  C:\ChenKhoon\JupyterNotebook\GenerateUnitTestCases\theory_evaluation\models.py:17: MovedIn20Warning: The ``declarative_base()`` function is now available as sqlalchemy.orm.declarative_base(). (deprecated since: 2.0) (Background on SQLAlchemy 2.0 at: https://sqlalche.me/e/b8d9)
    Base = declarative_base()

-- Docs: https://docs.pytest.org/en/stable/how-to/capture-warnings.html
=========================== short test summary info ===========================
FAILED temp/temp.py::test_theory_eval_user_performance_creation - sqlalchemy....
1 failed, 1 warning in 1.18s
TEST CASE 6 Retry 2
---------------
from sqlalchemy.dialects.postgresql import JSONB, UUID
from sqlalchemy import (
    Column,
    Integer,
    String,
    TIMESTAMP,
    create_engine,
    Float,
    ForeignKey,
    Text,
    UniqueConstraint,
)
from sqlalchemy.ext.declarative import declarative_base
from sqlalchemy.sql import func
import uuid
from theory_evaluation.models import Base, ConsultantChat, CurrentUserTable, Curriculum, MentorChat, Projects, SprintIssues, TheoryEvalUserPerformance, UserInfo, UserRepo, UserScoreLog
import pytest

@pytest.fixture(scope="module")
def engine():
    return create_engine("sqlite:///:memory:")

@pytest.fixture(scope="module")
def tables(engine):
    Base.metadata.create_all(engine)
    yield
    Base.metadata.drop_all(engine)

@pytest.fixture(scope="function")
def session(engine, tables):
    connection = engine.connect()
    transaction = connection.begin()
    Session = sessionmaker(bind=connection)
    session = Session()
    yield session
    session.close()
    transaction.rollback()
    connection.close()

from sqlalchemy import create_engine
from sqlalchemy.orm import sessionmaker
from sqlalchemy.exc import CompileError
import pytest

# Assuming the Base and all models are imported from the source code

# Create an in-memory SQLite database for testing
engine = create_engine('sqlite:///:memory:')
Session = sessionmaker(bind=engine)
session = Session()

# Create all tables in the database
try:
    Base.metadata.create_all(engine)
except CompileError as e:
    print(f"Error creating tables: {e}")

def test_theory_eval_user_performance_creation():
    user_info = UserInfo(
        first_name="Alice",
        last_name="Smith",
        email="alice.smith@example.com",
        github_username="alicesmith",
        status=1
    )
    curriculum = Curriculum(
        question="Explain SQLAlchemy",
        marking_scheme="Detail",
        model_answer="SQLAlchemy is a SQL toolkit and ORM."
    )
    session.add(user_info)
    session.add(curriculum)
    session.commit()

    assert session.query(UserInfo).filter_by(email="alice.smith@example.com").first() is not None
    assert session.query(Curriculum).filter_by(question="Explain SQLAlchemy").first() is not None

# Run the test
if __name__ == "__main__":
    pytest.main([__file__])

---------------
TEST CASE 6 Retry 2 - Result - Failed
Test Error -
c:\ChenKhoon\JupyterNotebook\GenerateUnitTestCases\unit_test_env\Lib\site-packages\pytest_asyncio\plugin.py:217: PytestDeprecationWarning: The configuration option "asyncio_default_fixture_loop_scope" is unset.
The event loop scope for asynchronous fixtures will default to the fixture caching scope. Future versions of pytest-asyncio will default the loop scope for asynchronous fixtures to function scope. Set the default fixture loop scope explicitly in order to avoid unexpected behavior in the future. Valid fixture loop scopes are: "function", "class", "module", "package", "session"

  warnings.warn(PytestDeprecationWarning(_DEFAULT_FIXTURE_LOOP_SCOPE_UNSET))
F                                                                        [100%]
================================== FAILURES ===================================
_________________ test_theory_eval_user_performance_creation __________________
unit_test_env\Lib\site-packages\sqlalchemy\engine\base.py:1964: in _exec_single_context
    self.dialect.do_execute(
unit_test_env\Lib\site-packages\sqlalchemy\engine\default.py:945: in do_execute
    cursor.execute(statement, parameters)
E   sqlite3.OperationalError: no such table: curriculum

The above exception was the direct cause of the following exception:
temp\temp.py:73: in test_theory_eval_user_performance_creation
    session.commit()
unit_test_env\Lib\site-packages\sqlalchemy\orm\session.py:2032: in commit
    trans.commit(_to_root=True)
<string>:2: in commit
    ???
unit_test_env\Lib\site-packages\sqlalchemy\orm\state_changes.py:139: in _go
    ret_value = fn(self, *arg, **kw)
unit_test_env\Lib\site-packages\sqlalchemy\orm\session.py:1313: in commit
    self._prepare_impl()
<string>:2: in _prepare_impl
    ???
unit_test_env\Lib\site-packages\sqlalchemy\orm\state_changes.py:139: in _go
    ret_value = fn(self, *arg, **kw)
unit_test_env\Lib\site-packages\sqlalchemy\orm\session.py:1288: in _prepare_impl
    self.session.flush()
unit_test_env\Lib\site-packages\sqlalchemy\orm\session.py:4353: in flush
    self._flush(objects)
unit_test_env\Lib\site-packages\sqlalchemy\orm\session.py:4488: in _flush
    with util.safe_reraise():
unit_test_env\Lib\site-packages\sqlalchemy\util\langhelpers.py:146: in __exit__
    raise exc_value.with_traceback(exc_tb)
unit_test_env\Lib\site-packages\sqlalchemy\orm\session.py:4449: in _flush
    flush_context.execute()
unit_test_env\Lib\site-packages\sqlalchemy\orm\unitofwork.py:466: in execute
    rec.execute(self)
unit_test_env\Lib\site-packages\sqlalchemy\orm\unitofwork.py:642: in execute
    util.preloaded.orm_persistence.save_obj(
unit_test_env\Lib\site-packages\sqlalchemy\orm\persistence.py:93: in save_obj
    _emit_insert_statements(
unit_test_env\Lib\site-packages\sqlalchemy\orm\persistence.py:1233: in _emit_insert_statements
    result = connection.execute(
unit_test_env\Lib\site-packages\sqlalchemy\engine\base.py:1416: in execute
    return meth(
unit_test_env\Lib\site-packages\sqlalchemy\sql\elements.py:523: in _execute_on_connection
    return connection._execute_clauseelement(
unit_test_env\Lib\site-packages\sqlalchemy\engine\base.py:1638: in _execute_clauseelement
    ret = self._execute_context(
unit_test_env\Lib\site-packages\sqlalchemy\engine\base.py:1843: in _execute_context
    return self._exec_single_context(
unit_test_env\Lib\site-packages\sqlalchemy\engine\base.py:1983: in _exec_single_context
    self._handle_dbapi_exception(
unit_test_env\Lib\site-packages\sqlalchemy\engine\base.py:2352: in _handle_dbapi_exception
    raise sqlalchemy_exception.with_traceback(exc_info[2]) from e
unit_test_env\Lib\site-packages\sqlalchemy\engine\base.py:1964: in _exec_single_context
    self.dialect.do_execute(
unit_test_env\Lib\site-packages\sqlalchemy\engine\default.py:945: in do_execute
    cursor.execute(statement, parameters)
E   sqlalchemy.exc.OperationalError: (sqlite3.OperationalError) no such table: curriculum
E   [SQL: INSERT INTO curriculum (id, question, marking_scheme, model_answer) VALUES (?, ?, ?, ?) RETURNING timestamp]
E   [parameters: ('8dd37a903d3043ecb66e245c64a57773', 'Explain SQLAlchemy', 'Detail', 'SQLAlchemy is a SQL toolkit and ORM.')]
E   (Background on this error at: https://sqlalche.me/e/20/e3q8)
============================== warnings summary ===============================
theory_evaluation\models.py:17
  C:\ChenKhoon\JupyterNotebook\GenerateUnitTestCases\theory_evaluation\models.py:17: MovedIn20Warning: The ``declarative_base()`` function is now available as sqlalchemy.orm.declarative_base(). (deprecated since: 2.0) (Background on SQLAlchemy 2.0 at: https://sqlalche.me/e/b8d9)
    Base = declarative_base()

-- Docs: https://docs.pytest.org/en/stable/how-to/capture-warnings.html
=========================== short test summary info ===========================
FAILED temp/temp.py::test_theory_eval_user_performance_creation - sqlalchemy....
1 failed, 1 warning in 0.97s
