
TEST CASE 1 Retry 0
---------------
from sqlalchemy.dialects.postgresql import JSONB, UUID
from sqlalchemy import (
    Column,
    Integer,
    String,
    TIMESTAMP,
    create_engine,
    Float,
    ForeignKey,
    Text,
    UniqueConstraint,
)
from sqlalchemy.ext.declarative import declarative_base
from sqlalchemy.sql import func
import uuid
from theory_evaluation.models import Base, UserInfo
from sqlalchemy.orm import sessionmaker
import pytest

@pytest.fixture(scope="module")
def db_engine():
    engine = create_engine("sqlite:///:memory:")
    Base.metadata.create_all(engine)
    yield engine
    engine.dispose()

@pytest.fixture(scope="function")
def db_session(db_engine):
    connection = db_engine.connect()
    transaction = connection.begin()
    Session = sessionmaker(bind=connection)
    session = Session()
    yield session
    session.close()
    transaction.rollback()
    connection.close()

def test_user_info_creation(db_session):
    user = UserInfo(
        first_name="John",
        last_name="Doe",
        email="john.doe@example.com",
        github_username="johndoe",
        payment_date=None,
        current_duration=0,
        course_duration=0,
        end_date=None,
        status=1
    )
    db_session.add(user)
    db_session.commit()
---------------
TEST CASE 1 Retry 0 - Result - Failed
Test Error -
c:\ChenKhoon\JupyterNotebook\GenerateUnitTestCases\unit_test_env\Lib\site-packages\pytest_asyncio\plugin.py:217: PytestDeprecationWarning: The configuration option "asyncio_default_fixture_loop_scope" is unset.
The event loop scope for asynchronous fixtures will default to the fixture caching scope. Future versions of pytest-asyncio will default the loop scope for asynchronous fixtures to function scope. Set the default fixture loop scope explicitly in order to avoid unexpected behavior in the future. Valid fixture loop scopes are: "function", "class", "module", "package", "session"

  warnings.warn(PytestDeprecationWarning(_DEFAULT_FIXTURE_LOOP_SCOPE_UNSET))
E                                                                        [100%]
=================================== ERRORS ====================================
__________________ ERROR at setup of test_user_info_creation __________________
unit_test_env\Lib\site-packages\sqlalchemy\sql\visitors.py:137: in _compiler_dispatch
    meth = getter(visitor)
E   AttributeError: 'SQLiteTypeCompiler' object has no attribute 'visit_JSONB'. Did you mean: 'visit_JSON'?

The above exception was the direct cause of the following exception:
unit_test_env\Lib\site-packages\sqlalchemy\sql\compiler.py:6716: in visit_create_table
    processed = self.process(
unit_test_env\Lib\site-packages\sqlalchemy\sql\compiler.py:932: in process
    return obj._compiler_dispatch(self, **kwargs)
unit_test_env\Lib\site-packages\sqlalchemy\sql\visitors.py:141: in _compiler_dispatch
    return meth(self, **kw)  # type: ignore  # noqa: E501
unit_test_env\Lib\site-packages\sqlalchemy\sql\compiler.py:6747: in visit_create_column
    text = self.get_column_specification(column, first_pk=first_pk)
unit_test_env\Lib\site-packages\sqlalchemy\dialects\sqlite\base.py:1598: in get_column_specification
    coltype = self.dialect.type_compiler_instance.process(
unit_test_env\Lib\site-packages\sqlalchemy\sql\compiler.py:977: in process
    return type_._compiler_dispatch(self, **kw)
unit_test_env\Lib\site-packages\sqlalchemy\sql\visitors.py:139: in _compiler_dispatch
    return visitor.visit_unsupported_compilation(self, err, **kw)  # type: ignore  # noqa: E501
unit_test_env\Lib\site-packages\sqlalchemy\sql\compiler.py:982: in visit_unsupported_compilation
    raise exc.UnsupportedCompilationError(self, element) from err
E   sqlalchemy.exc.UnsupportedCompilationError: Compiler <sqlalchemy.dialects.sqlite.base.SQLiteTypeCompiler object at 0x0000022717813CB0> can't render element of type JSONB (Background on this error at: https://sqlalche.me/e/20/l7de)

The above exception was the direct cause of the following exception:
temp\temp.py:23: in db_engine
    Base.metadata.create_all(engine)
unit_test_env\Lib\site-packages\sqlalchemy\sql\schema.py:5925: in create_all
    bind._run_ddl_visitor(
unit_test_env\Lib\site-packages\sqlalchemy\engine\base.py:3249: in _run_ddl_visitor
    conn._run_ddl_visitor(visitorcallable, element, **kwargs)
unit_test_env\Lib\site-packages\sqlalchemy\engine\base.py:2456: in _run_ddl_visitor
    visitorcallable(self.dialect, self, **kwargs).traverse_single(element)
unit_test_env\Lib\site-packages\sqlalchemy\sql\visitors.py:664: in traverse_single
    return meth(obj, **kw)
unit_test_env\Lib\site-packages\sqlalchemy\sql\ddl.py:981: in visit_metadata
    self.traverse_single(
unit_test_env\Lib\site-packages\sqlalchemy\sql\visitors.py:664: in traverse_single
    return meth(obj, **kw)
unit_test_env\Lib\site-packages\sqlalchemy\sql\ddl.py:1019: in visit_table
    )._invoke_with(self.connection)
unit_test_env\Lib\site-packages\sqlalchemy\sql\ddl.py:321: in _invoke_with
    return bind.execute(self)
unit_test_env\Lib\site-packages\sqlalchemy\engine\base.py:1416: in execute
    return meth(
unit_test_env\Lib\site-packages\sqlalchemy\sql\ddl.py:187: in _execute_on_connection
    return connection._execute_ddl(
unit_test_env\Lib\site-packages\sqlalchemy\engine\base.py:1524: in _execute_ddl
    compiled = ddl.compile(
unit_test_env\Lib\site-packages\sqlalchemy\sql\elements.py:308: in compile
    return self._compiler(dialect, **kw)
unit_test_env\Lib\site-packages\sqlalchemy\sql\ddl.py:76: in _compiler
    return dialect.ddl_compiler(dialect, self, **kw)
unit_test_env\Lib\site-packages\sqlalchemy\sql\compiler.py:886: in __init__
    self.string = self.process(self.statement, **compile_kwargs)
unit_test_env\Lib\site-packages\sqlalchemy\sql\compiler.py:932: in process
    return obj._compiler_dispatch(self, **kwargs)
unit_test_env\Lib\site-packages\sqlalchemy\sql\visitors.py:141: in _compiler_dispatch
    return meth(self, **kw)  # type: ignore  # noqa: E501
unit_test_env\Lib\site-packages\sqlalchemy\sql\compiler.py:6726: in visit_create_table
    raise exc.CompileError(
E   sqlalchemy.exc.CompileError: (in table 'projects', column 'problem_statement'): Compiler <sqlalchemy.dialects.sqlite.base.SQLiteTypeCompiler object at 0x0000022717813CB0> can't render element of type JSONB
============================== warnings summary ===============================
theory_evaluation\models.py:17
  C:\ChenKhoon\JupyterNotebook\GenerateUnitTestCases\theory_evaluation\models.py:17: MovedIn20Warning: The ``declarative_base()`` function is now available as sqlalchemy.orm.declarative_base(). (deprecated since: 2.0) (Background on SQLAlchemy 2.0 at: https://sqlalche.me/e/b8d9)
    Base = declarative_base()

-- Docs: https://docs.pytest.org/en/stable/how-to/capture-warnings.html
=========================== short test summary info ===========================
ERROR temp/temp.py::test_user_info_creation - sqlalchemy.exc.CompileError: (i...
1 warning, 1 error in 1.27s
TEST CASE 1 Retry 1
---------------
from sqlalchemy.dialects.postgresql import JSONB, UUID
from sqlalchemy import (
    Column,
    Integer,
    String,
    TIMESTAMP,
    create_engine,
    Float,
    ForeignKey,
    Text,
    UniqueConstraint,
)
from sqlalchemy.ext.declarative import declarative_base
from sqlalchemy.sql import func
import uuid
from theory_evaluation.models import Base, ConsultantChat, CurrentUserTable, Curriculum, MentorChat, Projects, SprintIssues, TheoryEvalUserPerformance, UserInfo, UserRepo, UserScoreLog
import pytest
from sqlalchemy.orm import sessionmaker
from sqlalchemy.exc import CompileError

@pytest.fixture(scope="module")
def db_engine():
    engine = create_engine("sqlite:///:memory:")
    Base.metadata.create_all(engine)
    yield engine
    engine.dispose()

@pytest.fixture(scope="function")
def db_session(db_engine):
    connection = db_engine.connect()
    transaction = connection.begin()
    Session = sessionmaker(bind=connection)
    session = Session()
    yield session
    session.close()
    transaction.rollback()
    connection.close()

def test_user_info_creation(db_session):
    try:
        user = UserInfo(
            first_name="John",
            last_name="Doe",
            email="john.doe@example.com",
            github_username="johndoe",
            payment_date=None,
            current_duration=0,
            course_duration=0,
            end_date=None,
            status=1
        )
        db_session.add(user)
        db_session.commit()
    except CompileError as e:
        pytest.fail(f"CompileError occurred: {e}")
---------------
TEST CASE 1 Retry 1 - Result - Failed
Test Error -
c:\ChenKhoon\JupyterNotebook\GenerateUnitTestCases\unit_test_env\Lib\site-packages\pytest_asyncio\plugin.py:217: PytestDeprecationWarning: The configuration option "asyncio_default_fixture_loop_scope" is unset.
The event loop scope for asynchronous fixtures will default to the fixture caching scope. Future versions of pytest-asyncio will default the loop scope for asynchronous fixtures to function scope. Set the default fixture loop scope explicitly in order to avoid unexpected behavior in the future. Valid fixture loop scopes are: "function", "class", "module", "package", "session"

  warnings.warn(PytestDeprecationWarning(_DEFAULT_FIXTURE_LOOP_SCOPE_UNSET))
E                                                                        [100%]
=================================== ERRORS ====================================
__________________ ERROR at setup of test_user_info_creation __________________
unit_test_env\Lib\site-packages\sqlalchemy\sql\visitors.py:137: in _compiler_dispatch
    meth = getter(visitor)
E   AttributeError: 'SQLiteTypeCompiler' object has no attribute 'visit_JSONB'. Did you mean: 'visit_JSON'?

The above exception was the direct cause of the following exception:
unit_test_env\Lib\site-packages\sqlalchemy\sql\compiler.py:6716: in visit_create_table
    processed = self.process(
unit_test_env\Lib\site-packages\sqlalchemy\sql\compiler.py:932: in process
    return obj._compiler_dispatch(self, **kwargs)
unit_test_env\Lib\site-packages\sqlalchemy\sql\visitors.py:141: in _compiler_dispatch
    return meth(self, **kw)  # type: ignore  # noqa: E501
unit_test_env\Lib\site-packages\sqlalchemy\sql\compiler.py:6747: in visit_create_column
    text = self.get_column_specification(column, first_pk=first_pk)
unit_test_env\Lib\site-packages\sqlalchemy\dialects\sqlite\base.py:1598: in get_column_specification
    coltype = self.dialect.type_compiler_instance.process(
unit_test_env\Lib\site-packages\sqlalchemy\sql\compiler.py:977: in process
    return type_._compiler_dispatch(self, **kw)
unit_test_env\Lib\site-packages\sqlalchemy\sql\visitors.py:139: in _compiler_dispatch
    return visitor.visit_unsupported_compilation(self, err, **kw)  # type: ignore  # noqa: E501
unit_test_env\Lib\site-packages\sqlalchemy\sql\compiler.py:982: in visit_unsupported_compilation
    raise exc.UnsupportedCompilationError(self, element) from err
E   sqlalchemy.exc.UnsupportedCompilationError: Compiler <sqlalchemy.dialects.sqlite.base.SQLiteTypeCompiler object at 0x000002D2C9E4FCB0> can't render element of type JSONB (Background on this error at: https://sqlalche.me/e/20/l7de)

The above exception was the direct cause of the following exception:
temp\temp.py:24: in db_engine
    Base.metadata.create_all(engine)
unit_test_env\Lib\site-packages\sqlalchemy\sql\schema.py:5925: in create_all
    bind._run_ddl_visitor(
unit_test_env\Lib\site-packages\sqlalchemy\engine\base.py:3249: in _run_ddl_visitor
    conn._run_ddl_visitor(visitorcallable, element, **kwargs)
unit_test_env\Lib\site-packages\sqlalchemy\engine\base.py:2456: in _run_ddl_visitor
    visitorcallable(self.dialect, self, **kwargs).traverse_single(element)
unit_test_env\Lib\site-packages\sqlalchemy\sql\visitors.py:664: in traverse_single
    return meth(obj, **kw)
unit_test_env\Lib\site-packages\sqlalchemy\sql\ddl.py:981: in visit_metadata
    self.traverse_single(
unit_test_env\Lib\site-packages\sqlalchemy\sql\visitors.py:664: in traverse_single
    return meth(obj, **kw)
unit_test_env\Lib\site-packages\sqlalchemy\sql\ddl.py:1019: in visit_table
    )._invoke_with(self.connection)
unit_test_env\Lib\site-packages\sqlalchemy\sql\ddl.py:321: in _invoke_with
    return bind.execute(self)
unit_test_env\Lib\site-packages\sqlalchemy\engine\base.py:1416: in execute
    return meth(
unit_test_env\Lib\site-packages\sqlalchemy\sql\ddl.py:187: in _execute_on_connection
    return connection._execute_ddl(
unit_test_env\Lib\site-packages\sqlalchemy\engine\base.py:1524: in _execute_ddl
    compiled = ddl.compile(
unit_test_env\Lib\site-packages\sqlalchemy\sql\elements.py:308: in compile
    return self._compiler(dialect, **kw)
unit_test_env\Lib\site-packages\sqlalchemy\sql\ddl.py:76: in _compiler
    return dialect.ddl_compiler(dialect, self, **kw)
unit_test_env\Lib\site-packages\sqlalchemy\sql\compiler.py:886: in __init__
    self.string = self.process(self.statement, **compile_kwargs)
unit_test_env\Lib\site-packages\sqlalchemy\sql\compiler.py:932: in process
    return obj._compiler_dispatch(self, **kwargs)
unit_test_env\Lib\site-packages\sqlalchemy\sql\visitors.py:141: in _compiler_dispatch
    return meth(self, **kw)  # type: ignore  # noqa: E501
unit_test_env\Lib\site-packages\sqlalchemy\sql\compiler.py:6726: in visit_create_table
    raise exc.CompileError(
E   sqlalchemy.exc.CompileError: (in table 'projects', column 'problem_statement'): Compiler <sqlalchemy.dialects.sqlite.base.SQLiteTypeCompiler object at 0x000002D2C9E4FCB0> can't render element of type JSONB
============================== warnings summary ===============================
theory_evaluation\models.py:17
  C:\ChenKhoon\JupyterNotebook\GenerateUnitTestCases\theory_evaluation\models.py:17: MovedIn20Warning: The ``declarative_base()`` function is now available as sqlalchemy.orm.declarative_base(). (deprecated since: 2.0) (Background on SQLAlchemy 2.0 at: https://sqlalche.me/e/b8d9)
    Base = declarative_base()

-- Docs: https://docs.pytest.org/en/stable/how-to/capture-warnings.html
=========================== short test summary info ===========================
ERROR temp/temp.py::test_user_info_creation - sqlalchemy.exc.CompileError: (i...
1 warning, 1 error in 1.04s
TEST CASE 1 Retry 2
---------------
from sqlalchemy.dialects.postgresql import JSONB, UUID
from sqlalchemy import (
    Column,
    Integer,
    String,
    TIMESTAMP,
    create_engine,
    Float,
    ForeignKey,
    Text,
    UniqueConstraint,
)
from sqlalchemy.ext.declarative import declarative_base
from sqlalchemy.sql import func
import uuid
from theory_evaluation.models import Base, ConsultantChat, CurrentUserTable, Curriculum, MentorChat, Projects, SprintIssues, TheoryEvalUserPerformance, UserInfo, UserRepo, UserScoreLog
import pytest
from sqlalchemy.orm import sessionmaker
from sqlalchemy.exc import CompileError

@pytest.fixture(scope="module")
def db_engine():
    engine = create_engine("sqlite:///:memory:")
    Base.metadata.create_all(engine)
    yield engine
    engine.dispose()

@pytest.fixture(scope="function")
def db_session(db_engine):
    connection = db_engine.connect()
    transaction = connection.begin()
    Session = sessionmaker(bind=connection)
    session = Session()
    yield session
    session.close()
    transaction.rollback()
    connection.close()

def test_user_info_creation(db_session):
    try:
        user = UserInfo(
            first_name="John",
            last_name="Doe",
            email="john.doe@example.com",
            github_username="johndoe",
            payment_date=None,
            current_duration=0,
            course_duration=0,
            end_date=None,
            status=1
        )
        db_session.add(user)
        db_session.commit()
    except CompileError as e:
        pytest.fail(f"CompileError occurred: {e}")
---------------
TEST CASE 1 Retry 2 - Result - Failed
Test Error -
c:\ChenKhoon\JupyterNotebook\GenerateUnitTestCases\unit_test_env\Lib\site-packages\pytest_asyncio\plugin.py:217: PytestDeprecationWarning: The configuration option "asyncio_default_fixture_loop_scope" is unset.
The event loop scope for asynchronous fixtures will default to the fixture caching scope. Future versions of pytest-asyncio will default the loop scope for asynchronous fixtures to function scope. Set the default fixture loop scope explicitly in order to avoid unexpected behavior in the future. Valid fixture loop scopes are: "function", "class", "module", "package", "session"

  warnings.warn(PytestDeprecationWarning(_DEFAULT_FIXTURE_LOOP_SCOPE_UNSET))
E                                                                        [100%]
=================================== ERRORS ====================================
__________________ ERROR at setup of test_user_info_creation __________________
unit_test_env\Lib\site-packages\sqlalchemy\sql\visitors.py:137: in _compiler_dispatch
    meth = getter(visitor)
E   AttributeError: 'SQLiteTypeCompiler' object has no attribute 'visit_JSONB'. Did you mean: 'visit_JSON'?

The above exception was the direct cause of the following exception:
unit_test_env\Lib\site-packages\sqlalchemy\sql\compiler.py:6716: in visit_create_table
    processed = self.process(
unit_test_env\Lib\site-packages\sqlalchemy\sql\compiler.py:932: in process
    return obj._compiler_dispatch(self, **kwargs)
unit_test_env\Lib\site-packages\sqlalchemy\sql\visitors.py:141: in _compiler_dispatch
    return meth(self, **kw)  # type: ignore  # noqa: E501
unit_test_env\Lib\site-packages\sqlalchemy\sql\compiler.py:6747: in visit_create_column
    text = self.get_column_specification(column, first_pk=first_pk)
unit_test_env\Lib\site-packages\sqlalchemy\dialects\sqlite\base.py:1598: in get_column_specification
    coltype = self.dialect.type_compiler_instance.process(
unit_test_env\Lib\site-packages\sqlalchemy\sql\compiler.py:977: in process
    return type_._compiler_dispatch(self, **kw)
unit_test_env\Lib\site-packages\sqlalchemy\sql\visitors.py:139: in _compiler_dispatch
    return visitor.visit_unsupported_compilation(self, err, **kw)  # type: ignore  # noqa: E501
unit_test_env\Lib\site-packages\sqlalchemy\sql\compiler.py:982: in visit_unsupported_compilation
    raise exc.UnsupportedCompilationError(self, element) from err
E   sqlalchemy.exc.UnsupportedCompilationError: Compiler <sqlalchemy.dialects.sqlite.base.SQLiteTypeCompiler object at 0x000001960C6BFCB0> can't render element of type JSONB (Background on this error at: https://sqlalche.me/e/20/l7de)

The above exception was the direct cause of the following exception:
temp\temp.py:24: in db_engine
    Base.metadata.create_all(engine)
unit_test_env\Lib\site-packages\sqlalchemy\sql\schema.py:5925: in create_all
    bind._run_ddl_visitor(
unit_test_env\Lib\site-packages\sqlalchemy\engine\base.py:3249: in _run_ddl_visitor
    conn._run_ddl_visitor(visitorcallable, element, **kwargs)
unit_test_env\Lib\site-packages\sqlalchemy\engine\base.py:2456: in _run_ddl_visitor
    visitorcallable(self.dialect, self, **kwargs).traverse_single(element)
unit_test_env\Lib\site-packages\sqlalchemy\sql\visitors.py:664: in traverse_single
    return meth(obj, **kw)
unit_test_env\Lib\site-packages\sqlalchemy\sql\ddl.py:981: in visit_metadata
    self.traverse_single(
unit_test_env\Lib\site-packages\sqlalchemy\sql\visitors.py:664: in traverse_single
    return meth(obj, **kw)
unit_test_env\Lib\site-packages\sqlalchemy\sql\ddl.py:1019: in visit_table
    )._invoke_with(self.connection)
unit_test_env\Lib\site-packages\sqlalchemy\sql\ddl.py:321: in _invoke_with
    return bind.execute(self)
unit_test_env\Lib\site-packages\sqlalchemy\engine\base.py:1416: in execute
    return meth(
unit_test_env\Lib\site-packages\sqlalchemy\sql\ddl.py:187: in _execute_on_connection
    return connection._execute_ddl(
unit_test_env\Lib\site-packages\sqlalchemy\engine\base.py:1524: in _execute_ddl
    compiled = ddl.compile(
unit_test_env\Lib\site-packages\sqlalchemy\sql\elements.py:308: in compile
    return self._compiler(dialect, **kw)
unit_test_env\Lib\site-packages\sqlalchemy\sql\ddl.py:76: in _compiler
    return dialect.ddl_compiler(dialect, self, **kw)
unit_test_env\Lib\site-packages\sqlalchemy\sql\compiler.py:886: in __init__
    self.string = self.process(self.statement, **compile_kwargs)
unit_test_env\Lib\site-packages\sqlalchemy\sql\compiler.py:932: in process
    return obj._compiler_dispatch(self, **kwargs)
unit_test_env\Lib\site-packages\sqlalchemy\sql\visitors.py:141: in _compiler_dispatch
    return meth(self, **kw)  # type: ignore  # noqa: E501
unit_test_env\Lib\site-packages\sqlalchemy\sql\compiler.py:6726: in visit_create_table
    raise exc.CompileError(
E   sqlalchemy.exc.CompileError: (in table 'projects', column 'problem_statement'): Compiler <sqlalchemy.dialects.sqlite.base.SQLiteTypeCompiler object at 0x000001960C6BFCB0> can't render element of type JSONB
============================== warnings summary ===============================
theory_evaluation\models.py:17
  C:\ChenKhoon\JupyterNotebook\GenerateUnitTestCases\theory_evaluation\models.py:17: MovedIn20Warning: The ``declarative_base()`` function is now available as sqlalchemy.orm.declarative_base(). (deprecated since: 2.0) (Background on SQLAlchemy 2.0 at: https://sqlalche.me/e/b8d9)
    Base = declarative_base()

-- Docs: https://docs.pytest.org/en/stable/how-to/capture-warnings.html
=========================== short test summary info ===========================
ERROR temp/temp.py::test_user_info_creation - sqlalchemy.exc.CompileError: (i...
1 warning, 1 error in 1.22s

TEST CASE 2 Retry 0
---------------
from sqlalchemy.dialects.postgresql import JSONB, UUID
from sqlalchemy import (
    Column,
    Integer,
    String,
    TIMESTAMP,
    create_engine,
    Float,
    ForeignKey,
    Text,
    UniqueConstraint,
)
from sqlalchemy.ext.declarative import declarative_base
from sqlalchemy.sql import func
import uuid
from theory_evaluation.models import Base, UserInfo
from sqlalchemy.orm import sessionmaker
import pytest

@pytest.fixture(scope="module")
def db_engine():
    engine = create_engine("sqlite:///:memory:")
    Base.metadata.create_all(engine)
    yield engine
    engine.dispose()

@pytest.fixture(scope="function")
def db_session(db_engine):
    connection = db_engine.connect()
    transaction = connection.begin()
    Session = sessionmaker(bind=connection)
    session = Session()
    yield session
    session.close()
    transaction.rollback()
    connection.close()

def test_user_info_unique_email_constraint(db_session):
    user1 = UserInfo(
        first_name="Jane",
        last_name="Doe",
        email="jane.doe@example.com",
        github_username="janedoe",
        payment_date=None,
        current_duration=0,
        course_duration=0,
        end_date=None,
        status=1
    )
    user2 = UserInfo(
        first_name="Jane",
        last_name="Smith",
        email="jane.doe@example.com",  # Duplicate email
        github_username="janesmith",
        payment_date=None,
        current_duration=0,
        course_duration=0,
        end_date=None,
        status=1
    )
    db_session.add(user1)
    db_session.commit()
---------------
TEST CASE 2 Retry 0 - Result - Failed
Test Error -
c:\ChenKhoon\JupyterNotebook\GenerateUnitTestCases\unit_test_env\Lib\site-packages\pytest_asyncio\plugin.py:217: PytestDeprecationWarning: The configuration option "asyncio_default_fixture_loop_scope" is unset.
The event loop scope for asynchronous fixtures will default to the fixture caching scope. Future versions of pytest-asyncio will default the loop scope for asynchronous fixtures to function scope. Set the default fixture loop scope explicitly in order to avoid unexpected behavior in the future. Valid fixture loop scopes are: "function", "class", "module", "package", "session"

  warnings.warn(PytestDeprecationWarning(_DEFAULT_FIXTURE_LOOP_SCOPE_UNSET))
E                                                                        [100%]
=================================== ERRORS ====================================
__________ ERROR at setup of test_user_info_unique_email_constraint ___________
unit_test_env\Lib\site-packages\sqlalchemy\sql\visitors.py:137: in _compiler_dispatch
    meth = getter(visitor)
E   AttributeError: 'SQLiteTypeCompiler' object has no attribute 'visit_JSONB'. Did you mean: 'visit_JSON'?

The above exception was the direct cause of the following exception:
unit_test_env\Lib\site-packages\sqlalchemy\sql\compiler.py:6716: in visit_create_table
    processed = self.process(
unit_test_env\Lib\site-packages\sqlalchemy\sql\compiler.py:932: in process
    return obj._compiler_dispatch(self, **kwargs)
unit_test_env\Lib\site-packages\sqlalchemy\sql\visitors.py:141: in _compiler_dispatch
    return meth(self, **kw)  # type: ignore  # noqa: E501
unit_test_env\Lib\site-packages\sqlalchemy\sql\compiler.py:6747: in visit_create_column
    text = self.get_column_specification(column, first_pk=first_pk)
unit_test_env\Lib\site-packages\sqlalchemy\dialects\sqlite\base.py:1598: in get_column_specification
    coltype = self.dialect.type_compiler_instance.process(
unit_test_env\Lib\site-packages\sqlalchemy\sql\compiler.py:977: in process
    return type_._compiler_dispatch(self, **kw)
unit_test_env\Lib\site-packages\sqlalchemy\sql\visitors.py:139: in _compiler_dispatch
    return visitor.visit_unsupported_compilation(self, err, **kw)  # type: ignore  # noqa: E501
unit_test_env\Lib\site-packages\sqlalchemy\sql\compiler.py:982: in visit_unsupported_compilation
    raise exc.UnsupportedCompilationError(self, element) from err
E   sqlalchemy.exc.UnsupportedCompilationError: Compiler <sqlalchemy.dialects.sqlite.base.SQLiteTypeCompiler object at 0x000001AA9506FCB0> can't render element of type JSONB (Background on this error at: https://sqlalche.me/e/20/l7de)

The above exception was the direct cause of the following exception:
temp\temp.py:23: in db_engine
    Base.metadata.create_all(engine)
unit_test_env\Lib\site-packages\sqlalchemy\sql\schema.py:5925: in create_all
    bind._run_ddl_visitor(
unit_test_env\Lib\site-packages\sqlalchemy\engine\base.py:3249: in _run_ddl_visitor
    conn._run_ddl_visitor(visitorcallable, element, **kwargs)
unit_test_env\Lib\site-packages\sqlalchemy\engine\base.py:2456: in _run_ddl_visitor
    visitorcallable(self.dialect, self, **kwargs).traverse_single(element)
unit_test_env\Lib\site-packages\sqlalchemy\sql\visitors.py:664: in traverse_single
    return meth(obj, **kw)
unit_test_env\Lib\site-packages\sqlalchemy\sql\ddl.py:981: in visit_metadata
    self.traverse_single(
unit_test_env\Lib\site-packages\sqlalchemy\sql\visitors.py:664: in traverse_single
    return meth(obj, **kw)
unit_test_env\Lib\site-packages\sqlalchemy\sql\ddl.py:1019: in visit_table
    )._invoke_with(self.connection)
unit_test_env\Lib\site-packages\sqlalchemy\sql\ddl.py:321: in _invoke_with
    return bind.execute(self)
unit_test_env\Lib\site-packages\sqlalchemy\engine\base.py:1416: in execute
    return meth(
unit_test_env\Lib\site-packages\sqlalchemy\sql\ddl.py:187: in _execute_on_connection
    return connection._execute_ddl(
unit_test_env\Lib\site-packages\sqlalchemy\engine\base.py:1524: in _execute_ddl
    compiled = ddl.compile(
unit_test_env\Lib\site-packages\sqlalchemy\sql\elements.py:308: in compile
    return self._compiler(dialect, **kw)
unit_test_env\Lib\site-packages\sqlalchemy\sql\ddl.py:76: in _compiler
    return dialect.ddl_compiler(dialect, self, **kw)
unit_test_env\Lib\site-packages\sqlalchemy\sql\compiler.py:886: in __init__
    self.string = self.process(self.statement, **compile_kwargs)
unit_test_env\Lib\site-packages\sqlalchemy\sql\compiler.py:932: in process
    return obj._compiler_dispatch(self, **kwargs)
unit_test_env\Lib\site-packages\sqlalchemy\sql\visitors.py:141: in _compiler_dispatch
    return meth(self, **kw)  # type: ignore  # noqa: E501
unit_test_env\Lib\site-packages\sqlalchemy\sql\compiler.py:6726: in visit_create_table
    raise exc.CompileError(
E   sqlalchemy.exc.CompileError: (in table 'projects', column 'problem_statement'): Compiler <sqlalchemy.dialects.sqlite.base.SQLiteTypeCompiler object at 0x000001AA9506FCB0> can't render element of type JSONB
============================== warnings summary ===============================
theory_evaluation\models.py:17
  C:\ChenKhoon\JupyterNotebook\GenerateUnitTestCases\theory_evaluation\models.py:17: MovedIn20Warning: The ``declarative_base()`` function is now available as sqlalchemy.orm.declarative_base(). (deprecated since: 2.0) (Background on SQLAlchemy 2.0 at: https://sqlalche.me/e/b8d9)
    Base = declarative_base()

-- Docs: https://docs.pytest.org/en/stable/how-to/capture-warnings.html
=========================== short test summary info ===========================
ERROR temp/temp.py::test_user_info_unique_email_constraint - sqlalchemy.exc.C...
1 warning, 1 error in 0.99s
TEST CASE 2 Retry 1
---------------
from sqlalchemy.dialects.postgresql import JSONB, UUID
from sqlalchemy import (
    Column,
    Integer,
    String,
    TIMESTAMP,
    create_engine,
    Float,
    ForeignKey,
    Text,
    UniqueConstraint,
)
from sqlalchemy.ext.declarative import declarative_base
from sqlalchemy.sql import func
import uuid
from theory_evaluation.models import Base, ConsultantChat, CurrentUserTable, Curriculum, MentorChat, Projects, SprintIssues, TheoryEvalUserPerformance, UserInfo, UserRepo, UserScoreLog
import pytest
from sqlalchemy.exc import IntegrityError
from sqlalchemy.orm import sessionmaker
from your_module import Base, UserInfo

@pytest.fixture(scope="module")
def db_engine():
    engine = create_engine("sqlite:///:memory:")
    Base.metadata.create_all(engine)
    yield engine
    engine.dispose()

@pytest.fixture(scope="function")
def db_session(db_engine):
    connection = db_engine.connect()
    transaction = connection.begin()
    Session = sessionmaker(bind=connection)
    session = Session()
    yield session
    session.close()
    transaction.rollback()
    connection.close()

def test_user_info_unique_email_constraint(db_session):
    user1 = UserInfo(
        first_name="Jane",
        last_name="Doe",
        email="jane.doe@example.com",
        github_username="janedoe",
        payment_date=None,
        current_duration=0,
        course_duration=0,
        end_date=None,
        status=1
    )
    user2 = UserInfo(
        first_name="Jane",
        last_name="Smith",
        email="jane.doe@example.com",  # Duplicate email
        github_username="janesmith",
        payment_date=None,
        current_duration=0,
        course_duration=0,
        end_date=None,
        status=1
    )
    db_session.add(user1)
    db_session.commit()
    
    db_session.add(user2)
    with pytest.raises(IntegrityError):
        db_session.commit()
---------------
TEST CASE 2 Retry 1 - Result - Failed
Test Error -
c:\ChenKhoon\JupyterNotebook\GenerateUnitTestCases\unit_test_env\Lib\site-packages\pytest_asyncio\plugin.py:217: PytestDeprecationWarning: The configuration option "asyncio_default_fixture_loop_scope" is unset.
The event loop scope for asynchronous fixtures will default to the fixture caching scope. Future versions of pytest-asyncio will default the loop scope for asynchronous fixtures to function scope. Set the default fixture loop scope explicitly in order to avoid unexpected behavior in the future. Valid fixture loop scopes are: "function", "class", "module", "package", "session"

  warnings.warn(PytestDeprecationWarning(_DEFAULT_FIXTURE_LOOP_SCOPE_UNSET))

=================================== ERRORS ====================================
________________________ ERROR collecting temp/temp.py ________________________
ImportError while importing test module 'C:\ChenKhoon\JupyterNotebook\GenerateUnitTestCases\temp\temp.py'.
Hint: make sure your test modules/packages have valid Python names.
Traceback:
C:\Users\User\AppData\Local\Programs\Python\Python313\Lib\importlib\__init__.py:88: in import_module
    return _bootstrap._gcd_import(name[level:], package, level)
temp\temp.py:20: in <module>
    from your_module import Base, UserInfo
E   ModuleNotFoundError: No module named 'your_module'
============================== warnings summary ===============================
theory_evaluation\models.py:17
  C:\ChenKhoon\JupyterNotebook\GenerateUnitTestCases\theory_evaluation\models.py:17: MovedIn20Warning: The ``declarative_base()`` function is now available as sqlalchemy.orm.declarative_base(). (deprecated since: 2.0) (Background on SQLAlchemy 2.0 at: https://sqlalche.me/e/b8d9)
    Base = declarative_base()

-- Docs: https://docs.pytest.org/en/stable/how-to/capture-warnings.html
=========================== short test summary info ===========================
ERROR temp/temp.py
!!!!!!!!!!!!!!!!!!! Interrupted: 1 error during collection !!!!!!!!!!!!!!!!!!!!
1 warning, 1 error in 0.74s
TEST CASE 2 Retry 2
---------------
from sqlalchemy.dialects.postgresql import JSONB, UUID
from sqlalchemy import (
    Column,
    Integer,
    String,
    TIMESTAMP,
    create_engine,
    Float,
    ForeignKey,
    Text,
    UniqueConstraint,
)
from sqlalchemy.ext.declarative import declarative_base
from sqlalchemy.sql import func
import uuid
from theory_evaluation.models import Base, ConsultantChat, CurrentUserTable, Curriculum, MentorChat, Projects, SprintIssues, TheoryEvalUserPerformance, UserInfo, UserRepo, UserScoreLog
import pytest
from sqlalchemy.exc import IntegrityError
from sqlalchemy.orm import sessionmaker

@pytest.fixture(scope="module")
def db_engine():
    engine = create_engine("sqlite:///:memory:")
    Base.metadata.create_all(engine)
    yield engine
    engine.dispose()

@pytest.fixture(scope="function")
def db_session(db_engine):
    connection = db_engine.connect()
    transaction = connection.begin()
    Session = sessionmaker(bind=connection)
    session = Session()
    yield session
    session.close()
    transaction.rollback()
    connection.close()

def test_user_info_unique_email_constraint(db_session):
    user1 = UserInfo(
        first_name="Jane",
        last_name="Doe",
        email="jane.doe@example.com",
        github_username="janedoe",
        payment_date=None,
        current_duration=0,
        course_duration=0,
        end_date=None,
        status=1
    )
    user2 = UserInfo(
        first_name="Jane",
        last_name="Smith",
        email="jane.doe@example.com",  # Duplicate email
        github_username="janesmith",
        payment_date=None,
        current_duration=0,
        course_duration=0,
        end_date=None,
        status=1
    )
    db_session.add(user1)
    db_session.commit()
    
    db_session.add(user2)
    with pytest.raises(IntegrityError):
        db_session.commit()
---------------
TEST CASE 2 Retry 2 - Result - Failed
Test Error -
c:\ChenKhoon\JupyterNotebook\GenerateUnitTestCases\unit_test_env\Lib\site-packages\pytest_asyncio\plugin.py:217: PytestDeprecationWarning: The configuration option "asyncio_default_fixture_loop_scope" is unset.
The event loop scope for asynchronous fixtures will default to the fixture caching scope. Future versions of pytest-asyncio will default the loop scope for asynchronous fixtures to function scope. Set the default fixture loop scope explicitly in order to avoid unexpected behavior in the future. Valid fixture loop scopes are: "function", "class", "module", "package", "session"

  warnings.warn(PytestDeprecationWarning(_DEFAULT_FIXTURE_LOOP_SCOPE_UNSET))
E                                                                        [100%]
=================================== ERRORS ====================================
__________ ERROR at setup of test_user_info_unique_email_constraint ___________
unit_test_env\Lib\site-packages\sqlalchemy\sql\visitors.py:137: in _compiler_dispatch
    meth = getter(visitor)
E   AttributeError: 'SQLiteTypeCompiler' object has no attribute 'visit_JSONB'. Did you mean: 'visit_JSON'?

The above exception was the direct cause of the following exception:
unit_test_env\Lib\site-packages\sqlalchemy\sql\compiler.py:6716: in visit_create_table
    processed = self.process(
unit_test_env\Lib\site-packages\sqlalchemy\sql\compiler.py:932: in process
    return obj._compiler_dispatch(self, **kwargs)
unit_test_env\Lib\site-packages\sqlalchemy\sql\visitors.py:141: in _compiler_dispatch
    return meth(self, **kw)  # type: ignore  # noqa: E501
unit_test_env\Lib\site-packages\sqlalchemy\sql\compiler.py:6747: in visit_create_column
    text = self.get_column_specification(column, first_pk=first_pk)
unit_test_env\Lib\site-packages\sqlalchemy\dialects\sqlite\base.py:1598: in get_column_specification
    coltype = self.dialect.type_compiler_instance.process(
unit_test_env\Lib\site-packages\sqlalchemy\sql\compiler.py:977: in process
    return type_._compiler_dispatch(self, **kw)
unit_test_env\Lib\site-packages\sqlalchemy\sql\visitors.py:139: in _compiler_dispatch
    return visitor.visit_unsupported_compilation(self, err, **kw)  # type: ignore  # noqa: E501
unit_test_env\Lib\site-packages\sqlalchemy\sql\compiler.py:982: in visit_unsupported_compilation
    raise exc.UnsupportedCompilationError(self, element) from err
E   sqlalchemy.exc.UnsupportedCompilationError: Compiler <sqlalchemy.dialects.sqlite.base.SQLiteTypeCompiler object at 0x000001AB223CFCB0> can't render element of type JSONB (Background on this error at: https://sqlalche.me/e/20/l7de)

The above exception was the direct cause of the following exception:
temp\temp.py:24: in db_engine
    Base.metadata.create_all(engine)
unit_test_env\Lib\site-packages\sqlalchemy\sql\schema.py:5925: in create_all
    bind._run_ddl_visitor(
unit_test_env\Lib\site-packages\sqlalchemy\engine\base.py:3249: in _run_ddl_visitor
    conn._run_ddl_visitor(visitorcallable, element, **kwargs)
unit_test_env\Lib\site-packages\sqlalchemy\engine\base.py:2456: in _run_ddl_visitor
    visitorcallable(self.dialect, self, **kwargs).traverse_single(element)
unit_test_env\Lib\site-packages\sqlalchemy\sql\visitors.py:664: in traverse_single
    return meth(obj, **kw)
unit_test_env\Lib\site-packages\sqlalchemy\sql\ddl.py:981: in visit_metadata
    self.traverse_single(
unit_test_env\Lib\site-packages\sqlalchemy\sql\visitors.py:664: in traverse_single
    return meth(obj, **kw)
unit_test_env\Lib\site-packages\sqlalchemy\sql\ddl.py:1019: in visit_table
    )._invoke_with(self.connection)
unit_test_env\Lib\site-packages\sqlalchemy\sql\ddl.py:321: in _invoke_with
    return bind.execute(self)
unit_test_env\Lib\site-packages\sqlalchemy\engine\base.py:1416: in execute
    return meth(
unit_test_env\Lib\site-packages\sqlalchemy\sql\ddl.py:187: in _execute_on_connection
    return connection._execute_ddl(
unit_test_env\Lib\site-packages\sqlalchemy\engine\base.py:1524: in _execute_ddl
    compiled = ddl.compile(
unit_test_env\Lib\site-packages\sqlalchemy\sql\elements.py:308: in compile
    return self._compiler(dialect, **kw)
unit_test_env\Lib\site-packages\sqlalchemy\sql\ddl.py:76: in _compiler
    return dialect.ddl_compiler(dialect, self, **kw)
unit_test_env\Lib\site-packages\sqlalchemy\sql\compiler.py:886: in __init__
    self.string = self.process(self.statement, **compile_kwargs)
unit_test_env\Lib\site-packages\sqlalchemy\sql\compiler.py:932: in process
    return obj._compiler_dispatch(self, **kwargs)
unit_test_env\Lib\site-packages\sqlalchemy\sql\visitors.py:141: in _compiler_dispatch
    return meth(self, **kw)  # type: ignore  # noqa: E501
unit_test_env\Lib\site-packages\sqlalchemy\sql\compiler.py:6726: in visit_create_table
    raise exc.CompileError(
E   sqlalchemy.exc.CompileError: (in table 'projects', column 'problem_statement'): Compiler <sqlalchemy.dialects.sqlite.base.SQLiteTypeCompiler object at 0x000001AB223CFCB0> can't render element of type JSONB
============================== warnings summary ===============================
theory_evaluation\models.py:17
  C:\ChenKhoon\JupyterNotebook\GenerateUnitTestCases\theory_evaluation\models.py:17: MovedIn20Warning: The ``declarative_base()`` function is now available as sqlalchemy.orm.declarative_base(). (deprecated since: 2.0) (Background on SQLAlchemy 2.0 at: https://sqlalche.me/e/b8d9)
    Base = declarative_base()

-- Docs: https://docs.pytest.org/en/stable/how-to/capture-warnings.html
=========================== short test summary info ===========================
ERROR temp/temp.py::test_user_info_unique_email_constraint - sqlalchemy.exc.C...
1 warning, 1 error in 1.03s

TEST CASE 3 Retry 0
---------------
from sqlalchemy.dialects.postgresql import JSONB, UUID
from sqlalchemy import (
    Column,
    Integer,
    String,
    TIMESTAMP,
    create_engine,
    Float,
    ForeignKey,
    Text,
    UniqueConstraint,
)
from sqlalchemy.ext.declarative import declarative_base
from sqlalchemy.sql import func
import uuid
from theory_evaluation.models import Base, Projects

@pytest.fixture(scope="module")
def db_engine():
    engine = create_engine("sqlite:///:memory:")
    Base.metadata.create_all(engine)
    yield engine
    engine.dispose()

@pytest.fixture(scope="function")
def db_session(db_engine):
    connection = db_engine.connect()
    transaction = connection.begin()
    Session = sessionmaker(bind=connection)
    session = Session()
    yield session
    session.close()
    transaction.rollback()
    connection.close()

def test_projects_creation(db_session):
    project = Projects(
        repo_name="example_repo",
        problem_statement={"key": "value"},
        bloblink="http://example.com/blob",
        mini_project_flag=1
    )
    db_session.add(project)
    db_session.commit()
---------------
TEST CASE 3 Retry 0 - Result - Failed
Test Error -
c:\ChenKhoon\JupyterNotebook\GenerateUnitTestCases\unit_test_env\Lib\site-packages\pytest_asyncio\plugin.py:217: PytestDeprecationWarning: The configuration option "asyncio_default_fixture_loop_scope" is unset.
The event loop scope for asynchronous fixtures will default to the fixture caching scope. Future versions of pytest-asyncio will default the loop scope for asynchronous fixtures to function scope. Set the default fixture loop scope explicitly in order to avoid unexpected behavior in the future. Valid fixture loop scopes are: "function", "class", "module", "package", "session"

  warnings.warn(PytestDeprecationWarning(_DEFAULT_FIXTURE_LOOP_SCOPE_UNSET))

=================================== ERRORS ====================================
________________________ ERROR collecting temp/temp.py ________________________
temp\temp.py:18: in <module>
    @pytest.fixture(scope="module")
E   NameError: name 'pytest' is not defined
============================== warnings summary ===============================
theory_evaluation\models.py:17
  C:\ChenKhoon\JupyterNotebook\GenerateUnitTestCases\theory_evaluation\models.py:17: MovedIn20Warning: The ``declarative_base()`` function is now available as sqlalchemy.orm.declarative_base(). (deprecated since: 2.0) (Background on SQLAlchemy 2.0 at: https://sqlalche.me/e/b8d9)
    Base = declarative_base()

-- Docs: https://docs.pytest.org/en/stable/how-to/capture-warnings.html
=========================== short test summary info ===========================
ERROR temp/temp.py - NameError: name 'pytest' is not defined
!!!!!!!!!!!!!!!!!!! Interrupted: 1 error during collection !!!!!!!!!!!!!!!!!!!!
1 warning, 1 error in 0.79s
TEST CASE 3 Retry 1
---------------
from sqlalchemy.dialects.postgresql import JSONB, UUID
from sqlalchemy import (
    Column,
    Integer,
    String,
    TIMESTAMP,
    create_engine,
    Float,
    ForeignKey,
    Text,
    UniqueConstraint,
)
from sqlalchemy.ext.declarative import declarative_base
from sqlalchemy.sql import func
import uuid
from theory_evaluation.models import Base, Projects
import pytest
from sqlalchemy.orm import sessionmaker

@pytest.fixture(scope="module")
def db_engine():
    engine = create_engine("sqlite:///:memory:")
    Base.metadata.create_all(engine)
    yield engine
    engine.dispose()

@pytest.fixture(scope="function")
def db_session(db_engine):
    connection = db_engine.connect()
    transaction = connection.begin()
    Session = sessionmaker(bind=connection)
    session = Session()
    yield session
    session.close()
    transaction.rollback()
    connection.close()

def test_projects_creation(db_session):
    project = Projects(
        repo_name="example_repo",
        problem_statement={"key": "value"},
        bloblink="http://example.com/blob",
        mini_project_flag=1
    )
    db_session.add(project)
    db_session.commit()
    
    retrieved_project = db_session.query(Projects).filter_by(repo_name="example_repo").first()
    assert retrieved_project is not None
    assert retrieved_project.repo_name == "example_repo"
    assert retrieved_project.problem_statement == {"key": "value"}
    assert retrieved_project.bloblink == "http://example.com/blob"
    assert retrieved_project.mini_project_flag == 1
---------------
TEST CASE 3 Retry 1 - Result - Failed
Test Error -
c:\ChenKhoon\JupyterNotebook\GenerateUnitTestCases\unit_test_env\Lib\site-packages\pytest_asyncio\plugin.py:217: PytestDeprecationWarning: The configuration option "asyncio_default_fixture_loop_scope" is unset.
The event loop scope for asynchronous fixtures will default to the fixture caching scope. Future versions of pytest-asyncio will default the loop scope for asynchronous fixtures to function scope. Set the default fixture loop scope explicitly in order to avoid unexpected behavior in the future. Valid fixture loop scopes are: "function", "class", "module", "package", "session"

  warnings.warn(PytestDeprecationWarning(_DEFAULT_FIXTURE_LOOP_SCOPE_UNSET))
E                                                                        [100%]
=================================== ERRORS ====================================
__________________ ERROR at setup of test_projects_creation ___________________
unit_test_env\Lib\site-packages\sqlalchemy\sql\visitors.py:137: in _compiler_dispatch
    meth = getter(visitor)
E   AttributeError: 'SQLiteTypeCompiler' object has no attribute 'visit_JSONB'. Did you mean: 'visit_JSON'?

The above exception was the direct cause of the following exception:
unit_test_env\Lib\site-packages\sqlalchemy\sql\compiler.py:6716: in visit_create_table
    processed = self.process(
unit_test_env\Lib\site-packages\sqlalchemy\sql\compiler.py:932: in process
    return obj._compiler_dispatch(self, **kwargs)
unit_test_env\Lib\site-packages\sqlalchemy\sql\visitors.py:141: in _compiler_dispatch
    return meth(self, **kw)  # type: ignore  # noqa: E501
unit_test_env\Lib\site-packages\sqlalchemy\sql\compiler.py:6747: in visit_create_column
    text = self.get_column_specification(column, first_pk=first_pk)
unit_test_env\Lib\site-packages\sqlalchemy\dialects\sqlite\base.py:1598: in get_column_specification
    coltype = self.dialect.type_compiler_instance.process(
unit_test_env\Lib\site-packages\sqlalchemy\sql\compiler.py:977: in process
    return type_._compiler_dispatch(self, **kw)
unit_test_env\Lib\site-packages\sqlalchemy\sql\visitors.py:139: in _compiler_dispatch
    return visitor.visit_unsupported_compilation(self, err, **kw)  # type: ignore  # noqa: E501
unit_test_env\Lib\site-packages\sqlalchemy\sql\compiler.py:982: in visit_unsupported_compilation
    raise exc.UnsupportedCompilationError(self, element) from err
E   sqlalchemy.exc.UnsupportedCompilationError: Compiler <sqlalchemy.dialects.sqlite.base.SQLiteTypeCompiler object at 0x0000020ED7EF3CB0> can't render element of type JSONB (Background on this error at: https://sqlalche.me/e/20/l7de)

The above exception was the direct cause of the following exception:
temp\temp.py:23: in db_engine
    Base.metadata.create_all(engine)
unit_test_env\Lib\site-packages\sqlalchemy\sql\schema.py:5925: in create_all
    bind._run_ddl_visitor(
unit_test_env\Lib\site-packages\sqlalchemy\engine\base.py:3249: in _run_ddl_visitor
    conn._run_ddl_visitor(visitorcallable, element, **kwargs)
unit_test_env\Lib\site-packages\sqlalchemy\engine\base.py:2456: in _run_ddl_visitor
    visitorcallable(self.dialect, self, **kwargs).traverse_single(element)
unit_test_env\Lib\site-packages\sqlalchemy\sql\visitors.py:664: in traverse_single
    return meth(obj, **kw)
unit_test_env\Lib\site-packages\sqlalchemy\sql\ddl.py:981: in visit_metadata
    self.traverse_single(
unit_test_env\Lib\site-packages\sqlalchemy\sql\visitors.py:664: in traverse_single
    return meth(obj, **kw)
unit_test_env\Lib\site-packages\sqlalchemy\sql\ddl.py:1019: in visit_table
    )._invoke_with(self.connection)
unit_test_env\Lib\site-packages\sqlalchemy\sql\ddl.py:321: in _invoke_with
    return bind.execute(self)
unit_test_env\Lib\site-packages\sqlalchemy\engine\base.py:1416: in execute
    return meth(
unit_test_env\Lib\site-packages\sqlalchemy\sql\ddl.py:187: in _execute_on_connection
    return connection._execute_ddl(
unit_test_env\Lib\site-packages\sqlalchemy\engine\base.py:1524: in _execute_ddl
    compiled = ddl.compile(
unit_test_env\Lib\site-packages\sqlalchemy\sql\elements.py:308: in compile
    return self._compiler(dialect, **kw)
unit_test_env\Lib\site-packages\sqlalchemy\sql\ddl.py:76: in _compiler
    return dialect.ddl_compiler(dialect, self, **kw)
unit_test_env\Lib\site-packages\sqlalchemy\sql\compiler.py:886: in __init__
    self.string = self.process(self.statement, **compile_kwargs)
unit_test_env\Lib\site-packages\sqlalchemy\sql\compiler.py:932: in process
    return obj._compiler_dispatch(self, **kwargs)
unit_test_env\Lib\site-packages\sqlalchemy\sql\visitors.py:141: in _compiler_dispatch
    return meth(self, **kw)  # type: ignore  # noqa: E501
unit_test_env\Lib\site-packages\sqlalchemy\sql\compiler.py:6726: in visit_create_table
    raise exc.CompileError(
E   sqlalchemy.exc.CompileError: (in table 'projects', column 'problem_statement'): Compiler <sqlalchemy.dialects.sqlite.base.SQLiteTypeCompiler object at 0x0000020ED7EF3CB0> can't render element of type JSONB
============================== warnings summary ===============================
theory_evaluation\models.py:17
  C:\ChenKhoon\JupyterNotebook\GenerateUnitTestCases\theory_evaluation\models.py:17: MovedIn20Warning: The ``declarative_base()`` function is now available as sqlalchemy.orm.declarative_base(). (deprecated since: 2.0) (Background on SQLAlchemy 2.0 at: https://sqlalche.me/e/b8d9)
    Base = declarative_base()

-- Docs: https://docs.pytest.org/en/stable/how-to/capture-warnings.html
=========================== short test summary info ===========================
ERROR temp/temp.py::test_projects_creation - sqlalchemy.exc.CompileError: (in...
1 warning, 1 error in 1.14s
TEST CASE 3 Retry 2
---------------
from sqlalchemy.dialects.postgresql import JSONB, UUID
from sqlalchemy import (
    Column,
    Integer,
    String,
    TIMESTAMP,
    create_engine,
    Float,
    ForeignKey,
    Text,
    UniqueConstraint,
)
from sqlalchemy.ext.declarative import declarative_base
from sqlalchemy.sql import func
import uuid
from theory_evaluation.models import Base, ConsultantChat, CurrentUserTable, Curriculum, MentorChat, Projects, SprintIssues, TheoryEvalUserPerformance, UserInfo, UserRepo, UserScoreLog
import pytest
from sqlalchemy.orm import sessionmaker
from sqlalchemy.dialects.sqlite import JSON
from your_module import Projects, Base

@pytest.fixture(scope="module")
def db_engine():
    engine = create_engine("sqlite:///:memory:")
    Base.metadata.create_all(engine)
    yield engine
    engine.dispose()

@pytest.fixture(scope="function")
def db_session(db_engine):
    connection = db_engine.connect()
    transaction = connection.begin()
    Session = sessionmaker(bind=connection)
    session = Session()
    yield session
    session.close()
    transaction.rollback()
    connection.close()

def test_projects_creation(db_session):
    project = Projects(
        repo_name="example_repo",
        problem_statement={"key": "value"},
        bloblink="http://example.com/blob",
        mini_project_flag=1
    )
    db_session.add(project)
    db_session.commit()
    
    retrieved_project = db_session.query(Projects).filter_by(repo_name="example_repo").first()
    assert retrieved_project is not None
    assert retrieved_project.repo_name == "example_repo"
    assert retrieved_project.problem_statement == {"key": "value"}
    assert retrieved_project.bloblink == "http://example.com/blob"
    assert retrieved_project.mini_project_flag == 1
---------------
TEST CASE 3 Retry 2 - Result - Failed
Test Error -
c:\ChenKhoon\JupyterNotebook\GenerateUnitTestCases\unit_test_env\Lib\site-packages\pytest_asyncio\plugin.py:217: PytestDeprecationWarning: The configuration option "asyncio_default_fixture_loop_scope" is unset.
The event loop scope for asynchronous fixtures will default to the fixture caching scope. Future versions of pytest-asyncio will default the loop scope for asynchronous fixtures to function scope. Set the default fixture loop scope explicitly in order to avoid unexpected behavior in the future. Valid fixture loop scopes are: "function", "class", "module", "package", "session"

  warnings.warn(PytestDeprecationWarning(_DEFAULT_FIXTURE_LOOP_SCOPE_UNSET))

=================================== ERRORS ====================================
________________________ ERROR collecting temp/temp.py ________________________
ImportError while importing test module 'C:\ChenKhoon\JupyterNotebook\GenerateUnitTestCases\temp\temp.py'.
Hint: make sure your test modules/packages have valid Python names.
Traceback:
C:\Users\User\AppData\Local\Programs\Python\Python313\Lib\importlib\__init__.py:88: in import_module
    return _bootstrap._gcd_import(name[level:], package, level)
temp\temp.py:20: in <module>
    from your_module import Projects, Base
E   ModuleNotFoundError: No module named 'your_module'
============================== warnings summary ===============================
theory_evaluation\models.py:17
  C:\ChenKhoon\JupyterNotebook\GenerateUnitTestCases\theory_evaluation\models.py:17: MovedIn20Warning: The ``declarative_base()`` function is now available as sqlalchemy.orm.declarative_base(). (deprecated since: 2.0) (Background on SQLAlchemy 2.0 at: https://sqlalche.me/e/b8d9)
    Base = declarative_base()

-- Docs: https://docs.pytest.org/en/stable/how-to/capture-warnings.html
=========================== short test summary info ===========================
ERROR temp/temp.py
!!!!!!!!!!!!!!!!!!! Interrupted: 1 error during collection !!!!!!!!!!!!!!!!!!!!
1 warning, 1 error in 0.81s

TEST CASE 4 Retry 0
---------------
from sqlalchemy.dialects.postgresql import JSONB, UUID
from sqlalchemy import (
    Column,
    Integer,
    String,
    TIMESTAMP,
    create_engine,
    Float,
    ForeignKey,
    Text,
    UniqueConstraint,
)
from sqlalchemy.ext.declarative import declarative_base
from sqlalchemy.sql import func
import uuid
from theory_evaluation.models import Base, UserRepo

@pytest.fixture(scope="module")
def db_engine():
    engine = create_engine("sqlite:///:memory:")
    Base.metadata.create_all(engine)
    yield engine
    engine.dispose()

@pytest.fixture(scope="function")
def db_session(db_engine):
    connection = db_engine.connect()
    transaction = connection.begin()
    Session = sessionmaker(bind=connection)
    session = Session()
    yield session
    session.close()
    transaction.rollback()
    connection.close()

def test_user_repo_unique_constraint(db_session):
    user_repo1 = UserRepo(
        user_id=1,
        psid=1,
        github_username="uniqueuser",
        repo_name="uniquerepo",
        github_url="http://github.com/uniqueuser/uniquerepo"
    )
    user_repo2 = UserRepo(
        user_id=2,
        psid=2,
        github_username="uniqueuser",
        repo_name="uniquerepo",  # Duplicate repo_name and github_username
        github_url="http://github.com/uniqueuser/uniquerepo2"
    )
    db_session.add(user_repo1)
    db_session.commit()
---------------
TEST CASE 4 Retry 0 - Result - Failed
Test Error -
c:\ChenKhoon\JupyterNotebook\GenerateUnitTestCases\unit_test_env\Lib\site-packages\pytest_asyncio\plugin.py:217: PytestDeprecationWarning: The configuration option "asyncio_default_fixture_loop_scope" is unset.
The event loop scope for asynchronous fixtures will default to the fixture caching scope. Future versions of pytest-asyncio will default the loop scope for asynchronous fixtures to function scope. Set the default fixture loop scope explicitly in order to avoid unexpected behavior in the future. Valid fixture loop scopes are: "function", "class", "module", "package", "session"

  warnings.warn(PytestDeprecationWarning(_DEFAULT_FIXTURE_LOOP_SCOPE_UNSET))

=================================== ERRORS ====================================
________________________ ERROR collecting temp/temp.py ________________________
temp\temp.py:18: in <module>
    @pytest.fixture(scope="module")
E   NameError: name 'pytest' is not defined
============================== warnings summary ===============================
theory_evaluation\models.py:17
  C:\ChenKhoon\JupyterNotebook\GenerateUnitTestCases\theory_evaluation\models.py:17: MovedIn20Warning: The ``declarative_base()`` function is now available as sqlalchemy.orm.declarative_base(). (deprecated since: 2.0) (Background on SQLAlchemy 2.0 at: https://sqlalche.me/e/b8d9)
    Base = declarative_base()

-- Docs: https://docs.pytest.org/en/stable/how-to/capture-warnings.html
=========================== short test summary info ===========================
ERROR temp/temp.py - NameError: name 'pytest' is not defined
!!!!!!!!!!!!!!!!!!! Interrupted: 1 error during collection !!!!!!!!!!!!!!!!!!!!
1 warning, 1 error in 0.65s
TEST CASE 4 Retry 1
---------------
from sqlalchemy.dialects.postgresql import JSONB, UUID
from sqlalchemy import (
    Column,
    Integer,
    String,
    TIMESTAMP,
    create_engine,
    Float,
    ForeignKey,
    Text,
    UniqueConstraint,
)
from sqlalchemy.ext.declarative import declarative_base
from sqlalchemy.sql import func
import uuid
from theory_evaluation.models import Base, ConsultantChat, CurrentUserTable, Curriculum, MentorChat, Projects, SprintIssues, TheoryEvalUserPerformance, UserInfo, UserRepo, UserScoreLog
import pytest
from sqlalchemy.exc import IntegrityError
from sqlalchemy.orm import sessionmaker

@pytest.fixture(scope="module")
def db_engine():
    engine = create_engine("sqlite:///:memory:")
    Base.metadata.create_all(engine)
    yield engine
    engine.dispose()

@pytest.fixture(scope="function")
def db_session(db_engine):
    connection = db_engine.connect()
    transaction = connection.begin()
    Session = sessionmaker(bind=connection)
    session = Session()
    yield session
    session.close()
    transaction.rollback()
    connection.close()

def test_user_repo_unique_constraint(db_session):
    user_repo1 = UserRepo(
        user_id=1,
        psid=1,
        github_username="uniqueuser",
        repo_name="uniquerepo",
        github_url="http://github.com/uniqueuser/uniquerepo"
    )
    user_repo2 = UserRepo(
        user_id=2,
        psid=2,
        github_username="uniqueuser",
        repo_name="uniquerepo",  # Duplicate repo_name and github_username
        github_url="http://github.com/uniqueuser/uniquerepo2"
    )
    db_session.add(user_repo1)
    db_session.commit()

    db_session.add(user_repo2)
    with pytest.raises(IntegrityError):
        db_session.commit()
---------------
TEST CASE 4 Retry 1 - Result - Failed
Test Error -
c:\ChenKhoon\JupyterNotebook\GenerateUnitTestCases\unit_test_env\Lib\site-packages\pytest_asyncio\plugin.py:217: PytestDeprecationWarning: The configuration option "asyncio_default_fixture_loop_scope" is unset.
The event loop scope for asynchronous fixtures will default to the fixture caching scope. Future versions of pytest-asyncio will default the loop scope for asynchronous fixtures to function scope. Set the default fixture loop scope explicitly in order to avoid unexpected behavior in the future. Valid fixture loop scopes are: "function", "class", "module", "package", "session"

  warnings.warn(PytestDeprecationWarning(_DEFAULT_FIXTURE_LOOP_SCOPE_UNSET))
E                                                                        [100%]
=================================== ERRORS ====================================
_____________ ERROR at setup of test_user_repo_unique_constraint ______________
unit_test_env\Lib\site-packages\sqlalchemy\sql\visitors.py:137: in _compiler_dispatch
    meth = getter(visitor)
E   AttributeError: 'SQLiteTypeCompiler' object has no attribute 'visit_JSONB'. Did you mean: 'visit_JSON'?

The above exception was the direct cause of the following exception:
unit_test_env\Lib\site-packages\sqlalchemy\sql\compiler.py:6716: in visit_create_table
    processed = self.process(
unit_test_env\Lib\site-packages\sqlalchemy\sql\compiler.py:932: in process
    return obj._compiler_dispatch(self, **kwargs)
unit_test_env\Lib\site-packages\sqlalchemy\sql\visitors.py:141: in _compiler_dispatch
    return meth(self, **kw)  # type: ignore  # noqa: E501
unit_test_env\Lib\site-packages\sqlalchemy\sql\compiler.py:6747: in visit_create_column
    text = self.get_column_specification(column, first_pk=first_pk)
unit_test_env\Lib\site-packages\sqlalchemy\dialects\sqlite\base.py:1598: in get_column_specification
    coltype = self.dialect.type_compiler_instance.process(
unit_test_env\Lib\site-packages\sqlalchemy\sql\compiler.py:977: in process
    return type_._compiler_dispatch(self, **kw)
unit_test_env\Lib\site-packages\sqlalchemy\sql\visitors.py:139: in _compiler_dispatch
    return visitor.visit_unsupported_compilation(self, err, **kw)  # type: ignore  # noqa: E501
unit_test_env\Lib\site-packages\sqlalchemy\sql\compiler.py:982: in visit_unsupported_compilation
    raise exc.UnsupportedCompilationError(self, element) from err
E   sqlalchemy.exc.UnsupportedCompilationError: Compiler <sqlalchemy.dialects.sqlite.base.SQLiteTypeCompiler object at 0x0000023DA1CA7E00> can't render element of type JSONB (Background on this error at: https://sqlalche.me/e/20/l7de)

The above exception was the direct cause of the following exception:
temp\temp.py:24: in db_engine
    Base.metadata.create_all(engine)
unit_test_env\Lib\site-packages\sqlalchemy\sql\schema.py:5925: in create_all
    bind._run_ddl_visitor(
unit_test_env\Lib\site-packages\sqlalchemy\engine\base.py:3249: in _run_ddl_visitor
    conn._run_ddl_visitor(visitorcallable, element, **kwargs)
unit_test_env\Lib\site-packages\sqlalchemy\engine\base.py:2456: in _run_ddl_visitor
    visitorcallable(self.dialect, self, **kwargs).traverse_single(element)
unit_test_env\Lib\site-packages\sqlalchemy\sql\visitors.py:664: in traverse_single
    return meth(obj, **kw)
unit_test_env\Lib\site-packages\sqlalchemy\sql\ddl.py:981: in visit_metadata
    self.traverse_single(
unit_test_env\Lib\site-packages\sqlalchemy\sql\visitors.py:664: in traverse_single
    return meth(obj, **kw)
unit_test_env\Lib\site-packages\sqlalchemy\sql\ddl.py:1019: in visit_table
    )._invoke_with(self.connection)
unit_test_env\Lib\site-packages\sqlalchemy\sql\ddl.py:321: in _invoke_with
    return bind.execute(self)
unit_test_env\Lib\site-packages\sqlalchemy\engine\base.py:1416: in execute
    return meth(
unit_test_env\Lib\site-packages\sqlalchemy\sql\ddl.py:187: in _execute_on_connection
    return connection._execute_ddl(
unit_test_env\Lib\site-packages\sqlalchemy\engine\base.py:1524: in _execute_ddl
    compiled = ddl.compile(
unit_test_env\Lib\site-packages\sqlalchemy\sql\elements.py:308: in compile
    return self._compiler(dialect, **kw)
unit_test_env\Lib\site-packages\sqlalchemy\sql\ddl.py:76: in _compiler
    return dialect.ddl_compiler(dialect, self, **kw)
unit_test_env\Lib\site-packages\sqlalchemy\sql\compiler.py:886: in __init__
    self.string = self.process(self.statement, **compile_kwargs)
unit_test_env\Lib\site-packages\sqlalchemy\sql\compiler.py:932: in process
    return obj._compiler_dispatch(self, **kwargs)
unit_test_env\Lib\site-packages\sqlalchemy\sql\visitors.py:141: in _compiler_dispatch
    return meth(self, **kw)  # type: ignore  # noqa: E501
unit_test_env\Lib\site-packages\sqlalchemy\sql\compiler.py:6726: in visit_create_table
    raise exc.CompileError(
E   sqlalchemy.exc.CompileError: (in table 'projects', column 'problem_statement'): Compiler <sqlalchemy.dialects.sqlite.base.SQLiteTypeCompiler object at 0x0000023DA1CA7E00> can't render element of type JSONB
============================== warnings summary ===============================
theory_evaluation\models.py:17
  C:\ChenKhoon\JupyterNotebook\GenerateUnitTestCases\theory_evaluation\models.py:17: MovedIn20Warning: The ``declarative_base()`` function is now available as sqlalchemy.orm.declarative_base(). (deprecated since: 2.0) (Background on SQLAlchemy 2.0 at: https://sqlalche.me/e/b8d9)
    Base = declarative_base()

-- Docs: https://docs.pytest.org/en/stable/how-to/capture-warnings.html
=========================== short test summary info ===========================
ERROR temp/temp.py::test_user_repo_unique_constraint - sqlalchemy.exc.Compile...
1 warning, 1 error in 1.06s
TEST CASE 4 Retry 2
---------------
from sqlalchemy.dialects.postgresql import JSONB, UUID
from sqlalchemy import (
    Column,
    Integer,
    String,
    TIMESTAMP,
    create_engine,
    Float,
    ForeignKey,
    Text,
    UniqueConstraint,
)
from sqlalchemy.ext.declarative import declarative_base
from sqlalchemy.sql import func
import uuid
from theory_evaluation.models import Base, ConsultantChat, CurrentUserTable, Curriculum, MentorChat, Projects, SprintIssues, TheoryEvalUserPerformance, UserInfo, UserRepo, UserScoreLog
import pytest
from sqlalchemy.exc import IntegrityError
from sqlalchemy.orm import sessionmaker

# Setup an in-memory SQLite database for testing
engine = create_engine('sqlite:///:memory:')
Base.metadata.create_all(engine)
Session = sessionmaker(bind=engine)

@pytest.fixture(scope="module")
def db_engine():
    engine = create_engine("sqlite:///:memory:")
    Base.metadata.create_all(engine)
    yield engine
    engine.dispose()

@pytest.fixture(scope="function")
def db_session():
    session = Session()
    yield session
    session.rollback()
    session.close()

def test_user_repo_unique_constraint(db_session):
    user_repo1 = UserRepo(
        user_id=1,
        psid=1,
        github_username="uniqueuser",
        repo_name="uniquerepo",
        github_url="http://github.com/uniqueuser/uniquerepo"
    )
    user_repo2 = UserRepo(
        user_id=2,
        psid=2,
        github_username="uniqueuser",
        repo_name="uniquerepo",  # Duplicate repo_name and github_username
        github_url="http://github.com/uniqueuser/uniquerepo2"
    )
    db_session.add(user_repo1)
    db_session.commit()

    db_session.add(user_repo2)
    with pytest.raises(IntegrityError):
        db_session.commit()
---------------
TEST CASE 4 Retry 2 - Result - Failed
Test Error -
c:\ChenKhoon\JupyterNotebook\GenerateUnitTestCases\unit_test_env\Lib\site-packages\pytest_asyncio\plugin.py:217: PytestDeprecationWarning: The configuration option "asyncio_default_fixture_loop_scope" is unset.
The event loop scope for asynchronous fixtures will default to the fixture caching scope. Future versions of pytest-asyncio will default the loop scope for asynchronous fixtures to function scope. Set the default fixture loop scope explicitly in order to avoid unexpected behavior in the future. Valid fixture loop scopes are: "function", "class", "module", "package", "session"

  warnings.warn(PytestDeprecationWarning(_DEFAULT_FIXTURE_LOOP_SCOPE_UNSET))

=================================== ERRORS ====================================
________________________ ERROR collecting temp/temp.py ________________________
unit_test_env\Lib\site-packages\sqlalchemy\sql\visitors.py:137: in _compiler_dispatch
    meth = getter(visitor)
E   AttributeError: 'SQLiteTypeCompiler' object has no attribute 'visit_JSONB'. Did you mean: 'visit_JSON'?

The above exception was the direct cause of the following exception:
unit_test_env\Lib\site-packages\sqlalchemy\sql\compiler.py:6716: in visit_create_table
    processed = self.process(
unit_test_env\Lib\site-packages\sqlalchemy\sql\compiler.py:932: in process
    return obj._compiler_dispatch(self, **kwargs)
unit_test_env\Lib\site-packages\sqlalchemy\sql\visitors.py:141: in _compiler_dispatch
    return meth(self, **kw)  # type: ignore  # noqa: E501
unit_test_env\Lib\site-packages\sqlalchemy\sql\compiler.py:6747: in visit_create_column
    text = self.get_column_specification(column, first_pk=first_pk)
unit_test_env\Lib\site-packages\sqlalchemy\dialects\sqlite\base.py:1598: in get_column_specification
    coltype = self.dialect.type_compiler_instance.process(
unit_test_env\Lib\site-packages\sqlalchemy\sql\compiler.py:977: in process
    return type_._compiler_dispatch(self, **kw)
unit_test_env\Lib\site-packages\sqlalchemy\sql\visitors.py:139: in _compiler_dispatch
    return visitor.visit_unsupported_compilation(self, err, **kw)  # type: ignore  # noqa: E501
unit_test_env\Lib\site-packages\sqlalchemy\sql\compiler.py:982: in visit_unsupported_compilation
    raise exc.UnsupportedCompilationError(self, element) from err
E   sqlalchemy.exc.UnsupportedCompilationError: Compiler <sqlalchemy.dialects.sqlite.base.SQLiteTypeCompiler object at 0x000002A60B25F8C0> can't render element of type JSONB (Background on this error at: https://sqlalche.me/e/20/l7de)

The above exception was the direct cause of the following exception:
temp\temp.py:23: in <module>
    Base.metadata.create_all(engine)
unit_test_env\Lib\site-packages\sqlalchemy\sql\schema.py:5925: in create_all
    bind._run_ddl_visitor(
unit_test_env\Lib\site-packages\sqlalchemy\engine\base.py:3249: in _run_ddl_visitor
    conn._run_ddl_visitor(visitorcallable, element, **kwargs)
unit_test_env\Lib\site-packages\sqlalchemy\engine\base.py:2456: in _run_ddl_visitor
    visitorcallable(self.dialect, self, **kwargs).traverse_single(element)
unit_test_env\Lib\site-packages\sqlalchemy\sql\visitors.py:664: in traverse_single
    return meth(obj, **kw)
unit_test_env\Lib\site-packages\sqlalchemy\sql\ddl.py:981: in visit_metadata
    self.traverse_single(
unit_test_env\Lib\site-packages\sqlalchemy\sql\visitors.py:664: in traverse_single
    return meth(obj, **kw)
unit_test_env\Lib\site-packages\sqlalchemy\sql\ddl.py:1019: in visit_table
    )._invoke_with(self.connection)
unit_test_env\Lib\site-packages\sqlalchemy\sql\ddl.py:321: in _invoke_with
    return bind.execute(self)
unit_test_env\Lib\site-packages\sqlalchemy\engine\base.py:1416: in execute
    return meth(
unit_test_env\Lib\site-packages\sqlalchemy\sql\ddl.py:187: in _execute_on_connection
    return connection._execute_ddl(
unit_test_env\Lib\site-packages\sqlalchemy\engine\base.py:1524: in _execute_ddl
    compiled = ddl.compile(
unit_test_env\Lib\site-packages\sqlalchemy\sql\elements.py:308: in compile
    return self._compiler(dialect, **kw)
unit_test_env\Lib\site-packages\sqlalchemy\sql\ddl.py:76: in _compiler
    return dialect.ddl_compiler(dialect, self, **kw)
unit_test_env\Lib\site-packages\sqlalchemy\sql\compiler.py:886: in __init__
    self.string = self.process(self.statement, **compile_kwargs)
unit_test_env\Lib\site-packages\sqlalchemy\sql\compiler.py:932: in process
    return obj._compiler_dispatch(self, **kwargs)
unit_test_env\Lib\site-packages\sqlalchemy\sql\visitors.py:141: in _compiler_dispatch
    return meth(self, **kw)  # type: ignore  # noqa: E501
unit_test_env\Lib\site-packages\sqlalchemy\sql\compiler.py:6726: in visit_create_table
    raise exc.CompileError(
E   sqlalchemy.exc.CompileError: (in table 'projects', column 'problem_statement'): Compiler <sqlalchemy.dialects.sqlite.base.SQLiteTypeCompiler object at 0x000002A60B25F8C0> can't render element of type JSONB
============================== warnings summary ===============================
theory_evaluation\models.py:17
  C:\ChenKhoon\JupyterNotebook\GenerateUnitTestCases\theory_evaluation\models.py:17: MovedIn20Warning: The ``declarative_base()`` function is now available as sqlalchemy.orm.declarative_base(). (deprecated since: 2.0) (Background on SQLAlchemy 2.0 at: https://sqlalche.me/e/b8d9)
    Base = declarative_base()

-- Docs: https://docs.pytest.org/en/stable/how-to/capture-warnings.html
=========================== short test summary info ===========================
ERROR temp/temp.py - sqlalchemy.exc.CompileError: (in table 'projects', colum...
!!!!!!!!!!!!!!!!!!! Interrupted: 1 error during collection !!!!!!!!!!!!!!!!!!!!
1 warning, 1 error in 1.50s

TEST CASE 5 Retry 0
---------------
from sqlalchemy.dialects.postgresql import JSONB, UUID
from sqlalchemy import (
    Column,
    Integer,
    String,
    TIMESTAMP,
    create_engine,
    Float,
    ForeignKey,
    Text,
    UniqueConstraint,
)
from sqlalchemy.ext.declarative import declarative_base
from sqlalchemy.sql import func
import uuid
from theory_evaluation.models import Base, Curriculum

@pytest.fixture(scope="module")
def db_engine():
    engine = create_engine("sqlite:///:memory:")
    Base.metadata.create_all(engine)
    yield engine
    engine.dispose()

@pytest.fixture(scope="function")
def db_session(db_engine):
    connection = db_engine.connect()
    transaction = connection.begin()
    Session = sessionmaker(bind=connection)
    session = Session()
    yield session
    session.close()
    transaction.rollback()
    connection.close()

def test_curriculum_creation(db_session):
    curriculum = Curriculum(
        question="What is Python?",
        marking_scheme="Correctness, Efficiency",
        model_answer="Python is a programming language."
    )
    db_session.add(curriculum)
    db_session.commit()
---------------
TEST CASE 5 Retry 0 - Result - Failed
Test Error -
c:\ChenKhoon\JupyterNotebook\GenerateUnitTestCases\unit_test_env\Lib\site-packages\pytest_asyncio\plugin.py:217: PytestDeprecationWarning: The configuration option "asyncio_default_fixture_loop_scope" is unset.
The event loop scope for asynchronous fixtures will default to the fixture caching scope. Future versions of pytest-asyncio will default the loop scope for asynchronous fixtures to function scope. Set the default fixture loop scope explicitly in order to avoid unexpected behavior in the future. Valid fixture loop scopes are: "function", "class", "module", "package", "session"

  warnings.warn(PytestDeprecationWarning(_DEFAULT_FIXTURE_LOOP_SCOPE_UNSET))

=================================== ERRORS ====================================
________________________ ERROR collecting temp/temp.py ________________________
temp\temp.py:18: in <module>
    @pytest.fixture(scope="module")
E   NameError: name 'pytest' is not defined
============================== warnings summary ===============================
theory_evaluation\models.py:17
  C:\ChenKhoon\JupyterNotebook\GenerateUnitTestCases\theory_evaluation\models.py:17: MovedIn20Warning: The ``declarative_base()`` function is now available as sqlalchemy.orm.declarative_base(). (deprecated since: 2.0) (Background on SQLAlchemy 2.0 at: https://sqlalche.me/e/b8d9)
    Base = declarative_base()

-- Docs: https://docs.pytest.org/en/stable/how-to/capture-warnings.html
=========================== short test summary info ===========================
ERROR temp/temp.py - NameError: name 'pytest' is not defined
!!!!!!!!!!!!!!!!!!! Interrupted: 1 error during collection !!!!!!!!!!!!!!!!!!!!
1 warning, 1 error in 0.99s
TEST CASE 5 Retry 1
---------------
from sqlalchemy.dialects.postgresql import JSONB, UUID
from sqlalchemy import (
    Column,
    Integer,
    String,
    TIMESTAMP,
    create_engine,
    Float,
    ForeignKey,
    Text,
    UniqueConstraint,
)
from sqlalchemy.ext.declarative import declarative_base
from sqlalchemy.sql import func
import uuid
from theory_evaluation.models import Base, ConsultantChat, CurrentUserTable, Curriculum, MentorChat, Projects, SprintIssues, TheoryEvalUserPerformance, UserInfo, UserRepo, UserScoreLog
import pytest
from sqlalchemy.orm import sessionmaker

@pytest.fixture(scope="module")
def db_engine():
    engine = create_engine("sqlite:///:memory:")
    Base.metadata.create_all(engine)
    yield engine
    engine.dispose()

@pytest.fixture(scope="function")
def db_session(db_engine):
    connection = db_engine.connect()
    transaction = connection.begin()
    Session = sessionmaker(bind=connection)
    session = Session()
    yield session
    session.close()
    transaction.rollback()
    connection.close()

def test_curriculum_creation(db_session):
    curriculum = Curriculum(
        question="What is Python?",
        marking_scheme="Correctness, Efficiency",
        model_answer="Python is a programming language."
    )
    db_session.add(curriculum)
    db_session.commit()
    retrieved_curriculum = db_session.query(Curriculum).filter_by(question="What is Python?").first()
    assert retrieved_curriculum is not None
    assert retrieved_curriculum.marking_scheme == "Correctness, Efficiency"
    assert retrieved_curriculum.model_answer == "Python is a programming language."
---------------
TEST CASE 5 Retry 1 - Result - Failed
Test Error -
c:\ChenKhoon\JupyterNotebook\GenerateUnitTestCases\unit_test_env\Lib\site-packages\pytest_asyncio\plugin.py:217: PytestDeprecationWarning: The configuration option "asyncio_default_fixture_loop_scope" is unset.
The event loop scope for asynchronous fixtures will default to the fixture caching scope. Future versions of pytest-asyncio will default the loop scope for asynchronous fixtures to function scope. Set the default fixture loop scope explicitly in order to avoid unexpected behavior in the future. Valid fixture loop scopes are: "function", "class", "module", "package", "session"

  warnings.warn(PytestDeprecationWarning(_DEFAULT_FIXTURE_LOOP_SCOPE_UNSET))
E                                                                        [100%]
=================================== ERRORS ====================================
_________________ ERROR at setup of test_curriculum_creation __________________
unit_test_env\Lib\site-packages\sqlalchemy\sql\visitors.py:137: in _compiler_dispatch
    meth = getter(visitor)
E   AttributeError: 'SQLiteTypeCompiler' object has no attribute 'visit_JSONB'. Did you mean: 'visit_JSON'?

The above exception was the direct cause of the following exception:
unit_test_env\Lib\site-packages\sqlalchemy\sql\compiler.py:6716: in visit_create_table
    processed = self.process(
unit_test_env\Lib\site-packages\sqlalchemy\sql\compiler.py:932: in process
    return obj._compiler_dispatch(self, **kwargs)
unit_test_env\Lib\site-packages\sqlalchemy\sql\visitors.py:141: in _compiler_dispatch
    return meth(self, **kw)  # type: ignore  # noqa: E501
unit_test_env\Lib\site-packages\sqlalchemy\sql\compiler.py:6747: in visit_create_column
    text = self.get_column_specification(column, first_pk=first_pk)
unit_test_env\Lib\site-packages\sqlalchemy\dialects\sqlite\base.py:1598: in get_column_specification
    coltype = self.dialect.type_compiler_instance.process(
unit_test_env\Lib\site-packages\sqlalchemy\sql\compiler.py:977: in process
    return type_._compiler_dispatch(self, **kw)
unit_test_env\Lib\site-packages\sqlalchemy\sql\visitors.py:139: in _compiler_dispatch
    return visitor.visit_unsupported_compilation(self, err, **kw)  # type: ignore  # noqa: E501
unit_test_env\Lib\site-packages\sqlalchemy\sql\compiler.py:982: in visit_unsupported_compilation
    raise exc.UnsupportedCompilationError(self, element) from err
E   sqlalchemy.exc.UnsupportedCompilationError: Compiler <sqlalchemy.dialects.sqlite.base.SQLiteTypeCompiler object at 0x000002CC2948FCB0> can't render element of type JSONB (Background on this error at: https://sqlalche.me/e/20/l7de)

The above exception was the direct cause of the following exception:
temp\temp.py:23: in db_engine
    Base.metadata.create_all(engine)
unit_test_env\Lib\site-packages\sqlalchemy\sql\schema.py:5925: in create_all
    bind._run_ddl_visitor(
unit_test_env\Lib\site-packages\sqlalchemy\engine\base.py:3249: in _run_ddl_visitor
    conn._run_ddl_visitor(visitorcallable, element, **kwargs)
unit_test_env\Lib\site-packages\sqlalchemy\engine\base.py:2456: in _run_ddl_visitor
    visitorcallable(self.dialect, self, **kwargs).traverse_single(element)
unit_test_env\Lib\site-packages\sqlalchemy\sql\visitors.py:664: in traverse_single
    return meth(obj, **kw)
unit_test_env\Lib\site-packages\sqlalchemy\sql\ddl.py:981: in visit_metadata
    self.traverse_single(
unit_test_env\Lib\site-packages\sqlalchemy\sql\visitors.py:664: in traverse_single
    return meth(obj, **kw)
unit_test_env\Lib\site-packages\sqlalchemy\sql\ddl.py:1019: in visit_table
    )._invoke_with(self.connection)
unit_test_env\Lib\site-packages\sqlalchemy\sql\ddl.py:321: in _invoke_with
    return bind.execute(self)
unit_test_env\Lib\site-packages\sqlalchemy\engine\base.py:1416: in execute
    return meth(
unit_test_env\Lib\site-packages\sqlalchemy\sql\ddl.py:187: in _execute_on_connection
    return connection._execute_ddl(
unit_test_env\Lib\site-packages\sqlalchemy\engine\base.py:1524: in _execute_ddl
    compiled = ddl.compile(
unit_test_env\Lib\site-packages\sqlalchemy\sql\elements.py:308: in compile
    return self._compiler(dialect, **kw)
unit_test_env\Lib\site-packages\sqlalchemy\sql\ddl.py:76: in _compiler
    return dialect.ddl_compiler(dialect, self, **kw)
unit_test_env\Lib\site-packages\sqlalchemy\sql\compiler.py:886: in __init__
    self.string = self.process(self.statement, **compile_kwargs)
unit_test_env\Lib\site-packages\sqlalchemy\sql\compiler.py:932: in process
    return obj._compiler_dispatch(self, **kwargs)
unit_test_env\Lib\site-packages\sqlalchemy\sql\visitors.py:141: in _compiler_dispatch
    return meth(self, **kw)  # type: ignore  # noqa: E501
unit_test_env\Lib\site-packages\sqlalchemy\sql\compiler.py:6726: in visit_create_table
    raise exc.CompileError(
E   sqlalchemy.exc.CompileError: (in table 'projects', column 'problem_statement'): Compiler <sqlalchemy.dialects.sqlite.base.SQLiteTypeCompiler object at 0x000002CC2948FCB0> can't render element of type JSONB
============================== warnings summary ===============================
theory_evaluation\models.py:17
  C:\ChenKhoon\JupyterNotebook\GenerateUnitTestCases\theory_evaluation\models.py:17: MovedIn20Warning: The ``declarative_base()`` function is now available as sqlalchemy.orm.declarative_base(). (deprecated since: 2.0) (Background on SQLAlchemy 2.0 at: https://sqlalche.me/e/b8d9)
    Base = declarative_base()

-- Docs: https://docs.pytest.org/en/stable/how-to/capture-warnings.html
=========================== short test summary info ===========================
ERROR temp/temp.py::test_curriculum_creation - sqlalchemy.exc.CompileError: (...
1 warning, 1 error in 1.14s
TEST CASE 5 Retry 2
---------------
from sqlalchemy.dialects.postgresql import JSONB, UUID
from sqlalchemy import (
    Column,
    Integer,
    String,
    TIMESTAMP,
    create_engine,
    Float,
    ForeignKey,
    Text,
    UniqueConstraint,
)
from sqlalchemy.ext.declarative import declarative_base
from sqlalchemy.sql import func
import uuid
from theory_evaluation.models import Base, ConsultantChat, CurrentUserTable, Curriculum, MentorChat, Projects, SprintIssues, TheoryEvalUserPerformance, UserInfo, UserRepo, UserScoreLog
import pytest
from sqlalchemy.orm import sessionmaker
from your_module import Curriculum, Base, Projects

@pytest.fixture(scope="module")
def db_engine():
    engine = create_engine("sqlite:///:memory:")
    Base.metadata.create_all(engine)
    yield engine
    engine.dispose()

@pytest.fixture(scope="function")
def db_session(db_engine):
    connection = db_engine.connect()
    transaction = connection.begin()
    Session = sessionmaker(bind=connection)
    session = Session()
    yield session
    session.close()
    transaction.rollback()
    connection.close()

def test_curriculum_creation(db_session):
    curriculum = Curriculum(
        question="What is Python?",
        marking_scheme="Correctness, Efficiency",
        model_answer="Python is a programming language."
    )
    db_session.add(curriculum)
    db_session.commit()
    retrieved_curriculum = db_session.query(Curriculum).filter_by(question="What is Python?").first()
    assert retrieved_curriculum is not None
    assert retrieved_curriculum.marking_scheme == "Correctness, Efficiency"
    assert retrieved_curriculum.model_answer == "Python is a programming language."
---------------
TEST CASE 5 Retry 2 - Result - Failed
Test Error -
c:\ChenKhoon\JupyterNotebook\GenerateUnitTestCases\unit_test_env\Lib\site-packages\pytest_asyncio\plugin.py:217: PytestDeprecationWarning: The configuration option "asyncio_default_fixture_loop_scope" is unset.
The event loop scope for asynchronous fixtures will default to the fixture caching scope. Future versions of pytest-asyncio will default the loop scope for asynchronous fixtures to function scope. Set the default fixture loop scope explicitly in order to avoid unexpected behavior in the future. Valid fixture loop scopes are: "function", "class", "module", "package", "session"

  warnings.warn(PytestDeprecationWarning(_DEFAULT_FIXTURE_LOOP_SCOPE_UNSET))

=================================== ERRORS ====================================
________________________ ERROR collecting temp/temp.py ________________________
ImportError while importing test module 'C:\ChenKhoon\JupyterNotebook\GenerateUnitTestCases\temp\temp.py'.
Hint: make sure your test modules/packages have valid Python names.
Traceback:
C:\Users\User\AppData\Local\Programs\Python\Python313\Lib\importlib\__init__.py:88: in import_module
    return _bootstrap._gcd_import(name[level:], package, level)
temp\temp.py:19: in <module>
    from your_module import Curriculum, Base, Projects
E   ModuleNotFoundError: No module named 'your_module'
============================== warnings summary ===============================
theory_evaluation\models.py:17
  C:\ChenKhoon\JupyterNotebook\GenerateUnitTestCases\theory_evaluation\models.py:17: MovedIn20Warning: The ``declarative_base()`` function is now available as sqlalchemy.orm.declarative_base(). (deprecated since: 2.0) (Background on SQLAlchemy 2.0 at: https://sqlalche.me/e/b8d9)
    Base = declarative_base()

-- Docs: https://docs.pytest.org/en/stable/how-to/capture-warnings.html
=========================== short test summary info ===========================
ERROR temp/temp.py
!!!!!!!!!!!!!!!!!!! Interrupted: 1 error during collection !!!!!!!!!!!!!!!!!!!!
1 warning, 1 error in 0.79s
