
TEST CASE 1 Retry 0
---------------
from sqlalchemy.dialects.postgresql import JSONB, UUID
from sqlalchemy import (
    Column,
    Integer,
    String,
    TIMESTAMP,
    create_engine,
    Float,
    ForeignKey,
    Text,
    UniqueConstraint,
)
from sqlalchemy.ext.declarative import declarative_base
from sqlalchemy.sql import func
import uuid
from theory_evaluation.models import Base, ConsultantChat, CurrentUserTable, Curriculum, MentorChat, Projects, SprintIssues, TheoryEvalUserPerformance, UserInfo, UserRepo, UserScoreLog
import pytest

@pytest.fixture(scope="module")
def db_engine():
    engine = create_engine(DATABASE_URL)
    Base.metadata.create_all(engine)
    yield engine
    Base.metadata.drop_all(engine)

@pytest.fixture(scope="function")
def db_session(db_engine):
    connection = db_engine.connect()
    transaction = connection.begin()
    Session = sessionmaker(bind=connection)
    session = Session()
    yield session
    session.close()
    transaction.rollback()
    connection.close()

def test_user_info_creation(db_session):
    user = UserInfo(
        first_name="John",
        last_name="Doe",
        email="john.doe@example.com",
        github_username="johndoe",
        payment_date=None,
        current_duration=0,
        course_duration=0,
        end_date=None,
        status=1
    )
    db_session.add(user)
    db_session.commit()

---------------
TEST CASE 1 Retry 0 - Result - Failed
Test Error - c:\ChenKhoon\JupyterNotebook\GenerateUnitTestCases\unit_test_env\Lib\site-packages\pytest_asyncio\plugin.py:217: PytestDeprecationWarning: The configuration option "asyncio_default_fixture_loop_scope" is unset.
The event loop scope for asynchronous fixtures will default to the fixture caching scope. Future versions of pytest-asyncio will default the loop scope for asynchronous fixtures to function scope. Set the default fixture loop scope explicitly in order to avoid unexpected behavior in the future. Valid fixture loop scopes are: "function", "class", "module", "package", "session"

  warnings.warn(PytestDeprecationWarning(_DEFAULT_FIXTURE_LOOP_SCOPE_UNSET))
E                                                                        [100%]
=================================== ERRORS ====================================
__________________ ERROR at setup of test_user_info_creation __________________
temp\temp.py:21: in db_engine
    engine = create_engine(DATABASE_URL)
E   NameError: name 'DATABASE_URL' is not defined
============================== warnings summary ===============================
theory_evaluation\models.py:17
  C:\ChenKhoon\JupyterNotebook\GenerateUnitTestCases\theory_evaluation\models.py:17: MovedIn20Warning: The ``declarative_base()`` function is now available as sqlalchemy.orm.declarative_base(). (deprecated since: 2.0) (Background on SQLAlchemy 2.0 at: https://sqlalche.me/e/b8d9)
    Base = declarative_base()

-- Docs: https://docs.pytest.org/en/stable/how-to/capture-warnings.html
=========================== short test summary info ===========================
ERROR temp/temp.py::test_user_info_creation - NameError: name 'DATABASE_URL' ...
1 warning, 1 error in 0.78s
TEST CASE 1 Retry 1
---------------
from sqlalchemy.dialects.postgresql import JSONB, UUID
from sqlalchemy import (
    Column,
    Integer,
    String,
    TIMESTAMP,
    create_engine,
    Float,
    ForeignKey,
    Text,
    UniqueConstraint,
)
from sqlalchemy.ext.declarative import declarative_base
from sqlalchemy.sql import func
import uuid
from theory_evaluation.models import Base, ConsultantChat, CurrentUserTable, Curriculum, MentorChat, Projects, SprintIssues, TheoryEvalUserPerformance, UserInfo, UserRepo, UserScoreLog
import pytest

@pytest.fixture(scope="module")
def db_engine():
    engine = create_engine(DATABASE_URL)
    Base.metadata.create_all(engine)
    yield engine
    Base.metadata.drop_all(engine)

@pytest.fixture(scope="function")
def db_session(db_engine):
    connection = db_engine.connect()
    transaction = connection.begin()
    Session = sessionmaker(bind=connection)
    session = Session()
    yield session
    session.close()
    transaction.rollback()
    connection.close()

import os
from sqlalchemy import create_engine
from sqlalchemy.orm import sessionmaker
from dotenv import load_dotenv

load_dotenv()

DATABASE_URL = os.getenv("DATABASE_URL")
engine = create_engine(DATABASE_URL)
SessionLocal = sessionmaker(autocommit=False, autoflush=False, bind=engine)

def test_user_info_creation():
    session = SessionLocal()
    try:
        user = UserInfo(
            first_name="John",
            last_name="Doe",
            email="john.doe@example.com",
            github_username="johndoe",
            payment_date=None,
            current_duration=0,
            course_duration=0,
            end_date=None,
            status=1
        )
        session.add(user)
        session.commit()
    finally:
        session.close()

---------------
TEST CASE 1 Retry 1 - Result - Failed
Test Error - c:\ChenKhoon\JupyterNotebook\GenerateUnitTestCases\unit_test_env\Lib\site-packages\pytest_asyncio\plugin.py:217: PytestDeprecationWarning: The configuration option "asyncio_default_fixture_loop_scope" is unset.
The event loop scope for asynchronous fixtures will default to the fixture caching scope. Future versions of pytest-asyncio will default the loop scope for asynchronous fixtures to function scope. Set the default fixture loop scope explicitly in order to avoid unexpected behavior in the future. Valid fixture loop scopes are: "function", "class", "module", "package", "session"

  warnings.warn(PytestDeprecationWarning(_DEFAULT_FIXTURE_LOOP_SCOPE_UNSET))

=================================== ERRORS ====================================
________________________ ERROR collecting temp/temp.py ________________________
temp\temp.py:45: in <module>
    engine = create_engine(DATABASE_URL)
<string>:2: in create_engine
    ???
unit_test_env\Lib\site-packages\sqlalchemy\util\deprecations.py:281: in warned
    return fn(*args, **kwargs)  # type: ignore[no-any-return]
unit_test_env\Lib\site-packages\sqlalchemy\engine\create.py:549: in create_engine
    u = _url.make_url(url)
unit_test_env\Lib\site-packages\sqlalchemy\engine\url.py:860: in make_url
    raise exc.ArgumentError(
E   sqlalchemy.exc.ArgumentError: Expected string or URL object, got None
============================== warnings summary ===============================
theory_evaluation\models.py:17
  C:\ChenKhoon\JupyterNotebook\GenerateUnitTestCases\theory_evaluation\models.py:17: MovedIn20Warning: The ``declarative_base()`` function is now available as sqlalchemy.orm.declarative_base(). (deprecated since: 2.0) (Background on SQLAlchemy 2.0 at: https://sqlalche.me/e/b8d9)
    Base = declarative_base()

-- Docs: https://docs.pytest.org/en/stable/how-to/capture-warnings.html
=========================== short test summary info ===========================
ERROR temp/temp.py - sqlalchemy.exc.ArgumentError: Expected string or URL obj...
!!!!!!!!!!!!!!!!!!! Interrupted: 1 error during collection !!!!!!!!!!!!!!!!!!!!
1 warning, 1 error in 0.80s
TEST CASE 1 Retry 2
---------------
from sqlalchemy.dialects.postgresql import JSONB, UUID
from sqlalchemy import (
    Column,
    Integer,
    String,
    TIMESTAMP,
    create_engine,
    Float,
    ForeignKey,
    Text,
    UniqueConstraint,
)
from sqlalchemy.ext.declarative import declarative_base
from sqlalchemy.sql import func
import uuid
from theory_evaluation.models import Base, ConsultantChat, CurrentUserTable, Curriculum, MentorChat, Projects, SprintIssues, TheoryEvalUserPerformance, UserInfo, UserRepo, UserScoreLog
import pytest

@pytest.fixture(scope="module")
def db_engine():
    engine = create_engine(DATABASE_URL)
    Base.metadata.create_all(engine)
    yield engine
    Base.metadata.drop_all(engine)

@pytest.fixture(scope="function")
def db_session(db_engine):
    connection = db_engine.connect()
    transaction = connection.begin()
    Session = sessionmaker(bind=connection)
    session = Session()
    yield session
    session.close()
    transaction.rollback()
    connection.close()

import os
from sqlalchemy import create_engine
from sqlalchemy.orm import sessionmaker
from dotenv import load_dotenv
from sqlalchemy.exc import ArgumentError

load_dotenv()

DATABASE_URL = os.getenv("DATABASE_URL")
if not DATABASE_URL:
    raise ArgumentError("DATABASE_URL environment variable not set")

engine = create_engine(DATABASE_URL)
SessionLocal = sessionmaker(autocommit=False, autoflush=False, bind=engine)

def test_user_info_creation():
    session = SessionLocal()
    try:
        user = UserInfo(
            first_name="John",
            last_name="Doe",
            email="john.doe@example.com",
            github_username="johndoe",
            payment_date=None,
            current_duration=0,
            course_duration=0,
            end_date=None,
            status=1
        )
        session.add(user)
        session.commit()
    finally:
        session.close()

---------------
TEST CASE 1 Retry 2 - Result - Failed
Test Error - c:\ChenKhoon\JupyterNotebook\GenerateUnitTestCases\unit_test_env\Lib\site-packages\pytest_asyncio\plugin.py:217: PytestDeprecationWarning: The configuration option "asyncio_default_fixture_loop_scope" is unset.
The event loop scope for asynchronous fixtures will default to the fixture caching scope. Future versions of pytest-asyncio will default the loop scope for asynchronous fixtures to function scope. Set the default fixture loop scope explicitly in order to avoid unexpected behavior in the future. Valid fixture loop scopes are: "function", "class", "module", "package", "session"

  warnings.warn(PytestDeprecationWarning(_DEFAULT_FIXTURE_LOOP_SCOPE_UNSET))

=================================== ERRORS ====================================
________________________ ERROR collecting temp/temp.py ________________________
temp\temp.py:47: in <module>
    raise ArgumentError("DATABASE_URL environment variable not set")
E   sqlalchemy.exc.ArgumentError: DATABASE_URL environment variable not set
============================== warnings summary ===============================
theory_evaluation\models.py:17
  C:\ChenKhoon\JupyterNotebook\GenerateUnitTestCases\theory_evaluation\models.py:17: MovedIn20Warning: The ``declarative_base()`` function is now available as sqlalchemy.orm.declarative_base(). (deprecated since: 2.0) (Background on SQLAlchemy 2.0 at: https://sqlalche.me/e/b8d9)
    Base = declarative_base()

-- Docs: https://docs.pytest.org/en/stable/how-to/capture-warnings.html
=========================== short test summary info ===========================
ERROR temp/temp.py - sqlalchemy.exc.ArgumentError: DATABASE_URL environment v...
!!!!!!!!!!!!!!!!!!! Interrupted: 1 error during collection !!!!!!!!!!!!!!!!!!!!
1 warning, 1 error in 0.78s

TEST CASE 3 Retry 0
---------------
from sqlalchemy.dialects.postgresql import JSONB, UUID
from sqlalchemy import (
    Column,
    Integer,
    String,
    TIMESTAMP,
    create_engine,
    Float,
    ForeignKey,
    Text,
    UniqueConstraint,
)
from sqlalchemy.ext.declarative import declarative_base
from sqlalchemy.sql import func
import uuid
from theory_evaluation.models import Base, ConsultantChat, CurrentUserTable, Curriculum, MentorChat, Projects, SprintIssues, TheoryEvalUserPerformance, UserInfo, UserRepo, UserScoreLog
import pytest

@pytest.fixture(scope="module")
def db_engine():
    engine = create_engine(DATABASE_URL)
    Base.metadata.create_all(engine)
    yield engine
    Base.metadata.drop_all(engine)

@pytest.fixture(scope="function")
def db_session(db_engine):
    connection = db_engine.connect()
    transaction = connection.begin()
    Session = sessionmaker(bind=connection)
    session = Session()
    yield session
    session.close()
    transaction.rollback()
    connection.close()

def test_projects_creation(db_session):
    project = Projects(
        repo_name="example_repo",
        problem_statement={"key": "value"},
        bloblink="http://example.com/blob",
        mini_project_flag=1
    )
    db_session.add(project)
    db_session.commit()

---------------
TEST CASE 3 Retry 0 - Result - Failed
Test Error - c:\ChenKhoon\JupyterNotebook\GenerateUnitTestCases\unit_test_env\Lib\site-packages\pytest_asyncio\plugin.py:217: PytestDeprecationWarning: The configuration option "asyncio_default_fixture_loop_scope" is unset.
The event loop scope for asynchronous fixtures will default to the fixture caching scope. Future versions of pytest-asyncio will default the loop scope for asynchronous fixtures to function scope. Set the default fixture loop scope explicitly in order to avoid unexpected behavior in the future. Valid fixture loop scopes are: "function", "class", "module", "package", "session"

  warnings.warn(PytestDeprecationWarning(_DEFAULT_FIXTURE_LOOP_SCOPE_UNSET))
E                                                                        [100%]
=================================== ERRORS ====================================
__________________ ERROR at setup of test_projects_creation ___________________
temp\temp.py:21: in db_engine
    engine = create_engine(DATABASE_URL)
E   NameError: name 'DATABASE_URL' is not defined
============================== warnings summary ===============================
theory_evaluation\models.py:17
  C:\ChenKhoon\JupyterNotebook\GenerateUnitTestCases\theory_evaluation\models.py:17: MovedIn20Warning: The ``declarative_base()`` function is now available as sqlalchemy.orm.declarative_base(). (deprecated since: 2.0) (Background on SQLAlchemy 2.0 at: https://sqlalche.me/e/b8d9)
    Base = declarative_base()

-- Docs: https://docs.pytest.org/en/stable/how-to/capture-warnings.html
=========================== short test summary info ===========================
ERROR temp/temp.py::test_projects_creation - NameError: name 'DATABASE_URL' i...
1 warning, 1 error in 0.56s
TEST CASE 3 Retry 1
---------------
from sqlalchemy.dialects.postgresql import JSONB, UUID
from sqlalchemy import (
    Column,
    Integer,
    String,
    TIMESTAMP,
    create_engine,
    Float,
    ForeignKey,
    Text,
    UniqueConstraint,
)
from sqlalchemy.ext.declarative import declarative_base
from sqlalchemy.sql import func
import uuid
from theory_evaluation.models import Base, ConsultantChat, CurrentUserTable, Curriculum, MentorChat, Projects, SprintIssues, TheoryEvalUserPerformance, UserInfo, UserRepo, UserScoreLog
import pytest

@pytest.fixture(scope="module")
def db_engine():
    engine = create_engine(DATABASE_URL)
    Base.metadata.create_all(engine)
    yield engine
    Base.metadata.drop_all(engine)

@pytest.fixture(scope="function")
def db_session(db_engine):
    connection = db_engine.connect()
    transaction = connection.begin()
    Session = sessionmaker(bind=connection)
    session = Session()
    yield session
    session.close()
    transaction.rollback()
    connection.close()

import pytest
from sqlalchemy import create_engine
from sqlalchemy.orm import sessionmaker
from your_module import Base, Projects  # Replace 'your_module' with the actual module name

DATABASE_URL = "sqlite:///:memory:"  # Use an in-memory SQLite database for testing

@pytest.fixture(scope='function')
def db_session():
    engine = create_engine(DATABASE_URL)
    Base.metadata.create_all(engine)
    Session = sessionmaker(bind=engine)
    session = Session()
    yield session
    session.close()
    Base.metadata.drop_all(engine)

def test_projects_creation(db_session):
    project = Projects(
        repo_name="example_repo",
        problem_statement={"key": "value"},
        bloblink="http://example.com/blob",
        mini_project_flag=1
    )
    db_session.add(project)
    db_session.commit()
    assert db_session.query(Projects).filter_by(repo_name="example_repo").first() is not None

---------------
TEST CASE 3 Retry 1 - Result - Failed
Test Error - c:\ChenKhoon\JupyterNotebook\GenerateUnitTestCases\unit_test_env\Lib\site-packages\pytest_asyncio\plugin.py:217: PytestDeprecationWarning: The configuration option "asyncio_default_fixture_loop_scope" is unset.
The event loop scope for asynchronous fixtures will default to the fixture caching scope. Future versions of pytest-asyncio will default the loop scope for asynchronous fixtures to function scope. Set the default fixture loop scope explicitly in order to avoid unexpected behavior in the future. Valid fixture loop scopes are: "function", "class", "module", "package", "session"

  warnings.warn(PytestDeprecationWarning(_DEFAULT_FIXTURE_LOOP_SCOPE_UNSET))

=================================== ERRORS ====================================
________________________ ERROR collecting temp/temp.py ________________________
ImportError while importing test module 'C:\ChenKhoon\JupyterNotebook\GenerateUnitTestCases\temp\temp.py'.
Hint: make sure your test modules/packages have valid Python names.
Traceback:
C:\Users\User\AppData\Local\Programs\Python\Python313\Lib\importlib\__init__.py:88: in import_module
    return _bootstrap._gcd_import(name[level:], package, level)
temp\temp.py:40: in <module>
    from your_module import Base, Projects  # Replace 'your_module' with the actual module name
E   ModuleNotFoundError: No module named 'your_module'
============================== warnings summary ===============================
theory_evaluation\models.py:17
  C:\ChenKhoon\JupyterNotebook\GenerateUnitTestCases\theory_evaluation\models.py:17: MovedIn20Warning: The ``declarative_base()`` function is now available as sqlalchemy.orm.declarative_base(). (deprecated since: 2.0) (Background on SQLAlchemy 2.0 at: https://sqlalche.me/e/b8d9)
    Base = declarative_base()

-- Docs: https://docs.pytest.org/en/stable/how-to/capture-warnings.html
=========================== short test summary info ===========================
ERROR temp/temp.py
!!!!!!!!!!!!!!!!!!! Interrupted: 1 error during collection !!!!!!!!!!!!!!!!!!!!
1 warning, 1 error in 0.85s
TEST CASE 3 Retry 2
---------------
from sqlalchemy.dialects.postgresql import JSONB, UUID
from sqlalchemy import (
    Column,
    Integer,
    String,
    TIMESTAMP,
    create_engine,
    Float,
    ForeignKey,
    Text,
    UniqueConstraint,
)
from sqlalchemy.ext.declarative import declarative_base
from sqlalchemy.sql import func
import uuid
from theory_evaluation.models import Base, ConsultantChat, CurrentUserTable, Curriculum, MentorChat, Projects, SprintIssues, TheoryEvalUserPerformance, UserInfo, UserRepo, UserScoreLog
import pytest

@pytest.fixture(scope="module")
def db_engine():
    engine = create_engine(DATABASE_URL)
    Base.metadata.create_all(engine)
    yield engine
    Base.metadata.drop_all(engine)

@pytest.fixture(scope="function")
def db_session(db_engine):
    connection = db_engine.connect()
    transaction = connection.begin()
    Session = sessionmaker(bind=connection)
    session = Session()
    yield session
    session.close()
    transaction.rollback()
    connection.close()

import pytest
from sqlalchemy import create_engine
from sqlalchemy.orm import sessionmaker
from your_actual_module_name import Base, Projects  # Replace 'your_actual_module_name' with the actual module name

DATABASE_URL = "sqlite:///:memory:"  # Use an in-memory SQLite database for testing

@pytest.fixture(scope='function')
def db_session():
    engine = create_engine(DATABASE_URL)
    Base.metadata.create_all(engine)
    Session = sessionmaker(bind=engine)
    session = Session()
    yield session
    session.close()
    Base.metadata.drop_all(engine)

def test_projects_creation(db_session):
    project = Projects(
        repo_name="example_repo",
        problem_statement={"key": "value"},
        bloblink="http://example.com/blob",
        mini_project_flag=1
    )
    db_session.add(project)
    db_session.commit()
    assert db_session.query(Projects).filter_by(repo_name="example_repo").first() is not None

---------------
TEST CASE 3 Retry 2 - Result - Failed
Test Error - c:\ChenKhoon\JupyterNotebook\GenerateUnitTestCases\unit_test_env\Lib\site-packages\pytest_asyncio\plugin.py:217: PytestDeprecationWarning: The configuration option "asyncio_default_fixture_loop_scope" is unset.
The event loop scope for asynchronous fixtures will default to the fixture caching scope. Future versions of pytest-asyncio will default the loop scope for asynchronous fixtures to function scope. Set the default fixture loop scope explicitly in order to avoid unexpected behavior in the future. Valid fixture loop scopes are: "function", "class", "module", "package", "session"

  warnings.warn(PytestDeprecationWarning(_DEFAULT_FIXTURE_LOOP_SCOPE_UNSET))

=================================== ERRORS ====================================
________________________ ERROR collecting temp/temp.py ________________________
ImportError while importing test module 'C:\ChenKhoon\JupyterNotebook\GenerateUnitTestCases\temp\temp.py'.
Hint: make sure your test modules/packages have valid Python names.
Traceback:
C:\Users\User\AppData\Local\Programs\Python\Python313\Lib\importlib\__init__.py:88: in import_module
    return _bootstrap._gcd_import(name[level:], package, level)
temp\temp.py:40: in <module>
    from your_actual_module_name import Base, Projects  # Replace 'your_actual_module_name' with the actual module name
E   ModuleNotFoundError: No module named 'your_actual_module_name'
============================== warnings summary ===============================
theory_evaluation\models.py:17
  C:\ChenKhoon\JupyterNotebook\GenerateUnitTestCases\theory_evaluation\models.py:17: MovedIn20Warning: The ``declarative_base()`` function is now available as sqlalchemy.orm.declarative_base(). (deprecated since: 2.0) (Background on SQLAlchemy 2.0 at: https://sqlalche.me/e/b8d9)
    Base = declarative_base()

-- Docs: https://docs.pytest.org/en/stable/how-to/capture-warnings.html
=========================== short test summary info ===========================
ERROR temp/temp.py
!!!!!!!!!!!!!!!!!!! Interrupted: 1 error during collection !!!!!!!!!!!!!!!!!!!!
1 warning, 1 error in 0.76s

TEST CASE 4 Retry 0
---------------
from sqlalchemy.dialects.postgresql import JSONB, UUID
from sqlalchemy import (
    Column,
    Integer,
    String,
    TIMESTAMP,
    create_engine,
    Float,
    ForeignKey,
    Text,
    UniqueConstraint,
)
from sqlalchemy.ext.declarative import declarative_base
from sqlalchemy.sql import func
import uuid
from theory_evaluation.models import Base, ConsultantChat, CurrentUserTable, Curriculum, MentorChat, Projects, SprintIssues, TheoryEvalUserPerformance, UserInfo, UserRepo, UserScoreLog
import pytest

@pytest.fixture(scope="module")
def db_engine():
    engine = create_engine(DATABASE_URL)
    Base.metadata.create_all(engine)
    yield engine
    Base.metadata.drop_all(engine)

@pytest.fixture(scope="function")
def db_session(db_engine):
    connection = db_engine.connect()
    transaction = connection.begin()
    Session = sessionmaker(bind=connection)
    session = Session()
    yield session
    session.close()
    transaction.rollback()
    connection.close()

def test_user_repo_unique_constraint(db_session):
    user = UserInfo(
        first_name="Alice",
        last_name="Smith",
        email="alice.smith@example.com",
        github_username="alicesmith",
        payment_date=None,
        current_duration=0,
        course_duration=0,
        end_date=None,
        status=1
    )
    db_session.add(user)
    db_session.commit()

---------------
TEST CASE 4 Retry 0 - Result - Failed
Test Error - c:\ChenKhoon\JupyterNotebook\GenerateUnitTestCases\unit_test_env\Lib\site-packages\pytest_asyncio\plugin.py:217: PytestDeprecationWarning: The configuration option "asyncio_default_fixture_loop_scope" is unset.
The event loop scope for asynchronous fixtures will default to the fixture caching scope. Future versions of pytest-asyncio will default the loop scope for asynchronous fixtures to function scope. Set the default fixture loop scope explicitly in order to avoid unexpected behavior in the future. Valid fixture loop scopes are: "function", "class", "module", "package", "session"

  warnings.warn(PytestDeprecationWarning(_DEFAULT_FIXTURE_LOOP_SCOPE_UNSET))
E                                                                        [100%]
=================================== ERRORS ====================================
_____________ ERROR at setup of test_user_repo_unique_constraint ______________
temp\temp.py:21: in db_engine
    engine = create_engine(DATABASE_URL)
E   NameError: name 'DATABASE_URL' is not defined
============================== warnings summary ===============================
theory_evaluation\models.py:17
  C:\ChenKhoon\JupyterNotebook\GenerateUnitTestCases\theory_evaluation\models.py:17: MovedIn20Warning: The ``declarative_base()`` function is now available as sqlalchemy.orm.declarative_base(). (deprecated since: 2.0) (Background on SQLAlchemy 2.0 at: https://sqlalche.me/e/b8d9)
    Base = declarative_base()

-- Docs: https://docs.pytest.org/en/stable/how-to/capture-warnings.html
=========================== short test summary info ===========================
ERROR temp/temp.py::test_user_repo_unique_constraint - NameError: name 'DATAB...
1 warning, 1 error in 0.95s
TEST CASE 4 Retry 1
---------------
from sqlalchemy.dialects.postgresql import JSONB, UUID
from sqlalchemy import (
    Column,
    Integer,
    String,
    TIMESTAMP,
    create_engine,
    Float,
    ForeignKey,
    Text,
    UniqueConstraint,
)
from sqlalchemy.ext.declarative import declarative_base
from sqlalchemy.sql import func
import uuid
from theory_evaluation.models import Base, ConsultantChat, CurrentUserTable, Curriculum, MentorChat, Projects, SprintIssues, TheoryEvalUserPerformance, UserInfo, UserRepo, UserScoreLog
import pytest

@pytest.fixture(scope="module")
def db_engine():
    engine = create_engine(DATABASE_URL)
    Base.metadata.create_all(engine)
    yield engine
    Base.metadata.drop_all(engine)

@pytest.fixture(scope="function")
def db_session(db_engine):
    connection = db_engine.connect()
    transaction = connection.begin()
    Session = sessionmaker(bind=connection)
    session = Session()
    yield session
    session.close()
    transaction.rollback()
    connection.close()

import pytest
from sqlalchemy import create_engine
from sqlalchemy.orm import sessionmaker
from sqlalchemy.exc import IntegrityError
from dotenv import load_dotenv
import os

# Load environment variables from .env file
load_dotenv()

# Define the database URL from environment variables
DATABASE_URL = os.getenv("DATABASE_URL")

# Create a new SQLAlchemy engine
engine = create_engine(DATABASE_URL)

# Create a configured "Session" class
Session = sessionmaker(bind=engine)

# Create a Session
db_session = Session()

def test_user_repo_unique_constraint():
    user = UserInfo(
        first_name="Alice",
        last_name="Smith",
        email="alice.smith@example.com",
        github_username="alicesmith",
        payment_date=None,
        current_duration=0,
        course_duration=0,
        end_date=None,
        status=1
    )
    db_session.add(user)
    db_session.commit()

    user_repo1 = UserRepo(
        user_id=user.id,
        psid=1,
        github_username="alicesmith",
        repo_name="repo1",
        github_url="https://github.com/alicesmith/repo1"
    )
    db_session.add(user_repo1)
    db_session.commit()

    user_repo2 = UserRepo(
        user_id=user.id,
        psid=2,
        github_username="alicesmith",
        repo_name="repo1",
        github_url="https://github.com/alicesmith/repo1"
    )
    db_session.add(user_repo2)
    
    with pytest.raises(IntegrityError):
        db_session.commit()

    db_session.rollback()

---------------
TEST CASE 4 Retry 1 - Result - Failed
Test Error - c:\ChenKhoon\JupyterNotebook\GenerateUnitTestCases\unit_test_env\Lib\site-packages\pytest_asyncio\plugin.py:217: PytestDeprecationWarning: The configuration option "asyncio_default_fixture_loop_scope" is unset.
The event loop scope for asynchronous fixtures will default to the fixture caching scope. Future versions of pytest-asyncio will default the loop scope for asynchronous fixtures to function scope. Set the default fixture loop scope explicitly in order to avoid unexpected behavior in the future. Valid fixture loop scopes are: "function", "class", "module", "package", "session"

  warnings.warn(PytestDeprecationWarning(_DEFAULT_FIXTURE_LOOP_SCOPE_UNSET))

=================================== ERRORS ====================================
________________________ ERROR collecting temp/temp.py ________________________
temp\temp.py:51: in <module>
    engine = create_engine(DATABASE_URL)
<string>:2: in create_engine
    ???
unit_test_env\Lib\site-packages\sqlalchemy\util\deprecations.py:281: in warned
    return fn(*args, **kwargs)  # type: ignore[no-any-return]
unit_test_env\Lib\site-packages\sqlalchemy\engine\create.py:549: in create_engine
    u = _url.make_url(url)
unit_test_env\Lib\site-packages\sqlalchemy\engine\url.py:860: in make_url
    raise exc.ArgumentError(
E   sqlalchemy.exc.ArgumentError: Expected string or URL object, got None
============================== warnings summary ===============================
theory_evaluation\models.py:17
  C:\ChenKhoon\JupyterNotebook\GenerateUnitTestCases\theory_evaluation\models.py:17: MovedIn20Warning: The ``declarative_base()`` function is now available as sqlalchemy.orm.declarative_base(). (deprecated since: 2.0) (Background on SQLAlchemy 2.0 at: https://sqlalche.me/e/b8d9)
    Base = declarative_base()

-- Docs: https://docs.pytest.org/en/stable/how-to/capture-warnings.html
=========================== short test summary info ===========================
ERROR temp/temp.py - sqlalchemy.exc.ArgumentError: Expected string or URL obj...
!!!!!!!!!!!!!!!!!!! Interrupted: 1 error during collection !!!!!!!!!!!!!!!!!!!!
1 warning, 1 error in 0.75s
TEST CASE 4 Retry 2
---------------
from sqlalchemy.dialects.postgresql import JSONB, UUID
from sqlalchemy import (
    Column,
    Integer,
    String,
    TIMESTAMP,
    create_engine,
    Float,
    ForeignKey,
    Text,
    UniqueConstraint,
)
from sqlalchemy.ext.declarative import declarative_base
from sqlalchemy.sql import func
import uuid
from theory_evaluation.models import Base, ConsultantChat, CurrentUserTable, Curriculum, MentorChat, Projects, SprintIssues, TheoryEvalUserPerformance, UserInfo, UserRepo, UserScoreLog
import pytest

@pytest.fixture(scope="module")
def db_engine():
    engine = create_engine(DATABASE_URL)
    Base.metadata.create_all(engine)
    yield engine
    Base.metadata.drop_all(engine)

@pytest.fixture(scope="function")
def db_session(db_engine):
    connection = db_engine.connect()
    transaction = connection.begin()
    Session = sessionmaker(bind=connection)
    session = Session()
    yield session
    session.close()
    transaction.rollback()
    connection.close()

import pytest
from sqlalchemy import create_engine
from sqlalchemy.orm import sessionmaker
from sqlalchemy.exc import IntegrityError
from dotenv import load_dotenv
import os

# Load environment variables from .env file
load_dotenv()

# Define the database URL from environment variables
DATABASE_URL = os.getenv("DATABASE_URL")

# Ensure DATABASE_URL is set
if not DATABASE_URL:
    raise ValueError("DATABASE_URL environment variable is not set.")

# Create a new SQLAlchemy engine
engine = create_engine(DATABASE_URL)

# Create a configured "Session" class
Session = sessionmaker(bind=engine)

# Create a Session
db_session = Session()

def test_user_repo_unique_constraint():
    user = UserInfo(
        first_name="Alice",
        last_name="Smith",
        email="alice.smith@example.com",
        github_username="alicesmith",
        payment_date=None,
        current_duration=0,
        course_duration=0,
        end_date=None,
        status=1
    )
    db_session.add(user)
    db_session.commit()

    user_repo1 = UserRepo(
        user_id=user.id,
        psid=1,
        github_username="alicesmith",
        repo_name="repo1",
        github_url="https://github.com/alicesmith/repo1"
    )
    db_session.add(user_repo1)
    db_session.commit()

    user_repo2 = UserRepo(
        user_id=user.id,
        psid=2,
        github_username="alicesmith",
        repo_name="repo1",
        github_url="https://github.com/alicesmith/repo1"
    )
    db_session.add(user_repo2)
    
    with pytest.raises(IntegrityError):
        db_session.commit()

    db_session.rollback()

---------------
TEST CASE 4 Retry 2 - Result - Failed
Test Error - c:\ChenKhoon\JupyterNotebook\GenerateUnitTestCases\unit_test_env\Lib\site-packages\pytest_asyncio\plugin.py:217: PytestDeprecationWarning: The configuration option "asyncio_default_fixture_loop_scope" is unset.
The event loop scope for asynchronous fixtures will default to the fixture caching scope. Future versions of pytest-asyncio will default the loop scope for asynchronous fixtures to function scope. Set the default fixture loop scope explicitly in order to avoid unexpected behavior in the future. Valid fixture loop scopes are: "function", "class", "module", "package", "session"

  warnings.warn(PytestDeprecationWarning(_DEFAULT_FIXTURE_LOOP_SCOPE_UNSET))

=================================== ERRORS ====================================
________________________ ERROR collecting temp/temp.py ________________________
temp\temp.py:52: in <module>
    raise ValueError("DATABASE_URL environment variable is not set.")
E   ValueError: DATABASE_URL environment variable is not set.
============================== warnings summary ===============================
theory_evaluation\models.py:17
  C:\ChenKhoon\JupyterNotebook\GenerateUnitTestCases\theory_evaluation\models.py:17: MovedIn20Warning: The ``declarative_base()`` function is now available as sqlalchemy.orm.declarative_base(). (deprecated since: 2.0) (Background on SQLAlchemy 2.0 at: https://sqlalche.me/e/b8d9)
    Base = declarative_base()

-- Docs: https://docs.pytest.org/en/stable/how-to/capture-warnings.html
=========================== short test summary info ===========================
ERROR temp/temp.py - ValueError: DATABASE_URL environment variable is not set.
!!!!!!!!!!!!!!!!!!! Interrupted: 1 error during collection !!!!!!!!!!!!!!!!!!!!
1 warning, 1 error in 0.70s

TEST CASE 5 Retry 0
---------------
from sqlalchemy.dialects.postgresql import JSONB, UUID
from sqlalchemy import (
    Column,
    Integer,
    String,
    TIMESTAMP,
    create_engine,
    Float,
    ForeignKey,
    Text,
    UniqueConstraint,
)
from sqlalchemy.ext.declarative import declarative_base
from sqlalchemy.sql import func
import uuid
from theory_evaluation.models import Base, ConsultantChat, CurrentUserTable, Curriculum, MentorChat, Projects, SprintIssues, TheoryEvalUserPerformance, UserInfo, UserRepo, UserScoreLog
import pytest

@pytest.fixture(scope="module")
def db_engine():
    engine = create_engine(DATABASE_URL)
    Base.metadata.create_all(engine)
    yield engine
    Base.metadata.drop_all(engine)

@pytest.fixture(scope="function")
def db_session(db_engine):
    connection = db_engine.connect()
    transaction = connection.begin()
    Session = sessionmaker(bind=connection)
    session = Session()
    yield session
    session.close()
    transaction.rollback()
    connection.close()

def test_curriculum_creation(db_session):
    curriculum = Curriculum(
        question="What is Python?",
        marking_scheme="Correctness and clarity",
        model_answer="Python is a programming language."
    )
    db_session.add(curriculum)
    db_session.commit()

---------------
TEST CASE 5 Retry 0 - Result - Failed
Test Error - c:\ChenKhoon\JupyterNotebook\GenerateUnitTestCases\unit_test_env\Lib\site-packages\pytest_asyncio\plugin.py:217: PytestDeprecationWarning: The configuration option "asyncio_default_fixture_loop_scope" is unset.
The event loop scope for asynchronous fixtures will default to the fixture caching scope. Future versions of pytest-asyncio will default the loop scope for asynchronous fixtures to function scope. Set the default fixture loop scope explicitly in order to avoid unexpected behavior in the future. Valid fixture loop scopes are: "function", "class", "module", "package", "session"

  warnings.warn(PytestDeprecationWarning(_DEFAULT_FIXTURE_LOOP_SCOPE_UNSET))
E                                                                        [100%]
=================================== ERRORS ====================================
_________________ ERROR at setup of test_curriculum_creation __________________
temp\temp.py:21: in db_engine
    engine = create_engine(DATABASE_URL)
E   NameError: name 'DATABASE_URL' is not defined
============================== warnings summary ===============================
theory_evaluation\models.py:17
  C:\ChenKhoon\JupyterNotebook\GenerateUnitTestCases\theory_evaluation\models.py:17: MovedIn20Warning: The ``declarative_base()`` function is now available as sqlalchemy.orm.declarative_base(). (deprecated since: 2.0) (Background on SQLAlchemy 2.0 at: https://sqlalche.me/e/b8d9)
    Base = declarative_base()

-- Docs: https://docs.pytest.org/en/stable/how-to/capture-warnings.html
=========================== short test summary info ===========================
ERROR temp/temp.py::test_curriculum_creation - NameError: name 'DATABASE_URL'...
1 warning, 1 error in 0.68s
TEST CASE 5 Retry 1
---------------
from sqlalchemy.dialects.postgresql import JSONB, UUID
from sqlalchemy import (
    Column,
    Integer,
    String,
    TIMESTAMP,
    create_engine,
    Float,
    ForeignKey,
    Text,
    UniqueConstraint,
)
from sqlalchemy.ext.declarative import declarative_base
from sqlalchemy.sql import func
import uuid
from theory_evaluation.models import Base, ConsultantChat, CurrentUserTable, Curriculum, MentorChat, Projects, SprintIssues, TheoryEvalUserPerformance, UserInfo, UserRepo, UserScoreLog
import pytest

@pytest.fixture(scope="module")
def db_engine():
    engine = create_engine(DATABASE_URL)
    Base.metadata.create_all(engine)
    yield engine
    Base.metadata.drop_all(engine)

@pytest.fixture(scope="function")
def db_session(db_engine):
    connection = db_engine.connect()
    transaction = connection.begin()
    Session = sessionmaker(bind=connection)
    session = Session()
    yield session
    session.close()
    transaction.rollback()
    connection.close()

import pytest
from sqlalchemy import create_engine
from sqlalchemy.orm import sessionmaker
from sqlalchemy.exc import IntegrityError
from your_module import Base, Curriculum  # Replace 'your_module' with the actual module name

# Assuming DATABASE_URL is defined in your environment or replace with actual URL
DATABASE_URL = "sqlite:///:memory:"  # Example for an in-memory SQLite database

@pytest.fixture(scope='function')
def db_session():
    engine = create_engine(DATABASE_URL)
    Base.metadata.create_all(engine)
    Session = sessionmaker(bind=engine)
    session = Session()
    yield session
    session.close()
    Base.metadata.drop_all(engine)

def test_curriculum_creation(db_session):
    curriculum = Curriculum(
        question="What is Python?",
        marking_scheme="Correctness and clarity",
        model_answer="Python is a programming language."
    )
    db_session.add(curriculum)
    db_session.commit()
    retrieved_curriculum = db_session.query(Curriculum).filter_by(question="What is Python?").first()
    assert retrieved_curriculum is not None
    assert retrieved_curriculum.marking_scheme == "Correctness and clarity"
    assert retrieved_curriculum.model_answer == "Python is a programming language."

---------------
TEST CASE 5 Retry 1 - Result - Failed
Test Error - c:\ChenKhoon\JupyterNotebook\GenerateUnitTestCases\unit_test_env\Lib\site-packages\pytest_asyncio\plugin.py:217: PytestDeprecationWarning: The configuration option "asyncio_default_fixture_loop_scope" is unset.
The event loop scope for asynchronous fixtures will default to the fixture caching scope. Future versions of pytest-asyncio will default the loop scope for asynchronous fixtures to function scope. Set the default fixture loop scope explicitly in order to avoid unexpected behavior in the future. Valid fixture loop scopes are: "function", "class", "module", "package", "session"

  warnings.warn(PytestDeprecationWarning(_DEFAULT_FIXTURE_LOOP_SCOPE_UNSET))

=================================== ERRORS ====================================
________________________ ERROR collecting temp/temp.py ________________________
ImportError while importing test module 'C:\ChenKhoon\JupyterNotebook\GenerateUnitTestCases\temp\temp.py'.
Hint: make sure your test modules/packages have valid Python names.
Traceback:
C:\Users\User\AppData\Local\Programs\Python\Python313\Lib\importlib\__init__.py:88: in import_module
    return _bootstrap._gcd_import(name[level:], package, level)
temp\temp.py:41: in <module>
    from your_module import Base, Curriculum  # Replace 'your_module' with the actual module name
E   ModuleNotFoundError: No module named 'your_module'
============================== warnings summary ===============================
theory_evaluation\models.py:17
  C:\ChenKhoon\JupyterNotebook\GenerateUnitTestCases\theory_evaluation\models.py:17: MovedIn20Warning: The ``declarative_base()`` function is now available as sqlalchemy.orm.declarative_base(). (deprecated since: 2.0) (Background on SQLAlchemy 2.0 at: https://sqlalche.me/e/b8d9)
    Base = declarative_base()

-- Docs: https://docs.pytest.org/en/stable/how-to/capture-warnings.html
=========================== short test summary info ===========================
ERROR temp/temp.py
!!!!!!!!!!!!!!!!!!! Interrupted: 1 error during collection !!!!!!!!!!!!!!!!!!!!
1 warning, 1 error in 1.02s
TEST CASE 5 Retry 2
---------------
from sqlalchemy.dialects.postgresql import JSONB, UUID
from sqlalchemy import (
    Column,
    Integer,
    String,
    TIMESTAMP,
    create_engine,
    Float,
    ForeignKey,
    Text,
    UniqueConstraint,
)
from sqlalchemy.ext.declarative import declarative_base
from sqlalchemy.sql import func
import uuid
from theory_evaluation.models import Base, ConsultantChat, CurrentUserTable, Curriculum, MentorChat, Projects, SprintIssues, TheoryEvalUserPerformance, UserInfo, UserRepo, UserScoreLog
import pytest

@pytest.fixture(scope="module")
def db_engine():
    engine = create_engine(DATABASE_URL)
    Base.metadata.create_all(engine)
    yield engine
    Base.metadata.drop_all(engine)

@pytest.fixture(scope="function")
def db_session(db_engine):
    connection = db_engine.connect()
    transaction = connection.begin()
    Session = sessionmaker(bind=connection)
    session = Session()
    yield session
    session.close()
    transaction.rollback()
    connection.close()

import pytest
from sqlalchemy import create_engine
from sqlalchemy.orm import sessionmaker
from sqlalchemy.exc import IntegrityError
from temp import Base, Curriculum  # Replace 'temp' with the actual module name

DATABASE_URL = "sqlite:///:memory:"  # Example for an in-memory SQLite database

@pytest.fixture(scope='function')
def db_session():
    engine = create_engine(DATABASE_URL)
    Base.metadata.create_all(engine)
    Session = sessionmaker(bind=engine)
    session = Session()
    yield session
    session.close()
    Base.metadata.drop_all(engine)

def test_curriculum_creation(db_session):
    curriculum = Curriculum(
        question="What is Python?",
        marking_scheme="Correctness and clarity",
        model_answer="Python is a programming language."
    )
    db_session.add(curriculum)
    db_session.commit()
    retrieved_curriculum = db_session.query(Curriculum).filter_by(question="What is Python?").first()
    assert retrieved_curriculum is not None
    assert retrieved_curriculum.marking_scheme == "Correctness and clarity"
    assert retrieved_curriculum.model_answer == "Python is a programming language."

---------------
TEST CASE 5 Retry 2 - Result - Failed
Test Error - c:\ChenKhoon\JupyterNotebook\GenerateUnitTestCases\unit_test_env\Lib\site-packages\pytest_asyncio\plugin.py:217: PytestDeprecationWarning: The configuration option "asyncio_default_fixture_loop_scope" is unset.
The event loop scope for asynchronous fixtures will default to the fixture caching scope. Future versions of pytest-asyncio will default the loop scope for asynchronous fixtures to function scope. Set the default fixture loop scope explicitly in order to avoid unexpected behavior in the future. Valid fixture loop scopes are: "function", "class", "module", "package", "session"

  warnings.warn(PytestDeprecationWarning(_DEFAULT_FIXTURE_LOOP_SCOPE_UNSET))
E                                                                        [100%]
=================================== ERRORS ====================================
_________________ ERROR at setup of test_curriculum_creation __________________
unit_test_env\Lib\site-packages\sqlalchemy\sql\visitors.py:137: in _compiler_dispatch
    meth = getter(visitor)
E   AttributeError: 'SQLiteTypeCompiler' object has no attribute 'visit_JSONB'. Did you mean: 'visit_JSON'?

The above exception was the direct cause of the following exception:
unit_test_env\Lib\site-packages\sqlalchemy\sql\compiler.py:6716: in visit_create_table
    processed = self.process(
unit_test_env\Lib\site-packages\sqlalchemy\sql\compiler.py:932: in process
    return obj._compiler_dispatch(self, **kwargs)
unit_test_env\Lib\site-packages\sqlalchemy\sql\visitors.py:141: in _compiler_dispatch
    return meth(self, **kw)  # type: ignore  # noqa: E501
unit_test_env\Lib\site-packages\sqlalchemy\sql\compiler.py:6747: in visit_create_column
    text = self.get_column_specification(column, first_pk=first_pk)
unit_test_env\Lib\site-packages\sqlalchemy\dialects\sqlite\base.py:1598: in get_column_specification
    coltype = self.dialect.type_compiler_instance.process(
unit_test_env\Lib\site-packages\sqlalchemy\sql\compiler.py:977: in process
    return type_._compiler_dispatch(self, **kw)
unit_test_env\Lib\site-packages\sqlalchemy\sql\visitors.py:139: in _compiler_dispatch
    return visitor.visit_unsupported_compilation(self, err, **kw)  # type: ignore  # noqa: E501
unit_test_env\Lib\site-packages\sqlalchemy\sql\compiler.py:982: in visit_unsupported_compilation
    raise exc.UnsupportedCompilationError(self, element) from err
E   sqlalchemy.exc.UnsupportedCompilationError: Compiler <sqlalchemy.dialects.sqlite.base.SQLiteTypeCompiler object at 0x00000172CCC6FB60> can't render element of type JSONB (Background on this error at: https://sqlalche.me/e/20/l7de)

The above exception was the direct cause of the following exception:
temp\temp.py:48: in db_session
    Base.metadata.create_all(engine)
unit_test_env\Lib\site-packages\sqlalchemy\sql\schema.py:5925: in create_all
    bind._run_ddl_visitor(
unit_test_env\Lib\site-packages\sqlalchemy\engine\base.py:3249: in _run_ddl_visitor
    conn._run_ddl_visitor(visitorcallable, element, **kwargs)
unit_test_env\Lib\site-packages\sqlalchemy\engine\base.py:2456: in _run_ddl_visitor
    visitorcallable(self.dialect, self, **kwargs).traverse_single(element)
unit_test_env\Lib\site-packages\sqlalchemy\sql\visitors.py:664: in traverse_single
    return meth(obj, **kw)
unit_test_env\Lib\site-packages\sqlalchemy\sql\ddl.py:981: in visit_metadata
    self.traverse_single(
unit_test_env\Lib\site-packages\sqlalchemy\sql\visitors.py:664: in traverse_single
    return meth(obj, **kw)
unit_test_env\Lib\site-packages\sqlalchemy\sql\ddl.py:1019: in visit_table
    )._invoke_with(self.connection)
unit_test_env\Lib\site-packages\sqlalchemy\sql\ddl.py:321: in _invoke_with
    return bind.execute(self)
unit_test_env\Lib\site-packages\sqlalchemy\engine\base.py:1416: in execute
    return meth(
unit_test_env\Lib\site-packages\sqlalchemy\sql\ddl.py:187: in _execute_on_connection
    return connection._execute_ddl(
unit_test_env\Lib\site-packages\sqlalchemy\engine\base.py:1524: in _execute_ddl
    compiled = ddl.compile(
unit_test_env\Lib\site-packages\sqlalchemy\sql\elements.py:308: in compile
    return self._compiler(dialect, **kw)
unit_test_env\Lib\site-packages\sqlalchemy\sql\ddl.py:76: in _compiler
    return dialect.ddl_compiler(dialect, self, **kw)
unit_test_env\Lib\site-packages\sqlalchemy\sql\compiler.py:886: in __init__
    self.string = self.process(self.statement, **compile_kwargs)
unit_test_env\Lib\site-packages\sqlalchemy\sql\compiler.py:932: in process
    return obj._compiler_dispatch(self, **kwargs)
unit_test_env\Lib\site-packages\sqlalchemy\sql\visitors.py:141: in _compiler_dispatch
    return meth(self, **kw)  # type: ignore  # noqa: E501
unit_test_env\Lib\site-packages\sqlalchemy\sql\compiler.py:6726: in visit_create_table
    raise exc.CompileError(
E   sqlalchemy.exc.CompileError: (in table 'projects', column 'problem_statement'): Compiler <sqlalchemy.dialects.sqlite.base.SQLiteTypeCompiler object at 0x00000172CCC6FB60> can't render element of type JSONB
============================== warnings summary ===============================
theory_evaluation\models.py:17
  C:\ChenKhoon\JupyterNotebook\GenerateUnitTestCases\theory_evaluation\models.py:17: MovedIn20Warning: The ``declarative_base()`` function is now available as sqlalchemy.orm.declarative_base(). (deprecated since: 2.0) (Background on SQLAlchemy 2.0 at: https://sqlalche.me/e/b8d9)
    Base = declarative_base()

-- Docs: https://docs.pytest.org/en/stable/how-to/capture-warnings.html
=========================== short test summary info ===========================
ERROR temp/temp.py::test_curriculum_creation - sqlalchemy.exc.CompileError: (...
1 warning, 1 error in 1.25s

TEST CASE 6 Retry 0
---------------
from sqlalchemy.dialects.postgresql import JSONB, UUID
from sqlalchemy import (
    Column,
    Integer,
    String,
    TIMESTAMP,
    create_engine,
    Float,
    ForeignKey,
    Text,
    UniqueConstraint,
)
from sqlalchemy.ext.declarative import declarative_base
from sqlalchemy.sql import func
import uuid
from theory_evaluation.models import Base, ConsultantChat, CurrentUserTable, Curriculum, MentorChat, Projects, SprintIssues, TheoryEvalUserPerformance, UserInfo, UserRepo, UserScoreLog
import pytest

@pytest.fixture(scope="module")
def db_engine():
    engine = create_engine(DATABASE_URL)
    Base.metadata.create_all(engine)
    yield engine
    Base.metadata.drop_all(engine)

@pytest.fixture(scope="function")
def db_session(db_engine):
    connection = db_engine.connect()
    transaction = connection.begin()
    Session = sessionmaker(bind=connection)
    session = Session()
    yield session
    session.close()
    transaction.rollback()
    connection.close()

def test_theory_eval_user_performance_creation(db_session):
    user = UserInfo(
        first_name="Bob",
        last_name="Brown",
        email="bob.brown@example.com",
        github_username="bobbrown",
        payment_date=None,
        current_duration=0,
        course_duration=0,
        end_date=None,
        status=1
    )
    db_session.add(user)
    db_session.commit()

---------------
TEST CASE 6 Retry 0 - Result - Failed
Test Error - c:\ChenKhoon\JupyterNotebook\GenerateUnitTestCases\unit_test_env\Lib\site-packages\pytest_asyncio\plugin.py:217: PytestDeprecationWarning: The configuration option "asyncio_default_fixture_loop_scope" is unset.
The event loop scope for asynchronous fixtures will default to the fixture caching scope. Future versions of pytest-asyncio will default the loop scope for asynchronous fixtures to function scope. Set the default fixture loop scope explicitly in order to avoid unexpected behavior in the future. Valid fixture loop scopes are: "function", "class", "module", "package", "session"

  warnings.warn(PytestDeprecationWarning(_DEFAULT_FIXTURE_LOOP_SCOPE_UNSET))
E                                                                        [100%]
=================================== ERRORS ====================================
________ ERROR at setup of test_theory_eval_user_performance_creation _________
temp\temp.py:21: in db_engine
    engine = create_engine(DATABASE_URL)
E   NameError: name 'DATABASE_URL' is not defined
============================== warnings summary ===============================
theory_evaluation\models.py:17
  C:\ChenKhoon\JupyterNotebook\GenerateUnitTestCases\theory_evaluation\models.py:17: MovedIn20Warning: The ``declarative_base()`` function is now available as sqlalchemy.orm.declarative_base(). (deprecated since: 2.0) (Background on SQLAlchemy 2.0 at: https://sqlalche.me/e/b8d9)
    Base = declarative_base()

-- Docs: https://docs.pytest.org/en/stable/how-to/capture-warnings.html
=========================== short test summary info ===========================
ERROR temp/temp.py::test_theory_eval_user_performance_creation - NameError: n...
1 warning, 1 error in 0.69s
TEST CASE 6 Retry 1
---------------
from sqlalchemy.dialects.postgresql import JSONB, UUID
from sqlalchemy import (
    Column,
    Integer,
    String,
    TIMESTAMP,
    create_engine,
    Float,
    ForeignKey,
    Text,
    UniqueConstraint,
)
from sqlalchemy.ext.declarative import declarative_base
from sqlalchemy.sql import func
import uuid
from theory_evaluation.models import Base, ConsultantChat, CurrentUserTable, Curriculum, MentorChat, Projects, SprintIssues, TheoryEvalUserPerformance, UserInfo, UserRepo, UserScoreLog
import pytest

@pytest.fixture(scope="module")
def db_engine():
    engine = create_engine(DATABASE_URL)
    Base.metadata.create_all(engine)
    yield engine
    Base.metadata.drop_all(engine)

@pytest.fixture(scope="function")
def db_session(db_engine):
    connection = db_engine.connect()
    transaction = connection.begin()
    Session = sessionmaker(bind=connection)
    session = Session()
    yield session
    session.close()
    transaction.rollback()
    connection.close()

from sqlalchemy import create_engine
from sqlalchemy.orm import sessionmaker
from sqlalchemy.exc import IntegrityError
import pytest

# Assuming DATABASE_URL is defined somewhere in your test setup
DATABASE_URL = "sqlite:///:memory:"  # Example for an in-memory SQLite database

# Create an engine and session for testing
engine = create_engine(DATABASE_URL)
Session = sessionmaker(bind=engine)
Base.metadata.create_all(engine)

@pytest.fixture
def db_session():
    session = Session()
    try:
        yield session
    finally:
        session.close()

def test_theory_eval_user_performance_creation(db_session):
    user = UserInfo(
        first_name="Bob",
        last_name="Brown",
        email="bob.brown@example.com",
        github_username="bobbrown",
        payment_date=None,
        current_duration=0,
        course_duration=0,
        end_date=None,
        status=1
    )
    db_session.add(user)
    db_session.commit()

    retrieved_user = db_session.query(UserInfo).filter_by(email="bob.brown@example.com").first()
    assert retrieved_user is not None
    assert retrieved_user.first_name == "Bob"
    assert retrieved_user.last_name == "Brown"
    assert retrieved_user.github_username == "bobbrown"

---------------
TEST CASE 6 Retry 1 - Result - Failed
Test Error - c:\ChenKhoon\JupyterNotebook\GenerateUnitTestCases\unit_test_env\Lib\site-packages\pytest_asyncio\plugin.py:217: PytestDeprecationWarning: The configuration option "asyncio_default_fixture_loop_scope" is unset.
The event loop scope for asynchronous fixtures will default to the fixture caching scope. Future versions of pytest-asyncio will default the loop scope for asynchronous fixtures to function scope. Set the default fixture loop scope explicitly in order to avoid unexpected behavior in the future. Valid fixture loop scopes are: "function", "class", "module", "package", "session"

  warnings.warn(PytestDeprecationWarning(_DEFAULT_FIXTURE_LOOP_SCOPE_UNSET))

=================================== ERRORS ====================================
________________________ ERROR collecting temp/temp.py ________________________
unit_test_env\Lib\site-packages\sqlalchemy\sql\visitors.py:137: in _compiler_dispatch
    meth = getter(visitor)
E   AttributeError: 'SQLiteTypeCompiler' object has no attribute 'visit_JSONB'. Did you mean: 'visit_JSON'?

The above exception was the direct cause of the following exception:
unit_test_env\Lib\site-packages\sqlalchemy\sql\compiler.py:6716: in visit_create_table
    processed = self.process(
unit_test_env\Lib\site-packages\sqlalchemy\sql\compiler.py:932: in process
    return obj._compiler_dispatch(self, **kwargs)
unit_test_env\Lib\site-packages\sqlalchemy\sql\visitors.py:141: in _compiler_dispatch
    return meth(self, **kw)  # type: ignore  # noqa: E501
unit_test_env\Lib\site-packages\sqlalchemy\sql\compiler.py:6747: in visit_create_column
    text = self.get_column_specification(column, first_pk=first_pk)
unit_test_env\Lib\site-packages\sqlalchemy\dialects\sqlite\base.py:1598: in get_column_specification
    coltype = self.dialect.type_compiler_instance.process(
unit_test_env\Lib\site-packages\sqlalchemy\sql\compiler.py:977: in process
    return type_._compiler_dispatch(self, **kw)
unit_test_env\Lib\site-packages\sqlalchemy\sql\visitors.py:139: in _compiler_dispatch
    return visitor.visit_unsupported_compilation(self, err, **kw)  # type: ignore  # noqa: E501
unit_test_env\Lib\site-packages\sqlalchemy\sql\compiler.py:982: in visit_unsupported_compilation
    raise exc.UnsupportedCompilationError(self, element) from err
E   sqlalchemy.exc.UnsupportedCompilationError: Compiler <sqlalchemy.dialects.sqlite.base.SQLiteTypeCompiler object at 0x0000016AE567F620> can't render element of type JSONB (Background on this error at: https://sqlalche.me/e/20/l7de)

The above exception was the direct cause of the following exception:
temp\temp.py:48: in <module>
    Base.metadata.create_all(engine)
unit_test_env\Lib\site-packages\sqlalchemy\sql\schema.py:5925: in create_all
    bind._run_ddl_visitor(
unit_test_env\Lib\site-packages\sqlalchemy\engine\base.py:3249: in _run_ddl_visitor
    conn._run_ddl_visitor(visitorcallable, element, **kwargs)
unit_test_env\Lib\site-packages\sqlalchemy\engine\base.py:2456: in _run_ddl_visitor
    visitorcallable(self.dialect, self, **kwargs).traverse_single(element)
unit_test_env\Lib\site-packages\sqlalchemy\sql\visitors.py:664: in traverse_single
    return meth(obj, **kw)
unit_test_env\Lib\site-packages\sqlalchemy\sql\ddl.py:981: in visit_metadata
    self.traverse_single(
unit_test_env\Lib\site-packages\sqlalchemy\sql\visitors.py:664: in traverse_single
    return meth(obj, **kw)
unit_test_env\Lib\site-packages\sqlalchemy\sql\ddl.py:1019: in visit_table
    )._invoke_with(self.connection)
unit_test_env\Lib\site-packages\sqlalchemy\sql\ddl.py:321: in _invoke_with
    return bind.execute(self)
unit_test_env\Lib\site-packages\sqlalchemy\engine\base.py:1416: in execute
    return meth(
unit_test_env\Lib\site-packages\sqlalchemy\sql\ddl.py:187: in _execute_on_connection
    return connection._execute_ddl(
unit_test_env\Lib\site-packages\sqlalchemy\engine\base.py:1524: in _execute_ddl
    compiled = ddl.compile(
unit_test_env\Lib\site-packages\sqlalchemy\sql\elements.py:308: in compile
    return self._compiler(dialect, **kw)
unit_test_env\Lib\site-packages\sqlalchemy\sql\ddl.py:76: in _compiler
    return dialect.ddl_compiler(dialect, self, **kw)
unit_test_env\Lib\site-packages\sqlalchemy\sql\compiler.py:886: in __init__
    self.string = self.process(self.statement, **compile_kwargs)
unit_test_env\Lib\site-packages\sqlalchemy\sql\compiler.py:932: in process
    return obj._compiler_dispatch(self, **kwargs)
unit_test_env\Lib\site-packages\sqlalchemy\sql\visitors.py:141: in _compiler_dispatch
    return meth(self, **kw)  # type: ignore  # noqa: E501
unit_test_env\Lib\site-packages\sqlalchemy\sql\compiler.py:6726: in visit_create_table
    raise exc.CompileError(
E   sqlalchemy.exc.CompileError: (in table 'projects', column 'problem_statement'): Compiler <sqlalchemy.dialects.sqlite.base.SQLiteTypeCompiler object at 0x0000016AE567F620> can't render element of type JSONB
============================== warnings summary ===============================
theory_evaluation\models.py:17
  C:\ChenKhoon\JupyterNotebook\GenerateUnitTestCases\theory_evaluation\models.py:17: MovedIn20Warning: The ``declarative_base()`` function is now available as sqlalchemy.orm.declarative_base(). (deprecated since: 2.0) (Background on SQLAlchemy 2.0 at: https://sqlalche.me/e/b8d9)
    Base = declarative_base()

-- Docs: https://docs.pytest.org/en/stable/how-to/capture-warnings.html
=========================== short test summary info ===========================
ERROR temp/temp.py - sqlalchemy.exc.CompileError: (in table 'projects', colum...
!!!!!!!!!!!!!!!!!!! Interrupted: 1 error during collection !!!!!!!!!!!!!!!!!!!!
1 warning, 1 error in 1.41s
TEST CASE 6 Retry 2
---------------
from sqlalchemy.dialects.postgresql import JSONB, UUID
from sqlalchemy import (
    Column,
    Integer,
    String,
    TIMESTAMP,
    create_engine,
    Float,
    ForeignKey,
    Text,
    UniqueConstraint,
)
from sqlalchemy.ext.declarative import declarative_base
from sqlalchemy.sql import func
import uuid
from theory_evaluation.models import Base, ConsultantChat, CurrentUserTable, Curriculum, MentorChat, Projects, SprintIssues, TheoryEvalUserPerformance, UserInfo, UserRepo, UserScoreLog
import pytest

@pytest.fixture(scope="module")
def db_engine():
    engine = create_engine(DATABASE_URL)
    Base.metadata.create_all(engine)
    yield engine
    Base.metadata.drop_all(engine)

@pytest.fixture(scope="function")
def db_session(db_engine):
    connection = db_engine.connect()
    transaction = connection.begin()
    Session = sessionmaker(bind=connection)
    session = Session()
    yield session
    session.close()
    transaction.rollback()
    connection.close()

from sqlalchemy import create_engine
from sqlalchemy.orm import sessionmaker
from sqlalchemy.exc import IntegrityError
import pytest

# Assuming DATABASE_URL is defined somewhere in your test setup
DATABASE_URL = "sqlite:///:memory:"  # Example for an in-memory SQLite database

# Create an engine and session for testing
engine = create_engine(DATABASE_URL)
Session = sessionmaker(bind=engine)
Base.metadata.create_all(engine)

@pytest.fixture
def db_session():
    session = Session()
    try:
        yield session
    finally:
        session.close()

def test_user_info_creation(db_session):
    user = UserInfo(
        first_name="Bob",
        last_name="Brown",
        email="bob.brown@example.com",
        github_username="bobbrown",
        payment_date=None,
        current_duration=0,
        course_duration=0,
        end_date=None,
        status=1
    )
    db_session.add(user)
    db_session.commit()

    retrieved_user = db_session.query(UserInfo).filter_by(email="bob.brown@example.com").first()
    assert retrieved_user is not None
    assert retrieved_user.first_name == "Bob"
    assert retrieved_user.last_name == "Brown"
    assert retrieved_user.github_username == "bobbrown"

---------------
TEST CASE 6 Retry 2 - Result - Failed
Test Error - c:\ChenKhoon\JupyterNotebook\GenerateUnitTestCases\unit_test_env\Lib\site-packages\pytest_asyncio\plugin.py:217: PytestDeprecationWarning: The configuration option "asyncio_default_fixture_loop_scope" is unset.
The event loop scope for asynchronous fixtures will default to the fixture caching scope. Future versions of pytest-asyncio will default the loop scope for asynchronous fixtures to function scope. Set the default fixture loop scope explicitly in order to avoid unexpected behavior in the future. Valid fixture loop scopes are: "function", "class", "module", "package", "session"

  warnings.warn(PytestDeprecationWarning(_DEFAULT_FIXTURE_LOOP_SCOPE_UNSET))

=================================== ERRORS ====================================
________________________ ERROR collecting temp/temp.py ________________________
unit_test_env\Lib\site-packages\sqlalchemy\sql\visitors.py:137: in _compiler_dispatch
    meth = getter(visitor)
E   AttributeError: 'SQLiteTypeCompiler' object has no attribute 'visit_JSONB'. Did you mean: 'visit_JSON'?

The above exception was the direct cause of the following exception:
unit_test_env\Lib\site-packages\sqlalchemy\sql\compiler.py:6716: in visit_create_table
    processed = self.process(
unit_test_env\Lib\site-packages\sqlalchemy\sql\compiler.py:932: in process
    return obj._compiler_dispatch(self, **kwargs)
unit_test_env\Lib\site-packages\sqlalchemy\sql\visitors.py:141: in _compiler_dispatch
    return meth(self, **kw)  # type: ignore  # noqa: E501
unit_test_env\Lib\site-packages\sqlalchemy\sql\compiler.py:6747: in visit_create_column
    text = self.get_column_specification(column, first_pk=first_pk)
unit_test_env\Lib\site-packages\sqlalchemy\dialects\sqlite\base.py:1598: in get_column_specification
    coltype = self.dialect.type_compiler_instance.process(
unit_test_env\Lib\site-packages\sqlalchemy\sql\compiler.py:977: in process
    return type_._compiler_dispatch(self, **kw)
unit_test_env\Lib\site-packages\sqlalchemy\sql\visitors.py:139: in _compiler_dispatch
    return visitor.visit_unsupported_compilation(self, err, **kw)  # type: ignore  # noqa: E501
unit_test_env\Lib\site-packages\sqlalchemy\sql\compiler.py:982: in visit_unsupported_compilation
    raise exc.UnsupportedCompilationError(self, element) from err
E   sqlalchemy.exc.UnsupportedCompilationError: Compiler <sqlalchemy.dialects.sqlite.base.SQLiteTypeCompiler object at 0x000002828FB5F620> can't render element of type JSONB (Background on this error at: https://sqlalche.me/e/20/l7de)

The above exception was the direct cause of the following exception:
temp\temp.py:48: in <module>
    Base.metadata.create_all(engine)
unit_test_env\Lib\site-packages\sqlalchemy\sql\schema.py:5925: in create_all
    bind._run_ddl_visitor(
unit_test_env\Lib\site-packages\sqlalchemy\engine\base.py:3249: in _run_ddl_visitor
    conn._run_ddl_visitor(visitorcallable, element, **kwargs)
unit_test_env\Lib\site-packages\sqlalchemy\engine\base.py:2456: in _run_ddl_visitor
    visitorcallable(self.dialect, self, **kwargs).traverse_single(element)
unit_test_env\Lib\site-packages\sqlalchemy\sql\visitors.py:664: in traverse_single
    return meth(obj, **kw)
unit_test_env\Lib\site-packages\sqlalchemy\sql\ddl.py:981: in visit_metadata
    self.traverse_single(
unit_test_env\Lib\site-packages\sqlalchemy\sql\visitors.py:664: in traverse_single
    return meth(obj, **kw)
unit_test_env\Lib\site-packages\sqlalchemy\sql\ddl.py:1019: in visit_table
    )._invoke_with(self.connection)
unit_test_env\Lib\site-packages\sqlalchemy\sql\ddl.py:321: in _invoke_with
    return bind.execute(self)
unit_test_env\Lib\site-packages\sqlalchemy\engine\base.py:1416: in execute
    return meth(
unit_test_env\Lib\site-packages\sqlalchemy\sql\ddl.py:187: in _execute_on_connection
    return connection._execute_ddl(
unit_test_env\Lib\site-packages\sqlalchemy\engine\base.py:1524: in _execute_ddl
    compiled = ddl.compile(
unit_test_env\Lib\site-packages\sqlalchemy\sql\elements.py:308: in compile
    return self._compiler(dialect, **kw)
unit_test_env\Lib\site-packages\sqlalchemy\sql\ddl.py:76: in _compiler
    return dialect.ddl_compiler(dialect, self, **kw)
unit_test_env\Lib\site-packages\sqlalchemy\sql\compiler.py:886: in __init__
    self.string = self.process(self.statement, **compile_kwargs)
unit_test_env\Lib\site-packages\sqlalchemy\sql\compiler.py:932: in process
    return obj._compiler_dispatch(self, **kwargs)
unit_test_env\Lib\site-packages\sqlalchemy\sql\visitors.py:141: in _compiler_dispatch
    return meth(self, **kw)  # type: ignore  # noqa: E501
unit_test_env\Lib\site-packages\sqlalchemy\sql\compiler.py:6726: in visit_create_table
    raise exc.CompileError(
E   sqlalchemy.exc.CompileError: (in table 'projects', column 'problem_statement'): Compiler <sqlalchemy.dialects.sqlite.base.SQLiteTypeCompiler object at 0x000002828FB5F620> can't render element of type JSONB
============================== warnings summary ===============================
theory_evaluation\models.py:17
  C:\ChenKhoon\JupyterNotebook\GenerateUnitTestCases\theory_evaluation\models.py:17: MovedIn20Warning: The ``declarative_base()`` function is now available as sqlalchemy.orm.declarative_base(). (deprecated since: 2.0) (Background on SQLAlchemy 2.0 at: https://sqlalche.me/e/b8d9)
    Base = declarative_base()

-- Docs: https://docs.pytest.org/en/stable/how-to/capture-warnings.html
=========================== short test summary info ===========================
ERROR temp/temp.py - sqlalchemy.exc.CompileError: (in table 'projects', colum...
!!!!!!!!!!!!!!!!!!! Interrupted: 1 error during collection !!!!!!!!!!!!!!!!!!!!
1 warning, 1 error in 1.29s
