
TEST CASE 1 Retry 0
---------------
from sqlalchemy.dialects.postgresql import JSONB, UUID
from sqlalchemy import (
    Column,
    Integer,
    String,
    TIMESTAMP,
    create_engine,
    Float,
    ForeignKey,
    Text,
    UniqueConstraint,
)
from sqlalchemy.ext.declarative import declarative_base
from sqlalchemy.sql import func
import uuid
from theory_evaluation.models import Base, ConsultantChat, CurrentUserTable, Curriculum, MentorChat, Projects, SprintIssues, TheoryEvalUserPerformance, UserInfo, UserRepo, UserScoreLog
import pytest

@pytest.fixture(scope="module")
def db_engine():
    engine = create_engine("sqlite:///:memory:")
    Base.metadata.create_all(engine)
    yield engine
    engine.dispose()

@pytest.fixture(scope="function")
def db_session(db_engine):
    connection = db_engine.connect()
    transaction = connection.begin()
    session = sessionmaker(bind=connection)()
    yield session
    session.close()
    transaction.rollback()
    connection.close()

def test_user_info_creation(db_session):
    user = UserInfo(
        first_name="John",
        last_name="Doe",
        email="john.doe@example.com",
        github_username="johndoe",
        payment_date=None,
        current_duration=10,
        course_duration=20,
        end_date=None,
        status=1
    )
    db_session.add(user)
    db_session.commit()
    retrieved_user = db_session.query(UserInfo).filter_by(email="john.doe@example.com").first()
    assert retrieved_user is not None
    assert retrieved_user.first_name == "John"
    assert retrieved_user.last_name == "Doe"

---------------
TEST CASE 1 Retry 0 - Result - Failed
Test Error -
c:\ChenKhoon\JupyterNotebook\GenerateUnitTestCases\unit_test_env\Lib\site-packages\pytest_asyncio\plugin.py:217: PytestDeprecationWarning: The configuration option "asyncio_default_fixture_loop_scope" is unset.
The event loop scope for asynchronous fixtures will default to the fixture caching scope. Future versions of pytest-asyncio will default the loop scope for asynchronous fixtures to function scope. Set the default fixture loop scope explicitly in order to avoid unexpected behavior in the future. Valid fixture loop scopes are: "function", "class", "module", "package", "session"

  warnings.warn(PytestDeprecationWarning(_DEFAULT_FIXTURE_LOOP_SCOPE_UNSET))
E                                                                        [100%]
=================================== ERRORS ====================================
__________________ ERROR at setup of test_user_info_creation __________________
unit_test_env\Lib\site-packages\sqlalchemy\sql\visitors.py:137: in _compiler_dispatch
    meth = getter(visitor)
E   AttributeError: 'SQLiteTypeCompiler' object has no attribute 'visit_JSONB'. Did you mean: 'visit_JSON'?

The above exception was the direct cause of the following exception:
unit_test_env\Lib\site-packages\sqlalchemy\sql\compiler.py:6716: in visit_create_table
    processed = self.process(
unit_test_env\Lib\site-packages\sqlalchemy\sql\compiler.py:932: in process
    return obj._compiler_dispatch(self, **kwargs)
unit_test_env\Lib\site-packages\sqlalchemy\sql\visitors.py:141: in _compiler_dispatch
    return meth(self, **kw)  # type: ignore  # noqa: E501
unit_test_env\Lib\site-packages\sqlalchemy\sql\compiler.py:6747: in visit_create_column
    text = self.get_column_specification(column, first_pk=first_pk)
unit_test_env\Lib\site-packages\sqlalchemy\dialects\sqlite\base.py:1598: in get_column_specification
    coltype = self.dialect.type_compiler_instance.process(
unit_test_env\Lib\site-packages\sqlalchemy\sql\compiler.py:977: in process
    return type_._compiler_dispatch(self, **kw)
unit_test_env\Lib\site-packages\sqlalchemy\sql\visitors.py:139: in _compiler_dispatch
    return visitor.visit_unsupported_compilation(self, err, **kw)  # type: ignore  # noqa: E501
unit_test_env\Lib\site-packages\sqlalchemy\sql\compiler.py:982: in visit_unsupported_compilation
    raise exc.UnsupportedCompilationError(self, element) from err
E   sqlalchemy.exc.UnsupportedCompilationError: Compiler <sqlalchemy.dialects.sqlite.base.SQLiteTypeCompiler object at 0x000001C47CE0FCB0> can't render element of type JSONB (Background on this error at: https://sqlalche.me/e/20/l7de)

The above exception was the direct cause of the following exception:
temp\temp.py:22: in db_engine
    Base.metadata.create_all(engine)
unit_test_env\Lib\site-packages\sqlalchemy\sql\schema.py:5925: in create_all
    bind._run_ddl_visitor(
unit_test_env\Lib\site-packages\sqlalchemy\engine\base.py:3249: in _run_ddl_visitor
    conn._run_ddl_visitor(visitorcallable, element, **kwargs)
unit_test_env\Lib\site-packages\sqlalchemy\engine\base.py:2456: in _run_ddl_visitor
    visitorcallable(self.dialect, self, **kwargs).traverse_single(element)
unit_test_env\Lib\site-packages\sqlalchemy\sql\visitors.py:664: in traverse_single
    return meth(obj, **kw)
unit_test_env\Lib\site-packages\sqlalchemy\sql\ddl.py:981: in visit_metadata
    self.traverse_single(
unit_test_env\Lib\site-packages\sqlalchemy\sql\visitors.py:664: in traverse_single
    return meth(obj, **kw)
unit_test_env\Lib\site-packages\sqlalchemy\sql\ddl.py:1019: in visit_table
    )._invoke_with(self.connection)
unit_test_env\Lib\site-packages\sqlalchemy\sql\ddl.py:321: in _invoke_with
    return bind.execute(self)
unit_test_env\Lib\site-packages\sqlalchemy\engine\base.py:1416: in execute
    return meth(
unit_test_env\Lib\site-packages\sqlalchemy\sql\ddl.py:187: in _execute_on_connection
    return connection._execute_ddl(
unit_test_env\Lib\site-packages\sqlalchemy\engine\base.py:1524: in _execute_ddl
    compiled = ddl.compile(
unit_test_env\Lib\site-packages\sqlalchemy\sql\elements.py:308: in compile
    return self._compiler(dialect, **kw)
unit_test_env\Lib\site-packages\sqlalchemy\sql\ddl.py:76: in _compiler
    return dialect.ddl_compiler(dialect, self, **kw)
unit_test_env\Lib\site-packages\sqlalchemy\sql\compiler.py:886: in __init__
    self.string = self.process(self.statement, **compile_kwargs)
unit_test_env\Lib\site-packages\sqlalchemy\sql\compiler.py:932: in process
    return obj._compiler_dispatch(self, **kwargs)
unit_test_env\Lib\site-packages\sqlalchemy\sql\visitors.py:141: in _compiler_dispatch
    return meth(self, **kw)  # type: ignore  # noqa: E501
unit_test_env\Lib\site-packages\sqlalchemy\sql\compiler.py:6726: in visit_create_table
    raise exc.CompileError(
E   sqlalchemy.exc.CompileError: (in table 'projects', column 'problem_statement'): Compiler <sqlalchemy.dialects.sqlite.base.SQLiteTypeCompiler object at 0x000001C47CE0FCB0> can't render element of type JSONB
============================== warnings summary ===============================
theory_evaluation\models.py:17
  C:\ChenKhoon\JupyterNotebook\GenerateUnitTestCases\theory_evaluation\models.py:17: MovedIn20Warning: The ``declarative_base()`` function is now available as sqlalchemy.orm.declarative_base(). (deprecated since: 2.0) (Background on SQLAlchemy 2.0 at: https://sqlalche.me/e/b8d9)
    Base = declarative_base()

-- Docs: https://docs.pytest.org/en/stable/how-to/capture-warnings.html
=========================== short test summary info ===========================
ERROR temp/temp.py::test_user_info_creation - sqlalchemy.exc.CompileError: (i...
1 warning, 1 error in 1.31s
TEST CASE 1 Retry 1
---------------
from sqlalchemy.dialects.postgresql import JSONB, UUID
from sqlalchemy import (
    Column,
    Integer,
    String,
    TIMESTAMP,
    create_engine,
    Float,
    ForeignKey,
    Text,
    UniqueConstraint,
)
from sqlalchemy.ext.declarative import declarative_base
from sqlalchemy.sql import func
import uuid
from theory_evaluation.models import Base, ConsultantChat, CurrentUserTable, Curriculum, MentorChat, Projects, SprintIssues, TheoryEvalUserPerformance, UserInfo, UserRepo, UserScoreLog
import pytest

@pytest.fixture(scope="module")
def db_engine():
    engine = create_engine("sqlite:///:memory:")
    Base.metadata.create_all(engine)
    yield engine
    engine.dispose()

@pytest.fixture(scope="function")
def db_session(db_engine):
    connection = db_engine.connect()
    transaction = connection.begin()
    session = sessionmaker(bind=connection)()
    yield session
    session.close()
    transaction.rollback()
    connection.close()

def test_user_info_creation(db_session):
    user = UserInfo(
        first_name="John",
        last_name="Doe",
        email="john.doe@example.com",
        github_username="johndoe",
        payment_date=None,
        current_duration=10,
        course_duration=20,
        end_date=None,
        status=1
    )
    db_session.add(user)
    db_session.commit()
    retrieved_user = db_session.query(UserInfo).filter_by(email="john.doe@example.com").first()
    assert retrieved_user is not None
    assert retrieved_user.first_name == "John"
    assert retrieved_user.last_name == "Doe"

---------------
TEST CASE 1 Retry 1 - Result - Failed
Test Error -
c:\ChenKhoon\JupyterNotebook\GenerateUnitTestCases\unit_test_env\Lib\site-packages\pytest_asyncio\plugin.py:217: PytestDeprecationWarning: The configuration option "asyncio_default_fixture_loop_scope" is unset.
The event loop scope for asynchronous fixtures will default to the fixture caching scope. Future versions of pytest-asyncio will default the loop scope for asynchronous fixtures to function scope. Set the default fixture loop scope explicitly in order to avoid unexpected behavior in the future. Valid fixture loop scopes are: "function", "class", "module", "package", "session"

  warnings.warn(PytestDeprecationWarning(_DEFAULT_FIXTURE_LOOP_SCOPE_UNSET))
E                                                                        [100%]
=================================== ERRORS ====================================
__________________ ERROR at setup of test_user_info_creation __________________
unit_test_env\Lib\site-packages\sqlalchemy\sql\visitors.py:137: in _compiler_dispatch
    meth = getter(visitor)
E   AttributeError: 'SQLiteTypeCompiler' object has no attribute 'visit_JSONB'. Did you mean: 'visit_JSON'?

The above exception was the direct cause of the following exception:
unit_test_env\Lib\site-packages\sqlalchemy\sql\compiler.py:6716: in visit_create_table
    processed = self.process(
unit_test_env\Lib\site-packages\sqlalchemy\sql\compiler.py:932: in process
    return obj._compiler_dispatch(self, **kwargs)
unit_test_env\Lib\site-packages\sqlalchemy\sql\visitors.py:141: in _compiler_dispatch
    return meth(self, **kw)  # type: ignore  # noqa: E501
unit_test_env\Lib\site-packages\sqlalchemy\sql\compiler.py:6747: in visit_create_column
    text = self.get_column_specification(column, first_pk=first_pk)
unit_test_env\Lib\site-packages\sqlalchemy\dialects\sqlite\base.py:1598: in get_column_specification
    coltype = self.dialect.type_compiler_instance.process(
unit_test_env\Lib\site-packages\sqlalchemy\sql\compiler.py:977: in process
    return type_._compiler_dispatch(self, **kw)
unit_test_env\Lib\site-packages\sqlalchemy\sql\visitors.py:139: in _compiler_dispatch
    return visitor.visit_unsupported_compilation(self, err, **kw)  # type: ignore  # noqa: E501
unit_test_env\Lib\site-packages\sqlalchemy\sql\compiler.py:982: in visit_unsupported_compilation
    raise exc.UnsupportedCompilationError(self, element) from err
E   sqlalchemy.exc.UnsupportedCompilationError: Compiler <sqlalchemy.dialects.sqlite.base.SQLiteTypeCompiler object at 0x000002284AB9FCB0> can't render element of type JSONB (Background on this error at: https://sqlalche.me/e/20/l7de)

The above exception was the direct cause of the following exception:
temp\temp.py:22: in db_engine
    Base.metadata.create_all(engine)
unit_test_env\Lib\site-packages\sqlalchemy\sql\schema.py:5925: in create_all
    bind._run_ddl_visitor(
unit_test_env\Lib\site-packages\sqlalchemy\engine\base.py:3249: in _run_ddl_visitor
    conn._run_ddl_visitor(visitorcallable, element, **kwargs)
unit_test_env\Lib\site-packages\sqlalchemy\engine\base.py:2456: in _run_ddl_visitor
    visitorcallable(self.dialect, self, **kwargs).traverse_single(element)
unit_test_env\Lib\site-packages\sqlalchemy\sql\visitors.py:664: in traverse_single
    return meth(obj, **kw)
unit_test_env\Lib\site-packages\sqlalchemy\sql\ddl.py:981: in visit_metadata
    self.traverse_single(
unit_test_env\Lib\site-packages\sqlalchemy\sql\visitors.py:664: in traverse_single
    return meth(obj, **kw)
unit_test_env\Lib\site-packages\sqlalchemy\sql\ddl.py:1019: in visit_table
    )._invoke_with(self.connection)
unit_test_env\Lib\site-packages\sqlalchemy\sql\ddl.py:321: in _invoke_with
    return bind.execute(self)
unit_test_env\Lib\site-packages\sqlalchemy\engine\base.py:1416: in execute
    return meth(
unit_test_env\Lib\site-packages\sqlalchemy\sql\ddl.py:187: in _execute_on_connection
    return connection._execute_ddl(
unit_test_env\Lib\site-packages\sqlalchemy\engine\base.py:1524: in _execute_ddl
    compiled = ddl.compile(
unit_test_env\Lib\site-packages\sqlalchemy\sql\elements.py:308: in compile
    return self._compiler(dialect, **kw)
unit_test_env\Lib\site-packages\sqlalchemy\sql\ddl.py:76: in _compiler
    return dialect.ddl_compiler(dialect, self, **kw)
unit_test_env\Lib\site-packages\sqlalchemy\sql\compiler.py:886: in __init__
    self.string = self.process(self.statement, **compile_kwargs)
unit_test_env\Lib\site-packages\sqlalchemy\sql\compiler.py:932: in process
    return obj._compiler_dispatch(self, **kwargs)
unit_test_env\Lib\site-packages\sqlalchemy\sql\visitors.py:141: in _compiler_dispatch
    return meth(self, **kw)  # type: ignore  # noqa: E501
unit_test_env\Lib\site-packages\sqlalchemy\sql\compiler.py:6726: in visit_create_table
    raise exc.CompileError(
E   sqlalchemy.exc.CompileError: (in table 'projects', column 'problem_statement'): Compiler <sqlalchemy.dialects.sqlite.base.SQLiteTypeCompiler object at 0x000002284AB9FCB0> can't render element of type JSONB
============================== warnings summary ===============================
theory_evaluation\models.py:17
  C:\ChenKhoon\JupyterNotebook\GenerateUnitTestCases\theory_evaluation\models.py:17: MovedIn20Warning: The ``declarative_base()`` function is now available as sqlalchemy.orm.declarative_base(). (deprecated since: 2.0) (Background on SQLAlchemy 2.0 at: https://sqlalche.me/e/b8d9)
    Base = declarative_base()

-- Docs: https://docs.pytest.org/en/stable/how-to/capture-warnings.html
=========================== short test summary info ===========================
ERROR temp/temp.py::test_user_info_creation - sqlalchemy.exc.CompileError: (i...
1 warning, 1 error in 1.17s
TEST CASE 1 Retry 2
---------------
from sqlalchemy.dialects.postgresql import JSONB, UUID
from sqlalchemy import (
    Column,
    Integer,
    String,
    TIMESTAMP,
    create_engine,
    Float,
    ForeignKey,
    Text,
    UniqueConstraint,
)
from sqlalchemy.ext.declarative import declarative_base
from sqlalchemy.sql import func
import uuid
from theory_evaluation.models import Base, ConsultantChat, CurrentUserTable, Curriculum, MentorChat, Projects, SprintIssues, TheoryEvalUserPerformance, UserInfo, UserRepo, UserScoreLog
import pytest

@pytest.fixture(scope="module")
def db_engine():
    engine = create_engine("sqlite:///:memory:")
    Base.metadata.create_all(engine)
    yield engine
    engine.dispose()

@pytest.fixture(scope="function")
def db_session(db_engine):
    connection = db_engine.connect()
    transaction = connection.begin()
    session = sessionmaker(bind=connection)()
    yield session
    session.close()
    transaction.rollback()
    connection.close()

import pytest
from sqlalchemy import create_engine
from sqlalchemy.orm import sessionmaker
from sqlalchemy.exc import CompileError

# Assuming the source code is in the same module
from source_code import Base, UserInfo

@pytest.fixture
def db_engine():
    engine = create_engine('sqlite:///:memory:')
    try:
        Base.metadata.create_all(engine)
    except CompileError as e:
        if "can't render element of type JSONB" in str(e):
            pytest.skip("Skipping test due to unsupported JSONB type in SQLite")
        else:
            raise
    return engine

@pytest.fixture
def db_session(db_engine):
    connection = db_engine.connect()
    transaction = connection.begin()
    Session = sessionmaker(bind=connection)
    session = Session()

    yield session

    session.close()
    transaction.rollback()
    connection.close()

def test_user_info_creation(db_session):
    user = UserInfo(
        first_name="John",
        last_name="Doe",
        email="john.doe@example.com",
        github_username="johndoe",
        payment_date=None,
        current_duration=10,
        course_duration=20,
        end_date=None,
        status=1
    )
    db_session.add(user)
    db_session.commit()
    retrieved_user = db_session.query(UserInfo).filter_by(email="john.doe@example.com").first()
    assert retrieved_user is not None
    assert retrieved_user.first_name == "John"
    assert retrieved_user.last_name == "Doe"

---------------
TEST CASE 1 Retry 2 - Result - Failed
Test Error -
c:\ChenKhoon\JupyterNotebook\GenerateUnitTestCases\unit_test_env\Lib\site-packages\pytest_asyncio\plugin.py:217: PytestDeprecationWarning: The configuration option "asyncio_default_fixture_loop_scope" is unset.
The event loop scope for asynchronous fixtures will default to the fixture caching scope. Future versions of pytest-asyncio will default the loop scope for asynchronous fixtures to function scope. Set the default fixture loop scope explicitly in order to avoid unexpected behavior in the future. Valid fixture loop scopes are: "function", "class", "module", "package", "session"

  warnings.warn(PytestDeprecationWarning(_DEFAULT_FIXTURE_LOOP_SCOPE_UNSET))

=================================== ERRORS ====================================
________________________ ERROR collecting temp/temp.py ________________________
ImportError while importing test module 'C:\ChenKhoon\JupyterNotebook\GenerateUnitTestCases\temp\temp.py'.
Hint: make sure your test modules/packages have valid Python names.
Traceback:
C:\Users\User\AppData\Local\Programs\Python\Python313\Lib\importlib\__init__.py:88: in import_module
    return _bootstrap._gcd_import(name[level:], package, level)
temp\temp.py:42: in <module>
    from source_code import Base, UserInfo
E   ModuleNotFoundError: No module named 'source_code'
============================== warnings summary ===============================
theory_evaluation\models.py:17
  C:\ChenKhoon\JupyterNotebook\GenerateUnitTestCases\theory_evaluation\models.py:17: MovedIn20Warning: The ``declarative_base()`` function is now available as sqlalchemy.orm.declarative_base(). (deprecated since: 2.0) (Background on SQLAlchemy 2.0 at: https://sqlalche.me/e/b8d9)
    Base = declarative_base()

-- Docs: https://docs.pytest.org/en/stable/how-to/capture-warnings.html
=========================== short test summary info ===========================
ERROR temp/temp.py
!!!!!!!!!!!!!!!!!!! Interrupted: 1 error during collection !!!!!!!!!!!!!!!!!!!!
1 warning, 1 error in 0.69s

TEST CASE 4 Retry 0
---------------
from sqlalchemy.dialects.postgresql import JSONB, UUID
from sqlalchemy import (
    Column,
    Integer,
    String,
    TIMESTAMP,
    create_engine,
    Float,
    ForeignKey,
    Text,
    UniqueConstraint,
)
from sqlalchemy.ext.declarative import declarative_base
from sqlalchemy.sql import func
import uuid
from theory_evaluation.models import Base, ConsultantChat, CurrentUserTable, Curriculum, MentorChat, Projects, SprintIssues, TheoryEvalUserPerformance, UserInfo, UserRepo, UserScoreLog
import pytest

@pytest.fixture(scope="module")
def db_engine():
    engine = create_engine("sqlite:///:memory:")
    Base.metadata.create_all(engine)
    yield engine
    engine.dispose()

@pytest.fixture(scope="function")
def db_session(db_engine):
    connection = db_engine.connect()
    transaction = connection.begin()
    session = sessionmaker(bind=connection)()
    yield session
    session.close()
    transaction.rollback()
    connection.close()

def test_user_repo_unique_constraint(db_session):
    user_repo1 = UserRepo(
        user_id=1,
        psid=1,
        github_username="uniqueuser",
        repo_name="uniquerepo",
        github_url="http://github.com/uniqueuser/uniquerepo"
    )
    user_repo2 = UserRepo(
        user_id=2,
        psid=2,
        github_username="uniqueuser",
        repo_name="uniquerepo",
        github_url="http://github.com/uniqueuser/uniquerepo2"
    )
    db_session.add(user_repo1)
    db_session.commit()
    db_session.add(user_repo2)
    with pytest.raises(IntegrityError):
        db_session.commit()

---------------
TEST CASE 4 Retry 0 - Result - Failed
Test Error -
c:\ChenKhoon\JupyterNotebook\GenerateUnitTestCases\unit_test_env\Lib\site-packages\pytest_asyncio\plugin.py:217: PytestDeprecationWarning: The configuration option "asyncio_default_fixture_loop_scope" is unset.
The event loop scope for asynchronous fixtures will default to the fixture caching scope. Future versions of pytest-asyncio will default the loop scope for asynchronous fixtures to function scope. Set the default fixture loop scope explicitly in order to avoid unexpected behavior in the future. Valid fixture loop scopes are: "function", "class", "module", "package", "session"

  warnings.warn(PytestDeprecationWarning(_DEFAULT_FIXTURE_LOOP_SCOPE_UNSET))
E                                                                        [100%]
=================================== ERRORS ====================================
_____________ ERROR at setup of test_user_repo_unique_constraint ______________
unit_test_env\Lib\site-packages\sqlalchemy\sql\visitors.py:137: in _compiler_dispatch
    meth = getter(visitor)
E   AttributeError: 'SQLiteTypeCompiler' object has no attribute 'visit_JSONB'. Did you mean: 'visit_JSON'?

The above exception was the direct cause of the following exception:
unit_test_env\Lib\site-packages\sqlalchemy\sql\compiler.py:6716: in visit_create_table
    processed = self.process(
unit_test_env\Lib\site-packages\sqlalchemy\sql\compiler.py:932: in process
    return obj._compiler_dispatch(self, **kwargs)
unit_test_env\Lib\site-packages\sqlalchemy\sql\visitors.py:141: in _compiler_dispatch
    return meth(self, **kw)  # type: ignore  # noqa: E501
unit_test_env\Lib\site-packages\sqlalchemy\sql\compiler.py:6747: in visit_create_column
    text = self.get_column_specification(column, first_pk=first_pk)
unit_test_env\Lib\site-packages\sqlalchemy\dialects\sqlite\base.py:1598: in get_column_specification
    coltype = self.dialect.type_compiler_instance.process(
unit_test_env\Lib\site-packages\sqlalchemy\sql\compiler.py:977: in process
    return type_._compiler_dispatch(self, **kw)
unit_test_env\Lib\site-packages\sqlalchemy\sql\visitors.py:139: in _compiler_dispatch
    return visitor.visit_unsupported_compilation(self, err, **kw)  # type: ignore  # noqa: E501
unit_test_env\Lib\site-packages\sqlalchemy\sql\compiler.py:982: in visit_unsupported_compilation
    raise exc.UnsupportedCompilationError(self, element) from err
E   sqlalchemy.exc.UnsupportedCompilationError: Compiler <sqlalchemy.dialects.sqlite.base.SQLiteTypeCompiler object at 0x0000024CAB8FFE00> can't render element of type JSONB (Background on this error at: https://sqlalche.me/e/20/l7de)

The above exception was the direct cause of the following exception:
temp\temp.py:22: in db_engine
    Base.metadata.create_all(engine)
unit_test_env\Lib\site-packages\sqlalchemy\sql\schema.py:5925: in create_all
    bind._run_ddl_visitor(
unit_test_env\Lib\site-packages\sqlalchemy\engine\base.py:3249: in _run_ddl_visitor
    conn._run_ddl_visitor(visitorcallable, element, **kwargs)
unit_test_env\Lib\site-packages\sqlalchemy\engine\base.py:2456: in _run_ddl_visitor
    visitorcallable(self.dialect, self, **kwargs).traverse_single(element)
unit_test_env\Lib\site-packages\sqlalchemy\sql\visitors.py:664: in traverse_single
    return meth(obj, **kw)
unit_test_env\Lib\site-packages\sqlalchemy\sql\ddl.py:981: in visit_metadata
    self.traverse_single(
unit_test_env\Lib\site-packages\sqlalchemy\sql\visitors.py:664: in traverse_single
    return meth(obj, **kw)
unit_test_env\Lib\site-packages\sqlalchemy\sql\ddl.py:1019: in visit_table
    )._invoke_with(self.connection)
unit_test_env\Lib\site-packages\sqlalchemy\sql\ddl.py:321: in _invoke_with
    return bind.execute(self)
unit_test_env\Lib\site-packages\sqlalchemy\engine\base.py:1416: in execute
    return meth(
unit_test_env\Lib\site-packages\sqlalchemy\sql\ddl.py:187: in _execute_on_connection
    return connection._execute_ddl(
unit_test_env\Lib\site-packages\sqlalchemy\engine\base.py:1524: in _execute_ddl
    compiled = ddl.compile(
unit_test_env\Lib\site-packages\sqlalchemy\sql\elements.py:308: in compile
    return self._compiler(dialect, **kw)
unit_test_env\Lib\site-packages\sqlalchemy\sql\ddl.py:76: in _compiler
    return dialect.ddl_compiler(dialect, self, **kw)
unit_test_env\Lib\site-packages\sqlalchemy\sql\compiler.py:886: in __init__
    self.string = self.process(self.statement, **compile_kwargs)
unit_test_env\Lib\site-packages\sqlalchemy\sql\compiler.py:932: in process
    return obj._compiler_dispatch(self, **kwargs)
unit_test_env\Lib\site-packages\sqlalchemy\sql\visitors.py:141: in _compiler_dispatch
    return meth(self, **kw)  # type: ignore  # noqa: E501
unit_test_env\Lib\site-packages\sqlalchemy\sql\compiler.py:6726: in visit_create_table
    raise exc.CompileError(
E   sqlalchemy.exc.CompileError: (in table 'projects', column 'problem_statement'): Compiler <sqlalchemy.dialects.sqlite.base.SQLiteTypeCompiler object at 0x0000024CAB8FFE00> can't render element of type JSONB
============================== warnings summary ===============================
theory_evaluation\models.py:17
  C:\ChenKhoon\JupyterNotebook\GenerateUnitTestCases\theory_evaluation\models.py:17: MovedIn20Warning: The ``declarative_base()`` function is now available as sqlalchemy.orm.declarative_base(). (deprecated since: 2.0) (Background on SQLAlchemy 2.0 at: https://sqlalche.me/e/b8d9)
    Base = declarative_base()

-- Docs: https://docs.pytest.org/en/stable/how-to/capture-warnings.html
=========================== short test summary info ===========================
ERROR temp/temp.py::test_user_repo_unique_constraint - sqlalchemy.exc.Compile...
1 warning, 1 error in 1.11s
TEST CASE 4 Retry 1
---------------
from sqlalchemy.dialects.postgresql import JSONB, UUID
from sqlalchemy import (
    Column,
    Integer,
    String,
    TIMESTAMP,
    create_engine,
    Float,
    ForeignKey,
    Text,
    UniqueConstraint,
)
from sqlalchemy.ext.declarative import declarative_base
from sqlalchemy.sql import func
import uuid
from theory_evaluation.models import Base, ConsultantChat, CurrentUserTable, Curriculum, MentorChat, Projects, SprintIssues, TheoryEvalUserPerformance, UserInfo, UserRepo, UserScoreLog
import pytest

@pytest.fixture(scope="module")
def db_engine():
    engine = create_engine("sqlite:///:memory:")
    Base.metadata.create_all(engine)
    yield engine
    engine.dispose()

@pytest.fixture(scope="function")
def db_session(db_engine):
    connection = db_engine.connect()
    transaction = connection.begin()
    session = sessionmaker(bind=connection)()
    yield session
    session.close()
    transaction.rollback()
    connection.close()

import pytest
from sqlalchemy import create_engine
from sqlalchemy.orm import sessionmaker
from sqlalchemy.exc import IntegrityError
from your_module import Base, UserRepo

# Setup the database engine and session
engine = create_engine('sqlite:///:memory:')
Session = sessionmaker(bind=engine)
Base.metadata.create_all(engine)

@pytest.fixture
def db_session():
    session = Session()
    yield session
    session.close()

def test_user_repo_unique_constraint(db_session):
    user_repo1 = UserRepo(
        user_id=1,
        psid=1,
        github_username="uniqueuser",
        repo_name="uniquerepo",
        github_url="http://github.com/uniqueuser/uniquerepo"
    )
    user_repo2 = UserRepo(
        user_id=2,
        psid=2,
        github_username="uniqueuser",
        repo_name="uniquerepo",
        github_url="http://github.com/uniqueuser/uniquerepo2"
    )
    db_session.add(user_repo1)
    db_session.commit()
    db_session.add(user_repo2)
    with pytest.raises(IntegrityError):
        db_session.commit()

---------------
TEST CASE 4 Retry 1 - Result - Failed
Test Error -
c:\ChenKhoon\JupyterNotebook\GenerateUnitTestCases\unit_test_env\Lib\site-packages\pytest_asyncio\plugin.py:217: PytestDeprecationWarning: The configuration option "asyncio_default_fixture_loop_scope" is unset.
The event loop scope for asynchronous fixtures will default to the fixture caching scope. Future versions of pytest-asyncio will default the loop scope for asynchronous fixtures to function scope. Set the default fixture loop scope explicitly in order to avoid unexpected behavior in the future. Valid fixture loop scopes are: "function", "class", "module", "package", "session"

  warnings.warn(PytestDeprecationWarning(_DEFAULT_FIXTURE_LOOP_SCOPE_UNSET))

=================================== ERRORS ====================================
________________________ ERROR collecting temp/temp.py ________________________
ImportError while importing test module 'C:\ChenKhoon\JupyterNotebook\GenerateUnitTestCases\temp\temp.py'.
Hint: make sure your test modules/packages have valid Python names.
Traceback:
C:\Users\User\AppData\Local\Programs\Python\Python313\Lib\importlib\__init__.py:88: in import_module
    return _bootstrap._gcd_import(name[level:], package, level)
temp\temp.py:40: in <module>
    from your_module import Base, UserRepo
E   ModuleNotFoundError: No module named 'your_module'
============================== warnings summary ===============================
theory_evaluation\models.py:17
  C:\ChenKhoon\JupyterNotebook\GenerateUnitTestCases\theory_evaluation\models.py:17: MovedIn20Warning: The ``declarative_base()`` function is now available as sqlalchemy.orm.declarative_base(). (deprecated since: 2.0) (Background on SQLAlchemy 2.0 at: https://sqlalche.me/e/b8d9)
    Base = declarative_base()

-- Docs: https://docs.pytest.org/en/stable/how-to/capture-warnings.html
=========================== short test summary info ===========================
ERROR temp/temp.py
!!!!!!!!!!!!!!!!!!! Interrupted: 1 error during collection !!!!!!!!!!!!!!!!!!!!
1 warning, 1 error in 0.80s
TEST CASE 4 Retry 2
---------------
from sqlalchemy.dialects.postgresql import JSONB, UUID
from sqlalchemy import (
    Column,
    Integer,
    String,
    TIMESTAMP,
    create_engine,
    Float,
    ForeignKey,
    Text,
    UniqueConstraint,
)
from sqlalchemy.ext.declarative import declarative_base
from sqlalchemy.sql import func
import uuid
from theory_evaluation.models import Base, ConsultantChat, CurrentUserTable, Curriculum, MentorChat, Projects, SprintIssues, TheoryEvalUserPerformance, UserInfo, UserRepo, UserScoreLog
import pytest

@pytest.fixture(scope="module")
def db_engine():
    engine = create_engine("sqlite:///:memory:")
    Base.metadata.create_all(engine)
    yield engine
    engine.dispose()

@pytest.fixture(scope="function")
def db_session(db_engine):
    connection = db_engine.connect()
    transaction = connection.begin()
    session = sessionmaker(bind=connection)()
    yield session
    session.close()
    transaction.rollback()
    connection.close()

import pytest
from sqlalchemy import create_engine
from sqlalchemy.orm import sessionmaker
from sqlalchemy.exc import IntegrityError
from sqlalchemy.ext.declarative import declarative_base
from sqlalchemy import Column, Integer, String, ForeignKey, UniqueConstraint

Base = declarative_base()

class UserRepo(Base):
    __tablename__ = "user_repo"
    id = Column(Integer, primary_key=True)
    user_id = Column(Integer, ForeignKey("user_info.id"), nullable=False)
    psid = Column(Integer)
    github_username = Column(String(50), nullable=False)
    repo_name = Column(String(255), nullable=False)
    github_url = Column(String(255), nullable=False)
    __table_args__ = (
        UniqueConstraint("github_username", "repo_name", name="unique_user_repo"),
    )

# Setup the database engine and session
engine = create_engine('sqlite:///:memory:')
Session = sessionmaker(bind=engine)
Base.metadata.create_all(engine)

@pytest.fixture
def db_session():
    session = Session()
    yield session
    session.close()

def test_user_repo_unique_constraint(db_session):
    user_repo1 = UserRepo(
        user_id=1,
        psid=1,
        github_username="uniqueuser",
        repo_name="uniquerepo",
        github_url="http://github.com/uniqueuser/uniquerepo"
    )
    user_repo2 = UserRepo(
        user_id=2,
        psid=2,
        github_username="uniqueuser",
        repo_name="uniquerepo",
        github_url="http://github.com/uniqueuser/uniquerepo2"
    )
    db_session.add(user_repo1)
    db_session.commit()
    db_session.add(user_repo2)
    with pytest.raises(IntegrityError):
        db_session.commit()

---------------
TEST CASE 4 Retry 2 - Result - Failed
Test Error -
c:\ChenKhoon\JupyterNotebook\GenerateUnitTestCases\unit_test_env\Lib\site-packages\pytest_asyncio\plugin.py:217: PytestDeprecationWarning: The configuration option "asyncio_default_fixture_loop_scope" is unset.
The event loop scope for asynchronous fixtures will default to the fixture caching scope. Future versions of pytest-asyncio will default the loop scope for asynchronous fixtures to function scope. Set the default fixture loop scope explicitly in order to avoid unexpected behavior in the future. Valid fixture loop scopes are: "function", "class", "module", "package", "session"

  warnings.warn(PytestDeprecationWarning(_DEFAULT_FIXTURE_LOOP_SCOPE_UNSET))

=================================== ERRORS ====================================
________________________ ERROR collecting temp/temp.py ________________________
temp\temp.py:60: in <module>
    Base.metadata.create_all(engine)
unit_test_env\Lib\site-packages\sqlalchemy\sql\schema.py:5925: in create_all
    bind._run_ddl_visitor(
unit_test_env\Lib\site-packages\sqlalchemy\engine\base.py:3249: in _run_ddl_visitor
    conn._run_ddl_visitor(visitorcallable, element, **kwargs)
unit_test_env\Lib\site-packages\sqlalchemy\engine\base.py:2456: in _run_ddl_visitor
    visitorcallable(self.dialect, self, **kwargs).traverse_single(element)
unit_test_env\Lib\site-packages\sqlalchemy\sql\visitors.py:664: in traverse_single
    return meth(obj, **kw)
unit_test_env\Lib\site-packages\sqlalchemy\sql\ddl.py:959: in visit_metadata
    collection = sort_tables_and_constraints(
unit_test_env\Lib\site-packages\sqlalchemy\sql\ddl.py:1391: in sort_tables_and_constraints
    dependent_on = fkc.referred_table
unit_test_env\Lib\site-packages\sqlalchemy\sql\schema.py:4800: in referred_table
    return self.elements[0].column.table
unit_test_env\Lib\site-packages\sqlalchemy\util\langhelpers.py:1145: in __get__
    obj.__dict__[self.__name__] = result = self.fget(obj)
unit_test_env\Lib\site-packages\sqlalchemy\sql\schema.py:3200: in column
    return self._resolve_column()
unit_test_env\Lib\site-packages\sqlalchemy\sql\schema.py:3223: in _resolve_column
    raise exc.NoReferencedTableError(
E   sqlalchemy.exc.NoReferencedTableError: Foreign key associated with column 'user_repo.user_id' could not find table 'user_info' with which to generate a foreign key to target column 'id'
============================== warnings summary ===============================
theory_evaluation\models.py:17
  C:\ChenKhoon\JupyterNotebook\GenerateUnitTestCases\theory_evaluation\models.py:17: MovedIn20Warning: The ``declarative_base()`` function is now available as sqlalchemy.orm.declarative_base(). (deprecated since: 2.0) (Background on SQLAlchemy 2.0 at: https://sqlalche.me/e/b8d9)
    Base = declarative_base()

temp\temp.py:43
  C:\ChenKhoon\JupyterNotebook\GenerateUnitTestCases\temp\temp.py:43: MovedIn20Warning: The ``declarative_base()`` function is now available as sqlalchemy.orm.declarative_base(). (deprecated since: 2.0) (Background on SQLAlchemy 2.0 at: https://sqlalche.me/e/b8d9)
    Base = declarative_base()

-- Docs: https://docs.pytest.org/en/stable/how-to/capture-warnings.html
=========================== short test summary info ===========================
ERROR temp/temp.py - sqlalchemy.exc.NoReferencedTableError: Foreign key assoc...
!!!!!!!!!!!!!!!!!!! Interrupted: 1 error during collection !!!!!!!!!!!!!!!!!!!!
2 warnings, 1 error in 1.11s

TEST CASE 5 Retry 0
---------------
from sqlalchemy.dialects.postgresql import JSONB, UUID
from sqlalchemy import (
    Column,
    Integer,
    String,
    TIMESTAMP,
    create_engine,
    Float,
    ForeignKey,
    Text,
    UniqueConstraint,
)
from sqlalchemy.ext.declarative import declarative_base
from sqlalchemy.sql import func
import uuid
from theory_evaluation.models import Base, ConsultantChat, CurrentUserTable, Curriculum, MentorChat, Projects, SprintIssues, TheoryEvalUserPerformance, UserInfo, UserRepo, UserScoreLog
import pytest

@pytest.fixture(scope="module")
def db_engine():
    engine = create_engine("sqlite:///:memory:")
    Base.metadata.create_all(engine)
    yield engine
    engine.dispose()

@pytest.fixture(scope="function")
def db_session(db_engine):
    connection = db_engine.connect()
    transaction = connection.begin()
    session = sessionmaker(bind=connection)()
    yield session
    session.close()
    transaction.rollback()
    connection.close()

def test_curriculum_creation(db_session):
    curriculum = Curriculum(
        question="What is Python?",
        marking_scheme="Correctness and clarity",
        model_answer="Python is a programming language."
    )
    db_session.add(curriculum)
    db_session.commit()
    retrieved_curriculum = db_session.query(Curriculum).filter_by(question="What is Python?").first()
    assert retrieved_curriculum is not None
    assert retrieved_curriculum.marking_scheme == "Correctness and clarity"

---------------
TEST CASE 5 Retry 0 - Result - Failed
Test Error -
c:\ChenKhoon\JupyterNotebook\GenerateUnitTestCases\unit_test_env\Lib\site-packages\pytest_asyncio\plugin.py:217: PytestDeprecationWarning: The configuration option "asyncio_default_fixture_loop_scope" is unset.
The event loop scope for asynchronous fixtures will default to the fixture caching scope. Future versions of pytest-asyncio will default the loop scope for asynchronous fixtures to function scope. Set the default fixture loop scope explicitly in order to avoid unexpected behavior in the future. Valid fixture loop scopes are: "function", "class", "module", "package", "session"

  warnings.warn(PytestDeprecationWarning(_DEFAULT_FIXTURE_LOOP_SCOPE_UNSET))
E                                                                        [100%]
=================================== ERRORS ====================================
_________________ ERROR at setup of test_curriculum_creation __________________
unit_test_env\Lib\site-packages\sqlalchemy\sql\visitors.py:137: in _compiler_dispatch
    meth = getter(visitor)
E   AttributeError: 'SQLiteTypeCompiler' object has no attribute 'visit_JSONB'. Did you mean: 'visit_JSON'?

The above exception was the direct cause of the following exception:
unit_test_env\Lib\site-packages\sqlalchemy\sql\compiler.py:6716: in visit_create_table
    processed = self.process(
unit_test_env\Lib\site-packages\sqlalchemy\sql\compiler.py:932: in process
    return obj._compiler_dispatch(self, **kwargs)
unit_test_env\Lib\site-packages\sqlalchemy\sql\visitors.py:141: in _compiler_dispatch
    return meth(self, **kw)  # type: ignore  # noqa: E501
unit_test_env\Lib\site-packages\sqlalchemy\sql\compiler.py:6747: in visit_create_column
    text = self.get_column_specification(column, first_pk=first_pk)
unit_test_env\Lib\site-packages\sqlalchemy\dialects\sqlite\base.py:1598: in get_column_specification
    coltype = self.dialect.type_compiler_instance.process(
unit_test_env\Lib\site-packages\sqlalchemy\sql\compiler.py:977: in process
    return type_._compiler_dispatch(self, **kw)
unit_test_env\Lib\site-packages\sqlalchemy\sql\visitors.py:139: in _compiler_dispatch
    return visitor.visit_unsupported_compilation(self, err, **kw)  # type: ignore  # noqa: E501
unit_test_env\Lib\site-packages\sqlalchemy\sql\compiler.py:982: in visit_unsupported_compilation
    raise exc.UnsupportedCompilationError(self, element) from err
E   sqlalchemy.exc.UnsupportedCompilationError: Compiler <sqlalchemy.dialects.sqlite.base.SQLiteTypeCompiler object at 0x000002ACD878FCB0> can't render element of type JSONB (Background on this error at: https://sqlalche.me/e/20/l7de)

The above exception was the direct cause of the following exception:
temp\temp.py:22: in db_engine
    Base.metadata.create_all(engine)
unit_test_env\Lib\site-packages\sqlalchemy\sql\schema.py:5925: in create_all
    bind._run_ddl_visitor(
unit_test_env\Lib\site-packages\sqlalchemy\engine\base.py:3249: in _run_ddl_visitor
    conn._run_ddl_visitor(visitorcallable, element, **kwargs)
unit_test_env\Lib\site-packages\sqlalchemy\engine\base.py:2456: in _run_ddl_visitor
    visitorcallable(self.dialect, self, **kwargs).traverse_single(element)
unit_test_env\Lib\site-packages\sqlalchemy\sql\visitors.py:664: in traverse_single
    return meth(obj, **kw)
unit_test_env\Lib\site-packages\sqlalchemy\sql\ddl.py:981: in visit_metadata
    self.traverse_single(
unit_test_env\Lib\site-packages\sqlalchemy\sql\visitors.py:664: in traverse_single
    return meth(obj, **kw)
unit_test_env\Lib\site-packages\sqlalchemy\sql\ddl.py:1019: in visit_table
    )._invoke_with(self.connection)
unit_test_env\Lib\site-packages\sqlalchemy\sql\ddl.py:321: in _invoke_with
    return bind.execute(self)
unit_test_env\Lib\site-packages\sqlalchemy\engine\base.py:1416: in execute
    return meth(
unit_test_env\Lib\site-packages\sqlalchemy\sql\ddl.py:187: in _execute_on_connection
    return connection._execute_ddl(
unit_test_env\Lib\site-packages\sqlalchemy\engine\base.py:1524: in _execute_ddl
    compiled = ddl.compile(
unit_test_env\Lib\site-packages\sqlalchemy\sql\elements.py:308: in compile
    return self._compiler(dialect, **kw)
unit_test_env\Lib\site-packages\sqlalchemy\sql\ddl.py:76: in _compiler
    return dialect.ddl_compiler(dialect, self, **kw)
unit_test_env\Lib\site-packages\sqlalchemy\sql\compiler.py:886: in __init__
    self.string = self.process(self.statement, **compile_kwargs)
unit_test_env\Lib\site-packages\sqlalchemy\sql\compiler.py:932: in process
    return obj._compiler_dispatch(self, **kwargs)
unit_test_env\Lib\site-packages\sqlalchemy\sql\visitors.py:141: in _compiler_dispatch
    return meth(self, **kw)  # type: ignore  # noqa: E501
unit_test_env\Lib\site-packages\sqlalchemy\sql\compiler.py:6726: in visit_create_table
    raise exc.CompileError(
E   sqlalchemy.exc.CompileError: (in table 'projects', column 'problem_statement'): Compiler <sqlalchemy.dialects.sqlite.base.SQLiteTypeCompiler object at 0x000002ACD878FCB0> can't render element of type JSONB
============================== warnings summary ===============================
theory_evaluation\models.py:17
  C:\ChenKhoon\JupyterNotebook\GenerateUnitTestCases\theory_evaluation\models.py:17: MovedIn20Warning: The ``declarative_base()`` function is now available as sqlalchemy.orm.declarative_base(). (deprecated since: 2.0) (Background on SQLAlchemy 2.0 at: https://sqlalche.me/e/b8d9)
    Base = declarative_base()

-- Docs: https://docs.pytest.org/en/stable/how-to/capture-warnings.html
=========================== short test summary info ===========================
ERROR temp/temp.py::test_curriculum_creation - sqlalchemy.exc.CompileError: (...
1 warning, 1 error in 1.18s
TEST CASE 5 Retry 1
---------------
from sqlalchemy.dialects.postgresql import JSONB, UUID
from sqlalchemy import (
    Column,
    Integer,
    String,
    TIMESTAMP,
    create_engine,
    Float,
    ForeignKey,
    Text,
    UniqueConstraint,
)
from sqlalchemy.ext.declarative import declarative_base
from sqlalchemy.sql import func
import uuid
from theory_evaluation.models import Base, ConsultantChat, CurrentUserTable, Curriculum, MentorChat, Projects, SprintIssues, TheoryEvalUserPerformance, UserInfo, UserRepo, UserScoreLog
import pytest

@pytest.fixture(scope="module")
def db_engine():
    engine = create_engine("sqlite:///:memory:")
    Base.metadata.create_all(engine)
    yield engine
    engine.dispose()

@pytest.fixture(scope="function")
def db_session(db_engine):
    connection = db_engine.connect()
    transaction = connection.begin()
    session = sessionmaker(bind=connection)()
    yield session
    session.close()
    transaction.rollback()
    connection.close()

import pytest
from sqlalchemy import create_engine
from sqlalchemy.orm import sessionmaker
from your_module import Base, Curriculum

@pytest.fixture
def db_session():
    engine = create_engine('postgresql://user:password@localhost/testdb')
    Base.metadata.create_all(engine)
    Session = sessionmaker(bind=engine)
    session = Session()
    yield session
    session.close()

def test_curriculum_creation(db_session):
    curriculum = Curriculum(
        question="What is Python?",
        marking_scheme="Correctness and clarity",
        model_answer="Python is a programming language."
    )
    db_session.add(curriculum)
    db_session.commit()
    retrieved_curriculum = db_session.query(Curriculum).filter_by(question="What is Python?").first()
    assert retrieved_curriculum is not None
    assert retrieved_curriculum.marking_scheme == "Correctness and clarity"

---------------
TEST CASE 5 Retry 1 - Result - Failed
Test Error -
c:\ChenKhoon\JupyterNotebook\GenerateUnitTestCases\unit_test_env\Lib\site-packages\pytest_asyncio\plugin.py:217: PytestDeprecationWarning: The configuration option "asyncio_default_fixture_loop_scope" is unset.
The event loop scope for asynchronous fixtures will default to the fixture caching scope. Future versions of pytest-asyncio will default the loop scope for asynchronous fixtures to function scope. Set the default fixture loop scope explicitly in order to avoid unexpected behavior in the future. Valid fixture loop scopes are: "function", "class", "module", "package", "session"

  warnings.warn(PytestDeprecationWarning(_DEFAULT_FIXTURE_LOOP_SCOPE_UNSET))

=================================== ERRORS ====================================
________________________ ERROR collecting temp/temp.py ________________________
ImportError while importing test module 'C:\ChenKhoon\JupyterNotebook\GenerateUnitTestCases\temp\temp.py'.
Hint: make sure your test modules/packages have valid Python names.
Traceback:
C:\Users\User\AppData\Local\Programs\Python\Python313\Lib\importlib\__init__.py:88: in import_module
    return _bootstrap._gcd_import(name[level:], package, level)
temp\temp.py:39: in <module>
    from your_module import Base, Curriculum
E   ModuleNotFoundError: No module named 'your_module'
============================== warnings summary ===============================
theory_evaluation\models.py:17
  C:\ChenKhoon\JupyterNotebook\GenerateUnitTestCases\theory_evaluation\models.py:17: MovedIn20Warning: The ``declarative_base()`` function is now available as sqlalchemy.orm.declarative_base(). (deprecated since: 2.0) (Background on SQLAlchemy 2.0 at: https://sqlalche.me/e/b8d9)
    Base = declarative_base()

-- Docs: https://docs.pytest.org/en/stable/how-to/capture-warnings.html
=========================== short test summary info ===========================
ERROR temp/temp.py
!!!!!!!!!!!!!!!!!!! Interrupted: 1 error during collection !!!!!!!!!!!!!!!!!!!!
1 warning, 1 error in 0.85s
TEST CASE 5 Retry 2
---------------
from sqlalchemy.dialects.postgresql import JSONB, UUID
from sqlalchemy import (
    Column,
    Integer,
    String,
    TIMESTAMP,
    create_engine,
    Float,
    ForeignKey,
    Text,
    UniqueConstraint,
)
from sqlalchemy.ext.declarative import declarative_base
from sqlalchemy.sql import func
import uuid
from theory_evaluation.models import Base, ConsultantChat, CurrentUserTable, Curriculum, MentorChat, Projects, SprintIssues, TheoryEvalUserPerformance, UserInfo, UserRepo, UserScoreLog
import pytest

@pytest.fixture(scope="module")
def db_engine():
    engine = create_engine("sqlite:///:memory:")
    Base.metadata.create_all(engine)
    yield engine
    engine.dispose()

@pytest.fixture(scope="function")
def db_session(db_engine):
    connection = db_engine.connect()
    transaction = connection.begin()
    session = sessionmaker(bind=connection)()
    yield session
    session.close()
    transaction.rollback()
    connection.close()

import pytest
from sqlalchemy import create_engine
from sqlalchemy.orm import sessionmaker
from sqlalchemy.ext.declarative import declarative_base
from sqlalchemy.dialects.postgresql import JSONB, UUID
from sqlalchemy import Column, Integer, String, TIMESTAMP, Float, ForeignKey, Text, UniqueConstraint
import uuid

Base = declarative_base()

class Curriculum(Base):
    __tablename__ = "curriculum"
    id = Column(UUID(as_uuid=True), primary_key=True, default=uuid.uuid4, nullable=False)
    question = Column(Text, unique=True, nullable=False)
    marking_scheme = Column(Text, nullable=False)
    model_answer = Column(Text, nullable=False)
    timestamp = Column(TIMESTAMP(timezone=True), server_default=func.now())

@pytest.fixture
def db_session():
    engine = create_engine('postgresql://user:password@localhost/testdb')
    Base.metadata.create_all(engine)
    Session = sessionmaker(bind=engine)
    session = Session()
    yield session
    session.close()

def test_curriculum_creation(db_session):
    curriculum = Curriculum(
        question="What is Python?",
        marking_scheme="Correctness and clarity",
        model_answer="Python is a programming language."
    )
    db_session.add(curriculum)
    db_session.commit()
    retrieved_curriculum = db_session.query(Curriculum).filter_by(question="What is Python?").first()
    assert retrieved_curriculum is not None
    assert retrieved_curriculum.marking_scheme == "Correctness and clarity"

---------------
TEST CASE 5 Retry 2 - Result - Failed
Test Error -
c:\ChenKhoon\JupyterNotebook\GenerateUnitTestCases\unit_test_env\Lib\site-packages\pytest_asyncio\plugin.py:217: PytestDeprecationWarning: The configuration option "asyncio_default_fixture_loop_scope" is unset.
The event loop scope for asynchronous fixtures will default to the fixture caching scope. Future versions of pytest-asyncio will default the loop scope for asynchronous fixtures to function scope. Set the default fixture loop scope explicitly in order to avoid unexpected behavior in the future. Valid fixture loop scopes are: "function", "class", "module", "package", "session"

  warnings.warn(PytestDeprecationWarning(_DEFAULT_FIXTURE_LOOP_SCOPE_UNSET))
E                                                                        [100%]
=================================== ERRORS ====================================
_________________ ERROR at setup of test_curriculum_creation __________________
temp\temp.py:56: in db_session
    engine = create_engine('postgresql://user:password@localhost/testdb')
<string>:2: in create_engine
    ???
unit_test_env\Lib\site-packages\sqlalchemy\util\deprecations.py:281: in warned
    return fn(*args, **kwargs)  # type: ignore[no-any-return]
unit_test_env\Lib\site-packages\sqlalchemy\engine\create.py:602: in create_engine
    dbapi = dbapi_meth(**dbapi_args)
unit_test_env\Lib\site-packages\sqlalchemy\dialects\postgresql\psycopg2.py:696: in import_dbapi
    import psycopg2
E   ModuleNotFoundError: No module named 'psycopg2'
============================== warnings summary ===============================
theory_evaluation\models.py:17
  C:\ChenKhoon\JupyterNotebook\GenerateUnitTestCases\theory_evaluation\models.py:17: MovedIn20Warning: The ``declarative_base()`` function is now available as sqlalchemy.orm.declarative_base(). (deprecated since: 2.0) (Background on SQLAlchemy 2.0 at: https://sqlalche.me/e/b8d9)
    Base = declarative_base()

temp\temp.py:44
  C:\ChenKhoon\JupyterNotebook\GenerateUnitTestCases\temp\temp.py:44: MovedIn20Warning: The ``declarative_base()`` function is now available as sqlalchemy.orm.declarative_base(). (deprecated since: 2.0) (Background on SQLAlchemy 2.0 at: https://sqlalche.me/e/b8d9)
    Base = declarative_base()

-- Docs: https://docs.pytest.org/en/stable/how-to/capture-warnings.html
=========================== short test summary info ===========================
ERROR temp/temp.py::test_curriculum_creation - ModuleNotFoundError: No module...
2 warnings, 1 error in 0.96s
