
TEST CASE 2 Retry 0
---------------
from sqlalchemy import create_engine
from theory_evaluation.models import Base, UserInfo
import pytest
from sqlalchemy.exc import IntegrityError
from sqlalchemy.orm import sessionmaker

@pytest.fixture(scope='module')
def engine():
    return create_engine('sqlite:///:memory:')

@pytest.fixture(scope='module')
def tables(engine):
    Base.metadata.create_all(engine)
    yield
    Base.metadata.drop_all(engine)

@pytest.fixture(scope='function')
def db_session(engine, tables):
    connection = engine.connect()
    transaction = connection.begin()
    Session = sessionmaker(bind=connection)
    session = Session()

    yield session

    session.close()
    transaction.rollback()
    connection.close()

def test_user_info_unique_email_constraint(db_session):
    user1 = UserInfo(
        first_name="Jane",
        last_name="Doe",
        email="jane.doe@example.com",
        github_username="janedoe",
        payment_date=None,
        current_duration=0,
        course_duration=10,
        end_date=None,
        status=1
    )
    user2 = UserInfo(
        first_name="Janet",
        last_name="Smith",
        email="jane.doe@example.com",
        github_username="janetsmith",
        payment_date=None,
        current_duration=0,
        course_duration=10,
        end_date=None,
        status=1
    )
    db_session.add(user1)
    db_session.commit()
    db_session.add(user2)
    with pytest.raises(IntegrityError):
        db_session.commit()
---------------
TEST CASE 2 Retry 0 - Result - Failed
Test Error -
c:\ChenKhoon\JupyterNotebook\GenerateUnitTestCases\unit_test_env\Lib\site-packages\pytest_asyncio\plugin.py:217: PytestDeprecationWarning: The configuration option "asyncio_default_fixture_loop_scope" is unset.
The event loop scope for asynchronous fixtures will default to the fixture caching scope. Future versions of pytest-asyncio will default the loop scope for asynchronous fixtures to function scope. Set the default fixture loop scope explicitly in order to avoid unexpected behavior in the future. Valid fixture loop scopes are: "function", "class", "module", "package", "session"

  warnings.warn(PytestDeprecationWarning(_DEFAULT_FIXTURE_LOOP_SCOPE_UNSET))
E                                                                        [100%]
=================================== ERRORS ====================================
__________ ERROR at setup of test_user_info_unique_email_constraint ___________
unit_test_env\Lib\site-packages\sqlalchemy\sql\visitors.py:137: in _compiler_dispatch
    meth = getter(visitor)
E   AttributeError: 'SQLiteTypeCompiler' object has no attribute 'visit_JSONB'. Did you mean: 'visit_JSON'?

The above exception was the direct cause of the following exception:
unit_test_env\Lib\site-packages\sqlalchemy\sql\compiler.py:6716: in visit_create_table
    processed = self.process(
unit_test_env\Lib\site-packages\sqlalchemy\sql\compiler.py:932: in process
    return obj._compiler_dispatch(self, **kwargs)
unit_test_env\Lib\site-packages\sqlalchemy\sql\visitors.py:141: in _compiler_dispatch
    return meth(self, **kw)  # type: ignore  # noqa: E501
unit_test_env\Lib\site-packages\sqlalchemy\sql\compiler.py:6747: in visit_create_column
    text = self.get_column_specification(column, first_pk=first_pk)
unit_test_env\Lib\site-packages\sqlalchemy\dialects\sqlite\base.py:1598: in get_column_specification
    coltype = self.dialect.type_compiler_instance.process(
unit_test_env\Lib\site-packages\sqlalchemy\sql\compiler.py:977: in process
    return type_._compiler_dispatch(self, **kw)
unit_test_env\Lib\site-packages\sqlalchemy\sql\visitors.py:139: in _compiler_dispatch
    return visitor.visit_unsupported_compilation(self, err, **kw)  # type: ignore  # noqa: E501
unit_test_env\Lib\site-packages\sqlalchemy\sql\compiler.py:982: in visit_unsupported_compilation
    raise exc.UnsupportedCompilationError(self, element) from err
E   sqlalchemy.exc.UnsupportedCompilationError: Compiler <sqlalchemy.dialects.sqlite.base.SQLiteTypeCompiler object at 0x000002395D11FB60> can't render element of type JSONB (Background on this error at: https://sqlalche.me/e/20/l7de)

The above exception was the direct cause of the following exception:
temp\temp.py:13: in tables
    Base.metadata.create_all(engine)
unit_test_env\Lib\site-packages\sqlalchemy\sql\schema.py:5925: in create_all
    bind._run_ddl_visitor(
unit_test_env\Lib\site-packages\sqlalchemy\engine\base.py:3249: in _run_ddl_visitor
    conn._run_ddl_visitor(visitorcallable, element, **kwargs)
unit_test_env\Lib\site-packages\sqlalchemy\engine\base.py:2456: in _run_ddl_visitor
    visitorcallable(self.dialect, self, **kwargs).traverse_single(element)
unit_test_env\Lib\site-packages\sqlalchemy\sql\visitors.py:664: in traverse_single
    return meth(obj, **kw)
unit_test_env\Lib\site-packages\sqlalchemy\sql\ddl.py:981: in visit_metadata
    self.traverse_single(
unit_test_env\Lib\site-packages\sqlalchemy\sql\visitors.py:664: in traverse_single
    return meth(obj, **kw)
unit_test_env\Lib\site-packages\sqlalchemy\sql\ddl.py:1019: in visit_table
    )._invoke_with(self.connection)
unit_test_env\Lib\site-packages\sqlalchemy\sql\ddl.py:321: in _invoke_with
    return bind.execute(self)
unit_test_env\Lib\site-packages\sqlalchemy\engine\base.py:1416: in execute
    return meth(
unit_test_env\Lib\site-packages\sqlalchemy\sql\ddl.py:187: in _execute_on_connection
    return connection._execute_ddl(
unit_test_env\Lib\site-packages\sqlalchemy\engine\base.py:1524: in _execute_ddl
    compiled = ddl.compile(
unit_test_env\Lib\site-packages\sqlalchemy\sql\elements.py:308: in compile
    return self._compiler(dialect, **kw)
unit_test_env\Lib\site-packages\sqlalchemy\sql\ddl.py:76: in _compiler
    return dialect.ddl_compiler(dialect, self, **kw)
unit_test_env\Lib\site-packages\sqlalchemy\sql\compiler.py:886: in __init__
    self.string = self.process(self.statement, **compile_kwargs)
unit_test_env\Lib\site-packages\sqlalchemy\sql\compiler.py:932: in process
    return obj._compiler_dispatch(self, **kwargs)
unit_test_env\Lib\site-packages\sqlalchemy\sql\visitors.py:141: in _compiler_dispatch
    return meth(self, **kw)  # type: ignore  # noqa: E501
unit_test_env\Lib\site-packages\sqlalchemy\sql\compiler.py:6726: in visit_create_table
    raise exc.CompileError(
E   sqlalchemy.exc.CompileError: (in table 'projects', column 'problem_statement'): Compiler <sqlalchemy.dialects.sqlite.base.SQLiteTypeCompiler object at 0x000002395D11FB60> can't render element of type JSONB
============================== warnings summary ===============================
theory_evaluation\models.py:17
  C:\ChenKhoon\JupyterNotebook\GenerateUnitTestCases\theory_evaluation\models.py:17: MovedIn20Warning: The ``declarative_base()`` function is now available as sqlalchemy.orm.declarative_base(). (deprecated since: 2.0) (Background on SQLAlchemy 2.0 at: https://sqlalche.me/e/b8d9)
    Base = declarative_base()

-- Docs: https://docs.pytest.org/en/stable/how-to/capture-warnings.html
=========================== short test summary info ===========================
ERROR temp/temp.py::test_user_info_unique_email_constraint - sqlalchemy.exc.C...
1 warning, 1 error in 1.32s
TEST CASE 2 Retry 1
---------------
from sqlalchemy.dialects.postgresql import JSONB, UUID
from sqlalchemy import (
    Column,
    Integer,
    String,
    TIMESTAMP,
    Float,
    ForeignKey,
    Text,
    UniqueConstraint,
)
from sqlalchemy.ext.declarative import declarative_base
from sqlalchemy.sql import func
import uuid
from theory_evaluation.models import Base, UserInfo
import pytest
from sqlalchemy.exc import IntegrityError
from sqlalchemy import create_engine
from sqlalchemy.orm import sessionmaker

@pytest.fixture(scope='module')
def engine():
    return create_engine('sqlite:///:memory:')

@pytest.fixture(scope='module')
def tables(engine):
    Base.metadata.create_all(engine)
    yield
    Base.metadata.drop_all(engine)

@pytest.fixture(scope='function')
def db_session(engine, tables):
    connection = engine.connect()
    transaction = connection.begin()
    Session = sessionmaker(bind=connection)
    session = Session()

    yield session

    session.close()
    transaction.rollback()
    connection.close()

def test_user_info_unique_email_constraint(db_session):
    user1 = UserInfo(
        first_name="Jane",
        last_name="Doe",
        email="jane.doe@example.com",
        github_username="janedoe",
        payment_date=None,
        current_duration=0,
        course_duration=10,
        end_date=None,
        status=1
    )
    user2 = UserInfo(
        first_name="Janet",
        last_name="Smith",
        email="jane.doe@example.com",
        github_username="janetsmith",
        payment_date=None,
        current_duration=0,
        course_duration=10,
        end_date=None,
        status=1
    )
    db_session.add(user1)
    db_session.commit()
    db_session.add(user2)
    with pytest.raises(IntegrityError):
        db_session.commit()
---------------
TEST CASE 2 Retry 1 - Result - Failed
Test Error -
c:\ChenKhoon\JupyterNotebook\GenerateUnitTestCases\unit_test_env\Lib\site-packages\pytest_asyncio\plugin.py:217: PytestDeprecationWarning: The configuration option "asyncio_default_fixture_loop_scope" is unset.
The event loop scope for asynchronous fixtures will default to the fixture caching scope. Future versions of pytest-asyncio will default the loop scope for asynchronous fixtures to function scope. Set the default fixture loop scope explicitly in order to avoid unexpected behavior in the future. Valid fixture loop scopes are: "function", "class", "module", "package", "session"

  warnings.warn(PytestDeprecationWarning(_DEFAULT_FIXTURE_LOOP_SCOPE_UNSET))
E                                                                        [100%]
=================================== ERRORS ====================================
__________ ERROR at setup of test_user_info_unique_email_constraint ___________
unit_test_env\Lib\site-packages\sqlalchemy\sql\visitors.py:137: in _compiler_dispatch
    meth = getter(visitor)
E   AttributeError: 'SQLiteTypeCompiler' object has no attribute 'visit_JSONB'. Did you mean: 'visit_JSON'?

The above exception was the direct cause of the following exception:
unit_test_env\Lib\site-packages\sqlalchemy\sql\compiler.py:6716: in visit_create_table
    processed = self.process(
unit_test_env\Lib\site-packages\sqlalchemy\sql\compiler.py:932: in process
    return obj._compiler_dispatch(self, **kwargs)
unit_test_env\Lib\site-packages\sqlalchemy\sql\visitors.py:141: in _compiler_dispatch
    return meth(self, **kw)  # type: ignore  # noqa: E501
unit_test_env\Lib\site-packages\sqlalchemy\sql\compiler.py:6747: in visit_create_column
    text = self.get_column_specification(column, first_pk=first_pk)
unit_test_env\Lib\site-packages\sqlalchemy\dialects\sqlite\base.py:1598: in get_column_specification
    coltype = self.dialect.type_compiler_instance.process(
unit_test_env\Lib\site-packages\sqlalchemy\sql\compiler.py:977: in process
    return type_._compiler_dispatch(self, **kw)
unit_test_env\Lib\site-packages\sqlalchemy\sql\visitors.py:139: in _compiler_dispatch
    return visitor.visit_unsupported_compilation(self, err, **kw)  # type: ignore  # noqa: E501
unit_test_env\Lib\site-packages\sqlalchemy\sql\compiler.py:982: in visit_unsupported_compilation
    raise exc.UnsupportedCompilationError(self, element) from err
E   sqlalchemy.exc.UnsupportedCompilationError: Compiler <sqlalchemy.dialects.sqlite.base.SQLiteTypeCompiler object at 0x0000023C84DAFB60> can't render element of type JSONB (Background on this error at: https://sqlalche.me/e/20/l7de)

The above exception was the direct cause of the following exception:
temp\temp.py:27: in tables
    Base.metadata.create_all(engine)
unit_test_env\Lib\site-packages\sqlalchemy\sql\schema.py:5925: in create_all
    bind._run_ddl_visitor(
unit_test_env\Lib\site-packages\sqlalchemy\engine\base.py:3249: in _run_ddl_visitor
    conn._run_ddl_visitor(visitorcallable, element, **kwargs)
unit_test_env\Lib\site-packages\sqlalchemy\engine\base.py:2456: in _run_ddl_visitor
    visitorcallable(self.dialect, self, **kwargs).traverse_single(element)
unit_test_env\Lib\site-packages\sqlalchemy\sql\visitors.py:664: in traverse_single
    return meth(obj, **kw)
unit_test_env\Lib\site-packages\sqlalchemy\sql\ddl.py:981: in visit_metadata
    self.traverse_single(
unit_test_env\Lib\site-packages\sqlalchemy\sql\visitors.py:664: in traverse_single
    return meth(obj, **kw)
unit_test_env\Lib\site-packages\sqlalchemy\sql\ddl.py:1019: in visit_table
    )._invoke_with(self.connection)
unit_test_env\Lib\site-packages\sqlalchemy\sql\ddl.py:321: in _invoke_with
    return bind.execute(self)
unit_test_env\Lib\site-packages\sqlalchemy\engine\base.py:1416: in execute
    return meth(
unit_test_env\Lib\site-packages\sqlalchemy\sql\ddl.py:187: in _execute_on_connection
    return connection._execute_ddl(
unit_test_env\Lib\site-packages\sqlalchemy\engine\base.py:1524: in _execute_ddl
    compiled = ddl.compile(
unit_test_env\Lib\site-packages\sqlalchemy\sql\elements.py:308: in compile
    return self._compiler(dialect, **kw)
unit_test_env\Lib\site-packages\sqlalchemy\sql\ddl.py:76: in _compiler
    return dialect.ddl_compiler(dialect, self, **kw)
unit_test_env\Lib\site-packages\sqlalchemy\sql\compiler.py:886: in __init__
    self.string = self.process(self.statement, **compile_kwargs)
unit_test_env\Lib\site-packages\sqlalchemy\sql\compiler.py:932: in process
    return obj._compiler_dispatch(self, **kwargs)
unit_test_env\Lib\site-packages\sqlalchemy\sql\visitors.py:141: in _compiler_dispatch
    return meth(self, **kw)  # type: ignore  # noqa: E501
unit_test_env\Lib\site-packages\sqlalchemy\sql\compiler.py:6726: in visit_create_table
    raise exc.CompileError(
E   sqlalchemy.exc.CompileError: (in table 'projects', column 'problem_statement'): Compiler <sqlalchemy.dialects.sqlite.base.SQLiteTypeCompiler object at 0x0000023C84DAFB60> can't render element of type JSONB
============================== warnings summary ===============================
theory_evaluation\models.py:17
  C:\ChenKhoon\JupyterNotebook\GenerateUnitTestCases\theory_evaluation\models.py:17: MovedIn20Warning: The ``declarative_base()`` function is now available as sqlalchemy.orm.declarative_base(). (deprecated since: 2.0) (Background on SQLAlchemy 2.0 at: https://sqlalche.me/e/b8d9)
    Base = declarative_base()

-- Docs: https://docs.pytest.org/en/stable/how-to/capture-warnings.html
=========================== short test summary info ===========================
ERROR temp/temp.py::test_user_info_unique_email_constraint - sqlalchemy.exc.C...
1 warning, 1 error in 1.21s
TEST CASE 2 Retry 2
---------------
from sqlalchemy.dialects.postgresql import UUID
from sqlalchemy import (
    Column,
    Integer,
    String,
    TIMESTAMP,
    create_engine,
    Float,
    ForeignKey,
    Text,
    UniqueConstraint,
)
from sqlalchemy.ext.declarative import declarative_base
from sqlalchemy.sql import func
import uuid
from theory_evaluation.models import Base, UserInfo
import pytest
from sqlalchemy.exc import IntegrityError
from sqlalchemy.orm import sessionmaker

@pytest.fixture(scope='module')
def engine():
    return create_engine('sqlite:///:memory:')

@pytest.fixture(scope='module')
def tables(engine):
    Base.metadata.create_all(engine)
    yield
    Base.metadata.drop_all(engine)

@pytest.fixture(scope='function')
def db_session(engine, tables):
    connection = engine.connect()
    transaction = connection.begin()
    Session = sessionmaker(bind=connection)
    session = Session()

    yield session

    session.close()
    transaction.rollback()
    connection.close()

engine = create_engine('postgresql://user:password@localhost/testdb')
Base.metadata.create_all(engine)
Session = sessionmaker(bind=engine)
db_session = Session()

def test_user_info_unique_email_constraint():
    user1 = UserInfo(
        first_name="Jane",
        last_name="Doe",
        email="jane.doe@example.com",
        github_username="janedoe",
        payment_date=None,
        current_duration=0,
        course_duration=10,
        end_date=None,
        status=1
    )
    user2 = UserInfo(
        first_name="Janet",
        last_name="Smith",
        email="jane.doe@example.com",
        github_username="janetsmith",
        payment_date=None,
        current_duration=0,
        course_duration=10,
        end_date=None,
        status=1
    )
    db_session.add(user1)
    db_session.commit()
    db_session.add(user2)
    with pytest.raises(IntegrityError):
        db_session.commit()
---------------
TEST CASE 2 Retry 2 - Result - Failed
Test Error -
c:\ChenKhoon\JupyterNotebook\GenerateUnitTestCases\unit_test_env\Lib\site-packages\pytest_asyncio\plugin.py:217: PytestDeprecationWarning: The configuration option "asyncio_default_fixture_loop_scope" is unset.
The event loop scope for asynchronous fixtures will default to the fixture caching scope. Future versions of pytest-asyncio will default the loop scope for asynchronous fixtures to function scope. Set the default fixture loop scope explicitly in order to avoid unexpected behavior in the future. Valid fixture loop scopes are: "function", "class", "module", "package", "session"

  warnings.warn(PytestDeprecationWarning(_DEFAULT_FIXTURE_LOOP_SCOPE_UNSET))

=================================== ERRORS ====================================
________________________ ERROR collecting temp/temp.py ________________________
ImportError while importing test module 'C:\ChenKhoon\JupyterNotebook\GenerateUnitTestCases\temp\temp.py'.
Hint: make sure your test modules/packages have valid Python names.
Traceback:
C:\Users\User\AppData\Local\Programs\Python\Python313\Lib\importlib\__init__.py:88: in import_module
    return _bootstrap._gcd_import(name[level:], package, level)
temp\temp.py:44: in <module>
    engine = create_engine('postgresql://user:password@localhost/testdb')
unit_test_env\Lib\site-packages\sqlalchemy\util\deprecations.py:281: in warned
    return fn(*args, **kwargs)  # type: ignore[no-any-return]
unit_test_env\Lib\site-packages\sqlalchemy\engine\create.py:602: in create_engine
    dbapi = dbapi_meth(**dbapi_args)
unit_test_env\Lib\site-packages\sqlalchemy\dialects\postgresql\psycopg2.py:696: in import_dbapi
    import psycopg2
E   ModuleNotFoundError: No module named 'psycopg2'
============================== warnings summary ===============================
theory_evaluation\models.py:17
  C:\ChenKhoon\JupyterNotebook\GenerateUnitTestCases\theory_evaluation\models.py:17: MovedIn20Warning: The ``declarative_base()`` function is now available as sqlalchemy.orm.declarative_base(). (deprecated since: 2.0) (Background on SQLAlchemy 2.0 at: https://sqlalche.me/e/b8d9)
    Base = declarative_base()

-- Docs: https://docs.pytest.org/en/stable/how-to/capture-warnings.html
=========================== short test summary info ===========================
ERROR temp/temp.py
!!!!!!!!!!!!!!!!!!! Interrupted: 1 error during collection !!!!!!!!!!!!!!!!!!!!
1 warning, 1 error in 0.72s

TEST CASE 3 Retry 0
---------------
from sqlalchemy import create_engine
from theory_evaluation.models import Base, Projects
import pytest

@pytest.fixture(scope='module')
def engine():
    return create_engine('sqlite:///:memory:')

@pytest.fixture(scope='module')
def tables(engine):
    Base.metadata.create_all(engine)
    yield
    Base.metadata.drop_all(engine)

@pytest.fixture(scope='function')
def db_session(engine, tables):
    connection = engine.connect()
    transaction = connection.begin()
    Session = sessionmaker(bind=connection)
    session = Session()

    yield session

    session.close()
    transaction.rollback()
    connection.close()

def test_projects_creation(db_session):
    project = Projects(
        repo_name="example_repo",
        problem_statement={"key": "value"},
        bloblink="http://example.com/blob",
        mini_project_flag=1
    )
    db_session.add(project)
    db_session.commit()
    retrieved_project = db_session.query(Projects).filter_by(repo_name="example_repo").first()
    assert retrieved_project is not None
    assert retrieved_project.problem_statement == {"key": "value"}
---------------
TEST CASE 3 Retry 0 - Result - Failed
Test Error -
c:\ChenKhoon\JupyterNotebook\GenerateUnitTestCases\unit_test_env\Lib\site-packages\pytest_asyncio\plugin.py:217: PytestDeprecationWarning: The configuration option "asyncio_default_fixture_loop_scope" is unset.
The event loop scope for asynchronous fixtures will default to the fixture caching scope. Future versions of pytest-asyncio will default the loop scope for asynchronous fixtures to function scope. Set the default fixture loop scope explicitly in order to avoid unexpected behavior in the future. Valid fixture loop scopes are: "function", "class", "module", "package", "session"

  warnings.warn(PytestDeprecationWarning(_DEFAULT_FIXTURE_LOOP_SCOPE_UNSET))
E                                                                        [100%]
=================================== ERRORS ====================================
__________________ ERROR at setup of test_projects_creation ___________________
unit_test_env\Lib\site-packages\sqlalchemy\sql\visitors.py:137: in _compiler_dispatch
    meth = getter(visitor)
E   AttributeError: 'SQLiteTypeCompiler' object has no attribute 'visit_JSONB'. Did you mean: 'visit_JSON'?

The above exception was the direct cause of the following exception:
unit_test_env\Lib\site-packages\sqlalchemy\sql\compiler.py:6716: in visit_create_table
    processed = self.process(
unit_test_env\Lib\site-packages\sqlalchemy\sql\compiler.py:932: in process
    return obj._compiler_dispatch(self, **kwargs)
unit_test_env\Lib\site-packages\sqlalchemy\sql\visitors.py:141: in _compiler_dispatch
    return meth(self, **kw)  # type: ignore  # noqa: E501
unit_test_env\Lib\site-packages\sqlalchemy\sql\compiler.py:6747: in visit_create_column
    text = self.get_column_specification(column, first_pk=first_pk)
unit_test_env\Lib\site-packages\sqlalchemy\dialects\sqlite\base.py:1598: in get_column_specification
    coltype = self.dialect.type_compiler_instance.process(
unit_test_env\Lib\site-packages\sqlalchemy\sql\compiler.py:977: in process
    return type_._compiler_dispatch(self, **kw)
unit_test_env\Lib\site-packages\sqlalchemy\sql\visitors.py:139: in _compiler_dispatch
    return visitor.visit_unsupported_compilation(self, err, **kw)  # type: ignore  # noqa: E501
unit_test_env\Lib\site-packages\sqlalchemy\sql\compiler.py:982: in visit_unsupported_compilation
    raise exc.UnsupportedCompilationError(self, element) from err
E   sqlalchemy.exc.UnsupportedCompilationError: Compiler <sqlalchemy.dialects.sqlite.base.SQLiteTypeCompiler object at 0x00000213B4A1FB60> can't render element of type JSONB (Background on this error at: https://sqlalche.me/e/20/l7de)

The above exception was the direct cause of the following exception:
temp\temp.py:11: in tables
    Base.metadata.create_all(engine)
unit_test_env\Lib\site-packages\sqlalchemy\sql\schema.py:5925: in create_all
    bind._run_ddl_visitor(
unit_test_env\Lib\site-packages\sqlalchemy\engine\base.py:3249: in _run_ddl_visitor
    conn._run_ddl_visitor(visitorcallable, element, **kwargs)
unit_test_env\Lib\site-packages\sqlalchemy\engine\base.py:2456: in _run_ddl_visitor
    visitorcallable(self.dialect, self, **kwargs).traverse_single(element)
unit_test_env\Lib\site-packages\sqlalchemy\sql\visitors.py:664: in traverse_single
    return meth(obj, **kw)
unit_test_env\Lib\site-packages\sqlalchemy\sql\ddl.py:981: in visit_metadata
    self.traverse_single(
unit_test_env\Lib\site-packages\sqlalchemy\sql\visitors.py:664: in traverse_single
    return meth(obj, **kw)
unit_test_env\Lib\site-packages\sqlalchemy\sql\ddl.py:1019: in visit_table
    )._invoke_with(self.connection)
unit_test_env\Lib\site-packages\sqlalchemy\sql\ddl.py:321: in _invoke_with
    return bind.execute(self)
unit_test_env\Lib\site-packages\sqlalchemy\engine\base.py:1416: in execute
    return meth(
unit_test_env\Lib\site-packages\sqlalchemy\sql\ddl.py:187: in _execute_on_connection
    return connection._execute_ddl(
unit_test_env\Lib\site-packages\sqlalchemy\engine\base.py:1524: in _execute_ddl
    compiled = ddl.compile(
unit_test_env\Lib\site-packages\sqlalchemy\sql\elements.py:308: in compile
    return self._compiler(dialect, **kw)
unit_test_env\Lib\site-packages\sqlalchemy\sql\ddl.py:76: in _compiler
    return dialect.ddl_compiler(dialect, self, **kw)
unit_test_env\Lib\site-packages\sqlalchemy\sql\compiler.py:886: in __init__
    self.string = self.process(self.statement, **compile_kwargs)
unit_test_env\Lib\site-packages\sqlalchemy\sql\compiler.py:932: in process
    return obj._compiler_dispatch(self, **kwargs)
unit_test_env\Lib\site-packages\sqlalchemy\sql\visitors.py:141: in _compiler_dispatch
    return meth(self, **kw)  # type: ignore  # noqa: E501
unit_test_env\Lib\site-packages\sqlalchemy\sql\compiler.py:6726: in visit_create_table
    raise exc.CompileError(
E   sqlalchemy.exc.CompileError: (in table 'projects', column 'problem_statement'): Compiler <sqlalchemy.dialects.sqlite.base.SQLiteTypeCompiler object at 0x00000213B4A1FB60> can't render element of type JSONB
============================== warnings summary ===============================
theory_evaluation\models.py:17
  C:\ChenKhoon\JupyterNotebook\GenerateUnitTestCases\theory_evaluation\models.py:17: MovedIn20Warning: The ``declarative_base()`` function is now available as sqlalchemy.orm.declarative_base(). (deprecated since: 2.0) (Background on SQLAlchemy 2.0 at: https://sqlalche.me/e/b8d9)
    Base = declarative_base()

-- Docs: https://docs.pytest.org/en/stable/how-to/capture-warnings.html
=========================== short test summary info ===========================
ERROR temp/temp.py::test_projects_creation - sqlalchemy.exc.CompileError: (in...
1 warning, 1 error in 1.50s
TEST CASE 3 Retry 1
---------------
from sqlalchemy import create_engine
from sqlalchemy.orm import sessionmaker
from theory_evaluation.models import Base, Projects
import pytest

@pytest.fixture(scope='module')
def engine():
    return create_engine('sqlite:///:memory:')

@pytest.fixture(scope='module')
def tables(engine):
    Base.metadata.create_all(engine)
    yield
    Base.metadata.drop_all(engine)

@pytest.fixture(scope='function')
def db_session(engine, tables):
    connection = engine.connect()
    transaction = connection.begin()
    Session = sessionmaker(bind=connection)
    session = Session()

    yield session

    session.close()
    transaction.rollback()
    connection.close()

def test_projects_creation(db_session):
    project = Projects(
        repo_name="example_repo",
        problem_statement={"key": "value"},
        bloblink="http://example.com/blob",
        mini_project_flag=1
    )
    db_session.add(project)
    db_session.commit()
    retrieved_project = db_session.query(Projects).filter_by(repo_name="example_repo").first()
    assert retrieved_project is not None
    assert retrieved_project.problem_statement == {"key": "value"}
---------------
TEST CASE 3 Retry 1 - Result - Failed
Test Error -
c:\ChenKhoon\JupyterNotebook\GenerateUnitTestCases\unit_test_env\Lib\site-packages\pytest_asyncio\plugin.py:217: PytestDeprecationWarning: The configuration option "asyncio_default_fixture_loop_scope" is unset.
The event loop scope for asynchronous fixtures will default to the fixture caching scope. Future versions of pytest-asyncio will default the loop scope for asynchronous fixtures to function scope. Set the default fixture loop scope explicitly in order to avoid unexpected behavior in the future. Valid fixture loop scopes are: "function", "class", "module", "package", "session"

  warnings.warn(PytestDeprecationWarning(_DEFAULT_FIXTURE_LOOP_SCOPE_UNSET))
E                                                                        [100%]
=================================== ERRORS ====================================
__________________ ERROR at setup of test_projects_creation ___________________
unit_test_env\Lib\site-packages\sqlalchemy\sql\visitors.py:137: in _compiler_dispatch
    meth = getter(visitor)
E   AttributeError: 'SQLiteTypeCompiler' object has no attribute 'visit_JSONB'. Did you mean: 'visit_JSON'?

The above exception was the direct cause of the following exception:
unit_test_env\Lib\site-packages\sqlalchemy\sql\compiler.py:6716: in visit_create_table
    processed = self.process(
unit_test_env\Lib\site-packages\sqlalchemy\sql\compiler.py:932: in process
    return obj._compiler_dispatch(self, **kwargs)
unit_test_env\Lib\site-packages\sqlalchemy\sql\visitors.py:141: in _compiler_dispatch
    return meth(self, **kw)  # type: ignore  # noqa: E501
unit_test_env\Lib\site-packages\sqlalchemy\sql\compiler.py:6747: in visit_create_column
    text = self.get_column_specification(column, first_pk=first_pk)
unit_test_env\Lib\site-packages\sqlalchemy\dialects\sqlite\base.py:1598: in get_column_specification
    coltype = self.dialect.type_compiler_instance.process(
unit_test_env\Lib\site-packages\sqlalchemy\sql\compiler.py:977: in process
    return type_._compiler_dispatch(self, **kw)
unit_test_env\Lib\site-packages\sqlalchemy\sql\visitors.py:139: in _compiler_dispatch
    return visitor.visit_unsupported_compilation(self, err, **kw)  # type: ignore  # noqa: E501
unit_test_env\Lib\site-packages\sqlalchemy\sql\compiler.py:982: in visit_unsupported_compilation
    raise exc.UnsupportedCompilationError(self, element) from err
E   sqlalchemy.exc.UnsupportedCompilationError: Compiler <sqlalchemy.dialects.sqlite.base.SQLiteTypeCompiler object at 0x000001FF16E63A10> can't render element of type JSONB (Background on this error at: https://sqlalche.me/e/20/l7de)

The above exception was the direct cause of the following exception:
temp\temp.py:12: in tables
    Base.metadata.create_all(engine)
unit_test_env\Lib\site-packages\sqlalchemy\sql\schema.py:5925: in create_all
    bind._run_ddl_visitor(
unit_test_env\Lib\site-packages\sqlalchemy\engine\base.py:3249: in _run_ddl_visitor
    conn._run_ddl_visitor(visitorcallable, element, **kwargs)
unit_test_env\Lib\site-packages\sqlalchemy\engine\base.py:2456: in _run_ddl_visitor
    visitorcallable(self.dialect, self, **kwargs).traverse_single(element)
unit_test_env\Lib\site-packages\sqlalchemy\sql\visitors.py:664: in traverse_single
    return meth(obj, **kw)
unit_test_env\Lib\site-packages\sqlalchemy\sql\ddl.py:981: in visit_metadata
    self.traverse_single(
unit_test_env\Lib\site-packages\sqlalchemy\sql\visitors.py:664: in traverse_single
    return meth(obj, **kw)
unit_test_env\Lib\site-packages\sqlalchemy\sql\ddl.py:1019: in visit_table
    )._invoke_with(self.connection)
unit_test_env\Lib\site-packages\sqlalchemy\sql\ddl.py:321: in _invoke_with
    return bind.execute(self)
unit_test_env\Lib\site-packages\sqlalchemy\engine\base.py:1416: in execute
    return meth(
unit_test_env\Lib\site-packages\sqlalchemy\sql\ddl.py:187: in _execute_on_connection
    return connection._execute_ddl(
unit_test_env\Lib\site-packages\sqlalchemy\engine\base.py:1524: in _execute_ddl
    compiled = ddl.compile(
unit_test_env\Lib\site-packages\sqlalchemy\sql\elements.py:308: in compile
    return self._compiler(dialect, **kw)
unit_test_env\Lib\site-packages\sqlalchemy\sql\ddl.py:76: in _compiler
    return dialect.ddl_compiler(dialect, self, **kw)
unit_test_env\Lib\site-packages\sqlalchemy\sql\compiler.py:886: in __init__
    self.string = self.process(self.statement, **compile_kwargs)
unit_test_env\Lib\site-packages\sqlalchemy\sql\compiler.py:932: in process
    return obj._compiler_dispatch(self, **kwargs)
unit_test_env\Lib\site-packages\sqlalchemy\sql\visitors.py:141: in _compiler_dispatch
    return meth(self, **kw)  # type: ignore  # noqa: E501
unit_test_env\Lib\site-packages\sqlalchemy\sql\compiler.py:6726: in visit_create_table
    raise exc.CompileError(
E   sqlalchemy.exc.CompileError: (in table 'projects', column 'problem_statement'): Compiler <sqlalchemy.dialects.sqlite.base.SQLiteTypeCompiler object at 0x000001FF16E63A10> can't render element of type JSONB
============================== warnings summary ===============================
theory_evaluation\models.py:17
  C:\ChenKhoon\JupyterNotebook\GenerateUnitTestCases\theory_evaluation\models.py:17: MovedIn20Warning: The ``declarative_base()`` function is now available as sqlalchemy.orm.declarative_base(). (deprecated since: 2.0) (Background on SQLAlchemy 2.0 at: https://sqlalche.me/e/b8d9)
    Base = declarative_base()

-- Docs: https://docs.pytest.org/en/stable/how-to/capture-warnings.html
=========================== short test summary info ===========================
ERROR temp/temp.py::test_projects_creation - sqlalchemy.exc.CompileError: (in...
1 warning, 1 error in 1.30s
TEST CASE 3 Retry 2
---------------
from sqlalchemy import create_engine
from sqlalchemy.orm import sessionmaker
from theory_evaluation.models import Base, Projects
import pytest

@pytest.fixture(scope='module')
def engine():
    return create_engine('sqlite:///:memory:')

@pytest.fixture(scope='module')
def tables(engine):
    Base.metadata.create_all(engine)
    yield
    Base.metadata.drop_all(engine)

@pytest.fixture(scope='function')
def db_session(engine, tables):
    connection = engine.connect()
    transaction = connection.begin()
    Session = sessionmaker(bind=connection)
    session = Session()

    yield session

    session.close()
    transaction.rollback()
    connection.close()

def test_projects_creation(db_session):
    project = Projects(
        repo_name="example_repo",
        problem_statement={"key": "value"},
        bloblink="http://example.com/blob",
        mini_project_flag=1
    )
    db_session.add(project)
    db_session.commit()
    retrieved_project = db_session.query(Projects).filter_by(repo_name="example_repo").first()
    assert retrieved_project is not None
    assert retrieved_project.problem_statement == {"key": "value"}
---------------
TEST CASE 3 Retry 2 - Result - Failed
Test Error -
c:\ChenKhoon\JupyterNotebook\GenerateUnitTestCases\unit_test_env\Lib\site-packages\pytest_asyncio\plugin.py:217: PytestDeprecationWarning: The configuration option "asyncio_default_fixture_loop_scope" is unset.
The event loop scope for asynchronous fixtures will default to the fixture caching scope. Future versions of pytest-asyncio will default the loop scope for asynchronous fixtures to function scope. Set the default fixture loop scope explicitly in order to avoid unexpected behavior in the future. Valid fixture loop scopes are: "function", "class", "module", "package", "session"

  warnings.warn(PytestDeprecationWarning(_DEFAULT_FIXTURE_LOOP_SCOPE_UNSET))
E                                                                        [100%]
=================================== ERRORS ====================================
__________________ ERROR at setup of test_projects_creation ___________________
unit_test_env\Lib\site-packages\sqlalchemy\sql\visitors.py:137: in _compiler_dispatch
    meth = getter(visitor)
E   AttributeError: 'SQLiteTypeCompiler' object has no attribute 'visit_JSONB'. Did you mean: 'visit_JSON'?

The above exception was the direct cause of the following exception:
unit_test_env\Lib\site-packages\sqlalchemy\sql\compiler.py:6716: in visit_create_table
    processed = self.process(
unit_test_env\Lib\site-packages\sqlalchemy\sql\compiler.py:932: in process
    return obj._compiler_dispatch(self, **kwargs)
unit_test_env\Lib\site-packages\sqlalchemy\sql\visitors.py:141: in _compiler_dispatch
    return meth(self, **kw)  # type: ignore  # noqa: E501
unit_test_env\Lib\site-packages\sqlalchemy\sql\compiler.py:6747: in visit_create_column
    text = self.get_column_specification(column, first_pk=first_pk)
unit_test_env\Lib\site-packages\sqlalchemy\dialects\sqlite\base.py:1598: in get_column_specification
    coltype = self.dialect.type_compiler_instance.process(
unit_test_env\Lib\site-packages\sqlalchemy\sql\compiler.py:977: in process
    return type_._compiler_dispatch(self, **kw)
unit_test_env\Lib\site-packages\sqlalchemy\sql\visitors.py:139: in _compiler_dispatch
    return visitor.visit_unsupported_compilation(self, err, **kw)  # type: ignore  # noqa: E501
unit_test_env\Lib\site-packages\sqlalchemy\sql\compiler.py:982: in visit_unsupported_compilation
    raise exc.UnsupportedCompilationError(self, element) from err
E   sqlalchemy.exc.UnsupportedCompilationError: Compiler <sqlalchemy.dialects.sqlite.base.SQLiteTypeCompiler object at 0x000001DFFB5A3A10> can't render element of type JSONB (Background on this error at: https://sqlalche.me/e/20/l7de)

The above exception was the direct cause of the following exception:
temp\temp.py:12: in tables
    Base.metadata.create_all(engine)
unit_test_env\Lib\site-packages\sqlalchemy\sql\schema.py:5925: in create_all
    bind._run_ddl_visitor(
unit_test_env\Lib\site-packages\sqlalchemy\engine\base.py:3249: in _run_ddl_visitor
    conn._run_ddl_visitor(visitorcallable, element, **kwargs)
unit_test_env\Lib\site-packages\sqlalchemy\engine\base.py:2456: in _run_ddl_visitor
    visitorcallable(self.dialect, self, **kwargs).traverse_single(element)
unit_test_env\Lib\site-packages\sqlalchemy\sql\visitors.py:664: in traverse_single
    return meth(obj, **kw)
unit_test_env\Lib\site-packages\sqlalchemy\sql\ddl.py:981: in visit_metadata
    self.traverse_single(
unit_test_env\Lib\site-packages\sqlalchemy\sql\visitors.py:664: in traverse_single
    return meth(obj, **kw)
unit_test_env\Lib\site-packages\sqlalchemy\sql\ddl.py:1019: in visit_table
    )._invoke_with(self.connection)
unit_test_env\Lib\site-packages\sqlalchemy\sql\ddl.py:321: in _invoke_with
    return bind.execute(self)
unit_test_env\Lib\site-packages\sqlalchemy\engine\base.py:1416: in execute
    return meth(
unit_test_env\Lib\site-packages\sqlalchemy\sql\ddl.py:187: in _execute_on_connection
    return connection._execute_ddl(
unit_test_env\Lib\site-packages\sqlalchemy\engine\base.py:1524: in _execute_ddl
    compiled = ddl.compile(
unit_test_env\Lib\site-packages\sqlalchemy\sql\elements.py:308: in compile
    return self._compiler(dialect, **kw)
unit_test_env\Lib\site-packages\sqlalchemy\sql\ddl.py:76: in _compiler
    return dialect.ddl_compiler(dialect, self, **kw)
unit_test_env\Lib\site-packages\sqlalchemy\sql\compiler.py:886: in __init__
    self.string = self.process(self.statement, **compile_kwargs)
unit_test_env\Lib\site-packages\sqlalchemy\sql\compiler.py:932: in process
    return obj._compiler_dispatch(self, **kwargs)
unit_test_env\Lib\site-packages\sqlalchemy\sql\visitors.py:141: in _compiler_dispatch
    return meth(self, **kw)  # type: ignore  # noqa: E501
unit_test_env\Lib\site-packages\sqlalchemy\sql\compiler.py:6726: in visit_create_table
    raise exc.CompileError(
E   sqlalchemy.exc.CompileError: (in table 'projects', column 'problem_statement'): Compiler <sqlalchemy.dialects.sqlite.base.SQLiteTypeCompiler object at 0x000001DFFB5A3A10> can't render element of type JSONB
============================== warnings summary ===============================
theory_evaluation\models.py:17
  C:\ChenKhoon\JupyterNotebook\GenerateUnitTestCases\theory_evaluation\models.py:17: MovedIn20Warning: The ``declarative_base()`` function is now available as sqlalchemy.orm.declarative_base(). (deprecated since: 2.0) (Background on SQLAlchemy 2.0 at: https://sqlalche.me/e/b8d9)
    Base = declarative_base()

-- Docs: https://docs.pytest.org/en/stable/how-to/capture-warnings.html
=========================== short test summary info ===========================
ERROR temp/temp.py::test_projects_creation - sqlalchemy.exc.CompileError: (in...
1 warning, 1 error in 1.22s

TEST CASE 4 Retry 0
---------------
from sqlalchemy import create_engine
from sqlalchemy.orm import sessionmaker
from theory_evaluation.models import Base, UserInfo, UserRepo
import pytest
from sqlalchemy.exc import IntegrityError

@pytest.fixture(scope='module')
def engine():
    return create_engine('sqlite:///:memory:')

@pytest.fixture(scope='module')
def tables(engine):
    Base.metadata.create_all(engine)
    yield
    Base.metadata.drop_all(engine)

@pytest.fixture(scope='function')
def db_session(engine, tables):
    connection = engine.connect()
    transaction = connection.begin()
    Session = sessionmaker(bind=connection)
    session = Session()

    yield session

    session.close()
    transaction.rollback()
    connection.close()

def test_user_repo_unique_constraint(db_session):
    user = UserInfo(
        first_name="Alice",
        last_name="Wonderland",
        email="alice@example.com",
        github_username="alice",
        payment_date=None,
        current_duration=0,
        course_duration=10,
        end_date=None,
        status=1
    )
    db_session.add(user)
    db_session.commit()
    repo1 = UserRepo(
        user_id=user.id,
        psid=1,
        github_username="alice",
        repo_name="repo1",
        github_url="http://github.com/alice/repo1"
    )
    repo2 = UserRepo(
        user_id=user.id,
        psid=2,
        github_username="alice",
        repo_name="repo1",
        github_url="http://github.com/alice/repo2"
    )
    db_session.add(repo1)
    db_session.commit()
    db_session.add(repo2)
    with pytest.raises(IntegrityError):
        db_session.commit()
---------------
TEST CASE 4 Retry 0 - Result - Failed
Test Error -
c:\ChenKhoon\JupyterNotebook\GenerateUnitTestCases\unit_test_env\Lib\site-packages\pytest_asyncio\plugin.py:217: PytestDeprecationWarning: The configuration option "asyncio_default_fixture_loop_scope" is unset.
The event loop scope for asynchronous fixtures will default to the fixture caching scope. Future versions of pytest-asyncio will default the loop scope for asynchronous fixtures to function scope. Set the default fixture loop scope explicitly in order to avoid unexpected behavior in the future. Valid fixture loop scopes are: "function", "class", "module", "package", "session"

  warnings.warn(PytestDeprecationWarning(_DEFAULT_FIXTURE_LOOP_SCOPE_UNSET))
E                                                                        [100%]
=================================== ERRORS ====================================
_____________ ERROR at setup of test_user_repo_unique_constraint ______________
unit_test_env\Lib\site-packages\sqlalchemy\sql\visitors.py:137: in _compiler_dispatch
    meth = getter(visitor)
E   AttributeError: 'SQLiteTypeCompiler' object has no attribute 'visit_JSONB'. Did you mean: 'visit_JSON'?

The above exception was the direct cause of the following exception:
unit_test_env\Lib\site-packages\sqlalchemy\sql\compiler.py:6716: in visit_create_table
    processed = self.process(
unit_test_env\Lib\site-packages\sqlalchemy\sql\compiler.py:932: in process
    return obj._compiler_dispatch(self, **kwargs)
unit_test_env\Lib\site-packages\sqlalchemy\sql\visitors.py:141: in _compiler_dispatch
    return meth(self, **kw)  # type: ignore  # noqa: E501
unit_test_env\Lib\site-packages\sqlalchemy\sql\compiler.py:6747: in visit_create_column
    text = self.get_column_specification(column, first_pk=first_pk)
unit_test_env\Lib\site-packages\sqlalchemy\dialects\sqlite\base.py:1598: in get_column_specification
    coltype = self.dialect.type_compiler_instance.process(
unit_test_env\Lib\site-packages\sqlalchemy\sql\compiler.py:977: in process
    return type_._compiler_dispatch(self, **kw)
unit_test_env\Lib\site-packages\sqlalchemy\sql\visitors.py:139: in _compiler_dispatch
    return visitor.visit_unsupported_compilation(self, err, **kw)  # type: ignore  # noqa: E501
unit_test_env\Lib\site-packages\sqlalchemy\sql\compiler.py:982: in visit_unsupported_compilation
    raise exc.UnsupportedCompilationError(self, element) from err
E   sqlalchemy.exc.UnsupportedCompilationError: Compiler <sqlalchemy.dialects.sqlite.base.SQLiteTypeCompiler object at 0x0000028C8AE13A10> can't render element of type JSONB (Background on this error at: https://sqlalche.me/e/20/l7de)

The above exception was the direct cause of the following exception:
temp\temp.py:13: in tables
    Base.metadata.create_all(engine)
unit_test_env\Lib\site-packages\sqlalchemy\sql\schema.py:5925: in create_all
    bind._run_ddl_visitor(
unit_test_env\Lib\site-packages\sqlalchemy\engine\base.py:3249: in _run_ddl_visitor
    conn._run_ddl_visitor(visitorcallable, element, **kwargs)
unit_test_env\Lib\site-packages\sqlalchemy\engine\base.py:2456: in _run_ddl_visitor
    visitorcallable(self.dialect, self, **kwargs).traverse_single(element)
unit_test_env\Lib\site-packages\sqlalchemy\sql\visitors.py:664: in traverse_single
    return meth(obj, **kw)
unit_test_env\Lib\site-packages\sqlalchemy\sql\ddl.py:981: in visit_metadata
    self.traverse_single(
unit_test_env\Lib\site-packages\sqlalchemy\sql\visitors.py:664: in traverse_single
    return meth(obj, **kw)
unit_test_env\Lib\site-packages\sqlalchemy\sql\ddl.py:1019: in visit_table
    )._invoke_with(self.connection)
unit_test_env\Lib\site-packages\sqlalchemy\sql\ddl.py:321: in _invoke_with
    return bind.execute(self)
unit_test_env\Lib\site-packages\sqlalchemy\engine\base.py:1416: in execute
    return meth(
unit_test_env\Lib\site-packages\sqlalchemy\sql\ddl.py:187: in _execute_on_connection
    return connection._execute_ddl(
unit_test_env\Lib\site-packages\sqlalchemy\engine\base.py:1524: in _execute_ddl
    compiled = ddl.compile(
unit_test_env\Lib\site-packages\sqlalchemy\sql\elements.py:308: in compile
    return self._compiler(dialect, **kw)
unit_test_env\Lib\site-packages\sqlalchemy\sql\ddl.py:76: in _compiler
    return dialect.ddl_compiler(dialect, self, **kw)
unit_test_env\Lib\site-packages\sqlalchemy\sql\compiler.py:886: in __init__
    self.string = self.process(self.statement, **compile_kwargs)
unit_test_env\Lib\site-packages\sqlalchemy\sql\compiler.py:932: in process
    return obj._compiler_dispatch(self, **kwargs)
unit_test_env\Lib\site-packages\sqlalchemy\sql\visitors.py:141: in _compiler_dispatch
    return meth(self, **kw)  # type: ignore  # noqa: E501
unit_test_env\Lib\site-packages\sqlalchemy\sql\compiler.py:6726: in visit_create_table
    raise exc.CompileError(
E   sqlalchemy.exc.CompileError: (in table 'projects', column 'problem_statement'): Compiler <sqlalchemy.dialects.sqlite.base.SQLiteTypeCompiler object at 0x0000028C8AE13A10> can't render element of type JSONB
============================== warnings summary ===============================
theory_evaluation\models.py:17
  C:\ChenKhoon\JupyterNotebook\GenerateUnitTestCases\theory_evaluation\models.py:17: MovedIn20Warning: The ``declarative_base()`` function is now available as sqlalchemy.orm.declarative_base(). (deprecated since: 2.0) (Background on SQLAlchemy 2.0 at: https://sqlalche.me/e/b8d9)
    Base = declarative_base()

-- Docs: https://docs.pytest.org/en/stable/how-to/capture-warnings.html
=========================== short test summary info ===========================
ERROR temp/temp.py::test_user_repo_unique_constraint - sqlalchemy.exc.Compile...
1 warning, 1 error in 1.44s
TEST CASE 4 Retry 1
---------------
from sqlalchemy.exc import IntegrityError
from sqlalchemy.orm import sessionmaker
from your_module import Base, UserInfo, UserRepo
import pytest
from sqlalchemy import create_engine

engine = create_engine('postgresql://user:password@localhost/testdb')
Base.metadata.create_all(engine)
Session = sessionmaker(bind=engine)
db_session = Session()

def test_user_repo_unique_constraint():
    user = UserInfo(
        first_name="Alice",
        last_name="Wonderland",
        email="alice@example.com",
        github_username="alice",
        payment_date=None,
        current_duration=0,
        course_duration=10,
        end_date=None,
        status=1
    )
    db_session.add(user)
    db_session.commit()
    repo1 = UserRepo(
        user_id=user.id,
        psid=1,
        github_username="alice",
        repo_name="repo1",
        github_url="http://github.com/alice/repo1"
    )
    repo2 = UserRepo(
        user_id=user.id,
        psid=2,
        github_username="alice",
        repo_name="repo1",
        github_url="http://github.com/alice/repo2"
    )
    db_session.add(repo1)
    db_session.commit()
    db_session.add(repo2)
    with pytest.raises(IntegrityError):
        db_session.commit()
---------------
TEST CASE 4 Retry 1 - Result - Failed
Test Error -
c:\ChenKhoon\JupyterNotebook\GenerateUnitTestCases\unit_test_env\Lib\site-packages\pytest_asyncio\plugin.py:217: PytestDeprecationWarning: The configuration option "asyncio_default_fixture_loop_scope" is unset.
The event loop scope for asynchronous fixtures will default to the fixture caching scope. Future versions of pytest-asyncio will default the loop scope for asynchronous fixtures to function scope. Set the default fixture loop scope explicitly in order to avoid unexpected behavior in the future. Valid fixture loop scopes are: "function", "class", "module", "package", "session"

  warnings.warn(PytestDeprecationWarning(_DEFAULT_FIXTURE_LOOP_SCOPE_UNSET))

=================================== ERRORS ====================================
________________________ ERROR collecting temp/temp.py ________________________
ImportError while importing test module 'C:\ChenKhoon\JupyterNotebook\GenerateUnitTestCases\temp\temp.py'.
Hint: make sure your test modules/packages have valid Python names.
Traceback:
C:\Users\User\AppData\Local\Programs\Python\Python313\Lib\importlib\__init__.py:88: in import_module
    return _bootstrap._gcd_import(name[level:], package, level)
temp\temp.py:3: in <module>
    from your_module import Base, UserInfo, UserRepo
E   ModuleNotFoundError: No module named 'your_module'
=========================== short test summary info ===========================
ERROR temp/temp.py
!!!!!!!!!!!!!!!!!!! Interrupted: 1 error during collection !!!!!!!!!!!!!!!!!!!!
1 error in 0.74s
TEST CASE 4 Retry 2
---------------
from sqlalchemy.dialects.postgresql import UUID
from sqlalchemy import (
    Column,
    Integer,
    String,
    TIMESTAMP,
    create_engine,
    Float,
    ForeignKey,
    Text,
    UniqueConstraint,
)
from sqlalchemy.exc import IntegrityError
from sqlalchemy.orm import sessionmaker
from sqlalchemy.ext.declarative import declarative_base
import pytest

Base = declarative_base()

class UserInfo(Base):
    __tablename__ = "user_info"
    id = Column(Integer, primary_key=True, index=True)
    first_name = Column(String(50))
    last_name = Column(String(50))
    email = Column(String(100), unique=True, nullable=False)
    github_username = Column(String(50), nullable=False)
    payment_date = Column(TIMESTAMP(timezone=True))
    current_duration = Column(Integer)
    course_duration = Column(Integer)
    end_date = Column(TIMESTAMP(timezone=True))
    status = Column(Integer)

class UserRepo(Base):
    __tablename__ = "user_repo"
    id = Column(Integer, primary_key=True)
    user_id = Column(Integer, ForeignKey("user_info.id"), nullable=False)
    psid = Column(Integer)
    github_username = Column(String(50), nullable=False)
    repo_name = Column(String(255), nullable=False)
    github_url = Column(String(255), nullable=False)
    __table_args__ = (
        UniqueConstraint("github_username", "repo_name", name="unique_user_repo"),
    )

engine = create_engine('postgresql://user:password@localhost/testdb')
Base.metadata.create_all(engine)
Session = sessionmaker(bind=engine)
db_session = Session()

def test_user_repo_unique_constraint():
    user = UserInfo(
        first_name="Alice",
        last_name="Wonderland",
        email="alice@example.com",
        github_username="alice",
        payment_date=None,
        current_duration=0,
        course_duration=10,
        end_date=None,
        status=1
    )
    db_session.add(user)
    db_session.commit()
    repo1 = UserRepo(
        user_id=user.id,
        psid=1,
        github_username="alice",
        repo_name="repo1",
        github_url="http://github.com/alice/repo1"
    )
    repo2 = UserRepo(
        user_id=user.id,
        psid=2,
        github_username="alice",
        repo_name="repo1",
        github_url="http://github.com/alice/repo2"
    )
    db_session.add(repo1)
    db_session.commit()
    db_session.add(repo2)
    with pytest.raises(IntegrityError):
        db_session.commit()
---------------
TEST CASE 4 Retry 2 - Result - Failed
Test Error -
c:\ChenKhoon\JupyterNotebook\GenerateUnitTestCases\unit_test_env\Lib\site-packages\pytest_asyncio\plugin.py:217: PytestDeprecationWarning: The configuration option "asyncio_default_fixture_loop_scope" is unset.
The event loop scope for asynchronous fixtures will default to the fixture caching scope. Future versions of pytest-asyncio will default the loop scope for asynchronous fixtures to function scope. Set the default fixture loop scope explicitly in order to avoid unexpected behavior in the future. Valid fixture loop scopes are: "function", "class", "module", "package", "session"

  warnings.warn(PytestDeprecationWarning(_DEFAULT_FIXTURE_LOOP_SCOPE_UNSET))

=================================== ERRORS ====================================
________________________ ERROR collecting temp/temp.py ________________________
ImportError while importing test module 'C:\ChenKhoon\JupyterNotebook\GenerateUnitTestCases\temp\temp.py'.
Hint: make sure your test modules/packages have valid Python names.
Traceback:
C:\Users\User\AppData\Local\Programs\Python\Python313\Lib\importlib\__init__.py:88: in import_module
    return _bootstrap._gcd_import(name[level:], package, level)
temp\temp.py:45: in <module>
    engine = create_engine('postgresql://user:password@localhost/testdb')
unit_test_env\Lib\site-packages\sqlalchemy\util\deprecations.py:281: in warned
    return fn(*args, **kwargs)  # type: ignore[no-any-return]
unit_test_env\Lib\site-packages\sqlalchemy\engine\create.py:602: in create_engine
    dbapi = dbapi_meth(**dbapi_args)
unit_test_env\Lib\site-packages\sqlalchemy\dialects\postgresql\psycopg2.py:696: in import_dbapi
    import psycopg2
E   ModuleNotFoundError: No module named 'psycopg2'
============================== warnings summary ===============================
temp\temp.py:18
  C:\ChenKhoon\JupyterNotebook\GenerateUnitTestCases\temp\temp.py:18: MovedIn20Warning: The ``declarative_base()`` function is now available as sqlalchemy.orm.declarative_base(). (deprecated since: 2.0) (Background on SQLAlchemy 2.0 at: https://sqlalche.me/e/b8d9)
    Base = declarative_base()

-- Docs: https://docs.pytest.org/en/stable/how-to/capture-warnings.html
=========================== short test summary info ===========================
ERROR temp/temp.py
!!!!!!!!!!!!!!!!!!! Interrupted: 1 error during collection !!!!!!!!!!!!!!!!!!!!
1 warning, 1 error in 0.76s

TEST CASE 5 Retry 0
---------------
from sqlalchemy import create_engine
from sqlalchemy.ext.declarative import declarative_base
from sqlalchemy.orm import sessionmaker
from theory_evaluation.models import Base, Curriculum
import pytest

@pytest.fixture(scope='module')
def engine():
    return create_engine('sqlite:///:memory:')

@pytest.fixture(scope='module')
def tables(engine):
    Base.metadata.create_all(engine)
    yield
    Base.metadata.drop_all(engine)

@pytest.fixture(scope='function')
def db_session(engine, tables):
    connection = engine.connect()
    transaction = connection.begin()
    Session = sessionmaker(bind=connection)
    session = Session()

    yield session

    session.close()
    transaction.rollback()
    connection.close()

def test_curriculum_creation(db_session):
    curriculum = Curriculum(
        question="What is Python?",
        marking_scheme="Correctness",
        model_answer="Python is a programming language."
    )
    db_session.add(curriculum)
    db_session.commit()
    retrieved_curriculum = db_session.query(Curriculum).filter_by(question="What is Python?").first()
    assert retrieved_curriculum is not None
    assert retrieved_curriculum.model_answer == "Python is a programming language."
---------------
TEST CASE 5 Retry 0 - Result - Failed
Test Error -
c:\ChenKhoon\JupyterNotebook\GenerateUnitTestCases\unit_test_env\Lib\site-packages\pytest_asyncio\plugin.py:217: PytestDeprecationWarning: The configuration option "asyncio_default_fixture_loop_scope" is unset.
The event loop scope for asynchronous fixtures will default to the fixture caching scope. Future versions of pytest-asyncio will default the loop scope for asynchronous fixtures to function scope. Set the default fixture loop scope explicitly in order to avoid unexpected behavior in the future. Valid fixture loop scopes are: "function", "class", "module", "package", "session"

  warnings.warn(PytestDeprecationWarning(_DEFAULT_FIXTURE_LOOP_SCOPE_UNSET))
E                                                                        [100%]
=================================== ERRORS ====================================
_________________ ERROR at setup of test_curriculum_creation __________________
unit_test_env\Lib\site-packages\sqlalchemy\sql\visitors.py:137: in _compiler_dispatch
    meth = getter(visitor)
E   AttributeError: 'SQLiteTypeCompiler' object has no attribute 'visit_JSONB'. Did you mean: 'visit_JSON'?

The above exception was the direct cause of the following exception:
unit_test_env\Lib\site-packages\sqlalchemy\sql\compiler.py:6716: in visit_create_table
    processed = self.process(
unit_test_env\Lib\site-packages\sqlalchemy\sql\compiler.py:932: in process
    return obj._compiler_dispatch(self, **kwargs)
unit_test_env\Lib\site-packages\sqlalchemy\sql\visitors.py:141: in _compiler_dispatch
    return meth(self, **kw)  # type: ignore  # noqa: E501
unit_test_env\Lib\site-packages\sqlalchemy\sql\compiler.py:6747: in visit_create_column
    text = self.get_column_specification(column, first_pk=first_pk)
unit_test_env\Lib\site-packages\sqlalchemy\dialects\sqlite\base.py:1598: in get_column_specification
    coltype = self.dialect.type_compiler_instance.process(
unit_test_env\Lib\site-packages\sqlalchemy\sql\compiler.py:977: in process
    return type_._compiler_dispatch(self, **kw)
unit_test_env\Lib\site-packages\sqlalchemy\sql\visitors.py:139: in _compiler_dispatch
    return visitor.visit_unsupported_compilation(self, err, **kw)  # type: ignore  # noqa: E501
unit_test_env\Lib\site-packages\sqlalchemy\sql\compiler.py:982: in visit_unsupported_compilation
    raise exc.UnsupportedCompilationError(self, element) from err
E   sqlalchemy.exc.UnsupportedCompilationError: Compiler <sqlalchemy.dialects.sqlite.base.SQLiteTypeCompiler object at 0x000001C4E1B5BB60> can't render element of type JSONB (Background on this error at: https://sqlalche.me/e/20/l7de)

The above exception was the direct cause of the following exception:
temp\temp.py:13: in tables
    Base.metadata.create_all(engine)
unit_test_env\Lib\site-packages\sqlalchemy\sql\schema.py:5925: in create_all
    bind._run_ddl_visitor(
unit_test_env\Lib\site-packages\sqlalchemy\engine\base.py:3249: in _run_ddl_visitor
    conn._run_ddl_visitor(visitorcallable, element, **kwargs)
unit_test_env\Lib\site-packages\sqlalchemy\engine\base.py:2456: in _run_ddl_visitor
    visitorcallable(self.dialect, self, **kwargs).traverse_single(element)
unit_test_env\Lib\site-packages\sqlalchemy\sql\visitors.py:664: in traverse_single
    return meth(obj, **kw)
unit_test_env\Lib\site-packages\sqlalchemy\sql\ddl.py:981: in visit_metadata
    self.traverse_single(
unit_test_env\Lib\site-packages\sqlalchemy\sql\visitors.py:664: in traverse_single
    return meth(obj, **kw)
unit_test_env\Lib\site-packages\sqlalchemy\sql\ddl.py:1019: in visit_table
    )._invoke_with(self.connection)
unit_test_env\Lib\site-packages\sqlalchemy\sql\ddl.py:321: in _invoke_with
    return bind.execute(self)
unit_test_env\Lib\site-packages\sqlalchemy\engine\base.py:1416: in execute
    return meth(
unit_test_env\Lib\site-packages\sqlalchemy\sql\ddl.py:187: in _execute_on_connection
    return connection._execute_ddl(
unit_test_env\Lib\site-packages\sqlalchemy\engine\base.py:1524: in _execute_ddl
    compiled = ddl.compile(
unit_test_env\Lib\site-packages\sqlalchemy\sql\elements.py:308: in compile
    return self._compiler(dialect, **kw)
unit_test_env\Lib\site-packages\sqlalchemy\sql\ddl.py:76: in _compiler
    return dialect.ddl_compiler(dialect, self, **kw)
unit_test_env\Lib\site-packages\sqlalchemy\sql\compiler.py:886: in __init__
    self.string = self.process(self.statement, **compile_kwargs)
unit_test_env\Lib\site-packages\sqlalchemy\sql\compiler.py:932: in process
    return obj._compiler_dispatch(self, **kwargs)
unit_test_env\Lib\site-packages\sqlalchemy\sql\visitors.py:141: in _compiler_dispatch
    return meth(self, **kw)  # type: ignore  # noqa: E501
unit_test_env\Lib\site-packages\sqlalchemy\sql\compiler.py:6726: in visit_create_table
    raise exc.CompileError(
E   sqlalchemy.exc.CompileError: (in table 'projects', column 'problem_statement'): Compiler <sqlalchemy.dialects.sqlite.base.SQLiteTypeCompiler object at 0x000001C4E1B5BB60> can't render element of type JSONB
============================== warnings summary ===============================
theory_evaluation\models.py:17
  C:\ChenKhoon\JupyterNotebook\GenerateUnitTestCases\theory_evaluation\models.py:17: MovedIn20Warning: The ``declarative_base()`` function is now available as sqlalchemy.orm.declarative_base(). (deprecated since: 2.0) (Background on SQLAlchemy 2.0 at: https://sqlalche.me/e/b8d9)
    Base = declarative_base()

-- Docs: https://docs.pytest.org/en/stable/how-to/capture-warnings.html
=========================== short test summary info ===========================
ERROR temp/temp.py::test_curriculum_creation - sqlalchemy.exc.CompileError: (...
1 warning, 1 error in 1.19s
TEST CASE 5 Retry 1
---------------
from sqlalchemy import create_engine
from sqlalchemy.orm import sessionmaker
from your_module import Base, Curriculum
import pytest

@pytest.fixture(scope='module')
def engine():
    return create_engine('sqlite:///:memory:')

@pytest.fixture(scope='module')
def tables(engine):
    Base.metadata.create_all(engine)
    yield
    Base.metadata.drop_all(engine)

@pytest.fixture(scope='function')
def db_session(engine, tables):
    connection = engine.connect()
    transaction = connection.begin()
    Session = sessionmaker(bind=connection)
    session = Session()

    yield session

    session.close()
    transaction.rollback()
    connection.close()

def test_curriculum_creation(db_session):
    curriculum = Curriculum(
        question="What is Python?",
        marking_scheme="Correctness",
        model_answer="Python is a programming language."
    )
    db_session.add(curriculum)
    db_session.commit()
    retrieved_curriculum = db_session.query(Curriculum).filter_by(question="What is Python?").first()
    assert retrieved_curriculum is not None
    assert retrieved_curriculum.model_answer == "Python is a programming language."
---------------
TEST CASE 5 Retry 1 - Result - Failed
Test Error -
c:\ChenKhoon\JupyterNotebook\GenerateUnitTestCases\unit_test_env\Lib\site-packages\pytest_asyncio\plugin.py:217: PytestDeprecationWarning: The configuration option "asyncio_default_fixture_loop_scope" is unset.
The event loop scope for asynchronous fixtures will default to the fixture caching scope. Future versions of pytest-asyncio will default the loop scope for asynchronous fixtures to function scope. Set the default fixture loop scope explicitly in order to avoid unexpected behavior in the future. Valid fixture loop scopes are: "function", "class", "module", "package", "session"

  warnings.warn(PytestDeprecationWarning(_DEFAULT_FIXTURE_LOOP_SCOPE_UNSET))

=================================== ERRORS ====================================
________________________ ERROR collecting temp/temp.py ________________________
ImportError while importing test module 'C:\ChenKhoon\JupyterNotebook\GenerateUnitTestCases\temp\temp.py'.
Hint: make sure your test modules/packages have valid Python names.
Traceback:
C:\Users\User\AppData\Local\Programs\Python\Python313\Lib\importlib\__init__.py:88: in import_module
    return _bootstrap._gcd_import(name[level:], package, level)
temp\temp.py:3: in <module>
    from your_module import Base, Curriculum
E   ModuleNotFoundError: No module named 'your_module'
=========================== short test summary info ===========================
ERROR temp/temp.py
!!!!!!!!!!!!!!!!!!! Interrupted: 1 error during collection !!!!!!!!!!!!!!!!!!!!
1 error in 0.78s
TEST CASE 5 Retry 2
---------------
from sqlalchemy.dialects.postgresql import UUID
from sqlalchemy import Column, TIMESTAMP, Text, create_engine
from sqlalchemy.sql import func
import uuid
from sqlalchemy.orm import sessionmaker
import pytest

Base = declarative_base()

class Curriculum(Base):
    __tablename__ = "curriculum"
    id = Column(
        UUID(as_uuid=True), primary_key=True, default=uuid.uuid4, nullable=False
    )
    question = Column(Text, unique=True, nullable=False)
    marking_scheme = Column(Text, nullable=False)
    model_answer = Column(Text, nullable=False)
    timestamp = Column(TIMESTAMP(timezone=True), server_default=func.now())

@pytest.fixture
def db_session():
    engine = create_engine('postgresql://user:password@localhost/testdb')
    Base.metadata.create_all(engine)
    Session = sessionmaker(bind=engine)
    session = Session()
    yield session
    session.close()

def test_curriculum_creation(db_session):
    curriculum = Curriculum(
        question="What is Python?",
        marking_scheme="Correctness",
        model_answer="Python is a programming language."
    )
    db_session.add(curriculum)
    db_session.commit()
    retrieved_curriculum = db_session.query(Curriculum).filter_by(question="What is Python?").first()
    assert retrieved_curriculum is not None
    assert retrieved_curriculum.model_answer == "Python is a programming language."
---------------
TEST CASE 5 Retry 2 - Result - Failed
Test Error -
c:\ChenKhoon\JupyterNotebook\GenerateUnitTestCases\unit_test_env\Lib\site-packages\pytest_asyncio\plugin.py:217: PytestDeprecationWarning: The configuration option "asyncio_default_fixture_loop_scope" is unset.
The event loop scope for asynchronous fixtures will default to the fixture caching scope. Future versions of pytest-asyncio will default the loop scope for asynchronous fixtures to function scope. Set the default fixture loop scope explicitly in order to avoid unexpected behavior in the future. Valid fixture loop scopes are: "function", "class", "module", "package", "session"

  warnings.warn(PytestDeprecationWarning(_DEFAULT_FIXTURE_LOOP_SCOPE_UNSET))

=================================== ERRORS ====================================
________________________ ERROR collecting temp/temp.py ________________________
temp\temp.py:8: in <module>
    Base = declarative_base()
E   NameError: name 'declarative_base' is not defined
=========================== short test summary info ===========================
ERROR temp/temp.py - NameError: name 'declarative_base' is not defined
!!!!!!!!!!!!!!!!!!! Interrupted: 1 error during collection !!!!!!!!!!!!!!!!!!!!
1 error in 0.63s

TEST CASE 6 Retry 0
---------------
from sqlalchemy import create_engine
from theory_evaluation.models import Base, Curriculum, TheoryEvalUserPerformance, UserInfo
import pytest
from sqlalchemy.orm import sessionmaker

@pytest.fixture(scope='module')
def engine():
    return create_engine('sqlite:///:memory:')

@pytest.fixture(scope='module')
def tables(engine):
    Base.metadata.create_all(engine)
    yield
    Base.metadata.drop_all(engine)

@pytest.fixture(scope='function')
def db_session(engine, tables):
    connection = engine.connect()
    transaction = connection.begin()
    Session = sessionmaker(bind=connection)
    session = Session()

    yield session

    session.close()
    transaction.rollback()
    connection.close()

def test_theory_eval_user_performance_creation(db_session):
    user = UserInfo(
        first_name="Bob",
        last_name="Builder",
        email="bob@example.com",
        github_username="bobbuilder",
        payment_date=None,
        current_duration=0,
        course_duration=10,
        end_date=None,
        status=1
    )
    db_session.add(user)
    db_session.commit()
    curriculum = Curriculum(
        question="Explain SQL.",
        marking_scheme="Detail",
        model_answer="SQL is a language for managing databases."
    )
    db_session.add(curriculum)
    db_session.commit()
    performance = TheoryEvalUserPerformance(
        email=user.email,
        question_id=curriculum.id,
        user_response="SQL is a query language.",
        llm_evaluation="Good",
        llm_score=0.9,
        user_grade="A",
        user_attempts=1,
        llm_evaluation_status=1
    )
    db_session.add(performance)
    db_session.commit()
    retrieved_performance = db_session.query(TheoryEvalUserPerformance).filter_by(email="bob@example.com").first()
    assert retrieved_performance is not None
    assert retrieved_performance.user_grade == "A"
---------------
TEST CASE 6 Retry 0 - Result - Failed
Test Error -
c:\ChenKhoon\JupyterNotebook\GenerateUnitTestCases\unit_test_env\Lib\site-packages\pytest_asyncio\plugin.py:217: PytestDeprecationWarning: The configuration option "asyncio_default_fixture_loop_scope" is unset.
The event loop scope for asynchronous fixtures will default to the fixture caching scope. Future versions of pytest-asyncio will default the loop scope for asynchronous fixtures to function scope. Set the default fixture loop scope explicitly in order to avoid unexpected behavior in the future. Valid fixture loop scopes are: "function", "class", "module", "package", "session"

  warnings.warn(PytestDeprecationWarning(_DEFAULT_FIXTURE_LOOP_SCOPE_UNSET))
E                                                                        [100%]
=================================== ERRORS ====================================
________ ERROR at setup of test_theory_eval_user_performance_creation _________
unit_test_env\Lib\site-packages\sqlalchemy\sql\visitors.py:137: in _compiler_dispatch
    meth = getter(visitor)
E   AttributeError: 'SQLiteTypeCompiler' object has no attribute 'visit_JSONB'. Did you mean: 'visit_JSON'?

The above exception was the direct cause of the following exception:
unit_test_env\Lib\site-packages\sqlalchemy\sql\compiler.py:6716: in visit_create_table
    processed = self.process(
unit_test_env\Lib\site-packages\sqlalchemy\sql\compiler.py:932: in process
    return obj._compiler_dispatch(self, **kwargs)
unit_test_env\Lib\site-packages\sqlalchemy\sql\visitors.py:141: in _compiler_dispatch
    return meth(self, **kw)  # type: ignore  # noqa: E501
unit_test_env\Lib\site-packages\sqlalchemy\sql\compiler.py:6747: in visit_create_column
    text = self.get_column_specification(column, first_pk=first_pk)
unit_test_env\Lib\site-packages\sqlalchemy\dialects\sqlite\base.py:1598: in get_column_specification
    coltype = self.dialect.type_compiler_instance.process(
unit_test_env\Lib\site-packages\sqlalchemy\sql\compiler.py:977: in process
    return type_._compiler_dispatch(self, **kw)
unit_test_env\Lib\site-packages\sqlalchemy\sql\visitors.py:139: in _compiler_dispatch
    return visitor.visit_unsupported_compilation(self, err, **kw)  # type: ignore  # noqa: E501
unit_test_env\Lib\site-packages\sqlalchemy\sql\compiler.py:982: in visit_unsupported_compilation
    raise exc.UnsupportedCompilationError(self, element) from err
E   sqlalchemy.exc.UnsupportedCompilationError: Compiler <sqlalchemy.dialects.sqlite.base.SQLiteTypeCompiler object at 0x00000297C247FB60> can't render element of type JSONB (Background on this error at: https://sqlalche.me/e/20/l7de)

The above exception was the direct cause of the following exception:
temp\temp.py:12: in tables
    Base.metadata.create_all(engine)
unit_test_env\Lib\site-packages\sqlalchemy\sql\schema.py:5925: in create_all
    bind._run_ddl_visitor(
unit_test_env\Lib\site-packages\sqlalchemy\engine\base.py:3249: in _run_ddl_visitor
    conn._run_ddl_visitor(visitorcallable, element, **kwargs)
unit_test_env\Lib\site-packages\sqlalchemy\engine\base.py:2456: in _run_ddl_visitor
    visitorcallable(self.dialect, self, **kwargs).traverse_single(element)
unit_test_env\Lib\site-packages\sqlalchemy\sql\visitors.py:664: in traverse_single
    return meth(obj, **kw)
unit_test_env\Lib\site-packages\sqlalchemy\sql\ddl.py:981: in visit_metadata
    self.traverse_single(
unit_test_env\Lib\site-packages\sqlalchemy\sql\visitors.py:664: in traverse_single
    return meth(obj, **kw)
unit_test_env\Lib\site-packages\sqlalchemy\sql\ddl.py:1019: in visit_table
    )._invoke_with(self.connection)
unit_test_env\Lib\site-packages\sqlalchemy\sql\ddl.py:321: in _invoke_with
    return bind.execute(self)
unit_test_env\Lib\site-packages\sqlalchemy\engine\base.py:1416: in execute
    return meth(
unit_test_env\Lib\site-packages\sqlalchemy\sql\ddl.py:187: in _execute_on_connection
    return connection._execute_ddl(
unit_test_env\Lib\site-packages\sqlalchemy\engine\base.py:1524: in _execute_ddl
    compiled = ddl.compile(
unit_test_env\Lib\site-packages\sqlalchemy\sql\elements.py:308: in compile
    return self._compiler(dialect, **kw)
unit_test_env\Lib\site-packages\sqlalchemy\sql\ddl.py:76: in _compiler
    return dialect.ddl_compiler(dialect, self, **kw)
unit_test_env\Lib\site-packages\sqlalchemy\sql\compiler.py:886: in __init__
    self.string = self.process(self.statement, **compile_kwargs)
unit_test_env\Lib\site-packages\sqlalchemy\sql\compiler.py:932: in process
    return obj._compiler_dispatch(self, **kwargs)
unit_test_env\Lib\site-packages\sqlalchemy\sql\visitors.py:141: in _compiler_dispatch
    return meth(self, **kw)  # type: ignore  # noqa: E501
unit_test_env\Lib\site-packages\sqlalchemy\sql\compiler.py:6726: in visit_create_table
    raise exc.CompileError(
E   sqlalchemy.exc.CompileError: (in table 'projects', column 'problem_statement'): Compiler <sqlalchemy.dialects.sqlite.base.SQLiteTypeCompiler object at 0x00000297C247FB60> can't render element of type JSONB
============================== warnings summary ===============================
theory_evaluation\models.py:17
  C:\ChenKhoon\JupyterNotebook\GenerateUnitTestCases\theory_evaluation\models.py:17: MovedIn20Warning: The ``declarative_base()`` function is now available as sqlalchemy.orm.declarative_base(). (deprecated since: 2.0) (Background on SQLAlchemy 2.0 at: https://sqlalche.me/e/b8d9)
    Base = declarative_base()

-- Docs: https://docs.pytest.org/en/stable/how-to/capture-warnings.html
=========================== short test summary info ===========================
ERROR temp/temp.py::test_theory_eval_user_performance_creation - sqlalchemy.e...
1 warning, 1 error in 1.30s
TEST CASE 6 Retry 1
---------------
from sqlalchemy import create_engine
from sqlalchemy.ext.declarative import declarative_base
from sqlalchemy.orm import sessionmaker
from theory_evaluation.models import Base, UserInfo, Curriculum, TheoryEvalUserPerformance
import pytest

@pytest.fixture(scope='module')
def engine():
    return create_engine('sqlite:///:memory:')

@pytest.fixture(scope='module')
def tables(engine):
    Base.metadata.create_all(engine)
    yield
    Base.metadata.drop_all(engine)

@pytest.fixture(scope='function')
def db_session(engine, tables):
    connection = engine.connect()
    transaction = connection.begin()
    Session = sessionmaker(bind=connection)
    session = Session()

    yield session

    session.close()
    transaction.rollback()
    connection.close()

def test_theory_eval_user_performance_creation(db_session):
    user = UserInfo(
        first_name="Bob",
        last_name="Builder",
        email="bob@example.com",
        github_username="bobbuilder",
        payment_date=None,
        current_duration=0,
        course_duration=10,
        end_date=None,
        status=1
    )
    db_session.add(user)
    db_session.commit()
    curriculum = Curriculum(
        question="Explain SQL.",
        marking_scheme="Detail",
        model_answer="SQL is a language for managing databases."
    )
    db_session.add(curriculum)
    db_session.commit()
    performance = TheoryEvalUserPerformance(
        email=user.email,
        question_id=curriculum.id,
        user_response="SQL is a query language.",
        llm_evaluation="Good",
        llm_score=0.9,
        user_grade="A",
        user_attempts=1,
        llm_evaluation_status=1
    )
    db_session.add(performance)
    db_session.commit()
    retrieved_performance = db_session.query(TheoryEvalUserPerformance).filter_by(email="bob@example.com").first()
    assert retrieved_performance is not None
    assert retrieved_performance.user_grade == "A"
---------------
TEST CASE 6 Retry 1 - Result - Failed
Test Error -
c:\ChenKhoon\JupyterNotebook\GenerateUnitTestCases\unit_test_env\Lib\site-packages\pytest_asyncio\plugin.py:217: PytestDeprecationWarning: The configuration option "asyncio_default_fixture_loop_scope" is unset.
The event loop scope for asynchronous fixtures will default to the fixture caching scope. Future versions of pytest-asyncio will default the loop scope for asynchronous fixtures to function scope. Set the default fixture loop scope explicitly in order to avoid unexpected behavior in the future. Valid fixture loop scopes are: "function", "class", "module", "package", "session"

  warnings.warn(PytestDeprecationWarning(_DEFAULT_FIXTURE_LOOP_SCOPE_UNSET))
E                                                                        [100%]
=================================== ERRORS ====================================
________ ERROR at setup of test_theory_eval_user_performance_creation _________
unit_test_env\Lib\site-packages\sqlalchemy\sql\visitors.py:137: in _compiler_dispatch
    meth = getter(visitor)
E   AttributeError: 'SQLiteTypeCompiler' object has no attribute 'visit_JSONB'. Did you mean: 'visit_JSON'?

The above exception was the direct cause of the following exception:
unit_test_env\Lib\site-packages\sqlalchemy\sql\compiler.py:6716: in visit_create_table
    processed = self.process(
unit_test_env\Lib\site-packages\sqlalchemy\sql\compiler.py:932: in process
    return obj._compiler_dispatch(self, **kwargs)
unit_test_env\Lib\site-packages\sqlalchemy\sql\visitors.py:141: in _compiler_dispatch
    return meth(self, **kw)  # type: ignore  # noqa: E501
unit_test_env\Lib\site-packages\sqlalchemy\sql\compiler.py:6747: in visit_create_column
    text = self.get_column_specification(column, first_pk=first_pk)
unit_test_env\Lib\site-packages\sqlalchemy\dialects\sqlite\base.py:1598: in get_column_specification
    coltype = self.dialect.type_compiler_instance.process(
unit_test_env\Lib\site-packages\sqlalchemy\sql\compiler.py:977: in process
    return type_._compiler_dispatch(self, **kw)
unit_test_env\Lib\site-packages\sqlalchemy\sql\visitors.py:139: in _compiler_dispatch
    return visitor.visit_unsupported_compilation(self, err, **kw)  # type: ignore  # noqa: E501
unit_test_env\Lib\site-packages\sqlalchemy\sql\compiler.py:982: in visit_unsupported_compilation
    raise exc.UnsupportedCompilationError(self, element) from err
E   sqlalchemy.exc.UnsupportedCompilationError: Compiler <sqlalchemy.dialects.sqlite.base.SQLiteTypeCompiler object at 0x00000173D865FB60> can't render element of type JSONB (Background on this error at: https://sqlalche.me/e/20/l7de)

The above exception was the direct cause of the following exception:
temp\temp.py:13: in tables
    Base.metadata.create_all(engine)
unit_test_env\Lib\site-packages\sqlalchemy\sql\schema.py:5925: in create_all
    bind._run_ddl_visitor(
unit_test_env\Lib\site-packages\sqlalchemy\engine\base.py:3249: in _run_ddl_visitor
    conn._run_ddl_visitor(visitorcallable, element, **kwargs)
unit_test_env\Lib\site-packages\sqlalchemy\engine\base.py:2456: in _run_ddl_visitor
    visitorcallable(self.dialect, self, **kwargs).traverse_single(element)
unit_test_env\Lib\site-packages\sqlalchemy\sql\visitors.py:664: in traverse_single
    return meth(obj, **kw)
unit_test_env\Lib\site-packages\sqlalchemy\sql\ddl.py:981: in visit_metadata
    self.traverse_single(
unit_test_env\Lib\site-packages\sqlalchemy\sql\visitors.py:664: in traverse_single
    return meth(obj, **kw)
unit_test_env\Lib\site-packages\sqlalchemy\sql\ddl.py:1019: in visit_table
    )._invoke_with(self.connection)
unit_test_env\Lib\site-packages\sqlalchemy\sql\ddl.py:321: in _invoke_with
    return bind.execute(self)
unit_test_env\Lib\site-packages\sqlalchemy\engine\base.py:1416: in execute
    return meth(
unit_test_env\Lib\site-packages\sqlalchemy\sql\ddl.py:187: in _execute_on_connection
    return connection._execute_ddl(
unit_test_env\Lib\site-packages\sqlalchemy\engine\base.py:1524: in _execute_ddl
    compiled = ddl.compile(
unit_test_env\Lib\site-packages\sqlalchemy\sql\elements.py:308: in compile
    return self._compiler(dialect, **kw)
unit_test_env\Lib\site-packages\sqlalchemy\sql\ddl.py:76: in _compiler
    return dialect.ddl_compiler(dialect, self, **kw)
unit_test_env\Lib\site-packages\sqlalchemy\sql\compiler.py:886: in __init__
    self.string = self.process(self.statement, **compile_kwargs)
unit_test_env\Lib\site-packages\sqlalchemy\sql\compiler.py:932: in process
    return obj._compiler_dispatch(self, **kwargs)
unit_test_env\Lib\site-packages\sqlalchemy\sql\visitors.py:141: in _compiler_dispatch
    return meth(self, **kw)  # type: ignore  # noqa: E501
unit_test_env\Lib\site-packages\sqlalchemy\sql\compiler.py:6726: in visit_create_table
    raise exc.CompileError(
E   sqlalchemy.exc.CompileError: (in table 'projects', column 'problem_statement'): Compiler <sqlalchemy.dialects.sqlite.base.SQLiteTypeCompiler object at 0x00000173D865FB60> can't render element of type JSONB
============================== warnings summary ===============================
theory_evaluation\models.py:17
  C:\ChenKhoon\JupyterNotebook\GenerateUnitTestCases\theory_evaluation\models.py:17: MovedIn20Warning: The ``declarative_base()`` function is now available as sqlalchemy.orm.declarative_base(). (deprecated since: 2.0) (Background on SQLAlchemy 2.0 at: https://sqlalche.me/e/b8d9)
    Base = declarative_base()

-- Docs: https://docs.pytest.org/en/stable/how-to/capture-warnings.html
=========================== short test summary info ===========================
ERROR temp/temp.py::test_theory_eval_user_performance_creation - sqlalchemy.e...
1 warning, 1 error in 1.19s
TEST CASE 6 Retry 2
---------------
from sqlalchemy import create_engine
from sqlalchemy.ext.declarative import declarative_base
from sqlalchemy.orm import sessionmaker
from theory_evaluation.models import Base, Curriculum, TheoryEvalUserPerformance, UserInfo
import pytest

@pytest.fixture(scope='module')
def engine():
    return create_engine('sqlite:///:memory:')

@pytest.fixture(scope='module')
def tables(engine):
    Base.metadata.create_all(engine)
    yield
    Base.metadata.drop_all(engine)

@pytest.fixture(scope='function')
def db_session(engine, tables):
    connection = engine.connect()
    transaction = connection.begin()
    Session = sessionmaker(bind=connection)
    session = Session()

    yield session

    session.close()
    transaction.rollback()
    connection.close()

def test_theory_eval_user_performance_creation(db_session):
    user = UserInfo(
        first_name="Bob",
        last_name="Builder",
        email="bob@example.com",
        github_username="bobbuilder",
        payment_date=None,
        current_duration=0,
        course_duration=10,
        end_date=None,
        status=1
    )
    db_session.add(user)
    db_session.commit()
    curriculum = Curriculum(
        question="Explain SQL.",
        marking_scheme="Detail",
        model_answer="SQL is a language for managing databases."
    )
    db_session.add(curriculum)
    db_session.commit()
    performance = TheoryEvalUserPerformance(
        email=user.email,
        question_id=curriculum.id,
        user_response="SQL is a query language.",
        llm_evaluation="Good",
        llm_score=0.9,
        user_grade="A",
        user_attempts=1,
        llm_evaluation_status=1
    )
    db_session.add(performance)
    db_session.commit()
    retrieved_performance = db_session.query(TheoryEvalUserPerformance).filter_by(email="bob@example.com").first()
    assert retrieved_performance is not None
    assert retrieved_performance.user_grade == "A"
---------------
TEST CASE 6 Retry 2 - Result - Failed
Test Error -
c:\ChenKhoon\JupyterNotebook\GenerateUnitTestCases\unit_test_env\Lib\site-packages\pytest_asyncio\plugin.py:217: PytestDeprecationWarning: The configuration option "asyncio_default_fixture_loop_scope" is unset.
The event loop scope for asynchronous fixtures will default to the fixture caching scope. Future versions of pytest-asyncio will default the loop scope for asynchronous fixtures to function scope. Set the default fixture loop scope explicitly in order to avoid unexpected behavior in the future. Valid fixture loop scopes are: "function", "class", "module", "package", "session"

  warnings.warn(PytestDeprecationWarning(_DEFAULT_FIXTURE_LOOP_SCOPE_UNSET))
E                                                                        [100%]
=================================== ERRORS ====================================
________ ERROR at setup of test_theory_eval_user_performance_creation _________
unit_test_env\Lib\site-packages\sqlalchemy\sql\visitors.py:137: in _compiler_dispatch
    meth = getter(visitor)
E   AttributeError: 'SQLiteTypeCompiler' object has no attribute 'visit_JSONB'. Did you mean: 'visit_JSON'?

The above exception was the direct cause of the following exception:
unit_test_env\Lib\site-packages\sqlalchemy\sql\compiler.py:6716: in visit_create_table
    processed = self.process(
unit_test_env\Lib\site-packages\sqlalchemy\sql\compiler.py:932: in process
    return obj._compiler_dispatch(self, **kwargs)
unit_test_env\Lib\site-packages\sqlalchemy\sql\visitors.py:141: in _compiler_dispatch
    return meth(self, **kw)  # type: ignore  # noqa: E501
unit_test_env\Lib\site-packages\sqlalchemy\sql\compiler.py:6747: in visit_create_column
    text = self.get_column_specification(column, first_pk=first_pk)
unit_test_env\Lib\site-packages\sqlalchemy\dialects\sqlite\base.py:1598: in get_column_specification
    coltype = self.dialect.type_compiler_instance.process(
unit_test_env\Lib\site-packages\sqlalchemy\sql\compiler.py:977: in process
    return type_._compiler_dispatch(self, **kw)
unit_test_env\Lib\site-packages\sqlalchemy\sql\visitors.py:139: in _compiler_dispatch
    return visitor.visit_unsupported_compilation(self, err, **kw)  # type: ignore  # noqa: E501
unit_test_env\Lib\site-packages\sqlalchemy\sql\compiler.py:982: in visit_unsupported_compilation
    raise exc.UnsupportedCompilationError(self, element) from err
E   sqlalchemy.exc.UnsupportedCompilationError: Compiler <sqlalchemy.dialects.sqlite.base.SQLiteTypeCompiler object at 0x000002194F81FB60> can't render element of type JSONB (Background on this error at: https://sqlalche.me/e/20/l7de)

The above exception was the direct cause of the following exception:
temp\temp.py:13: in tables
    Base.metadata.create_all(engine)
unit_test_env\Lib\site-packages\sqlalchemy\sql\schema.py:5925: in create_all
    bind._run_ddl_visitor(
unit_test_env\Lib\site-packages\sqlalchemy\engine\base.py:3249: in _run_ddl_visitor
    conn._run_ddl_visitor(visitorcallable, element, **kwargs)
unit_test_env\Lib\site-packages\sqlalchemy\engine\base.py:2456: in _run_ddl_visitor
    visitorcallable(self.dialect, self, **kwargs).traverse_single(element)
unit_test_env\Lib\site-packages\sqlalchemy\sql\visitors.py:664: in traverse_single
    return meth(obj, **kw)
unit_test_env\Lib\site-packages\sqlalchemy\sql\ddl.py:981: in visit_metadata
    self.traverse_single(
unit_test_env\Lib\site-packages\sqlalchemy\sql\visitors.py:664: in traverse_single
    return meth(obj, **kw)
unit_test_env\Lib\site-packages\sqlalchemy\sql\ddl.py:1019: in visit_table
    )._invoke_with(self.connection)
unit_test_env\Lib\site-packages\sqlalchemy\sql\ddl.py:321: in _invoke_with
    return bind.execute(self)
unit_test_env\Lib\site-packages\sqlalchemy\engine\base.py:1416: in execute
    return meth(
unit_test_env\Lib\site-packages\sqlalchemy\sql\ddl.py:187: in _execute_on_connection
    return connection._execute_ddl(
unit_test_env\Lib\site-packages\sqlalchemy\engine\base.py:1524: in _execute_ddl
    compiled = ddl.compile(
unit_test_env\Lib\site-packages\sqlalchemy\sql\elements.py:308: in compile
    return self._compiler(dialect, **kw)
unit_test_env\Lib\site-packages\sqlalchemy\sql\ddl.py:76: in _compiler
    return dialect.ddl_compiler(dialect, self, **kw)
unit_test_env\Lib\site-packages\sqlalchemy\sql\compiler.py:886: in __init__
    self.string = self.process(self.statement, **compile_kwargs)
unit_test_env\Lib\site-packages\sqlalchemy\sql\compiler.py:932: in process
    return obj._compiler_dispatch(self, **kwargs)
unit_test_env\Lib\site-packages\sqlalchemy\sql\visitors.py:141: in _compiler_dispatch
    return meth(self, **kw)  # type: ignore  # noqa: E501
unit_test_env\Lib\site-packages\sqlalchemy\sql\compiler.py:6726: in visit_create_table
    raise exc.CompileError(
E   sqlalchemy.exc.CompileError: (in table 'projects', column 'problem_statement'): Compiler <sqlalchemy.dialects.sqlite.base.SQLiteTypeCompiler object at 0x000002194F81FB60> can't render element of type JSONB
============================== warnings summary ===============================
theory_evaluation\models.py:17
  C:\ChenKhoon\JupyterNotebook\GenerateUnitTestCases\theory_evaluation\models.py:17: MovedIn20Warning: The ``declarative_base()`` function is now available as sqlalchemy.orm.declarative_base(). (deprecated since: 2.0) (Background on SQLAlchemy 2.0 at: https://sqlalche.me/e/b8d9)
    Base = declarative_base()

-- Docs: https://docs.pytest.org/en/stable/how-to/capture-warnings.html
=========================== short test summary info ===========================
ERROR temp/temp.py::test_theory_eval_user_performance_creation - sqlalchemy.e...
1 warning, 1 error in 1.52s
