
TEST CASE 1 Retry 0
---------------
from sqlalchemy.dialects.postgresql import JSONB, UUID
from sqlalchemy import (
    Column,
    Integer,
    String,
    TIMESTAMP,
    create_engine,
    Float,
    ForeignKey,
    Text,
    UniqueConstraint,
)
from sqlalchemy.ext.declarative import declarative_base
from sqlalchemy.sql import func
import uuid
from theory_evaluation.models import Base, ConsultantChat, CurrentUserTable, Curriculum, MentorChat, Projects, SprintIssues, TheoryEvalUserPerformance, UserInfo, UserRepo, UserScoreLog
import pytest

@pytest.fixture(scope="module")
def setup_database():
    engine = create_engine(DATABASE_URL)
    Base.metadata.create_all(engine)
    Session = sessionmaker(bind=engine)
    session = Session()
    yield session
    session.close()
    Base.metadata.drop_all(engine)

def test_user_info_creation(setup_database):
    session = setup_database
    user = UserInfo(
        first_name="John",
        last_name="Doe",
        email="john.doe@example.com",
        github_username="johndoe",
        payment_date=None,
        current_duration=0,
        course_duration=0,
        end_date=None,
        status=1
    )
    session.add(user)
    session.commit()

---------------
TEST CASE 1 Retry 0 - Result - Failed
Test Error -
c:\ChenKhoon\JupyterNotebook\GenerateUnitTestCases\unit_test_env\Lib\site-packages\pytest_asyncio\plugin.py:217: PytestDeprecationWarning: The configuration option "asyncio_default_fixture_loop_scope" is unset.
The event loop scope for asynchronous fixtures will default to the fixture caching scope. Future versions of pytest-asyncio will default the loop scope for asynchronous fixtures to function scope. Set the default fixture loop scope explicitly in order to avoid unexpected behavior in the future. Valid fixture loop scopes are: "function", "class", "module", "package", "session"

  warnings.warn(PytestDeprecationWarning(_DEFAULT_FIXTURE_LOOP_SCOPE_UNSET))
E                                                                        [100%]
=================================== ERRORS ====================================
__________________ ERROR at setup of test_user_info_creation __________________
temp\temp.py:21: in setup_database
    engine = create_engine(DATABASE_URL)
E   NameError: name 'DATABASE_URL' is not defined
============================== warnings summary ===============================
theory_evaluation\models.py:17
  C:\ChenKhoon\JupyterNotebook\GenerateUnitTestCases\theory_evaluation\models.py:17: MovedIn20Warning: The ``declarative_base()`` function is now available as sqlalchemy.orm.declarative_base(). (deprecated since: 2.0) (Background on SQLAlchemy 2.0 at: https://sqlalche.me/e/b8d9)
    Base = declarative_base()

-- Docs: https://docs.pytest.org/en/stable/how-to/capture-warnings.html
=========================== short test summary info ===========================
ERROR temp/temp.py::test_user_info_creation - NameError: name 'DATABASE_URL' ...
1 warning, 1 error in 0.91s
TEST CASE 1 Retry 1
---------------
from sqlalchemy.dialects.postgresql import JSONB, UUID
from sqlalchemy import (
    Column,
    Integer,
    String,
    TIMESTAMP,
    create_engine,
    Float,
    ForeignKey,
    Text,
    UniqueConstraint,
)
from sqlalchemy.ext.declarative import declarative_base
from sqlalchemy.sql import func
import uuid
from theory_evaluation.models import Base, ConsultantChat, CurrentUserTable, Curriculum, MentorChat, Projects, SprintIssues, TheoryEvalUserPerformance, UserInfo, UserRepo, UserScoreLog
import pytest

@pytest.fixture(scope="module")
def setup_database():
    engine = create_engine(DATABASE_URL)
    Base.metadata.create_all(engine)
    Session = sessionmaker(bind=engine)
    session = Session()
    yield session
    session.close()
    Base.metadata.drop_all(engine)

import os
from sqlalchemy import create_engine
from sqlalchemy.orm import sessionmaker
from dotenv import load_dotenv
import pytest

load_dotenv()

DATABASE_URL = os.getenv("DATABASE_URL")

engine = create_engine(DATABASE_URL)
SessionLocal = sessionmaker(autocommit=False, autoflush=False, bind=engine)

@pytest.fixture
def setup_database():
    Base.metadata.create_all(bind=engine)
    session = SessionLocal()
    yield session
    session.close()
    Base.metadata.drop_all(bind=engine)

def test_user_info_creation(setup_database):
    session = setup_database
    user = UserInfo(
        first_name="John",
        last_name="Doe",
        email="john.doe@example.com",
        github_username="johndoe",
        payment_date=None,
        current_duration=0,
        course_duration=0,
        end_date=None,
        status=1
    )
    session.add(user)
    session.commit()
    assert session.query(UserInfo).filter_by(email="john.doe@example.com").first() is not None

---------------
TEST CASE 1 Retry 1 - Result - Failed
Test Error -
c:\ChenKhoon\JupyterNotebook\GenerateUnitTestCases\unit_test_env\Lib\site-packages\pytest_asyncio\plugin.py:217: PytestDeprecationWarning: The configuration option "asyncio_default_fixture_loop_scope" is unset.
The event loop scope for asynchronous fixtures will default to the fixture caching scope. Future versions of pytest-asyncio will default the loop scope for asynchronous fixtures to function scope. Set the default fixture loop scope explicitly in order to avoid unexpected behavior in the future. Valid fixture loop scopes are: "function", "class", "module", "package", "session"

  warnings.warn(PytestDeprecationWarning(_DEFAULT_FIXTURE_LOOP_SCOPE_UNSET))

=================================== ERRORS ====================================
________________________ ERROR collecting temp/temp.py ________________________
temp\temp.py:39: in <module>
    engine = create_engine(DATABASE_URL)
<string>:2: in create_engine
    ???
unit_test_env\Lib\site-packages\sqlalchemy\util\deprecations.py:281: in warned
    return fn(*args, **kwargs)  # type: ignore[no-any-return]
unit_test_env\Lib\site-packages\sqlalchemy\engine\create.py:549: in create_engine
    u = _url.make_url(url)
unit_test_env\Lib\site-packages\sqlalchemy\engine\url.py:860: in make_url
    raise exc.ArgumentError(
E   sqlalchemy.exc.ArgumentError: Expected string or URL object, got None
============================== warnings summary ===============================
theory_evaluation\models.py:17
  C:\ChenKhoon\JupyterNotebook\GenerateUnitTestCases\theory_evaluation\models.py:17: MovedIn20Warning: The ``declarative_base()`` function is now available as sqlalchemy.orm.declarative_base(). (deprecated since: 2.0) (Background on SQLAlchemy 2.0 at: https://sqlalche.me/e/b8d9)
    Base = declarative_base()

-- Docs: https://docs.pytest.org/en/stable/how-to/capture-warnings.html
=========================== short test summary info ===========================
ERROR temp/temp.py - sqlalchemy.exc.ArgumentError: Expected string or URL obj...
!!!!!!!!!!!!!!!!!!! Interrupted: 1 error during collection !!!!!!!!!!!!!!!!!!!!
1 warning, 1 error in 1.40s
TEST CASE 1 Retry 2
---------------
from sqlalchemy.dialects.postgresql import JSONB, UUID
from sqlalchemy import (
    Column,
    Integer,
    String,
    TIMESTAMP,
    create_engine,
    Float,
    ForeignKey,
    Text,
    UniqueConstraint,
)
from sqlalchemy.ext.declarative import declarative_base
from sqlalchemy.sql import func
import uuid
from theory_evaluation.models import Base, ConsultantChat, CurrentUserTable, Curriculum, MentorChat, Projects, SprintIssues, TheoryEvalUserPerformance, UserInfo, UserRepo, UserScoreLog
import pytest

@pytest.fixture(scope="module")
def setup_database():
    engine = create_engine(DATABASE_URL)
    Base.metadata.create_all(engine)
    Session = sessionmaker(bind=engine)
    session = Session()
    yield session
    session.close()
    Base.metadata.drop_all(engine)

import os
from sqlalchemy import create_engine
from sqlalchemy.orm import sessionmaker
from sqlalchemy.exc import ArgumentError
from dotenv import load_dotenv
import pytest

load_dotenv()

DATABASE_URL = os.getenv("DATABASE_URL")

if not DATABASE_URL:
    raise ArgumentError("Expected string or URL object, got None")

engine = create_engine(DATABASE_URL)
SessionLocal = sessionmaker(autocommit=False, autoflush=False, bind=engine)

@pytest.fixture
def setup_database():
    Base.metadata.create_all(bind=engine)
    session = SessionLocal()
    yield session
    session.close()
    Base.metadata.drop_all(bind=engine)

def test_user_info_creation(setup_database):
    session = setup_database
    user = UserInfo(
        first_name="John",
        last_name="Doe",
        email="john.doe@example.com",
        github_username="johndoe",
        payment_date=None,
        current_duration=0,
        course_duration=0,
        end_date=None,
        status=1
    )
    session.add(user)
    session.commit()
    assert session.query(UserInfo).filter_by(email="john.doe@example.com").first() is not None

---------------
TEST CASE 1 Retry 2 - Result - Failed
Test Error -
c:\ChenKhoon\JupyterNotebook\GenerateUnitTestCases\unit_test_env\Lib\site-packages\pytest_asyncio\plugin.py:217: PytestDeprecationWarning: The configuration option "asyncio_default_fixture_loop_scope" is unset.
The event loop scope for asynchronous fixtures will default to the fixture caching scope. Future versions of pytest-asyncio will default the loop scope for asynchronous fixtures to function scope. Set the default fixture loop scope explicitly in order to avoid unexpected behavior in the future. Valid fixture loop scopes are: "function", "class", "module", "package", "session"

  warnings.warn(PytestDeprecationWarning(_DEFAULT_FIXTURE_LOOP_SCOPE_UNSET))

=================================== ERRORS ====================================
________________________ ERROR collecting temp/temp.py ________________________
temp\temp.py:41: in <module>
    raise ArgumentError("Expected string or URL object, got None")
E   sqlalchemy.exc.ArgumentError: Expected string or URL object, got None
============================== warnings summary ===============================
theory_evaluation\models.py:17
  C:\ChenKhoon\JupyterNotebook\GenerateUnitTestCases\theory_evaluation\models.py:17: MovedIn20Warning: The ``declarative_base()`` function is now available as sqlalchemy.orm.declarative_base(). (deprecated since: 2.0) (Background on SQLAlchemy 2.0 at: https://sqlalche.me/e/b8d9)
    Base = declarative_base()

-- Docs: https://docs.pytest.org/en/stable/how-to/capture-warnings.html
=========================== short test summary info ===========================
ERROR temp/temp.py - sqlalchemy.exc.ArgumentError: Expected string or URL obj...
!!!!!!!!!!!!!!!!!!! Interrupted: 1 error during collection !!!!!!!!!!!!!!!!!!!!
1 warning, 1 error in 0.89s

TEST CASE 3 Retry 0
---------------
from sqlalchemy.dialects.postgresql import JSONB, UUID
from sqlalchemy import (
    Column,
    Integer,
    String,
    TIMESTAMP,
    create_engine,
    Float,
    ForeignKey,
    Text,
    UniqueConstraint,
)
from sqlalchemy.ext.declarative import declarative_base
from sqlalchemy.sql import func
import uuid
from theory_evaluation.models import Base, ConsultantChat, CurrentUserTable, Curriculum, MentorChat, Projects, SprintIssues, TheoryEvalUserPerformance, UserInfo, UserRepo, UserScoreLog
import pytest

@pytest.fixture(scope="module")
def setup_database():
    engine = create_engine(DATABASE_URL)
    Base.metadata.create_all(engine)
    Session = sessionmaker(bind=engine)
    session = Session()
    yield session
    session.close()
    Base.metadata.drop_all(engine)

def test_projects_creation(setup_database):
    session = setup_database
    project = Projects(
        repo_name="test_repo",
        problem_statement={"key": "value"},
        bloblink="http://example.com/blob",
        mini_project_flag=1
    )
    session.add(project)
    session.commit()

---------------
TEST CASE 3 Retry 0 - Result - Failed
Test Error -
c:\ChenKhoon\JupyterNotebook\GenerateUnitTestCases\unit_test_env\Lib\site-packages\pytest_asyncio\plugin.py:217: PytestDeprecationWarning: The configuration option "asyncio_default_fixture_loop_scope" is unset.
The event loop scope for asynchronous fixtures will default to the fixture caching scope. Future versions of pytest-asyncio will default the loop scope for asynchronous fixtures to function scope. Set the default fixture loop scope explicitly in order to avoid unexpected behavior in the future. Valid fixture loop scopes are: "function", "class", "module", "package", "session"

  warnings.warn(PytestDeprecationWarning(_DEFAULT_FIXTURE_LOOP_SCOPE_UNSET))
E                                                                        [100%]
=================================== ERRORS ====================================
__________________ ERROR at setup of test_projects_creation ___________________
temp\temp.py:21: in setup_database
    engine = create_engine(DATABASE_URL)
E   NameError: name 'DATABASE_URL' is not defined
============================== warnings summary ===============================
theory_evaluation\models.py:17
  C:\ChenKhoon\JupyterNotebook\GenerateUnitTestCases\theory_evaluation\models.py:17: MovedIn20Warning: The ``declarative_base()`` function is now available as sqlalchemy.orm.declarative_base(). (deprecated since: 2.0) (Background on SQLAlchemy 2.0 at: https://sqlalche.me/e/b8d9)
    Base = declarative_base()

-- Docs: https://docs.pytest.org/en/stable/how-to/capture-warnings.html
=========================== short test summary info ===========================
ERROR temp/temp.py::test_projects_creation - NameError: name 'DATABASE_URL' i...
1 warning, 1 error in 0.69s
TEST CASE 3 Retry 1
---------------
from sqlalchemy.dialects.postgresql import JSONB, UUID
from sqlalchemy import (
    Column,
    Integer,
    String,
    TIMESTAMP,
    create_engine,
    Float,
    ForeignKey,
    Text,
    UniqueConstraint,
)
from sqlalchemy.ext.declarative import declarative_base
from sqlalchemy.sql import func
import uuid
from theory_evaluation.models import Base, ConsultantChat, CurrentUserTable, Curriculum, MentorChat, Projects, SprintIssues, TheoryEvalUserPerformance, UserInfo, UserRepo, UserScoreLog
import pytest

@pytest.fixture(scope="module")
def setup_database():
    engine = create_engine(DATABASE_URL)
    Base.metadata.create_all(engine)
    Session = sessionmaker(bind=engine)
    session = Session()
    yield session
    session.close()
    Base.metadata.drop_all(engine)

import pytest
from sqlalchemy import create_engine
from sqlalchemy.orm import sessionmaker
from your_module import Base, Projects  # Replace 'your_module' with the actual module name

DATABASE_URL = "sqlite:///:memory:"  # Example in-memory database URL

@pytest.fixture
def setup_database():
    engine = create_engine(DATABASE_URL)
    Base.metadata.create_all(engine)
    Session = sessionmaker(bind=engine)
    session = Session()
    yield session
    session.close()
    Base.metadata.drop_all(engine)

def test_projects_creation(setup_database):
    session = setup_database
    project = Projects(
        repo_name="test_repo",
        problem_statement={"key": "value"},
        bloblink="http://example.com/blob",
        mini_project_flag=1
    )
    session.add(project)
    session.commit()
    retrieved_project = session.query(Projects).filter_by(repo_name="test_repo").first()
    assert retrieved_project is not None
    assert retrieved_project.repo_name == "test_repo"
    assert retrieved_project.problem_statement == {"key": "value"}
    assert retrieved_project.bloblink == "http://example.com/blob"
    assert retrieved_project.mini_project_flag == 1

---------------
TEST CASE 3 Retry 1 - Result - Failed
Test Error -
c:\ChenKhoon\JupyterNotebook\GenerateUnitTestCases\unit_test_env\Lib\site-packages\pytest_asyncio\plugin.py:217: PytestDeprecationWarning: The configuration option "asyncio_default_fixture_loop_scope" is unset.
The event loop scope for asynchronous fixtures will default to the fixture caching scope. Future versions of pytest-asyncio will default the loop scope for asynchronous fixtures to function scope. Set the default fixture loop scope explicitly in order to avoid unexpected behavior in the future. Valid fixture loop scopes are: "function", "class", "module", "package", "session"

  warnings.warn(PytestDeprecationWarning(_DEFAULT_FIXTURE_LOOP_SCOPE_UNSET))

=================================== ERRORS ====================================
________________________ ERROR collecting temp/temp.py ________________________
ImportError while importing test module 'C:\ChenKhoon\JupyterNotebook\GenerateUnitTestCases\temp\temp.py'.
Hint: make sure your test modules/packages have valid Python names.
Traceback:
C:\Users\User\AppData\Local\Programs\Python\Python313\Lib\importlib\__init__.py:88: in import_module
    return _bootstrap._gcd_import(name[level:], package, level)
temp\temp.py:32: in <module>
    from your_module import Base, Projects  # Replace 'your_module' with the actual module name
E   ModuleNotFoundError: No module named 'your_module'
============================== warnings summary ===============================
theory_evaluation\models.py:17
  C:\ChenKhoon\JupyterNotebook\GenerateUnitTestCases\theory_evaluation\models.py:17: MovedIn20Warning: The ``declarative_base()`` function is now available as sqlalchemy.orm.declarative_base(). (deprecated since: 2.0) (Background on SQLAlchemy 2.0 at: https://sqlalche.me/e/b8d9)
    Base = declarative_base()

-- Docs: https://docs.pytest.org/en/stable/how-to/capture-warnings.html
=========================== short test summary info ===========================
ERROR temp/temp.py
!!!!!!!!!!!!!!!!!!! Interrupted: 1 error during collection !!!!!!!!!!!!!!!!!!!!
1 warning, 1 error in 0.83s
TEST CASE 3 Retry 2
---------------
from sqlalchemy.dialects.postgresql import JSONB, UUID
from sqlalchemy import (
    Column,
    Integer,
    String,
    TIMESTAMP,
    create_engine,
    Float,
    ForeignKey,
    Text,
    UniqueConstraint,
)
from sqlalchemy.ext.declarative import declarative_base
from sqlalchemy.sql import func
import uuid
from theory_evaluation.models import Base, ConsultantChat, CurrentUserTable, Curriculum, MentorChat, Projects, SprintIssues, TheoryEvalUserPerformance, UserInfo, UserRepo, UserScoreLog
import pytest

@pytest.fixture(scope="module")
def setup_database():
    engine = create_engine(DATABASE_URL)
    Base.metadata.create_all(engine)
    Session = sessionmaker(bind=engine)
    session = Session()
    yield session
    session.close()
    Base.metadata.drop_all(engine)

import pytest
from sqlalchemy import create_engine
from sqlalchemy.orm import sessionmaker
from your_actual_module_name import Base, Projects  # Replace 'your_actual_module_name' with the actual module name

DATABASE_URL = "sqlite:///:memory:"  # Example in-memory database URL

@pytest.fixture
def setup_database():
    engine = create_engine(DATABASE_URL)
    Base.metadata.create_all(engine)
    Session = sessionmaker(bind=engine)
    session = Session()
    yield session
    session.close()
    Base.metadata.drop_all(engine)

def test_projects_creation(setup_database):
    session = setup_database
    project = Projects(
        repo_name="test_repo",
        problem_statement={"key": "value"},
        bloblink="http://example.com/blob",
        mini_project_flag=1
    )
    session.add(project)
    session.commit()
    retrieved_project = session.query(Projects).filter_by(repo_name="test_repo").first()
    assert retrieved_project is not None
    assert retrieved_project.repo_name == "test_repo"
    assert retrieved_project.problem_statement == {"key": "value"}
    assert retrieved_project.bloblink == "http://example.com/blob"
    assert retrieved_project.mini_project_flag == 1

---------------
TEST CASE 3 Retry 2 - Result - Failed
Test Error -
c:\ChenKhoon\JupyterNotebook\GenerateUnitTestCases\unit_test_env\Lib\site-packages\pytest_asyncio\plugin.py:217: PytestDeprecationWarning: The configuration option "asyncio_default_fixture_loop_scope" is unset.
The event loop scope for asynchronous fixtures will default to the fixture caching scope. Future versions of pytest-asyncio will default the loop scope for asynchronous fixtures to function scope. Set the default fixture loop scope explicitly in order to avoid unexpected behavior in the future. Valid fixture loop scopes are: "function", "class", "module", "package", "session"

  warnings.warn(PytestDeprecationWarning(_DEFAULT_FIXTURE_LOOP_SCOPE_UNSET))

=================================== ERRORS ====================================
________________________ ERROR collecting temp/temp.py ________________________
ImportError while importing test module 'C:\ChenKhoon\JupyterNotebook\GenerateUnitTestCases\temp\temp.py'.
Hint: make sure your test modules/packages have valid Python names.
Traceback:
C:\Users\User\AppData\Local\Programs\Python\Python313\Lib\importlib\__init__.py:88: in import_module
    return _bootstrap._gcd_import(name[level:], package, level)
temp\temp.py:32: in <module>
    from your_actual_module_name import Base, Projects  # Replace 'your_actual_module_name' with the actual module name
E   ModuleNotFoundError: No module named 'your_actual_module_name'
============================== warnings summary ===============================
theory_evaluation\models.py:17
  C:\ChenKhoon\JupyterNotebook\GenerateUnitTestCases\theory_evaluation\models.py:17: MovedIn20Warning: The ``declarative_base()`` function is now available as sqlalchemy.orm.declarative_base(). (deprecated since: 2.0) (Background on SQLAlchemy 2.0 at: https://sqlalche.me/e/b8d9)
    Base = declarative_base()

-- Docs: https://docs.pytest.org/en/stable/how-to/capture-warnings.html
=========================== short test summary info ===========================
ERROR temp/temp.py
!!!!!!!!!!!!!!!!!!! Interrupted: 1 error during collection !!!!!!!!!!!!!!!!!!!!
1 warning, 1 error in 0.87s

TEST CASE 4 Retry 0
---------------
from sqlalchemy.dialects.postgresql import JSONB, UUID
from sqlalchemy import (
    Column,
    Integer,
    String,
    TIMESTAMP,
    create_engine,
    Float,
    ForeignKey,
    Text,
    UniqueConstraint,
)
from sqlalchemy.ext.declarative import declarative_base
from sqlalchemy.sql import func
import uuid
from theory_evaluation.models import Base, ConsultantChat, CurrentUserTable, Curriculum, MentorChat, Projects, SprintIssues, TheoryEvalUserPerformance, UserInfo, UserRepo, UserScoreLog
import pytest

@pytest.fixture(scope="module")
def setup_database():
    engine = create_engine(DATABASE_URL)
    Base.metadata.create_all(engine)
    Session = sessionmaker(bind=engine)
    session = Session()
    yield session
    session.close()
    Base.metadata.drop_all(engine)

def test_user_repo_unique_constraint(setup_database):
    session = setup_database
    user_repo1 = UserRepo(
        user_id=1,
        psid=1,
        github_username="uniqueuser",
        repo_name="uniquerepo",
        github_url="http://github.com/uniqueuser/uniquerepo"
    )
    user_repo2 = UserRepo(
        user_id=1,
        psid=2,
        github_username="uniqueuser",
        repo_name="uniquerepo",
        github_url="http://github.com/uniqueuser/uniquerepo2"
    )
    session.add(user_repo1)
    session.commit()

---------------
TEST CASE 4 Retry 0 - Result - Failed
Test Error -
c:\ChenKhoon\JupyterNotebook\GenerateUnitTestCases\unit_test_env\Lib\site-packages\pytest_asyncio\plugin.py:217: PytestDeprecationWarning: The configuration option "asyncio_default_fixture_loop_scope" is unset.
The event loop scope for asynchronous fixtures will default to the fixture caching scope. Future versions of pytest-asyncio will default the loop scope for asynchronous fixtures to function scope. Set the default fixture loop scope explicitly in order to avoid unexpected behavior in the future. Valid fixture loop scopes are: "function", "class", "module", "package", "session"

  warnings.warn(PytestDeprecationWarning(_DEFAULT_FIXTURE_LOOP_SCOPE_UNSET))
E                                                                        [100%]
=================================== ERRORS ====================================
_____________ ERROR at setup of test_user_repo_unique_constraint ______________
temp\temp.py:21: in setup_database
    engine = create_engine(DATABASE_URL)
E   NameError: name 'DATABASE_URL' is not defined
============================== warnings summary ===============================
theory_evaluation\models.py:17
  C:\ChenKhoon\JupyterNotebook\GenerateUnitTestCases\theory_evaluation\models.py:17: MovedIn20Warning: The ``declarative_base()`` function is now available as sqlalchemy.orm.declarative_base(). (deprecated since: 2.0) (Background on SQLAlchemy 2.0 at: https://sqlalche.me/e/b8d9)
    Base = declarative_base()

-- Docs: https://docs.pytest.org/en/stable/how-to/capture-warnings.html
=========================== short test summary info ===========================
ERROR temp/temp.py::test_user_repo_unique_constraint - NameError: name 'DATAB...
1 warning, 1 error in 0.94s
TEST CASE 4 Retry 1
---------------
from sqlalchemy.dialects.postgresql import JSONB, UUID
from sqlalchemy import (
    Column,
    Integer,
    String,
    TIMESTAMP,
    create_engine,
    Float,
    ForeignKey,
    Text,
    UniqueConstraint,
)
from sqlalchemy.ext.declarative import declarative_base
from sqlalchemy.sql import func
import uuid
from theory_evaluation.models import Base, ConsultantChat, CurrentUserTable, Curriculum, MentorChat, Projects, SprintIssues, TheoryEvalUserPerformance, UserInfo, UserRepo, UserScoreLog
import pytest

@pytest.fixture(scope="module")
def setup_database():
    engine = create_engine(DATABASE_URL)
    Base.metadata.create_all(engine)
    Session = sessionmaker(bind=engine)
    session = Session()
    yield session
    session.close()
    Base.metadata.drop_all(engine)

import pytest
from sqlalchemy import create_engine
from sqlalchemy.orm import sessionmaker
from sqlalchemy.exc import IntegrityError

# Assuming DATABASE_URL is defined somewhere in your environment
DATABASE_URL = "sqlite:///:memory:"  # Example for in-memory SQLite database

@pytest.fixture
def setup_database():
    engine = create_engine(DATABASE_URL)
    Base.metadata.create_all(engine)
    Session = sessionmaker(bind=engine)
    session = Session()
    yield session
    session.close()
    Base.metadata.drop_all(engine)

def test_user_repo_unique_constraint(setup_database):
    session = setup_database
    user_repo1 = UserRepo(
        user_id=1,
        psid=1,
        github_username="uniqueuser",
        repo_name="uniquerepo",
        github_url="http://github.com/uniqueuser/uniquerepo"
    )
    user_repo2 = UserRepo(
        user_id=1,
        psid=2,
        github_username="uniqueuser",
        repo_name="uniquerepo",
        github_url="http://github.com/uniqueuser/uniquerepo2"
    )
    session.add(user_repo1)
    session.commit()
    
    session.add(user_repo2)
    with pytest.raises(IntegrityError):
        session.commit()

---------------
TEST CASE 4 Retry 1 - Result - Failed
Test Error -
c:\ChenKhoon\JupyterNotebook\GenerateUnitTestCases\unit_test_env\Lib\site-packages\pytest_asyncio\plugin.py:217: PytestDeprecationWarning: The configuration option "asyncio_default_fixture_loop_scope" is unset.
The event loop scope for asynchronous fixtures will default to the fixture caching scope. Future versions of pytest-asyncio will default the loop scope for asynchronous fixtures to function scope. Set the default fixture loop scope explicitly in order to avoid unexpected behavior in the future. Valid fixture loop scopes are: "function", "class", "module", "package", "session"

  warnings.warn(PytestDeprecationWarning(_DEFAULT_FIXTURE_LOOP_SCOPE_UNSET))
E                                                                        [100%]
=================================== ERRORS ====================================
_____________ ERROR at setup of test_user_repo_unique_constraint ______________
unit_test_env\Lib\site-packages\sqlalchemy\sql\visitors.py:137: in _compiler_dispatch
    meth = getter(visitor)
E   AttributeError: 'SQLiteTypeCompiler' object has no attribute 'visit_JSONB'. Did you mean: 'visit_JSON'?

The above exception was the direct cause of the following exception:
unit_test_env\Lib\site-packages\sqlalchemy\sql\compiler.py:6716: in visit_create_table
    processed = self.process(
unit_test_env\Lib\site-packages\sqlalchemy\sql\compiler.py:932: in process
    return obj._compiler_dispatch(self, **kwargs)
unit_test_env\Lib\site-packages\sqlalchemy\sql\visitors.py:141: in _compiler_dispatch
    return meth(self, **kw)  # type: ignore  # noqa: E501
unit_test_env\Lib\site-packages\sqlalchemy\sql\compiler.py:6747: in visit_create_column
    text = self.get_column_specification(column, first_pk=first_pk)
unit_test_env\Lib\site-packages\sqlalchemy\dialects\sqlite\base.py:1598: in get_column_specification
    coltype = self.dialect.type_compiler_instance.process(
unit_test_env\Lib\site-packages\sqlalchemy\sql\compiler.py:977: in process
    return type_._compiler_dispatch(self, **kw)
unit_test_env\Lib\site-packages\sqlalchemy\sql\visitors.py:139: in _compiler_dispatch
    return visitor.visit_unsupported_compilation(self, err, **kw)  # type: ignore  # noqa: E501
unit_test_env\Lib\site-packages\sqlalchemy\sql\compiler.py:982: in visit_unsupported_compilation
    raise exc.UnsupportedCompilationError(self, element) from err
E   sqlalchemy.exc.UnsupportedCompilationError: Compiler <sqlalchemy.dialects.sqlite.base.SQLiteTypeCompiler object at 0x0000024D78E5FCB0> can't render element of type JSONB (Background on this error at: https://sqlalche.me/e/20/l7de)

The above exception was the direct cause of the following exception:
temp\temp.py:40: in setup_database
    Base.metadata.create_all(engine)
unit_test_env\Lib\site-packages\sqlalchemy\sql\schema.py:5925: in create_all
    bind._run_ddl_visitor(
unit_test_env\Lib\site-packages\sqlalchemy\engine\base.py:3249: in _run_ddl_visitor
    conn._run_ddl_visitor(visitorcallable, element, **kwargs)
unit_test_env\Lib\site-packages\sqlalchemy\engine\base.py:2456: in _run_ddl_visitor
    visitorcallable(self.dialect, self, **kwargs).traverse_single(element)
unit_test_env\Lib\site-packages\sqlalchemy\sql\visitors.py:664: in traverse_single
    return meth(obj, **kw)
unit_test_env\Lib\site-packages\sqlalchemy\sql\ddl.py:981: in visit_metadata
    self.traverse_single(
unit_test_env\Lib\site-packages\sqlalchemy\sql\visitors.py:664: in traverse_single
    return meth(obj, **kw)
unit_test_env\Lib\site-packages\sqlalchemy\sql\ddl.py:1019: in visit_table
    )._invoke_with(self.connection)
unit_test_env\Lib\site-packages\sqlalchemy\sql\ddl.py:321: in _invoke_with
    return bind.execute(self)
unit_test_env\Lib\site-packages\sqlalchemy\engine\base.py:1416: in execute
    return meth(
unit_test_env\Lib\site-packages\sqlalchemy\sql\ddl.py:187: in _execute_on_connection
    return connection._execute_ddl(
unit_test_env\Lib\site-packages\sqlalchemy\engine\base.py:1524: in _execute_ddl
    compiled = ddl.compile(
unit_test_env\Lib\site-packages\sqlalchemy\sql\elements.py:308: in compile
    return self._compiler(dialect, **kw)
unit_test_env\Lib\site-packages\sqlalchemy\sql\ddl.py:76: in _compiler
    return dialect.ddl_compiler(dialect, self, **kw)
unit_test_env\Lib\site-packages\sqlalchemy\sql\compiler.py:886: in __init__
    self.string = self.process(self.statement, **compile_kwargs)
unit_test_env\Lib\site-packages\sqlalchemy\sql\compiler.py:932: in process
    return obj._compiler_dispatch(self, **kwargs)
unit_test_env\Lib\site-packages\sqlalchemy\sql\visitors.py:141: in _compiler_dispatch
    return meth(self, **kw)  # type: ignore  # noqa: E501
unit_test_env\Lib\site-packages\sqlalchemy\sql\compiler.py:6726: in visit_create_table
    raise exc.CompileError(
E   sqlalchemy.exc.CompileError: (in table 'projects', column 'problem_statement'): Compiler <sqlalchemy.dialects.sqlite.base.SQLiteTypeCompiler object at 0x0000024D78E5FCB0> can't render element of type JSONB
============================== warnings summary ===============================
theory_evaluation\models.py:17
  C:\ChenKhoon\JupyterNotebook\GenerateUnitTestCases\theory_evaluation\models.py:17: MovedIn20Warning: The ``declarative_base()`` function is now available as sqlalchemy.orm.declarative_base(). (deprecated since: 2.0) (Background on SQLAlchemy 2.0 at: https://sqlalche.me/e/b8d9)
    Base = declarative_base()

-- Docs: https://docs.pytest.org/en/stable/how-to/capture-warnings.html
=========================== short test summary info ===========================
ERROR temp/temp.py::test_user_repo_unique_constraint - sqlalchemy.exc.Compile...
1 warning, 1 error in 1.17s
TEST CASE 4 Retry 2
---------------
from sqlalchemy.dialects.postgresql import JSONB, UUID
from sqlalchemy import (
    Column,
    Integer,
    String,
    TIMESTAMP,
    create_engine,
    Float,
    ForeignKey,
    Text,
    UniqueConstraint,
)
from sqlalchemy.ext.declarative import declarative_base
from sqlalchemy.sql import func
import uuid
from theory_evaluation.models import Base, ConsultantChat, CurrentUserTable, Curriculum, MentorChat, Projects, SprintIssues, TheoryEvalUserPerformance, UserInfo, UserRepo, UserScoreLog
import pytest

@pytest.fixture(scope="module")
def setup_database():
    engine = create_engine(DATABASE_URL)
    Base.metadata.create_all(engine)
    Session = sessionmaker(bind=engine)
    session = Session()
    yield session
    session.close()
    Base.metadata.drop_all(engine)

import pytest
from sqlalchemy import create_engine
from sqlalchemy.orm import sessionmaker
from sqlalchemy.exc import IntegrityError
from sqlalchemy.dialects.sqlite import JSON

# Assuming DATABASE_URL is defined somewhere in your environment
DATABASE_URL = "sqlite:///:memory:"  # Example for in-memory SQLite database

@pytest.fixture
def setup_database():
    engine = create_engine(DATABASE_URL)
    Base.metadata.create_all(engine)
    Session = sessionmaker(bind=engine)
    session = Session()
    yield session
    session.close()
    Base.metadata.drop_all(engine)

def test_user_repo_unique_constraint(setup_database):
    session = setup_database
    user_repo1 = UserRepo(
        user_id=1,
        psid=1,
        github_username="uniqueuser",
        repo_name="uniquerepo",
        github_url="http://github.com/uniqueuser/uniquerepo"
    )
    user_repo2 = UserRepo(
        user_id=1,
        psid=2,
        github_username="uniqueuser",
        repo_name="uniquerepo",
        github_url="http://github.com/uniqueuser/uniquerepo2"
    )
    session.add(user_repo1)
    session.commit()
    
    session.add(user_repo2)
    with pytest.raises(IntegrityError):
        session.commit()

---------------
TEST CASE 4 Retry 2 - Result - Failed
Test Error -
c:\ChenKhoon\JupyterNotebook\GenerateUnitTestCases\unit_test_env\Lib\site-packages\pytest_asyncio\plugin.py:217: PytestDeprecationWarning: The configuration option "asyncio_default_fixture_loop_scope" is unset.
The event loop scope for asynchronous fixtures will default to the fixture caching scope. Future versions of pytest-asyncio will default the loop scope for asynchronous fixtures to function scope. Set the default fixture loop scope explicitly in order to avoid unexpected behavior in the future. Valid fixture loop scopes are: "function", "class", "module", "package", "session"

  warnings.warn(PytestDeprecationWarning(_DEFAULT_FIXTURE_LOOP_SCOPE_UNSET))
E                                                                        [100%]
=================================== ERRORS ====================================
_____________ ERROR at setup of test_user_repo_unique_constraint ______________
unit_test_env\Lib\site-packages\sqlalchemy\sql\visitors.py:137: in _compiler_dispatch
    meth = getter(visitor)
E   AttributeError: 'SQLiteTypeCompiler' object has no attribute 'visit_JSONB'. Did you mean: 'visit_JSON'?

The above exception was the direct cause of the following exception:
unit_test_env\Lib\site-packages\sqlalchemy\sql\compiler.py:6716: in visit_create_table
    processed = self.process(
unit_test_env\Lib\site-packages\sqlalchemy\sql\compiler.py:932: in process
    return obj._compiler_dispatch(self, **kwargs)
unit_test_env\Lib\site-packages\sqlalchemy\sql\visitors.py:141: in _compiler_dispatch
    return meth(self, **kw)  # type: ignore  # noqa: E501
unit_test_env\Lib\site-packages\sqlalchemy\sql\compiler.py:6747: in visit_create_column
    text = self.get_column_specification(column, first_pk=first_pk)
unit_test_env\Lib\site-packages\sqlalchemy\dialects\sqlite\base.py:1598: in get_column_specification
    coltype = self.dialect.type_compiler_instance.process(
unit_test_env\Lib\site-packages\sqlalchemy\sql\compiler.py:977: in process
    return type_._compiler_dispatch(self, **kw)
unit_test_env\Lib\site-packages\sqlalchemy\sql\visitors.py:139: in _compiler_dispatch
    return visitor.visit_unsupported_compilation(self, err, **kw)  # type: ignore  # noqa: E501
unit_test_env\Lib\site-packages\sqlalchemy\sql\compiler.py:982: in visit_unsupported_compilation
    raise exc.UnsupportedCompilationError(self, element) from err
E   sqlalchemy.exc.UnsupportedCompilationError: Compiler <sqlalchemy.dialects.sqlite.base.SQLiteTypeCompiler object at 0x000001906782FCB0> can't render element of type JSONB (Background on this error at: https://sqlalche.me/e/20/l7de)

The above exception was the direct cause of the following exception:
temp\temp.py:41: in setup_database
    Base.metadata.create_all(engine)
unit_test_env\Lib\site-packages\sqlalchemy\sql\schema.py:5925: in create_all
    bind._run_ddl_visitor(
unit_test_env\Lib\site-packages\sqlalchemy\engine\base.py:3249: in _run_ddl_visitor
    conn._run_ddl_visitor(visitorcallable, element, **kwargs)
unit_test_env\Lib\site-packages\sqlalchemy\engine\base.py:2456: in _run_ddl_visitor
    visitorcallable(self.dialect, self, **kwargs).traverse_single(element)
unit_test_env\Lib\site-packages\sqlalchemy\sql\visitors.py:664: in traverse_single
    return meth(obj, **kw)
unit_test_env\Lib\site-packages\sqlalchemy\sql\ddl.py:981: in visit_metadata
    self.traverse_single(
unit_test_env\Lib\site-packages\sqlalchemy\sql\visitors.py:664: in traverse_single
    return meth(obj, **kw)
unit_test_env\Lib\site-packages\sqlalchemy\sql\ddl.py:1019: in visit_table
    )._invoke_with(self.connection)
unit_test_env\Lib\site-packages\sqlalchemy\sql\ddl.py:321: in _invoke_with
    return bind.execute(self)
unit_test_env\Lib\site-packages\sqlalchemy\engine\base.py:1416: in execute
    return meth(
unit_test_env\Lib\site-packages\sqlalchemy\sql\ddl.py:187: in _execute_on_connection
    return connection._execute_ddl(
unit_test_env\Lib\site-packages\sqlalchemy\engine\base.py:1524: in _execute_ddl
    compiled = ddl.compile(
unit_test_env\Lib\site-packages\sqlalchemy\sql\elements.py:308: in compile
    return self._compiler(dialect, **kw)
unit_test_env\Lib\site-packages\sqlalchemy\sql\ddl.py:76: in _compiler
    return dialect.ddl_compiler(dialect, self, **kw)
unit_test_env\Lib\site-packages\sqlalchemy\sql\compiler.py:886: in __init__
    self.string = self.process(self.statement, **compile_kwargs)
unit_test_env\Lib\site-packages\sqlalchemy\sql\compiler.py:932: in process
    return obj._compiler_dispatch(self, **kwargs)
unit_test_env\Lib\site-packages\sqlalchemy\sql\visitors.py:141: in _compiler_dispatch
    return meth(self, **kw)  # type: ignore  # noqa: E501
unit_test_env\Lib\site-packages\sqlalchemy\sql\compiler.py:6726: in visit_create_table
    raise exc.CompileError(
E   sqlalchemy.exc.CompileError: (in table 'projects', column 'problem_statement'): Compiler <sqlalchemy.dialects.sqlite.base.SQLiteTypeCompiler object at 0x000001906782FCB0> can't render element of type JSONB
============================== warnings summary ===============================
theory_evaluation\models.py:17
  C:\ChenKhoon\JupyterNotebook\GenerateUnitTestCases\theory_evaluation\models.py:17: MovedIn20Warning: The ``declarative_base()`` function is now available as sqlalchemy.orm.declarative_base(). (deprecated since: 2.0) (Background on SQLAlchemy 2.0 at: https://sqlalche.me/e/b8d9)
    Base = declarative_base()

-- Docs: https://docs.pytest.org/en/stable/how-to/capture-warnings.html
=========================== short test summary info ===========================
ERROR temp/temp.py::test_user_repo_unique_constraint - sqlalchemy.exc.Compile...
1 warning, 1 error in 1.28s

TEST CASE 5 Retry 0
---------------
from sqlalchemy.dialects.postgresql import JSONB, UUID
from sqlalchemy import (
    Column,
    Integer,
    String,
    TIMESTAMP,
    create_engine,
    Float,
    ForeignKey,
    Text,
    UniqueConstraint,
)
from sqlalchemy.ext.declarative import declarative_base
from sqlalchemy.sql import func
import uuid
from theory_evaluation.models import Base, ConsultantChat, CurrentUserTable, Curriculum, MentorChat, Projects, SprintIssues, TheoryEvalUserPerformance, UserInfo, UserRepo, UserScoreLog
import pytest

@pytest.fixture(scope="module")
def setup_database():
    engine = create_engine(DATABASE_URL)
    Base.metadata.create_all(engine)
    Session = sessionmaker(bind=engine)
    session = Session()
    yield session
    session.close()
    Base.metadata.drop_all(engine)

def test_curriculum_creation(setup_database):
    session = setup_database
    curriculum = Curriculum(
        question="What is Python?",
        marking_scheme="Correctness",
        model_answer="Python is a programming language."
    )
    session.add(curriculum)
    session.commit()

---------------
TEST CASE 5 Retry 0 - Result - Failed
Test Error -
c:\ChenKhoon\JupyterNotebook\GenerateUnitTestCases\unit_test_env\Lib\site-packages\pytest_asyncio\plugin.py:217: PytestDeprecationWarning: The configuration option "asyncio_default_fixture_loop_scope" is unset.
The event loop scope for asynchronous fixtures will default to the fixture caching scope. Future versions of pytest-asyncio will default the loop scope for asynchronous fixtures to function scope. Set the default fixture loop scope explicitly in order to avoid unexpected behavior in the future. Valid fixture loop scopes are: "function", "class", "module", "package", "session"

  warnings.warn(PytestDeprecationWarning(_DEFAULT_FIXTURE_LOOP_SCOPE_UNSET))
E                                                                        [100%]
=================================== ERRORS ====================================
_________________ ERROR at setup of test_curriculum_creation __________________
temp\temp.py:21: in setup_database
    engine = create_engine(DATABASE_URL)
E   NameError: name 'DATABASE_URL' is not defined
============================== warnings summary ===============================
theory_evaluation\models.py:17
  C:\ChenKhoon\JupyterNotebook\GenerateUnitTestCases\theory_evaluation\models.py:17: MovedIn20Warning: The ``declarative_base()`` function is now available as sqlalchemy.orm.declarative_base(). (deprecated since: 2.0) (Background on SQLAlchemy 2.0 at: https://sqlalche.me/e/b8d9)
    Base = declarative_base()

-- Docs: https://docs.pytest.org/en/stable/how-to/capture-warnings.html
=========================== short test summary info ===========================
ERROR temp/temp.py::test_curriculum_creation - NameError: name 'DATABASE_URL'...
1 warning, 1 error in 0.71s
TEST CASE 5 Retry 1
---------------
from sqlalchemy.dialects.postgresql import JSONB, UUID
from sqlalchemy import (
    Column,
    Integer,
    String,
    TIMESTAMP,
    create_engine,
    Float,
    ForeignKey,
    Text,
    UniqueConstraint,
)
from sqlalchemy.ext.declarative import declarative_base
from sqlalchemy.sql import func
import uuid
from theory_evaluation.models import Base, ConsultantChat, CurrentUserTable, Curriculum, MentorChat, Projects, SprintIssues, TheoryEvalUserPerformance, UserInfo, UserRepo, UserScoreLog
import pytest

@pytest.fixture(scope="module")
def setup_database():
    engine = create_engine(DATABASE_URL)
    Base.metadata.create_all(engine)
    Session = sessionmaker(bind=engine)
    session = Session()
    yield session
    session.close()
    Base.metadata.drop_all(engine)

import os
from sqlalchemy import create_engine
from sqlalchemy.orm import sessionmaker
from dotenv import load_dotenv
import pytest

load_dotenv()

DATABASE_URL = os.getenv("DATABASE_URL")

engine = create_engine(DATABASE_URL)
Session = sessionmaker(bind=engine)

@pytest.fixture
def setup_database():
    session = Session()
    yield session
    session.rollback()
    session.close()

def test_curriculum_creation(setup_database):
    session = setup_database
    curriculum = Curriculum(
        question="What is Python?",
        marking_scheme="Correctness",
        model_answer="Python is a programming language."
    )
    session.add(curriculum)
    session.commit()
    retrieved_curriculum = session.query(Curriculum).filter_by(question="What is Python?").first()
    assert retrieved_curriculum is not None
    assert retrieved_curriculum.marking_scheme == "Correctness"
    assert retrieved_curriculum.model_answer == "Python is a programming language."

---------------
TEST CASE 5 Retry 1 - Result - Failed
Test Error -
c:\ChenKhoon\JupyterNotebook\GenerateUnitTestCases\unit_test_env\Lib\site-packages\pytest_asyncio\plugin.py:217: PytestDeprecationWarning: The configuration option "asyncio_default_fixture_loop_scope" is unset.
The event loop scope for asynchronous fixtures will default to the fixture caching scope. Future versions of pytest-asyncio will default the loop scope for asynchronous fixtures to function scope. Set the default fixture loop scope explicitly in order to avoid unexpected behavior in the future. Valid fixture loop scopes are: "function", "class", "module", "package", "session"

  warnings.warn(PytestDeprecationWarning(_DEFAULT_FIXTURE_LOOP_SCOPE_UNSET))

=================================== ERRORS ====================================
________________________ ERROR collecting temp/temp.py ________________________
temp\temp.py:39: in <module>
    engine = create_engine(DATABASE_URL)
<string>:2: in create_engine
    ???
unit_test_env\Lib\site-packages\sqlalchemy\util\deprecations.py:281: in warned
    return fn(*args, **kwargs)  # type: ignore[no-any-return]
unit_test_env\Lib\site-packages\sqlalchemy\engine\create.py:549: in create_engine
    u = _url.make_url(url)
unit_test_env\Lib\site-packages\sqlalchemy\engine\url.py:860: in make_url
    raise exc.ArgumentError(
E   sqlalchemy.exc.ArgumentError: Expected string or URL object, got None
============================== warnings summary ===============================
theory_evaluation\models.py:17
  C:\ChenKhoon\JupyterNotebook\GenerateUnitTestCases\theory_evaluation\models.py:17: MovedIn20Warning: The ``declarative_base()`` function is now available as sqlalchemy.orm.declarative_base(). (deprecated since: 2.0) (Background on SQLAlchemy 2.0 at: https://sqlalche.me/e/b8d9)
    Base = declarative_base()

-- Docs: https://docs.pytest.org/en/stable/how-to/capture-warnings.html
=========================== short test summary info ===========================
ERROR temp/temp.py - sqlalchemy.exc.ArgumentError: Expected string or URL obj...
!!!!!!!!!!!!!!!!!!! Interrupted: 1 error during collection !!!!!!!!!!!!!!!!!!!!
1 warning, 1 error in 0.98s
TEST CASE 5 Retry 2
---------------
from sqlalchemy.dialects.postgresql import JSONB, UUID
from sqlalchemy import (
    Column,
    Integer,
    String,
    TIMESTAMP,
    create_engine,
    Float,
    ForeignKey,
    Text,
    UniqueConstraint,
)
from sqlalchemy.ext.declarative import declarative_base
from sqlalchemy.sql import func
import uuid
from theory_evaluation.models import Base, ConsultantChat, CurrentUserTable, Curriculum, MentorChat, Projects, SprintIssues, TheoryEvalUserPerformance, UserInfo, UserRepo, UserScoreLog
import pytest

@pytest.fixture(scope="module")
def setup_database():
    engine = create_engine(DATABASE_URL)
    Base.metadata.create_all(engine)
    Session = sessionmaker(bind=engine)
    session = Session()
    yield session
    session.close()
    Base.metadata.drop_all(engine)

import os
from sqlalchemy import create_engine
from sqlalchemy.orm import sessionmaker
from dotenv import load_dotenv
import pytest

load_dotenv()

DATABASE_URL = os.getenv("DATABASE_URL")

if not DATABASE_URL:
    raise ValueError("DATABASE_URL environment variable is not set")

engine = create_engine(DATABASE_URL)
Session = sessionmaker(bind=engine)

@pytest.fixture
def setup_database():
    session = Session()
    yield session
    session.rollback()
    session.close()

def test_curriculum_creation(setup_database):
    session = setup_database
    curriculum = Curriculum(
        question="What is Python?",
        marking_scheme="Correctness",
        model_answer="Python is a programming language."
    )
    session.add(curriculum)
    session.commit()
    retrieved_curriculum = session.query(Curriculum).filter_by(question="What is Python?").first()
    assert retrieved_curriculum is not None
    assert retrieved_curriculum.marking_scheme == "Correctness"
    assert retrieved_curriculum.model_answer == "Python is a programming language."

---------------
TEST CASE 5 Retry 2 - Result - Failed
Test Error -
c:\ChenKhoon\JupyterNotebook\GenerateUnitTestCases\unit_test_env\Lib\site-packages\pytest_asyncio\plugin.py:217: PytestDeprecationWarning: The configuration option "asyncio_default_fixture_loop_scope" is unset.
The event loop scope for asynchronous fixtures will default to the fixture caching scope. Future versions of pytest-asyncio will default the loop scope for asynchronous fixtures to function scope. Set the default fixture loop scope explicitly in order to avoid unexpected behavior in the future. Valid fixture loop scopes are: "function", "class", "module", "package", "session"

  warnings.warn(PytestDeprecationWarning(_DEFAULT_FIXTURE_LOOP_SCOPE_UNSET))

=================================== ERRORS ====================================
________________________ ERROR collecting temp/temp.py ________________________
temp\temp.py:40: in <module>
    raise ValueError("DATABASE_URL environment variable is not set")
E   ValueError: DATABASE_URL environment variable is not set
============================== warnings summary ===============================
theory_evaluation\models.py:17
  C:\ChenKhoon\JupyterNotebook\GenerateUnitTestCases\theory_evaluation\models.py:17: MovedIn20Warning: The ``declarative_base()`` function is now available as sqlalchemy.orm.declarative_base(). (deprecated since: 2.0) (Background on SQLAlchemy 2.0 at: https://sqlalche.me/e/b8d9)
    Base = declarative_base()

-- Docs: https://docs.pytest.org/en/stable/how-to/capture-warnings.html
=========================== short test summary info ===========================
ERROR temp/temp.py - ValueError: DATABASE_URL environment variable is not set
!!!!!!!!!!!!!!!!!!! Interrupted: 1 error during collection !!!!!!!!!!!!!!!!!!!!
1 warning, 1 error in 1.02s

TEST CASE 6 Retry 0
---------------
from sqlalchemy.dialects.postgresql import JSONB, UUID
from sqlalchemy import (
    Column,
    Integer,
    String,
    TIMESTAMP,
    create_engine,
    Float,
    ForeignKey,
    Text,
    UniqueConstraint,
)
from sqlalchemy.ext.declarative import declarative_base
from sqlalchemy.sql import func
import uuid
from theory_evaluation.models import Base, ConsultantChat, CurrentUserTable, Curriculum, MentorChat, Projects, SprintIssues, TheoryEvalUserPerformance, UserInfo, UserRepo, UserScoreLog
import pytest

@pytest.fixture(scope="module")
def setup_database():
    engine = create_engine(DATABASE_URL)
    Base.metadata.create_all(engine)
    Session = sessionmaker(bind=engine)
    session = Session()
    yield session
    session.close()
    Base.metadata.drop_all(engine)

def test_theory_eval_user_performance_creation(setup_database):
    session = setup_database
    performance = TheoryEvalUserPerformance(
        email="john.doe@example.com",
        question_id=uuid.uuid4(),
        user_response="Python is a programming language.",
        llm_evaluation="Correct",
        llm_score=95.0,
        user_grade="A",
        user_attempts=1,
        llm_evaluation_status=1
    )
    session.add(performance)
    session.commit()

---------------
TEST CASE 6 Retry 0 - Result - Failed
Test Error -
c:\ChenKhoon\JupyterNotebook\GenerateUnitTestCases\unit_test_env\Lib\site-packages\pytest_asyncio\plugin.py:217: PytestDeprecationWarning: The configuration option "asyncio_default_fixture_loop_scope" is unset.
The event loop scope for asynchronous fixtures will default to the fixture caching scope. Future versions of pytest-asyncio will default the loop scope for asynchronous fixtures to function scope. Set the default fixture loop scope explicitly in order to avoid unexpected behavior in the future. Valid fixture loop scopes are: "function", "class", "module", "package", "session"

  warnings.warn(PytestDeprecationWarning(_DEFAULT_FIXTURE_LOOP_SCOPE_UNSET))
E                                                                        [100%]
=================================== ERRORS ====================================
________ ERROR at setup of test_theory_eval_user_performance_creation _________
temp\temp.py:21: in setup_database
    engine = create_engine(DATABASE_URL)
E   NameError: name 'DATABASE_URL' is not defined
============================== warnings summary ===============================
theory_evaluation\models.py:17
  C:\ChenKhoon\JupyterNotebook\GenerateUnitTestCases\theory_evaluation\models.py:17: MovedIn20Warning: The ``declarative_base()`` function is now available as sqlalchemy.orm.declarative_base(). (deprecated since: 2.0) (Background on SQLAlchemy 2.0 at: https://sqlalche.me/e/b8d9)
    Base = declarative_base()

-- Docs: https://docs.pytest.org/en/stable/how-to/capture-warnings.html
=========================== short test summary info ===========================
ERROR temp/temp.py::test_theory_eval_user_performance_creation - NameError: n...
1 warning, 1 error in 0.80s
TEST CASE 6 Retry 1
---------------
from sqlalchemy.dialects.postgresql import JSONB, UUID
from sqlalchemy import (
    Column,
    Integer,
    String,
    TIMESTAMP,
    create_engine,
    Float,
    ForeignKey,
    Text,
    UniqueConstraint,
)
from sqlalchemy.ext.declarative import declarative_base
from sqlalchemy.sql import func
import uuid
from theory_evaluation.models import Base, ConsultantChat, CurrentUserTable, Curriculum, MentorChat, Projects, SprintIssues, TheoryEvalUserPerformance, UserInfo, UserRepo, UserScoreLog
import pytest

@pytest.fixture(scope="module")
def setup_database():
    engine = create_engine(DATABASE_URL)
    Base.metadata.create_all(engine)
    Session = sessionmaker(bind=engine)
    session = Session()
    yield session
    session.close()
    Base.metadata.drop_all(engine)

import os
import uuid
import pytest
from sqlalchemy import create_engine
from sqlalchemy.orm import sessionmaker
from sqlalchemy.exc import IntegrityError
from dotenv import load_dotenv
from models import TheoryEvalUserPerformance, Base

load_dotenv()

DATABASE_URL = os.getenv("DATABASE_URL")

@pytest.fixture(scope="function")
def setup_database():
    if not DATABASE_URL:
        pytest.fail("DATABASE_URL is not defined in the environment variables.")
    engine = create_engine(DATABASE_URL)
    Base.metadata.create_all(engine)
    Session = sessionmaker(bind=engine)
    session = Session()
    yield session
    session.close()

def test_theory_eval_user_performance_creation(setup_database):
    session = setup_database
    performance = TheoryEvalUserPerformance(
        email="john.doe@example.com",
        question_id=uuid.uuid4(),
        user_response="Python is a programming language.",
        llm_evaluation="Correct",
        llm_score=95.0,
        user_grade="A",
        user_attempts=1,
        llm_evaluation_status=1
    )
    session.add(performance)
    try:
        session.commit()
    except IntegrityError:
        session.rollback()
        pytest.fail("IntegrityError: Possible foreign key constraint violation.")
    assert performance.id is not None

---------------
TEST CASE 6 Retry 1 - Result - Failed
Test Error -
c:\ChenKhoon\JupyterNotebook\GenerateUnitTestCases\unit_test_env\Lib\site-packages\pytest_asyncio\plugin.py:217: PytestDeprecationWarning: The configuration option "asyncio_default_fixture_loop_scope" is unset.
The event loop scope for asynchronous fixtures will default to the fixture caching scope. Future versions of pytest-asyncio will default the loop scope for asynchronous fixtures to function scope. Set the default fixture loop scope explicitly in order to avoid unexpected behavior in the future. Valid fixture loop scopes are: "function", "class", "module", "package", "session"

  warnings.warn(PytestDeprecationWarning(_DEFAULT_FIXTURE_LOOP_SCOPE_UNSET))

=================================== ERRORS ====================================
________________________ ERROR collecting temp/temp.py ________________________
ImportError while importing test module 'C:\ChenKhoon\JupyterNotebook\GenerateUnitTestCases\temp\temp.py'.
Hint: make sure your test modules/packages have valid Python names.
Traceback:
C:\Users\User\AppData\Local\Programs\Python\Python313\Lib\importlib\__init__.py:88: in import_module
    return _bootstrap._gcd_import(name[level:], package, level)
temp\temp.py:36: in <module>
    from models import TheoryEvalUserPerformance, Base
E   ModuleNotFoundError: No module named 'models'
============================== warnings summary ===============================
theory_evaluation\models.py:17
  C:\ChenKhoon\JupyterNotebook\GenerateUnitTestCases\theory_evaluation\models.py:17: MovedIn20Warning: The ``declarative_base()`` function is now available as sqlalchemy.orm.declarative_base(). (deprecated since: 2.0) (Background on SQLAlchemy 2.0 at: https://sqlalche.me/e/b8d9)
    Base = declarative_base()

-- Docs: https://docs.pytest.org/en/stable/how-to/capture-warnings.html
=========================== short test summary info ===========================
ERROR temp/temp.py
!!!!!!!!!!!!!!!!!!! Interrupted: 1 error during collection !!!!!!!!!!!!!!!!!!!!
1 warning, 1 error in 0.92s
TEST CASE 6 Retry 2
---------------
from sqlalchemy.dialects.postgresql import JSONB, UUID
from sqlalchemy import (
    Column,
    Integer,
    String,
    TIMESTAMP,
    create_engine,
    Float,
    ForeignKey,
    Text,
    UniqueConstraint,
)
from sqlalchemy.ext.declarative import declarative_base
from sqlalchemy.sql import func
import uuid
from theory_evaluation.models import Base, ConsultantChat, CurrentUserTable, Curriculum, MentorChat, Projects, SprintIssues, TheoryEvalUserPerformance, UserInfo, UserRepo, UserScoreLog
import pytest

@pytest.fixture(scope="module")
def setup_database():
    engine = create_engine(DATABASE_URL)
    Base.metadata.create_all(engine)
    Session = sessionmaker(bind=engine)
    session = Session()
    yield session
    session.close()
    Base.metadata.drop_all(engine)

import os
import uuid
import pytest
from sqlalchemy import create_engine
from sqlalchemy.orm import sessionmaker
from sqlalchemy.exc import IntegrityError
from dotenv import load_dotenv
from your_module_name import TheoryEvalUserPerformance, Base  # Replace 'your_module_name' with the actual module name

load_dotenv()

DATABASE_URL = os.getenv("DATABASE_URL")

@pytest.fixture(scope="function")
def setup_database():
    if not DATABASE_URL:
        pytest.fail("DATABASE_URL is not defined in the environment variables.")
    engine = create_engine(DATABASE_URL)
    Base.metadata.create_all(engine)
    Session = sessionmaker(bind=engine)
    session = Session()
    yield session
    session.close()

def test_theory_eval_user_performance_creation(setup_database):
    session = setup_database
    performance = TheoryEvalUserPerformance(
        email="john.doe@example.com",
        question_id=uuid.uuid4(),
        user_response="Python is a programming language.",
        llm_evaluation="Correct",
        llm_score=95.0,
        user_grade="A",
        user_attempts=1,
        llm_evaluation_status=1
    )
    session.add(performance)
    try:
        session.commit()
    except IntegrityError:
        session.rollback()
        pytest.fail("IntegrityError: Possible foreign key constraint violation.")
    assert performance.id is not None

---------------
TEST CASE 6 Retry 2 - Result - Failed
Test Error -
c:\ChenKhoon\JupyterNotebook\GenerateUnitTestCases\unit_test_env\Lib\site-packages\pytest_asyncio\plugin.py:217: PytestDeprecationWarning: The configuration option "asyncio_default_fixture_loop_scope" is unset.
The event loop scope for asynchronous fixtures will default to the fixture caching scope. Future versions of pytest-asyncio will default the loop scope for asynchronous fixtures to function scope. Set the default fixture loop scope explicitly in order to avoid unexpected behavior in the future. Valid fixture loop scopes are: "function", "class", "module", "package", "session"

  warnings.warn(PytestDeprecationWarning(_DEFAULT_FIXTURE_LOOP_SCOPE_UNSET))

=================================== ERRORS ====================================
________________________ ERROR collecting temp/temp.py ________________________
ImportError while importing test module 'C:\ChenKhoon\JupyterNotebook\GenerateUnitTestCases\temp\temp.py'.
Hint: make sure your test modules/packages have valid Python names.
Traceback:
C:\Users\User\AppData\Local\Programs\Python\Python313\Lib\importlib\__init__.py:88: in import_module
    return _bootstrap._gcd_import(name[level:], package, level)
temp\temp.py:36: in <module>
    from your_module_name import TheoryEvalUserPerformance, Base  # Replace 'your_module_name' with the actual module name
E   ModuleNotFoundError: No module named 'your_module_name'
============================== warnings summary ===============================
theory_evaluation\models.py:17
  C:\ChenKhoon\JupyterNotebook\GenerateUnitTestCases\theory_evaluation\models.py:17: MovedIn20Warning: The ``declarative_base()`` function is now available as sqlalchemy.orm.declarative_base(). (deprecated since: 2.0) (Background on SQLAlchemy 2.0 at: https://sqlalche.me/e/b8d9)
    Base = declarative_base()

-- Docs: https://docs.pytest.org/en/stable/how-to/capture-warnings.html
=========================== short test summary info ===========================
ERROR temp/temp.py
!!!!!!!!!!!!!!!!!!! Interrupted: 1 error during collection !!!!!!!!!!!!!!!!!!!!
1 warning, 1 error in 1.12s
